Workbook

Sheet REPORTE DIARIO
B3: COBRANZA GENERAL SAMANTHA
B4: Segmento | C4: Cuentas | D4: Recuperación
B5: Extrajudicial - 0 a 28 semanas de atraso | C5: 6150 | D5: 87970.67
B6: Extrajudicial - 29 a 39 semanas de atraso | C6: 5799 | D6: 50902
B7: Extrajudicial - 40 a 55 semanas de atraso | C7: 8698 | D7: 29053
B8: JUDICIAL | C8: 21 | D8: 0
B9: Mas 55 semanas de atraso | C9: 21160 | D9: 83195.88
B10: Total general | C10: =SUM(C5:C9) -> 41828 | D10: =SUM(D5:D9) -> 251121.55
B12: COBRANZA GENERAL SAMANTHA 2
B13: Segmento | C13: Cuentas | D13: Recuperación
B14: Extrajudicial - 0 a 28 semanas de atraso | C14: 2514 | D14: 39817.17
B15: Extrajudicial - 29 a 39 semanas de atraso | C15: 1445 | D15: 1626
B16: Extrajudicial - 40 a 55 semanas de atraso | C16: 3310 | D16: 20380
B17: JUDICIAL | C17: 2 | D17: 0
B18: Mas 55 semanas de atraso | C18: 21194 | D18: 45963.14
B19: Total general | C19: =SUM(C14:C18) -> 28465 | D19: =SUM(D14:D18) -> 107786.31
B21: COBRANZA GENERAL EDITH
B22: Segmento | C22: Cuentas | D22: Recuperación
B23: Extrajudicial - 0 a 28 semanas de atraso | C23: 1762 | D23: 26610.98
B24: Extrajudicial - 29 a 39 semanas de atraso | C24: 2126 | D24: 28866.02
B25: Extrajudicial - 40 a 55 semanas de atraso | C25: 872 | D25: 3660
B26: Mas 55 semanas de atraso | C26: 8901 | D26: 2683
B27: Total general | C27: =SUM(C23:C26) -> 13661 | D27: =SUM(D23:D26) -> 61820
B29: COBRANZA GENERAL SOFIA
B30: Segmento | C30: Cuentas | D30: Recuperación
B31: Extrajudicial - 0 a 28 semanas de atraso | C31: 1366 | D31: 10165.19
B32: Extrajudicial - 29 a 39 semanas de atraso | C32: 1930 | D32: 13738.92
B33: Extrajudicial - 40 a 55 semanas de atraso | C33: 2781 | D33: 198
B34: Mas 55 semanas de atraso | C34: 4264 | D34: 971
B35: Total general | C35: =SUM(C31:C34) -> 10341 | D35: =SUM(D31:D34) -> 25073.11
B37: COBRANZA GENERAL FERNANDO
B38: Segmento | C38: Cuentas | D38: Recuperación
B39: Extrajudicial - 0 a 28 semanas de atraso | C39: 2663 | D39: 9735
B40: Total general | C40: =SUM(C39:C39) -> 2663 | D40: =SUM(D39:D39) -> 9735
B42: COBRANZA GENERAL FEDERICO
B43: Segmento | C43: Cuentas | D43: Recuperación
B44: Extrajudicial - 0 a 28 semanas de atraso | C44: 39 | D44: 0
B45: Extrajudicial - 29 a 39 semanas de atraso | C45: 222 | D45: 10
B46: Extrajudicial - 40 a 55 semanas de atraso | C46: 213 | D46: 546
B47: Mas 55 semanas de atraso | C47: 1896 | D47: 0
...

Sheet DATA

Sheet EPR 11 ABR
B2: REPORTE CONSOLIDADO POR SEGMENTOS
B3: COBRANZA 11 ABRIL
B5: COORDINADOR | C5: SEGMENTO | D5: CUENTAS | E5: COBRANZA REAL | F5: CUOTA IDEAL | G5: VARIACION | H5: % VAR | I5: EPR | J5: EPR IDEAL | K5: VAR EPR
B6: Samatha y Zareth | C6: Extrajudicial - 0 a 28 semanas de atraso | D6: =SUMIF('REPORTE DIARIO'!B:B,'EPR 11 ABR'!C6, 'REPORTE DIARIO'!C:C) -> 14495 | E6: =SUMIF('REPORTE DIARIO'!B:B,'EPR 11 ABR'!C6, 'REPORTE DIARIO'!D:D) -> 174299.01 | F6: =J6*D6 -> 414142.86 | G6: =+E6-F6 -> -239843.85 | H6: =ABS(G6/F6) -> 0.57913313 | I6: =E6/D6 -> 12.024768 | J6: =200/7 -> 28.571429 | K6: =+I6-J6 -> -16.546661
B7: Gabriel | C7: Extrajudicial - 29 a 39 semanas de atraso | D7: =SUMIF('REPORTE DIARIO'!B:B,'EPR 11 ABR'!C7, 'REPORTE DIARIO'!C:C) -> 11522 | E7: =SUMIF('REPORTE DIARIO'!B:B,'EPR 11 ABR'!C7, 'REPORTE DIARIO'!D:D) -> 95142.94 | F7: =J7*D7 -> 181060 | G7: =+E7-F7 -> -85917.06 | H7: =ABS(G7/F7) -> 0.47452259 | I7: =E7/D7 -> 8.2575022 | J7: =110/7 -> 15.714286 | K7: =+I7-J7 -> -7.4567835
B8: Gabriel | C8: Extrajudicial - 40 a 55 semanas de atraso | D8: =SUMIF('REPORTE DIARIO'!B:B,'EPR 11 ABR'!C8, 'REPORTE DIARIO'!C:C) -> 15874 | E8: =SUMIF('REPORTE DIARIO'!B:B,'EPR 11 ABR'!C8, 'REPORTE DIARIO'!D:D) -> 53837 | F8: =J8*D8 -> 102047.14 | G8: =+E8-F8 -> -48210.143 | H8: =ABS(G8/F8) -> 0.47243011 | I8: =E8/D8 -> 3.3915207 | J8: =45/7 -> 6.4285714 | K8: =+I8-J8 -> -3.0370507
B9: Fernando | C9: Mas 55 semanas de atraso | D9: =SUMIF('REPORTE DIARIO'!B:B,'EPR 11 ABR'!C9, 'REPORTE DIARIO'!C:C) -> 57417 | E9: =SUMIF('REPORTE DIARIO'!B:B,'EPR 11 ABR'!C9, 'REPORTE DIARIO'!D:D) -> 132813.02 | F9: =J9*D9 -> 123036.43 | G9: =+E9-F9 -> 9776.5914 | H9: =ABS(G9/F9) -> 0.079460949 | I9: =E9/D9 -> 2.3131306 | J9: =15/7 -> 2.1428571 | K9: =+I9-J9 -> 0.17027346
C10: TOTAL | D10: =SUM(D6:D9) -> 99308 | E10: =SUM(E6:E9) -> 456091.97 | F10: =SUM(F6:F9) -> 820286.43 | G10: =+E10-F10 -> -364194.46 | H10: =ABS(G10/F10) -> 0.4439845 | I10: =E10/D10 -> 4.5927012 | J10: =F10/D10 -> 8.2600236 | K10: =I10-J10 -> -3.6673225
B12: Nota:
B13: El saldo consolidado incluye los siguientes despachos
B14: Samantha, Samantha 2, Sofia, Edith, Olguin, Fernando y Federico
