Workbook

Sheet REPORTE DIARIO
B3: COBRANZA GENERAL SAMANTHA
B4: Segmento | C4: Cuentas | D4: Recuperación
B5: Extrajudicial - 0 a 28 semanas de atraso | C5: 5881 | D5: 714335.42
B6: Extrajudicial - 29 a 39 semanas de atraso | C6: 6717 | D6: 623937.35
B7: Extrajudicial - 40 a 55 semanas de atraso | C7: 9854 | D7: 302512.72
B8: JUDICIAL | C8: 21 | D8: 1150
B9: Mas 55 semanas de atraso | C9: 28872 | D9: 598105.13
B10: Total general | C10: =SUM(C5:C9) -> 51345 | D10: =SUM(D5:D9) -> 2240040.6
B12: COBRANZA GENERAL EDITH
B13: Segmento | C13: Cuentas | D13: Recuperación
B14: Extrajudicial - 0 a 28 semanas de atraso | C14: 1668 | D14: 256804.7
B15: Extrajudicial - 29 a 39 semanas de atraso | C15: 1503 | D15: 262607.22
B16: Extrajudicial - 40 a 55 semanas de atraso | C16: 847 | D16: 26274
B17: Mas 55 semanas de atraso | C17: 8351 | D17: 93165.45
B18: Total general | C18: =SUM(C14:C17) -> 12369 | D18: =SUM(D14:D17) -> 638851.37
B20: COBRANZA GENERAL SAMANTHA 2
B21: Segmento | C21: Cuentas | D21: Recuperación
B22: Extrajudicial - 0 a 28 semanas de atraso | C22: 2509 | D22: 270115.66
B23: Extrajudicial - 29 a 39 semanas de atraso | C23: 1409 | D23: 79736.57
B24: Extrajudicial - 40 a 55 semanas de atraso | C24: 3380 | D24: 55763.63
B25: JUDICIAL | C25: 2 | D25: 0
B26: Mas 55 semanas de atraso | C26: 21141 | D26: 219608.58
B27: Total general | C27: =SUM(C22:C26) -> 28441 | D27: =SUM(D22:D26) -> 625224.44
B29: COBRANZA GENERAL SOFIA
B30: Segmento | C30: Cuentas | D30: Recuperación
B31: Extrajudicial - 0 a 28 semanas de atraso | C31: 1397 | D31: 263624.53
B32: Extrajudicial - 29 a 39 semanas de atraso | C32: 1293 | D32: 134703.07
B33: Extrajudicial - 40 a 55 semanas de atraso | C33: 2932 | D33: 40301
B34: Mas 55 semanas de atraso | C34: 1828 | D34: 22966
B35: Total general | C35: =SUM(C31:C34) -> 7450 | D35: =SUM(D31:D34) -> 461594.6
B37: COBRANZA GENERAL FERNANDO
B38: Segmento | C38: Cuentas | D38: Recuperación
B39: Extrajudicial - 0 a 28 semanas de atraso | C39: 2735 | D39: 76820
B40: Total general | C40: =SUM(C39:C39) -> 2735 | D40: =SUM(D39:D39) -> 76820
B42: COBRANZA GENERAL FEDERICO
B43: Segmento | C43: Cuentas | D43: Recuperación
B44: Extrajudicial - 0 a 28 semanas de atraso | C44: 35 | D44: 2019
B45: Extrajudicial - 29 a 39 semanas de atraso | C45: 139 | D45: 400
B46: Extrajudicial - 40 a 55 semanas de atraso | C46: 153 | D46: 0
B47: Mas 55 semanas de atraso | C47: 1691 | D47: 14973
...

Sheet DATA

Sheet EPR 6 ABR
B2: REPORTE CONSOLIDADO POR SEGMENTOS
B3: SALDO ACUMULADO SEMANA 14
B5: COORDINADOR | C5: SEGMENTO | D5: CUENTAS | E5: COBRANZA REAL | F5: CUOTA IDEAL | G5: VARIACION | H5: % VAR | I5: EPR | J5: EPR IDEAL | K5: VAR EPR
B6: Samatha y Zareth | C6: Extrajudicial - 0 a 28 semanas de atraso | D6: =SUMIF('REPORTE DIARIO'!B:B,'EPR 6 ABR'!C6, 'REPORTE DIARIO'!C:C) -> 14293 | E6: =SUMIF('REPORTE DIARIO'!B:B,'EPR 6 ABR'!C6, 'REPORTE DIARIO'!D:D) -> 1586689.3 | F6: =J6*D6 -> 2858600 | G6: =+E6-F6 -> -1271910.7 | H6: =ABS(G6/F6) -> 0.44494182 | I6: =E6/D6 -> 111.01164 | J6: =(200/7)*7 -> 200 | K6: =+I6-J6 -> -88.988364
B7: Gabriel | C7: Extrajudicial - 29 a 39 semanas de atraso | D7: =SUMIF('REPORTE DIARIO'!B:B,'EPR 6 ABR'!C7, 'REPORTE DIARIO'!C:C) -> 11123 | E7: =SUMIF('REPORTE DIARIO'!B:B,'EPR 6 ABR'!C7, 'REPORTE DIARIO'!D:D) -> 1101384.2 | F7: =J7*D7 -> 1223530 | G7: =+E7-F7 -> -122145.79 | H7: =ABS(G7/F7) -> 0.099830646 | I7: =E7/D7 -> 99.018629 | J7: =(110/7)*7 -> 110 | K7: =+I7-J7 -> -10.981371
B8: Gabriel | C8: Extrajudicial - 40 a 55 semanas de atraso | D8: =SUMIF('REPORTE DIARIO'!B:B,'EPR 6 ABR'!C8, 'REPORTE DIARIO'!C:C) -> 17179 | E8: =SUMIF('REPORTE DIARIO'!B:B,'EPR 6 ABR'!C8, 'REPORTE DIARIO'!D:D) -> 424851.35 | F8: =J8*D8 -> 773055 | G8: =+E8-F8 -> -348203.65 | H8: =ABS(G8/F8) -> 0.45042545 | I8: =E8/D8 -> 24.730855 | J8: =(45/7)*7 -> 45 | K8: =+I8-J8 -> -20.269145
B9: Fernando | C9: Mas 55 semanas de atraso | D9: =SUMIF('REPORTE DIARIO'!B:B,'EPR 6 ABR'!C9, 'REPORTE DIARIO'!C:C) -> 61892 | E9: =SUMIF('REPORTE DIARIO'!B:B,'EPR 6 ABR'!C9, 'REPORTE DIARIO'!D:D) -> 948818.16 | F9: =J9*D9 -> 928380 | G9: =+E9-F9 -> 20438.16 | H9: =ABS(G9/F9) -> 0.022014865 | I9: =E9/D9 -> 15.330223 | J9: =(15/7)*7 -> 15 | K9: =+I9-J9 -> 0.33022297
C10: TOTAL | D10: =SUM(D6:D9) -> 104487 | E10: =SUM(E6:E9) -> 4061743 | F10: =SUM(F6:F9) -> 5783565 | G10: =+E10-F10 -> -1721822 | H10: =ABS(G10/F10) -> 0.29770945 | I10: =E10/D10 -> 38.87319 | J10: =F10/D10 -> 55.352006 | K10: =I10-J10 -> -16.478815
B12: Nota:
B13: El saldo consolidado incluye los siguientes despachos
B14: Samantha, Samantha 2, Sofia, Edith, Olguin, Fernando y Federico
