Workbook

Sheet REPORTE DIARIO
B3: COBRANZA GENERAL SAMANTHA
B4: Segmento | C4: Cuentas | D4: Recuperación
B5: Extrajudicial - 0 a 28 semanas de atraso | C5: 4239 | D5: 402630.99
B6: Extrajudicial - 29 a 39 semanas de atraso | C6: 4553 | D6: 268648.41
B7: Extrajudicial - 40 a 55 semanas de atraso | C7: 6249 | D7: 194581.33
B8: JUDICIAL | C8: 10 | D8: 0
B9: Mas 55 semanas de atraso | C9: 13424 | D9: 330368.97
B10: Total general | C10: =SUM(C5:C9) -> 28475 | D10: =SUM(D5:D9) -> 1196229.7
B12: COBRANZA GENERAL SAMANTHA 2
B13: Segmento | C13: Cuentas | D13: Recuperación
B14: Extrajudicial - 0 a 28 semanas de atraso | C14: 1981 | D14: 203457.24
B15: Extrajudicial - 29 a 39 semanas de atraso | C15: 1735 | D15: 175191.8
B16: Extrajudicial - 40 a 55 semanas de atraso | C16: 3083 | D16: 37418.55
B17: JUDICIAL | C17: 2 | D17: 0
B18: Mas 55 semanas de atraso | C18: 21626 | D18: 190089.57
B19: Total general | C19: =SUM(C14:C18) -> 28427 | D19: =SUM(D14:D18) -> 606157.16
B21: COBRANZA GENERAL EDITH
B22: Segmento | C22: Cuentas | D22: Recuperación
B23: Extrajudicial - 0 a 28 semanas de atraso | C23: 3867 | D23: 308765.85
B24: Extrajudicial - 29 a 39 semanas de atraso | C24: 2266 | D24: 131636.84
B25: Extrajudicial - 40 a 55 semanas de atraso | C25: 1874 | D25: 33099.38
B26: Mas 55 semanas de atraso | C26: 9601 | D26: 29067.04
B27: Total general | C27: =SUM(C23:C26) -> 17608 | D27: =SUM(D23:D26) -> 502569.11
B29: COBRANZA GENERAL SOFIA
B30: Segmento | C30: Cuentas | D30: Recuperación
B31: Extrajudicial - 0 a 28 semanas de atraso | C31: 322 | D31: 75049.99
B32: Extrajudicial - 29 a 39 semanas de atraso | C32: 1305 | D32: 65809.38
B33: Extrajudicial - 40 a 55 semanas de atraso | C33: 2374 | D33: 12422.15
B34: Mas 55 semanas de atraso | C34: 4259 | D34: 30001
B35: Total general | C35: =SUM(C31:C34) -> 8260 | D35: =SUM(D31:D34) -> 183282.52
B37: COBRANZA GENERAL FERNANDO
B38: Segmento | C38: Cuentas | D38: Recuperación
B39: Extrajudicial - 0 a 28 semanas de atraso | C39: 2060 | D39: 53045
B40: Total general | C40: =SUM(C39:C39) -> 2060 | D40: =SUM(D39:D39) -> 53045
B42: COBRANZA GENERAL FEDERICO
B43: Segmento | C43: Cuentas | D43: Recuperación
B44: Extrajudicial - 0 a 28 semanas de atraso | C44: 37 | D44: 2323.72
B45: Extrajudicial - 29 a 39 semanas de atraso | C45: 481 | D45: 3823
B46: Extrajudicial - 40 a 55 semanas de atraso | C46: 340 | D46: 1920
B47: Mas 55 semanas de atraso | C47: 1990 | D47: 12113
...

Sheet DATA

Sheet EPR 03 MAYO
B2: REPORTE CONSOLIDADO POR SEGMENTOS
B3: SALDO ACUMULADO SEMANA 18
B5: COORDINADOR | C5: SEGMENTO | D5: CUENTAS | E5: COBRANZA REAL | F5: CUOTA IDEAL | G5: VARIACION | H5: % VAR | I5: EPR | J5: EPR IDEAL | K5: VAR EPR
B6: Samatha y Zareth | C6: Extrajudicial - 0 a 28 semanas de atraso | D6: =SUMIF('REPORTE DIARIO'!B:B,'EPR 03 MAYO'!C6, 'REPORTE DIARIO'!C:C) -> 12581 | E6: =SUMIF('REPORTE DIARIO'!B:B,'EPR 03 MAYO'!C6, 'REPORTE DIARIO'!D:D) -> 1047909.8 | F6: =J6*D6 -> 2372417.1 | G6: =+E6-F6 -> -1324507.4 | H6: =ABS(G6/F6) -> 0.55829446 | I6: =E6/D6 -> 83.293044 | J6: =(220/7)*6 -> 188.57143 | K6: =+I6-J6 -> -105.27838
B7: Gabriel | C7: Extrajudicial - 29 a 39 semanas de atraso | D7: =SUMIF('REPORTE DIARIO'!B:B,'EPR 03 MAYO'!C7, 'REPORTE DIARIO'!C:C) -> 10645 | E7: =SUMIF('REPORTE DIARIO'!B:B,'EPR 03 MAYO'!C7, 'REPORTE DIARIO'!D:D) -> 646738.43 | F7: =J7*D7 -> 1003671.4 | G7: =+E7-F7 -> -356933 | H7: =ABS(G7/F7) -> 0.35562734 | I7: =E7/D7 -> 60.755137 | J7: =(110/7)*6 -> 94.285714 | K7: =+I7-J7 -> -33.530578
B8: Gabriel | C8: Extrajudicial - 40 a 55 semanas de atraso | D8: =SUMIF('REPORTE DIARIO'!B:B,'EPR 03 MAYO'!C8, 'REPORTE DIARIO'!C:C) -> 14570 | E8: =SUMIF('REPORTE DIARIO'!B:B,'EPR 03 MAYO'!C8, 'REPORTE DIARIO'!D:D) -> 279441.41 | F8: =J8*D8 -> 561985.71 | G8: =+E8-F8 -> -282544.3 | H8: =ABS(G8/F8) -> 0.50276065 | I8: =E8/D8 -> 19.179232 | J8: =(45/7)*6 -> 38.571429 | K8: =+I8-J8 -> -19.392197
B9: Fernando | C9: Mas 55 semanas de atraso | D9: =SUMIF('REPORTE DIARIO'!B:B,'EPR 03 MAYO'!C9, 'REPORTE DIARIO'!C:C) -> 51783 | E9: =SUMIF('REPORTE DIARIO'!B:B,'EPR 03 MAYO'!C9, 'REPORTE DIARIO'!D:D) -> 593924.58 | F9: =J9*D9 -> 665781.43 | G9: =+E9-F9 -> -71856.849 | H9: =ABS(G9/F9) -> 0.10792859 | I9: =E9/D9 -> 11.46949 | J9: =(15/7)*6 -> 12.857143 | K9: =+I9-J9 -> -1.3876533
C10: TOTAL | D10: =SUM(D6:D9) -> 89579 | E10: =SUM(E6:E9) -> 2568014.2 | F10: =SUM(F6:F9) -> 4603855.7 | G10: =+E10-F10 -> -2035841.5 | H10: =ABS(G10/F10) -> 0.44220359 | I10: =E10/D10 -> 28.667592 | J10: =F10/D10 -> 51.394364 | K10: =I10-J10 -> -22.726772
B12: Nota:
B13: El saldo consolidado incluye los siguientes despachos
B14: Samantha, Samantha 2, Sofia, Edith, Fernando, Olguin y Federico
