Workbook

Sheet REPORTE DIARIO
B3: COBRANZA GENERAL SAMANTHA
B4: Segmento | C4: Cuentas | D4: Recuperación
B5: Extrajudicial - 0 a 28 semanas de atraso | C5: 6306 | D5: 411236.35
B6: Extrajudicial - 29 a 39 semanas de atraso | C6: 3342 | D6: 232997.16
B7: Extrajudicial - 40 a 55 semanas de atraso | C7: 7785 | D7: 195607.37
B8: JUDICIAL | C8: 1039 | D8: 0
B9: Mas 55 semanas de atraso | C9: 37925 | D9: 313536.09
B10: Total general | C10: =SUM(C5:C9) -> 56397 | D10: =SUM(D5:D9) -> 1153377
B12: COBRANZA GENERAL ANDREA
B13: Segmento | C13: Cuentas | D13: Recuperación
B14: Extrajudicial - 0 a 28 semanas de atraso | C14: 127 | D14: 43669.6
B15: Extrajudicial - 29 a 39 semanas de atraso | C15: 285 | D15: 50978.89
B16: Extrajudicial - 40 a 55 semanas de atraso | C16: 395 | D16: 29728
B17: Mas 55 semanas de atraso | C17: 15154 | D17: 87759.78
B18: Total general | C18: =SUM(C14:C17) -> 15961 | D18: =SUM(D14:D17) -> 212136.27
B20: COBRANZA GENERAL FERNANDO
B21: Segmento | C21: Cuentas | D21: Recuperación
B22: Extrajudicial - 0 a 28 semanas de atraso | C22: 5001 | D22: 149969.72
B23: Extrajudicial - 29 a 39 semanas de atraso | C23: 1339 | D23: 26104
B24: Extrajudicial - 40 a 55 semanas de atraso | C24: 3826 | D24: 25178.91
B25: Mas 55 semanas de atraso | C25: 1029 | D25: 399
B26: Total general | C26: =SUM(C22:C25) -> 11195 | D26: =SUM(D22:D25) -> 201651.63
B28: COBRANZA GENERAL EDITH
B29: Segmento | C29: Cuentas | D29: Recuperación
B30: Extrajudicial - 0 a 28 semanas de atraso | C30: 352 | D30: 27796.11
B31: Extrajudicial - 29 a 39 semanas de atraso | C31: 1327 | D31: 48086.11
B32: Extrajudicial - 40 a 55 semanas de atraso | C32: 145 | D32: 31116.59
B33: Mas 55 semanas de atraso | C33: 1193 | D33: 37916.84
B34: Total general | C34: =SUM(C30:C33) -> 3017 | D34: =SUM(D30:D33) -> 144915.65
B36: COBRANZA GENERAL FEDERICO
B37: Segmento | C37: Cuentas | D37: Recuperación
B38: Extrajudicial - 0 a 28 semanas de atraso | C38: 23 | D38: 825
B39: Extrajudicial - 29 a 39 semanas de atraso | C39: 42 | D39: 0
B40: Extrajudicial - 40 a 55 semanas de atraso | C40: 4 | D40: 970
B41: Mas 55 semanas de atraso | C41: 743 | D41: 14044
B42: Total general | C42: =SUM(C38:C41) -> 812 | D42: =SUM(D38:D41) -> 15839
B50: Cobranza Total | C50: =SUMIF(B:B, "Total general", C:C) -> 87382 | D50: =SUMIF(B:B, "Total general", D:D) -> 1727919.5

Sheet CDC-OLGUIN
B1: ETIQUETA PROYECTO CDC
B3: COBRANZA GENERAL CDC 100
B4: Segmento | C4: Cuentas | D4: Recuperación
B5: Extrajudicial - 0 a 28 semanas de atraso | C5: 8532 | D5: 125741.31
B6: Extrajudicial - 29 a 39 semanas de atraso | C6: 6177 | D6: 74363
B7: Extrajudicial - 40 a 55 semanas de atraso | C7: 5025 | D7: 106476.37
B8: JUDICIAL | C8: 2739 | D8: 100
B9: Mas 55 semanas de atraso | C9: 2916 | D9: 25972.45
B10: Total general | C10: =SUM(C5:C9) -> 25389 | D10: =SUM(D5:D9) -> 332653.13
B12: COBRANZA GENERAL FERNANDO
B13: Segmento | C13: Cuentas | D13: Recuperación
B14: Extrajudicial - 0 a 28 semanas de atraso | C14: 4900 | D14: 147929.72
B15: Extrajudicial - 29 a 39 semanas de atraso | C15: 769 | D15: 21333
B16: Extrajudicial - 40 a 55 semanas de atraso | C16: 3525 | D16: 23512.91
B17: Mas 55 semanas de atraso | C17: 26 | D17: 399
B18: Total general | C18: =SUM(C14:C17) -> 9220 | D18: =SUM(D14:D17) -> 193174.63
B20: COBRANZA GENERAL SAMANTHA
B21: Segmento | C21: Cuentas | D21: Recuperación
B22: Extrajudicial - 0 a 28 semanas de atraso | C22: 7 | D22: 2556
B23: Extrajudicial - 29 a 39 semanas de atraso | C23: 68 | D23: 2100
B24: Extrajudicial - 40 a 55 semanas de atraso | C24: 1 | D24: 800
B25: JUDICIAL | C25: 0 | D25: 0
B26: Mas 55 semanas de atraso | C26: 303 | D26: 6019.04
B27: Total general | C27: =SUM(C22:C26) -> 379 | D27: =SUM(D22:D26) -> 11475.04
B29: COBRANZA GENERAL ANDREA
B30: Segmento | C30: Cuentas | D30: Recuperación
B31: Extrajudicial - 0 a 28 semanas de atraso | C31: 3 | D31: 1331
B32: Extrajudicial - 29 a 39 semanas de atraso | C32: 0 | D32: 0
B33: Extrajudicial - 40 a 55 semanas de atraso | C33: 2 | D33: 0
B34: Mas 55 semanas de atraso | C34: 331 | D34: 1498
B35: Total general | C35: =SUM(C31:C34) -> 336 | D35: =SUM(D31:D34) -> 2829
B37: COBRANZA GENERAL EDITH
B38: Segmento | C38: Cuentas | D38: Recuperación
B39: Extrajudicial - 0 a 28 semanas de atraso | C39: 2 | D39: 9
B40: Extrajudicial - 29 a 39 semanas de atraso | C40: 1 | D40: 0
B41: Mas 55 semanas de atraso | C41: 167 | D41: 2312
B42: Total general | C42: =SUM(C39:C41) -> 170 | D42: =SUM(D39:D41) -> 2321
B44: COBRANZA GENERAL FEDERICO
B45: Segmento | C45: Cuentas | D45: Recuperación
B46: Extrajudicial - 0 a 28 semanas de atraso | C46: 3 | D46: 0
...

Sheet COBRANZA CDC
B1: ETIQUETA PROYECTO CDC
B2: Segmento | C2: Cuentas | D2: Recuperación
B3: Extrajudicial - 0 a 28 semanas de atraso | C3: =SUMIF('CDC-OLGUIN'!B:B, "Extrajudicial - 0 a 28 semanas de atraso", 'CDC-OLGUIN'!C:C) -> 13447 | D3: =SUMIF('CDC-OLGUIN'!B:B, "Extrajudicial - 0 a 28 semanas de atraso", 'CDC-OLGUIN'!D:D) -> 277567.03
B4: Extrajudicial - 29 a 39 semanas de atraso | C4: =SUMIF('CDC-OLGUIN'!B:B, "Extrajudicial - 29 a 39 semanas de atraso", 'CDC-OLGUIN'!C:C) -> 7015 | D4: =SUMIF('CDC-OLGUIN'!B:B, "Extrajudicial - 29 a 39 semanas de atraso", 'CDC-OLGUIN'!D:D) -> 97796
B5: Extrajudicial - 40 a 55 semanas de atraso | C5: =SUMIF('CDC-OLGUIN'!B:B, "Extrajudicial - 40 a 55 semanas de atraso", 'CDC-OLGUIN'!C:C) -> 8553 | D5: =SUMIF('CDC-OLGUIN'!B:B, "Extrajudicial - 40 a 55 semanas de atraso", 'CDC-OLGUIN'!D:D) -> 130789.28
B6: JUDICIAL | C6: =SUMIF('CDC-OLGUIN'!B:B, "JUDICIAL", 'CDC-OLGUIN'!C:C) -> 2739 | D6: =SUMIF('CDC-OLGUIN'!B:B, "JUDICIAL", 'CDC-OLGUIN'!D:D) -> 100
B7: Mas 55 semanas de atraso | C7: =SUMIF('CDC-OLGUIN'!B:B, "Mas 55 semanas de atraso", 'CDC-OLGUIN'!C:C) -> 3807 | D7: =SUMIF('CDC-OLGUIN'!B:B, "Mas 55 semanas de atraso", 'CDC-OLGUIN'!D:D) -> 36200.49
B8: Total general | C8: =SUM(C3:C7) -> 35561 | D8: =SUM(D3:D7) -> 542452.8

Sheet EPR 26 JUN
B2: REPORTE CONSOLIDADO POR SEGMENTOS
B3: SALDO ACUMULADO SEMANA 26
B5: COORDINADOR | C5: SEGMENTO | D5: CUENTAS | E5: COBRANZA REAL | F5: CUOTA IDEAL | G5: VARIACION | H5: % VAR | I5: EPR | J5: EPR IDEAL | K5: VAR EPR
B6: Zareth | C6: Extrajudicial - 0 a 28 semanas de atraso | D6: =SUMIF('REPORTE DIARIO'!B:B,'EPR 26 JUN'!C6, 'REPORTE DIARIO'!C:C) -> 11809 | E6: =SUMIF('REPORTE DIARIO'!B:B,'EPR 26 JUN'!C6, 'REPORTE DIARIO'!D:D) -> 633496.78 | F6: =J6*D6 -> 742280 | G6: =+E6-F6 -> -108783.22 | H6: =ABS(G6/F6) -> 0.14655281 | I6: =E6/D6 -> 53.645252 | J6: =(220/7)*2 -> 62.857143 | K6: =+I6-J6 -> -9.2118909
B7: Gabriel | C7: Extrajudicial - 29 a 39 semanas de atraso | D7: =SUMIF('REPORTE DIARIO'!B:B,'EPR 26 JUN'!C7, 'REPORTE DIARIO'!C:C) -> 6335 | E7: =SUMIF('REPORTE DIARIO'!B:B,'EPR 26 JUN'!C7, 'REPORTE DIARIO'!D:D) -> 358166.16 | F7: =J7*D7 -> 199100 | G7: =+E7-F7 -> 159066.16 | H7: =ABS(G7/F7) -> 0.79892597 | I7: =E7/D7 -> 56.537673 | J7: =(110/7)*2 -> 31.428571 | K7: =+I7-J7 -> 25.109102
B8: Gabriel | C8: Extrajudicial - 40 a 55 semanas de atraso | D8: =SUMIF('REPORTE DIARIO'!B:B,'EPR 26 JUN'!C8, 'REPORTE DIARIO'!C:C) -> 12155 | E8: =SUMIF('REPORTE DIARIO'!B:B,'EPR 26 JUN'!C8, 'REPORTE DIARIO'!D:D) -> 282600.87 | F8: =J8*D8 -> 156278.57 | G8: =+E8-F8 -> 126322.3 | H8: =ABS(G8/F8) -> 0.8083149 | I8: =E8/D8 -> 23.249763 | J8: =(45/7)*2 -> 12.857143 | K8: =+I8-J8 -> 10.39262
B9: Fernando (Naucalpan) | C9: Mas 55 semanas de atraso | D9: =SUMIF('REPORTE DIARIO'!B:B,'EPR 26 JUN'!C9, 'REPORTE DIARIO'!C:C) -> 56044 | E9: =SUMIF('REPORTE DIARIO'!B:B,'EPR 26 JUN'!C9, 'REPORTE DIARIO'!D:D) -> 453655.71 | F9: =J9*D9 -> 240188.57 | G9: =+E9-F9 -> 213467.14 | H9: =ABS(G9/F9) -> 0.88874811 | I9: =E9/D9 -> 8.0946348 | J9: =(15/7)*2 -> 4.2857143 | K9: =+I9-J9 -> 3.8089205
C10: TOTAL | D10: =SUM(D6:D9) -> 86343 | E10: =SUM(E6:E9) -> 1727919.5 | F10: =SUM(F6:F9) -> 1337847.1 | G10: =+E10-F10 -> 390072.38 | H10: =ABS(G10/F10) -> 0.29156722 | I10: =E10/D10 -> 20.012271 | J10: =F10/D10 -> 15.494564 | K10: =I10-J10 -> 4.517707
B12: Nota:
B13: El saldo consolidado incluye los siguientes despachos
B14: Samantha, Samantha 2, Sofia, Edith, Fernando, Olguin y Federico
