Workbook

Sheet REPORTE DIARIO
B3: COBRANZA GENERAL SAMANTHA
B4: Segmento | C4: Cuentas | D4: Recuperación
B5: Extrajudicial - 0 a 28 semanas de atraso | C5: 7195 | D5: 236245.11
B6: Extrajudicial - 29 a 39 semanas de atraso | C6: 7719 | D6: 252026.56
B7: Extrajudicial - 40 a 55 semanas de atraso | C7: 10316 | D7: 70332.45
B8: JUDICIAL | C8: 21 | D8: 1150
B9: Mas 55 semanas de atraso | C9: 29580 | D9: 250965.42
B10: Total general | C10: =SUM(C5:C9) -> 54831 | D10: =SUM(D5:D9) -> 810719.54
B12: COBRANZA GENERAL SAMANTHA 2
B13: Segmento | C13: Cuentas | D13: Recuperación
B14: Extrajudicial - 0 a 28 semanas de atraso | C14: 3020 | D14: 94192.45
B15: Extrajudicial - 29 a 39 semanas de atraso | C15: 1701 | D15: 22117.57
B16: Extrajudicial - 40 a 55 semanas de atraso | C16: 3524 | D16: 16454.63
B17: JUDICIAL | C17: 2 | D17: 0
B18: Mas 55 semanas de atraso | C18: 21195 | D18: 79921.01
B19: Total general | C19: =SUM(C14:C18) -> 29442 | D19: =SUM(D14:D18) -> 212685.66
B21: COBRANZA GENERAL EDITH
B22: Segmento | C22: Cuentas | D22: Recuperación
B23: Extrajudicial - 0 a 28 semanas de atraso | C23: 1491 | D23: 75921.39
B24: Extrajudicial - 29 a 39 semanas de atraso | C24: 1393 | D24: 74951.59
B25: Extrajudicial - 40 a 55 semanas de atraso | C25: 755 | D25: 4780
B26: Mas 55 semanas de atraso | C26: 8493 | D26: 22626
B27: Total general | C27: =SUM(C23:C26) -> 12132 | D27: =SUM(D23:D26) -> 178278.98
B29: COBRANZA GENERAL SOFIA
B30: Segmento | C30: Cuentas | D30: Recuperación
B31: Extrajudicial - 0 a 28 semanas de atraso | C31: 1255 | D31: 88045.4
B32: Extrajudicial - 29 a 39 semanas de atraso | C32: 1188 | D32: 27997
B33: Extrajudicial - 40 a 55 semanas de atraso | C33: 2996 | D33: 21000
B34: Mas 55 semanas de atraso | C34: 1900 | D34: 1166
B35: Total general | C35: =SUM(C31:C34) -> 7339 | D35: =SUM(D31:D34) -> 138208.4
B37: COBRANZA GENERAL FERNANDO
B38: Segmento | C38: Cuentas | D38: Recuperación
B39: Extrajudicial - 0 a 28 semanas de atraso | C39: 2803 | D39: 21527
B40: Total general | C40: =SUM(C39:C39) -> 2803 | D40: =SUM(D39:D39) -> 21527
B42: COBRANZA GENERAL FEDERICO
B43: Segmento | C43: Cuentas | D43: Recuperación
B44: Extrajudicial - 0 a 28 semanas de atraso | C44: 0 | D44: 0
B45: Extrajudicial - 29 a 39 semanas de atraso | C45: 121 | D45: 0
B46: Extrajudicial - 40 a 55 semanas de atraso | C46: 164 | D46: 0
B47: Mas 55 semanas de atraso | C47: 1305 | D47: 6291
...

Sheet DATA

Sheet EPR 2 ABR
B2: REPORTE CONSOLIDADO POR SEGMENTOS
B3: SALDO ACUMULADO SEMANA 14
B5: COORDINADOR | C5: SEGMENTO | D5: CUENTAS | E5: COBRANZA REAL | F5: CUOTA IDEAL | G5: VARIACION | H5: % VAR | I5: EPR | J5: EPR IDEAL | K5: VAR EPR
B6: Samatha y Zareth | C6: Extrajudicial - 0 a 28 semanas de atraso | D6: =SUMIF('REPORTE DIARIO'!B:B,'EPR 2 ABR'!C6, 'REPORTE DIARIO'!C:C) -> 15832 | E6: =SUMIF('REPORTE DIARIO'!B:B,'EPR 2 ABR'!C6, 'REPORTE DIARIO'!D:D) -> 517931.35 | F6: =J6*D6 -> 1357028.6 | G6: =+E6-F6 -> -839097.22 | H6: =ABS(G6/F6) -> 0.61833423 | I6: =E6/D6 -> 32.714209 | J6: =(200/7)*3 -> 85.714286 | K6: =+I6-J6 -> -53.000077
B7: Gabriel | C7: Extrajudicial - 29 a 39 semanas de atraso | D7: =SUMIF('REPORTE DIARIO'!B:B,'EPR 2 ABR'!C7, 'REPORTE DIARIO'!C:C) -> 12302 | E7: =SUMIF('REPORTE DIARIO'!B:B,'EPR 2 ABR'!C7, 'REPORTE DIARIO'!D:D) -> 377092.72 | F7: =J7*D7 -> 579951.43 | G7: =+E7-F7 -> -202858.71 | H7: =ABS(G7/F7) -> 0.34978569 | I7: =E7/D7 -> 30.65296 | J7: =(110/7)*3 -> 47.142857 | K7: =+I7-J7 -> -16.489897
B8: Gabriel | C8: Extrajudicial - 40 a 55 semanas de atraso | D8: =SUMIF('REPORTE DIARIO'!B:B,'EPR 2 ABR'!C8, 'REPORTE DIARIO'!C:C) -> 17823 | E8: =SUMIF('REPORTE DIARIO'!B:B,'EPR 2 ABR'!C8, 'REPORTE DIARIO'!D:D) -> 112567.08 | F8: =J8*D8 -> 343729.29 | G8: =+E8-F8 -> -231162.21 | H8: =ABS(G8/F8) -> 0.6725124 | I8: =E8/D8 -> 6.3158324 | J8: =(45/7)*3 -> 19.285714 | K8: =+I8-J8 -> -12.969882
B9: Fernando | C9: Mas 55 semanas de atraso | D9: =SUMIF('REPORTE DIARIO'!B:B,'EPR 2 ABR'!C9, 'REPORTE DIARIO'!C:C) -> 62483 | E9: =SUMIF('REPORTE DIARIO'!B:B,'EPR 2 ABR'!C9, 'REPORTE DIARIO'!D:D) -> 360969.43 | F9: =J9*D9 -> 401676.43 | G9: =+E9-F9 -> -40706.999 | H9: =ABS(G9/F9) -> 0.10134276 | I9: =E9/D9 -> 5.7770822 | J9: =(15/7)*3 -> 6.4285714 | K9: =+I9-J9 -> -0.65148918
C10: TOTAL | D10: =SUM(D6:D9) -> 108440 | E10: =SUM(E6:E9) -> 1368560.6 | F10: =SUM(F6:F9) -> 2682385.7 | G10: =+E10-F10 -> -1313825.1 | H10: =ABS(G10/F10) -> 0.48979725 | I10: =E10/D10 -> 12.620441 | J10: =F10/D10 -> 24.736128 | K10: =I10-J10 -> -12.115687
B12: Nota:
B13: El saldo consolidado incluye los siguientes despachos
B14: Samantha, Samantha 2, Sofia, Edith, Olguin, Fernando y Federico
