Workbook

Sheet REPORTE DIARIO
B3: COBRANZA GENERAL SAMANTHA
B4: Segmento | C4: Cuentas | D4: Recuperación
B5: Extrajudicial - 0 a 28 semanas de atraso | C5: 4151 | D5: 64447.5
B6: Extrajudicial - 29 a 39 semanas de atraso | C6: 4374 | D6: 98580.85
B7: Extrajudicial - 40 a 55 semanas de atraso | C7: 4307 | D7: 20082
B8: JUDICIAL | C8: 12 | D8: 0
B9: Mas 55 semanas de atraso | C9: 11375 | D9: 41224.98
B10: Total general | C10: =SUM(C5:C9) -> 24219 | D10: =SUM(D5:D9) -> 224335.33
B12: COBRANZA GENERAL SOFIA
B13: Segmento | C13: Cuentas | D13: Recuperación
B14: Extrajudicial - 0 a 28 semanas de atraso | C14: 227 | D14: 22652.18
B15: Extrajudicial - 29 a 39 semanas de atraso | C15: 3222 | D15: 67666
B16: Extrajudicial - 40 a 55 semanas de atraso | C16: 626 | D16: 41317
B17: Mas 55 semanas de atraso | C17: 3969 | D17: 2000
B18: Total general | C18: =SUM(C14:C17) -> 8044 | D18: =SUM(D14:D17) -> 133635.18
B20: COBRANZA GENERAL EDITH
B21: Segmento | C21: Cuentas | D21: Recuperación
B22: Extrajudicial - 0 a 28 semanas de atraso | C22: 3308 | D22: 63175.01
B23: Extrajudicial - 29 a 39 semanas de atraso | C23: 1486 | D23: 4428
B24: Extrajudicial - 40 a 55 semanas de atraso | C24: 2158 | D24: 4681
B25: JUDICIAL | C25: 1 | D25: 0
B26: Mas 55 semanas de atraso | C26: 17193 | D26: 7483
B27: Total general | C27: =SUM(C22:C26) -> 24146 | D27: =SUM(D22:D26) -> 79767.01
B29: COBRANZA GENERAL SAMANTHA 2
B30: Segmento | C30: Cuentas | D30: Recuperación
B31: Extrajudicial - 0 a 28 semanas de atraso | C31: 2030 | D31: 20332
B32: Extrajudicial - 29 a 39 semanas de atraso | C32: 2074 | D32: 4985
B33: Extrajudicial - 40 a 55 semanas de atraso | C33: 2164 | D33: 11037.84
B34: JUDICIAL | C34: 2 | D34: 0
B35: Mas 55 semanas de atraso | C35: 20791 | D35: 7359
B36: Total general | C36: =SUM(C31:C35) -> 27061 | D36: =SUM(D31:D35) -> 43713.84
B38: COBRANZA GENERAL FEDERICO
B39: Segmento | C39: Cuentas | D39: Recuperación
B40: Extrajudicial - 0 a 28 semanas de atraso | C40: 509 | D40: 3700
B41: Extrajudicial - 29 a 39 semanas de atraso | C41: 850 | D41: 6133
B42: Extrajudicial - 40 a 55 semanas de atraso | C42: 775 | D42: 0
B43: Mas 55 semanas de atraso | C43: 2414 | D43: 3133
B44: Total general | C44: =SUM(C40:C43) -> 4548 | D44: =SUM(D40:D43) -> 12966
B46: COBRANZA GENERAL FERNANDO
B47: Segmento | C47: Cuentas | D47: Recuperación
...

Sheet DATA

Sheet EPR 20 MAYO
B2: REPORTE CONSOLIDADO POR SEGMENTOS
B3: COBRANZA 20 MAYO
B5: COORDINADOR | C5: SEGMENTO | D5: CUENTAS | E5: COBRANZA REAL | F5: CUOTA IDEAL | G5: VARIACION | H5: % VAR | I5: EPR | J5: EPR IDEAL | K5: VAR EPR
B6: Zareth | C6: Extrajudicial - 0 a 28 semanas de atraso | D6: =SUMIF('REPORTE DIARIO'!B:B,'EPR 20 MAYO'!C6, 'REPORTE DIARIO'!C:C) -> 12940 | E6: =SUMIF('REPORTE DIARIO'!B:B,'EPR 20 MAYO'!C6, 'REPORTE DIARIO'!D:D) -> 188180.69 | F6: =J6*D6 -> 406685.71 | G6: =+E6-F6 -> -218505.02 | H6: =ABS(G6/F6) -> 0.53728227 | I6: =E6/D6 -> 14.542557 | J6: =220/7 -> 31.428571 | K6: =+I6-J6 -> -16.886014
B7: Gabriel | C7: Extrajudicial - 29 a 39 semanas de atraso | D7: =SUMIF('REPORTE DIARIO'!B:B,'EPR 20 MAYO'!C7, 'REPORTE DIARIO'!C:C) -> 12704 | E7: =SUMIF('REPORTE DIARIO'!B:B,'EPR 20 MAYO'!C7, 'REPORTE DIARIO'!D:D) -> 182992.85 | F7: =J7*D7 -> 199634.29 | G7: =+E7-F7 -> -16641.436 | H7: =ABS(G7/F7) -> 0.083359608 | I7: =E7/D7 -> 14.404349 | J7: =110/7 -> 15.714286 | K7: =+I7-J7 -> -1.3099367
B8: Gabriel | C8: Extrajudicial - 40 a 55 semanas de atraso | D8: =SUMIF('REPORTE DIARIO'!B:B,'EPR 20 MAYO'!C8, 'REPORTE DIARIO'!C:C) -> 11228 | E8: =SUMIF('REPORTE DIARIO'!B:B,'EPR 20 MAYO'!C8, 'REPORTE DIARIO'!D:D) -> 78739.84 | F8: =J8*D8 -> 72180 | G8: =+E8-F8 -> 6559.84 | H8: =ABS(G8/F8) -> 0.090881685 | I8: =E8/D8 -> 7.0128108 | J8: =45/7 -> 6.4285714 | K8: =+I8-J8 -> 0.5842394
B9: Fernando (Naucalpan) | C9: Mas 55 semanas de atraso | D9: =SUMIF('REPORTE DIARIO'!B:B,'EPR 20 MAYO'!C9, 'REPORTE DIARIO'!C:C) -> 57052 | E9: =SUMIF('REPORTE DIARIO'!B:B,'EPR 20 MAYO'!C9, 'REPORTE DIARIO'!D:D) -> 62844.98 | F9: =J9*D9 -> 122254.29 | G9: =+E9-F9 -> -59409.306 | H9: =ABS(G9/F9) -> 0.48594866 | I9: =E9/D9 -> 1.1015386 | J9: =15/7 -> 2.1428571 | K9: =+I9-J9 -> -1.0413185
C10: TOTAL | D10: =SUM(D6:D9) -> 93924 | E10: =SUM(E6:E9) -> 512758.36 | F10: =SUM(F6:F9) -> 800754.29 | G10: =+E10-F10 -> -287995.93 | H10: =ABS(G10/F10) -> 0.3596558 | I10: =E10/D10 -> 5.4592901 | J10: =F10/D10 -> 8.5255556 | K10: =I10-J10 -> -3.0662656
B12: Nota:
B13: El saldo consolidado incluye los siguientes despachos
B14: Samantha, Samantha 2, Sofia, Edith, Fernando, Olguin y Federico
