Workbook

Sheet REPORTE DIARIO
B3: COBRANZA GENERAL SAMANTHA
B4: Segmento | C4: Cuentas | D4: Recuperación
B5: Extrajudicial - 0 a 28 semanas de atraso | C5: 4791 | D5: 362899.32
B6: Extrajudicial - 29 a 39 semanas de atraso | C6: 3997 | D6: 99272.49
B7: Extrajudicial - 40 a 55 semanas de atraso | C7: 6767 | D7: 99930.74
B8: JUDICIAL | C8: 11 | D8: 0
B9: Mas 55 semanas de atraso | C9: 21455 | D9: 202127.11
B10: Total general | C10: =SUM(C5:C9) -> 37021 | D10: =SUM(D5:D9) -> 764229.66
B12: COBRANZA GENERAL EDITH
B13: Segmento | C13: Cuentas | D13: Recuperación
B14: Extrajudicial - 0 a 28 semanas de atraso | C14: 2295 | D14: 114172.33
B15: Extrajudicial - 29 a 39 semanas de atraso | C15: 411 | D15: 33579.55
B16: Extrajudicial - 40 a 55 semanas de atraso | C16: 1345 | D16: 17378
B17: JUDICIAL | C17: 1 | D17: 44
B18: Mas 55 semanas de atraso | C18: 12069 | D18: 29752.72
B19: Total general | C19: =SUM(C14:C18) -> 16121 | D19: =SUM(D14:D18) -> 194926.6
B21: COBRANZA GENERAL ANDREA
B22: Segmento | C22: Cuentas | D22: Recuperación
B23: Extrajudicial - 0 a 28 semanas de atraso | C23: 1901 | D23: 45937.4
B24: Extrajudicial - 29 a 39 semanas de atraso | C24: 1300 | D24: 10163
B25: Extrajudicial - 40 a 55 semanas de atraso | C25: 3520 | D25: 36008
B26: JUDICIAL | C26: 0 | D26: 0
B27: Mas 55 semanas de atraso | C27: 18239 | D27: 37044.88
B28: Total general | C28: =SUM(C23:C27) -> 24960 | D28: =SUM(D23:D27) -> 129153.28
B30: COBRANZA GENERAL SOFIA
B31: Segmento | C31: Cuentas | D31: Recuperación
B32: Extrajudicial - 0 a 28 semanas de atraso | C32: 569 | D32: 36167.26
B33: Extrajudicial - 29 a 39 semanas de atraso | C33: 407 | D33: 38476.59
B34: Extrajudicial - 40 a 55 semanas de atraso | C34: 307 | D34: 20287.6
B35: Mas 55 semanas de atraso | C35: 711 | D35: 3027
B36: Total general | C36: =SUM(C32:C35) -> 1994 | D36: =SUM(D32:D35) -> 97958.45
B38: COBRANZA GENERAL OLGUIN
B39: Segmento | C39: Cuentas | D39: Recuperación
B40: Extrajudicial - 0 a 28 semanas de atraso | C40: 809 | D40: 25436.48
B41: Extrajudicial - 29 a 39 semanas de atraso | C41: 694 | D41: 2476
B42: Extrajudicial - 40 a 55 semanas de atraso | C42: 1001 | D42: 2979
B43: Mas 55 semanas de atraso | C43: 368 | D43: 3045
B44: Total general | C44: =SUM(C40:C43) -> 2872 | D44: =SUM(D40:D43) -> 33936.48
B46: COBRANZA GENERAL FEDERICO
B47: Segmento | C47: Cuentas | D47: Recuperación
...

Sheet CDC-OLGUIN
B1: ETIQUETA PROYECTO CDC
B3: COBRANZA GENERAL CDC 100
B4: Segmento | C4: Cuentas | D4: Recuperación
B5: Extrajudicial - 0 a 28 semanas de atraso | C5: 10434 | D5: 133253.22
B6: Extrajudicial - 29 a 39 semanas de atraso | C6: 5752 | D6: 49622.26
B7: Extrajudicial - 40 a 55 semanas de atraso | C7: 9588 | D7: 28746
B8: JUDICIAL | C8: 2739 | D8: 0
B9: Mas 55 semanas de atraso | C9: 60961 | D9: 6137
B10: Total general | C10: =SUM(C5:C9) -> 89474 | D10: =SUM(D5:D9) -> 217758.48
B12: COBRANZA GENERAL OLGUIN
B13: Segmento | C13: Cuentas | D13: Recuperación
B14: Extrajudicial - 0 a 28 semanas de atraso | C14: 809 | D14: 25436.48
B15: Extrajudicial - 29 a 39 semanas de atraso | C15: 694 | D15: 2476
B16: Extrajudicial - 40 a 55 semanas de atraso | C16: 1001 | D16: 2979
B17: Mas 55 semanas de atraso | C17: 368 | D17: 3045
B18: Total general | C18: =SUM(C14:C17) -> 2872 | D18: =SUM(D14:D17) -> 33936.48
B20: COBRANZA GENERAL SAMANTHA
B21: Segmento | C21: Cuentas | D21: Recuperación
B22: Extrajudicial - 0 a 28 semanas de atraso | C22: 14 | D22: 2932
B23: Extrajudicial - 29 a 39 semanas de atraso | C23: 7 | D23: 2461
B24: Extrajudicial - 40 a 55 semanas de atraso | C24: 81 | D24: 443
B25: JUDICIAL | C25: 1 | D25: 0
B26: Mas 55 semanas de atraso | C26: 321 | D26: 7556
B27: Total general | C27: =SUM(C22:C26) -> 424 | D27: =SUM(D22:D26) -> 13392
B29: COBRANZA GENERAL EDITH
B30: Segmento | C30: Cuentas | D30: Recuperación
B31: Extrajudicial - 0 a 28 semanas de atraso | C31: 5 | D31: 339
B32: Extrajudicial - 29 a 39 semanas de atraso | C32: 3 | D32: 659
B33: Extrajudicial - 40 a 55 semanas de atraso | C33: 28 | D33: 3696
B34: JUDICIAL | C34: 0 | D34: 0
B35: Mas 55 semanas de atraso | C35: 175 | D35: 600
B36: Total general | C36: =SUM(C31:C35) -> 211 | D36: =SUM(D31:D35) -> 5294
B38: COBRANZA GENERAL FEDERICO
B39: Segmento | C39: Cuentas | D39: Recuperación
B40: Extrajudicial - 0 a 28 semanas de atraso | C40: 2 | D40: 0
B41: Extrajudicial - 29 a 39 semanas de atraso | C41: 1 | D41: 1926
B42: Extrajudicial - 40 a 55 semanas de atraso | C42: 10 | D42: 0
B43: Mas 55 semanas de atraso | C43: 64 | D43: 0
B44: Total general | C44: =SUM(C40:C43) -> 77 | D44: =SUM(D40:D43) -> 1926
B46: COBRANZA GENERAL ANDREA
...

Sheet EPR 26 JUN
B2: REPORTE CONSOLIDADO POR SEGMENTOS
B3: SALDO ACUMULADO SEMANA 26
B5: COORDINADOR | C5: SEGMENTO | D5: CUENTAS | E5: COBRANZA REAL | F5: CUOTA IDEAL | G5: VARIACION | H5: % VAR | I5: EPR | J5: EPR IDEAL | K5: VAR EPR
B6: Zareth | C6: Extrajudicial - 0 a 28 semanas de atraso | D6: =SUMIF('REPORTE DIARIO'!B:B,'EPR 26 JUN'!C6, 'REPORTE DIARIO'!C:C) -> 13182 | E6: =SUMIF('REPORTE DIARIO'!B:B,'EPR 26 JUN'!C6, 'REPORTE DIARIO'!D:D) -> 615425.78 | F6: =J6*D6 -> 828582.86 | G6: =+E6-F6 -> -213157.08 | H6: =ABS(G6/F6) -> 0.25725499 | I6: =E6/D6 -> 46.686829 | J6: =(220/7)*2 -> 62.857143 | K6: =+I6-J6 -> -16.170314
B7: Gabriel | C7: Extrajudicial - 29 a 39 semanas de atraso | D7: =SUMIF('REPORTE DIARIO'!B:B,'EPR 26 JUN'!C7, 'REPORTE DIARIO'!C:C) -> 7888 | E7: =SUMIF('REPORTE DIARIO'!B:B,'EPR 26 JUN'!C7, 'REPORTE DIARIO'!D:D) -> 185893.63 | F7: =J7*D7 -> 247908.57 | G7: =+E7-F7 -> -62014.941 | H7: =ABS(G7/F7) -> 0.25015247 | I7: =E7/D7 -> 23.566637 | J7: =(110/7)*2 -> 31.428571 | K7: =+I7-J7 -> -7.8619348
B8: Gabriel | C8: Extrajudicial - 40 a 55 semanas de atraso | D8: =SUMIF('REPORTE DIARIO'!B:B,'EPR 26 JUN'!C8, 'REPORTE DIARIO'!C:C) -> 13468 | E8: =SUMIF('REPORTE DIARIO'!B:B,'EPR 26 JUN'!C8, 'REPORTE DIARIO'!D:D) -> 177903.34 | F8: =J8*D8 -> 173160 | G8: =+E8-F8 -> 4743.34 | H8: =ABS(G8/F8) -> 0.027392816 | I8: =E8/D8 -> 13.209336 | J8: =(45/7)*2 -> 12.857143 | K8: =+I8-J8 -> 0.35219335
B9: Fernando (Naucalpan) | C9: Mas 55 semanas de atraso | D9: =SUMIF('REPORTE DIARIO'!B:B,'EPR 26 JUN'!C9, 'REPORTE DIARIO'!C:C) -> 55138 | E9: =SUMIF('REPORTE DIARIO'!B:B,'EPR 26 JUN'!C9, 'REPORTE DIARIO'!D:D) -> 277954.71 | F9: =J9*D9 -> 236305.71 | G9: =+E9-F9 -> 41648.996 | H9: =ABS(G9/F9) -> 0.17625048 | I9: =E9/D9 -> 5.0410735 | J9: =(15/7)*2 -> 4.2857143 | K9: =+I9-J9 -> 0.7553592
C10: TOTAL | D10: =SUM(D6:D9) -> 89676 | E10: =SUM(E6:E9) -> 1257177.5 | F10: =SUM(F6:F9) -> 1485957.1 | G10: =+E10-F10 -> -228779.68 | H10: =ABS(G10/F10) -> 0.15396116 | I10: =E10/D10 -> 14.019107 | J10: =F10/D10 -> 16.570288 | K10: =I10-J10 -> -2.5511807
B12: Nota:
B13: El saldo consolidado incluye los siguientes despachos
B14: Samantha, Samantha 2, Sofia, Edith, Fernando, Olguin y Federico
