Workbook

Sheet REPORTE DIARIO
B3: COBRANZA GENERAL SAMANTHA
B4: Segmento | C4: Cuentas | D4: Recuperación
B5: Extrajudicial - 0 a 28 semanas de atraso | C5: 3007 | D5: 259175.3
B6: Extrajudicial - 29 a 39 semanas de atraso | C6: 3149 | D6: 125490
B7: Extrajudicial - 40 a 55 semanas de atraso | C7: 6066 | D7: 133735.46
B8: JUDICIAL | C8: 11 | D8: 0
B9: Mas 55 semanas de atraso | C9: 12535 | D9: 174785
B10: Total general | C10: =SUM(C5:C9) -> 24768 | D10: =SUM(D5:D9) -> 693185.76
B12: COBRANZA GENERAL EDITH
B13: Segmento | C13: Cuentas | D13: Recuperación
B14: Extrajudicial - 0 a 28 semanas de atraso | C14: 3402 | D14: 164081.65
B15: Extrajudicial - 29 a 39 semanas de atraso | C15: 1031 | D15: 13251.5
B16: Extrajudicial - 40 a 55 semanas de atraso | C16: 2069 | D16: 102608.8
B17: JUDICIAL | C17: 1 | D17: 0
B18: Mas 55 semanas de atraso | C18: 16858 | D18: 38186
B19: Total general | C19: =SUM(C14:C18) -> 23361 | D19: =SUM(D14:D18) -> 318127.95
B21: COBRANZA GENERAL SAMANTHA 2
B22: Segmento | C22: Cuentas | D22: Recuperación
B23: Extrajudicial - 0 a 28 semanas de atraso | C23: 2867 | D23: 59755
B24: Extrajudicial - 29 a 39 semanas de atraso | C24: 1918 | D24: 38802.32
B25: Extrajudicial - 40 a 55 semanas de atraso | C25: 2529 | D25: 36146
B26: JUDICIAL | C26: 0 | D26: 0
B27: Mas 55 semanas de atraso | C27: 12741 | D27: 45356.9
B28: Total general | C28: =SUM(C23:C27) -> 20055 | D28: =SUM(D23:D27) -> 180060.22
B30: COBRANZA GENERAL SOFIA
B31: Segmento | C31: Cuentas | D31: Recuperación
B32: Extrajudicial - 0 a 28 semanas de atraso | C32: 323 | D32: 68723.68
B33: Extrajudicial - 29 a 39 semanas de atraso | C33: 2867 | D33: 35975.5
B34: Extrajudicial - 40 a 55 semanas de atraso | C34: 287 | D34: 1637
B35: Mas 55 semanas de atraso | C35: 3964 | D35: 7800
B36: Total general | C36: =SUM(C32:C35) -> 7441 | D36: =SUM(D32:D35) -> 114136.18
B38: COBRANZA GENERAL OLGUIN
B39: Segmento | C39: Cuentas | D39: Recuperación
B40: Extrajudicial - 0 a 28 semanas de atraso | C40: 2266 | D40: 52769
B41: Extrajudicial - 29 a 39 semanas de atraso | C41: 1386 | D41: 12413
B42: Extrajudicial - 40 a 55 semanas de atraso | C42: 2003 | D42: 9580
B43: Mas 55 semanas de atraso | C43: 1810 | D43: 7200
B44: Total general | C44: =SUM(C40:C43) -> 7465 | D44: =SUM(D40:D43) -> 81962
B46: COBRANZA GENERAL FERNANDO
B47: Segmento | C47: Cuentas | D47: Recuperación
...

Sheet DATA

Sheet EPR 11 JUN
B2: REPORTE CONSOLIDADO POR SEGMENTOS
B3: SALDO ACUMULADO SEMANA 24
B5: COORDINADOR | C5: SEGMENTO | D5: CUENTAS | E5: COBRANZA REAL | F5: CUOTA IDEAL | G5: VARIACION | H5: % VAR | I5: EPR | J5: EPR IDEAL | K5: VAR EPR
B6: Zareth | C6: Extrajudicial - 0 a 28 semanas de atraso | D6: =SUMIF('REPORTE DIARIO'!B:B,'EPR 11 JUN'!C6, 'REPORTE DIARIO'!C:C) -> 15175 | E6: =SUMIF('REPORTE DIARIO'!B:B,'EPR 11 JUN'!C6, 'REPORTE DIARIO'!D:D) -> 637270.63 | F6: =J6*D6 -> 1907714.3 | G6: =+E6-F6 -> -1270443.7 | H6: =ABS(G6/F6) -> 0.6659507 | I6: =E6/D6 -> 41.99477 | J6: =(220/7)*4 -> 125.71429 | K6: =+I6-J6 -> -83.719516
B7: Gabriel | C7: Extrajudicial - 29 a 39 semanas de atraso | D7: =SUMIF('REPORTE DIARIO'!B:B,'EPR 11 JUN'!C7, 'REPORTE DIARIO'!C:C) -> 10958 | E7: =SUMIF('REPORTE DIARIO'!B:B,'EPR 11 JUN'!C7, 'REPORTE DIARIO'!D:D) -> 230585.32 | F7: =J7*D7 -> 688788.57 | G7: =+E7-F7 -> -458203.25 | H7: =ABS(G7/F7) -> 0.66523062 | I7: =E7/D7 -> 21.042646 | J7: =(110/7)*4 -> 62.857143 | K7: =+I7-J7 -> -41.814496
B8: Gabriel | C8: Extrajudicial - 40 a 55 semanas de atraso | D8: =SUMIF('REPORTE DIARIO'!B:B,'EPR 11 JUN'!C8, 'REPORTE DIARIO'!C:C) -> 13758 | E8: =SUMIF('REPORTE DIARIO'!B:B,'EPR 11 JUN'!C8, 'REPORTE DIARIO'!D:D) -> 283707.26 | F8: =J8*D8 -> 353777.14 | G8: =+E8-F8 -> -70069.883 | H8: =ABS(G8/F8) -> 0.19806221 | I8: =E8/D8 -> 20.621257 | J8: =(45/7)*4 -> 25.714286 | K8: =+I8-J8 -> -5.0930283
B9: Fernando (Naucalpan) | C9: Mas 55 semanas de atraso | D9: =SUMIF('REPORTE DIARIO'!B:B,'EPR 11 JUN'!C9, 'REPORTE DIARIO'!C:C) -> 50369 | E9: =SUMIF('REPORTE DIARIO'!B:B,'EPR 11 JUN'!C9, 'REPORTE DIARIO'!D:D) -> 276864.9 | F9: =J9*D9 -> 431734.29 | G9: =+E9-F9 -> -154869.39 | H9: =ABS(G9/F9) -> 0.35871459 | I9: =E9/D9 -> 5.4967321 | J9: =(15/7)*4 -> 8.5714286 | K9: =+I9-J9 -> -3.0746965
C10: TOTAL | D10: =SUM(D6:D9) -> 90260 | E10: =SUM(E6:E9) -> 1428428.1 | F10: =SUM(F6:F9) -> 3382014.3 | G10: =+E10-F10 -> -1953586.2 | H10: =ABS(G10/F10) -> 0.57763984 | I10: =E10/D10 -> 15.825705 | J10: =F10/D10 -> 37.469691 | K10: =I10-J10 -> -21.643986
B12: Nota:
B13: El saldo consolidado incluye los siguientes despachos
B14: Samantha, Samantha 2, Sofia, Edith, Fernando, Olguin y Federico
