Workbook

Sheet REPORTE DIARIO
B3: COBRANZA GENERAL SAMANTHA
B4: Segmento | C4: Cuentas | D4: Recuperación
B5: Extrajudicial - 0 a 28 semanas de atraso | C5: 2626 | D5: 144367.05
B6: Extrajudicial - 29 a 39 semanas de atraso | C6: 2960 | D6: 227179.88
B7: Extrajudicial - 40 a 55 semanas de atraso | C7: 5515 | D7: 139276.31
B8: JUDICIAL | C8: 11 | D8: 0
B9: Mas 55 semanas de atraso | C9: 11575 | D9: 227260.38
B10: Total general | C10: =SUM(C5:C9) -> 22687 | D10: =SUM(D5:D9) -> 738083.62
B12: COBRANZA GENERAL SAMANTHA 2
B13: Segmento | C13: Cuentas | D13: Recuperación
B14: Extrajudicial - 0 a 28 semanas de atraso | C14: 2880 | D14: 130108.05
B15: Extrajudicial - 29 a 39 semanas de atraso | C15: 2114 | D15: 66982.94
B16: Extrajudicial - 40 a 55 semanas de atraso | C16: 2743 | D16: 70615.17
B17: JUDICIAL | C17: 2 | D17: 0
B18: Mas 55 semanas de atraso | C18: 17881 | D18: 45850.73
B19: Total general | C19: =SUM(C14:C18) -> 25620 | D19: =SUM(D14:D18) -> 313556.89
B21: COBRANZA GENERAL EDITH
B22: Segmento | C22: Cuentas | D22: Recuperación
B23: Extrajudicial - 0 a 28 semanas de atraso | C23: 3218 | D23: 143081.27
B24: Extrajudicial - 29 a 39 semanas de atraso | C24: 1015 | D24: 21319.61
B25: Extrajudicial - 40 a 55 semanas de atraso | C25: 2120 | D25: 17192.45
B26: JUDICIAL | C26: 1 | D26: 0
B27: Mas 55 semanas de atraso | C27: 16874 | D27: 21522.4
B28: Total general | C28: =SUM(C23:C27) -> 23228 | D28: =SUM(D23:D27) -> 203115.73
B30: COBRANZA GENERAL SOFIA
B31: Segmento | C31: Cuentas | D31: Recuperación
B32: Extrajudicial - 0 a 28 semanas de atraso | C32: 52 | D32: 8731.5
B33: Extrajudicial - 29 a 39 semanas de atraso | C33: 3312 | D33: 103973.57
B34: Extrajudicial - 40 a 55 semanas de atraso | C34: 286 | D34: 14808
B35: Mas 55 semanas de atraso | C35: 3953 | D35: 3219
B36: Total general | C36: =SUM(C32:C35) -> 7603 | D36: =SUM(D32:D35) -> 130732.07
B38: COBRANZA GENERAL OLGUIN
B39: Segmento | C39: Cuentas | D39: Recuperación
B40: Extrajudicial - 0 a 28 semanas de atraso | C40: 2196 | D40: 40213.9
B41: Extrajudicial - 29 a 39 semanas de atraso | C41: 1346 | D41: 4985
B42: Extrajudicial - 40 a 55 semanas de atraso | C42: 2200 | D42: 1731
B43: Mas 55 semanas de atraso | C43: 2186 | D43: 53809.21
B44: Total general | C44: =SUM(C40:C43) -> 7928 | D44: =SUM(D40:D43) -> 100739.11
B46: COBRANZA GENERAL FEDERICO
B47: Segmento | C47: Cuentas | D47: Recuperación
...

Sheet DATA

Sheet EPR 05 JUN
B2: REPORTE CONSOLIDADO POR SEGMENTOS
B3: SALDO ACUMULADO SEMANA 23
B5: COORDINADOR | C5: SEGMENTO | D5: CUENTAS | E5: COBRANZA REAL | F5: CUOTA IDEAL | G5: VARIACION | H5: % VAR | I5: EPR | J5: EPR IDEAL | K5: VAR EPR
B6: Zareth | C6: Extrajudicial - 0 a 28 semanas de atraso | D6: =SUMIF('REPORTE DIARIO'!B:B,'EPR 05 JUN'!C6, 'REPORTE DIARIO'!C:C) -> 14394 | E6: =SUMIF('REPORTE DIARIO'!B:B,'EPR 05 JUN'!C6, 'REPORTE DIARIO'!D:D) -> 582946.7 | F6: =J6*D6 -> 1809531.4 | G6: =+E6-F6 -> -1226584.7 | H6: =ABS(G6/F6) -> 0.6778466 | I6: =E6/D6 -> 40.499284 | J6: =(220/7)*4 -> 125.71429 | K6: =+I6-J6 -> -85.215001
B7: Gabriel | C7: Extrajudicial - 29 a 39 semanas de atraso | D7: =SUMIF('REPORTE DIARIO'!B:B,'EPR 05 JUN'!C7, 'REPORTE DIARIO'!C:C) -> 11389 | E7: =SUMIF('REPORTE DIARIO'!B:B,'EPR 05 JUN'!C7, 'REPORTE DIARIO'!D:D) -> 430404 | F7: =J7*D7 -> 715880 | G7: =+E7-F7 -> -285476 | H7: =ABS(G7/F7) -> 0.39877633 | I7: =E7/D7 -> 37.791202 | J7: =(110/7)*4 -> 62.857143 | K7: =+I7-J7 -> -25.065941
B8: Gabriel | C8: Extrajudicial - 40 a 55 semanas de atraso | D8: =SUMIF('REPORTE DIARIO'!B:B,'EPR 05 JUN'!C8, 'REPORTE DIARIO'!C:C) -> 13669 | E8: =SUMIF('REPORTE DIARIO'!B:B,'EPR 05 JUN'!C8, 'REPORTE DIARIO'!D:D) -> 244113.93 | F8: =J8*D8 -> 351488.57 | G8: =+E8-F8 -> -107374.64 | H8: =ABS(G8/F8) -> 0.30548544 | I8: =E8/D8 -> 17.858946 | J8: =(45/7)*4 -> 25.714286 | K8: =+I8-J8 -> -7.8553399
B9: Fernando (Naucalpan) | C9: Mas 55 semanas de atraso | D9: =SUMIF('REPORTE DIARIO'!B:B,'EPR 05 JUN'!C9, 'REPORTE DIARIO'!C:C) -> 54938 | E9: =SUMIF('REPORTE DIARIO'!B:B,'EPR 05 JUN'!C9, 'REPORTE DIARIO'!D:D) -> 359722.72 | F9: =J9*D9 -> 470897.14 | G9: =+E9-F9 -> -111174.42 | H9: =ABS(G9/F9) -> 0.23609067 | I9: =E9/D9 -> 6.5477942 | J9: =(15/7)*4 -> 8.5714286 | K9: =+I9-J9 -> -2.0236343
C10: TOTAL | D10: =SUM(D6:D9) -> 94390 | E10: =SUM(E6:E9) -> 1617187.4 | F10: =SUM(F6:F9) -> 3347797.1 | G10: =+E10-F10 -> -1730609.8 | H10: =ABS(G10/F10) -> 0.51693986 | I10: =E10/D10 -> 17.133037 | J10: =F10/D10 -> 35.46771 | K10: =I10-J10 -> -18.334673
B12: Nota:
B13: El saldo consolidado incluye los siguientes despachos
B14: Samantha, Samantha 2, Sofia, Edith, Fernando, Olguin y Federico
