Workbook

Sheet REPORTE DIARIO
B3: COBRANZA GENERAL SAMANTHA
B4: Segmento | C4: Cuentas | D4: Recuperación
B5: Extrajudicial - 0 a 28 semanas de atraso | C5: 5920 | D5: 149345
B6: Extrajudicial - 29 a 39 semanas de atraso | C6: 6656 | D6: 90729
B7: Extrajudicial - 40 a 55 semanas de atraso | C7: 9854 | D7: 34717
B8: JUDICIAL | C8: 21 | D8: 0
B9: Mas 55 semanas de atraso | C9: 28822 | D9: 66662.84
B10: Total general | C10: =SUM(C5:C9) -> 51273 | D10: =SUM(D5:D9) -> 341453.84
B12: COBRANZA GENERAL SAMANTHA 2
B13: Segmento | C13: Cuentas | D13: Recuperación
B14: Extrajudicial - 0 a 28 semanas de atraso | C14: 2357 | D14: 22792.3
B15: Extrajudicial - 29 a 39 semanas de atraso | C15: 1431 | D15: 23524
B16: Extrajudicial - 40 a 55 semanas de atraso | C16: 3415 | D16: 6729
B17: JUDICIAL | C17: 2 | D17: 0
B18: Mas 55 semanas de atraso | C18: 21143 | D18: 32599
B19: Total general | C19: =SUM(C14:C18) -> 28348 | D19: =SUM(D14:D18) -> 85644.3
B21: COBRANZA GENERAL EDITH
B22: Segmento | C22: Cuentas | D22: Recuperación
B23: Extrajudicial - 0 a 28 semanas de atraso | C23: 1466 | D23: 21127.97
B24: Extrajudicial - 29 a 39 semanas de atraso | C24: 1495 | D24: 21034
B25: Extrajudicial - 40 a 55 semanas de atraso | C25: 840 | D25: 4376
B26: Mas 55 semanas de atraso | C26: 8341 | D26: 18764
B27: Total general | C27: =SUM(C23:C26) -> 12142 | D27: =SUM(D23:D26) -> 65301.97
B29: COBRANZA GENERAL SOFIA
B30: Segmento | C30: Cuentas | D30: Recuperación
B31: Extrajudicial - 0 a 28 semanas de atraso | C31: 1195 | D31: 27219
B32: Extrajudicial - 29 a 39 semanas de atraso | C32: 1282 | D32: 6187
B33: Extrajudicial - 40 a 55 semanas de atraso | C33: 2933 | D33: 698
B34: Mas 55 semanas de atraso | C34: 1828 | D34: 1110
B35: Total general | C35: =SUM(C31:C34) -> 7238 | D35: =SUM(D31:D34) -> 35214
B37: COBRANZA GENERAL FERNANDO
B38: Segmento | C38: Cuentas | D38: Recuperación
B39: Extrajudicial - 0 a 28 semanas de atraso | C39: 2740 | D39: 19251
B40: Total general | C40: =SUM(C39:C39) -> 2740 | D40: =SUM(D39:D39) -> 19251
B42: COBRANZA GENERAL FEDERICO
B43: Segmento | C43: Cuentas | D43: Recuperación
B44: Extrajudicial - 0 a 28 semanas de atraso | C44: 3 | D44: 0
B45: Extrajudicial - 29 a 39 semanas de atraso | C45: 110 | D45: 0
B46: Extrajudicial - 40 a 55 semanas de atraso | C46: 135 | D46: 0
B47: Mas 55 semanas de atraso | C47: 1494 | D47: 1753
...

Sheet DATA

Sheet EPR 4 ABR
B2: REPORTE CONSOLIDADO POR SEGMENTOS
B3: COBRANZA 04 ABRIL
B5: COORDINADOR | C5: SEGMENTO | D5: CUENTAS | E5: COBRANZA REAL | F5: CUOTA IDEAL | G5: VARIACION | H5: % VAR | I5: EPR | J5: EPR IDEAL | K5: VAR EPR
B6: Samatha y Zareth | C6: Extrajudicial - 0 a 28 semanas de atraso | D6: =SUMIF('REPORTE DIARIO'!B:B,'EPR 4 ABR'!C6, 'REPORTE DIARIO'!C:C) -> 13749 | E6: =SUMIF('REPORTE DIARIO'!B:B,'EPR 4 ABR'!C6, 'REPORTE DIARIO'!D:D) -> 239735.27 | F6: =J6*D6 -> 392828.57 | G6: =+E6-F6 -> -153093.3 | H6: =ABS(G6/F6) -> 0.38972038 | I6: =E6/D6 -> 17.43656 | J6: =200/7 -> 28.571429 | K6: =+I6-J6 -> -11.134868
B7: Gabriel | C7: Extrajudicial - 29 a 39 semanas de atraso | D7: =SUMIF('REPORTE DIARIO'!B:B,'EPR 4 ABR'!C7, 'REPORTE DIARIO'!C:C) -> 11036 | E7: =SUMIF('REPORTE DIARIO'!B:B,'EPR 4 ABR'!C7, 'REPORTE DIARIO'!D:D) -> 141474 | F7: =J7*D7 -> 173422.86 | G7: =+E7-F7 -> -31948.857 | H7: =ABS(G7/F7) -> 0.18422518 | I7: =E7/D7 -> 12.819319 | J7: =110/7 -> 15.714286 | K7: =+I7-J7 -> -2.8949671
B8: Gabriel | C8: Extrajudicial - 40 a 55 semanas de atraso | D8: =SUMIF('REPORTE DIARIO'!B:B,'EPR 4 ABR'!C8, 'REPORTE DIARIO'!C:C) -> 17190 | E8: =SUMIF('REPORTE DIARIO'!B:B,'EPR 4 ABR'!C8, 'REPORTE DIARIO'!D:D) -> 46520 | F8: =J8*D8 -> 110507.14 | G8: =+E8-F8 -> -63987.143 | H8: =ABS(G8/F8) -> 0.57903174 | I8: =E8/D8 -> 2.7062245 | J8: =45/7 -> 6.4285714 | K8: =+I8-J8 -> -3.7223469
B9: Fernando | C9: Mas 55 semanas de atraso | D9: =SUMIF('REPORTE DIARIO'!B:B,'EPR 4 ABR'!C9, 'REPORTE DIARIO'!C:C) -> 61637 | E9: =SUMIF('REPORTE DIARIO'!B:B,'EPR 4 ABR'!C9, 'REPORTE DIARIO'!D:D) -> 120888.84 | F9: =J9*D9 -> 132079.29 | G9: =+E9-F9 -> -11190.446 | H9: =ABS(G9/F9) -> 0.084725214 | I9: =E9/D9 -> 1.9613031 | J9: =15/7 -> 2.1428571 | K9: =+I9-J9 -> -0.18155403
C10: TOTAL | D10: =SUM(D6:D9) -> 103612 | E10: =SUM(E6:E9) -> 548618.11 | F10: =SUM(F6:F9) -> 808837.86 | G10: =+E10-F10 -> -260219.75 | H10: =ABS(G10/F10) -> 0.32172053 | I10: =E10/D10 -> 5.2949283 | J10: =F10/D10 -> 7.806411 | K10: =I10-J10 -> -2.5114827
B12: Nota:
B13: El saldo consolidado incluye los siguientes despachos
B14: Samantha, Samantha 2, Sofia, Edith, Olguin, Fernando y Federico
