Workbook

Sheet REPORTE DIARIO
B3: COBRANZA GENERAL SAMANTHA
B4: Segmento | C4: Cuentas | D4: Recuperación
B5: Extrajudicial - 0 a 28 semanas de atraso | C5: 2485 | D5: 70217.89
B6: Extrajudicial - 29 a 39 semanas de atraso | C6: 2914 | D6: 74035.88
B7: Extrajudicial - 40 a 55 semanas de atraso | C7: 5095 | D7: 87020.3
B8: JUDICIAL | C8: 11 | D8: 0
B9: Mas 55 semanas de atraso | C9: 11392 | D9: 114262.69
B10: Total general | C10: =SUM(C5:C9) -> 21897 | D10: =SUM(D5:D9) -> 345536.76
B12: COBRANZA GENERAL SAMANTHA 2
B13: Segmento | C13: Cuentas | D13: Recuperación
B14: Extrajudicial - 0 a 28 semanas de atraso | C14: 2791 | D14: 66990.28
B15: Extrajudicial - 29 a 39 semanas de atraso | C15: 2174 | D15: 22410.01
B16: Extrajudicial - 40 a 55 semanas de atraso | C16: 2555 | D16: 15416.17
B17: JUDICIAL | C17: 2 | D17: 0
B18: Mas 55 semanas de atraso | C18: 17753 | D18: 22742
B19: Total general | C19: =SUM(C14:C18) -> 25275 | D19: =SUM(D14:D18) -> 127558.46
B21: COBRANZA GENERAL EDITH
B22: Segmento | C22: Cuentas | D22: Recuperación
B23: Extrajudicial - 0 a 28 semanas de atraso | C23: 3145 | D23: 68880.87
B24: Extrajudicial - 29 a 39 semanas de atraso | C24: 1138 | D24: 16273.61
B25: Extrajudicial - 40 a 55 semanas de atraso | C25: 2148 | D25: 14124.45
B26: JUDICIAL | C26: 1 | D26: 0
B27: Mas 55 semanas de atraso | C27: 17174 | D27: 16732.39
B28: Total general | C28: =SUM(C23:C27) -> 23606 | D28: =SUM(D23:D27) -> 116011.32
B30: COBRANZA GENERAL FEDERICO
B31: Segmento | C31: Cuentas | D31: Recuperación
B32: Extrajudicial - 0 a 28 semanas de atraso | C32: 586 | D32: 55401.93
B33: Extrajudicial - 29 a 39 semanas de atraso | C33: 647 | D33: 4323
B34: Extrajudicial - 40 a 55 semanas de atraso | C34: 807 | D34: 491
B35: Mas 55 semanas de atraso | C35: 2471 | D35: 5694
B36: Total general | C36: =SUM(C32:C35) -> 4511 | D36: =SUM(D32:D35) -> 65909.93
B38: COBRANZA GENERAL SOFIA
B39: Segmento | C39: Cuentas | D39: Recuperación
B40: Extrajudicial - 0 a 28 semanas de atraso | C40: 53 | D40: 4052.5
B41: Extrajudicial - 29 a 39 semanas de atraso | C41: 3433 | D41: 47931.39
B42: Extrajudicial - 40 a 55 semanas de atraso | C42: 289 | D42: 3860
B43: Mas 55 semanas de atraso | C43: 3972 | D43: 1112
B44: Total general | C44: =SUM(C40:C43) -> 7747 | D44: =SUM(D40:D43) -> 56955.89
B46: COBRANZA GENERAL OLGUIN
B47: Segmento | C47: Cuentas | D47: Recuperación
...

Sheet DATA

Sheet EPR 03 JUN
B2: REPORTE CONSOLIDADO POR SEGMENTOS
B3: SALDO ACUMULADO SEMANA 23
B5: COORDINADOR | C5: SEGMENTO | D5: CUENTAS | E5: COBRANZA REAL | F5: CUOTA IDEAL | G5: VARIACION | H5: % VAR | I5: EPR | J5: EPR IDEAL | K5: VAR EPR
B6: Zareth | C6: Extrajudicial - 0 a 28 semanas de atraso | D6: =SUMIF('REPORTE DIARIO'!B:B,'EPR 03 JUN'!C6, 'REPORTE DIARIO'!C:C) -> 13945 | E6: =SUMIF('REPORTE DIARIO'!B:B,'EPR 03 JUN'!C6, 'REPORTE DIARIO'!D:D) -> 292846.37 | F6: =J6*D6 -> 876542.86 | G6: =+E6-F6 -> -583696.49 | H6: =ABS(G6/F6) -> 0.66590753 | I6: =E6/D6 -> 21.000098 | J6: =(220/7)*2 -> 62.857143 | K6: =+I6-J6 -> -41.857045
B7: Gabriel | C7: Extrajudicial - 29 a 39 semanas de atraso | D7: =SUMIF('REPORTE DIARIO'!B:B,'EPR 03 JUN'!C7, 'REPORTE DIARIO'!C:C) -> 11597 | E7: =SUMIF('REPORTE DIARIO'!B:B,'EPR 03 JUN'!C7, 'REPORTE DIARIO'!D:D) -> 166379.89 | F7: =J7*D7 -> 364477.14 | G7: =+E7-F7 -> -198097.25 | H7: =ABS(G7/F7) -> 0.54351077 | I7: =E7/D7 -> 14.346804 | J7: =(110/7)*2 -> 31.428571 | K7: =+I7-J7 -> -17.081767
B8: Gabriel | C8: Extrajudicial - 40 a 55 semanas de atraso | D8: =SUMIF('REPORTE DIARIO'!B:B,'EPR 03 JUN'!C8, 'REPORTE DIARIO'!C:C) -> 12911 | E8: =SUMIF('REPORTE DIARIO'!B:B,'EPR 03 JUN'!C8, 'REPORTE DIARIO'!D:D) -> 120911.92 | F8: =J8*D8 -> 165998.57 | G8: =+E8-F8 -> -45086.651 | H8: =ABS(G8/F8) -> 0.27160867 | I8: =E8/D8 -> 9.3650314 | J8: =(45/7)*2 -> 12.857143 | K8: =+I8-J8 -> -3.4921115
B9: Fernando (Naucalpan) | C9: Mas 55 semanas de atraso | D9: =SUMIF('REPORTE DIARIO'!B:B,'EPR 03 JUN'!C9, 'REPORTE DIARIO'!C:C) -> 54808 | E9: =SUMIF('REPORTE DIARIO'!B:B,'EPR 03 JUN'!C9, 'REPORTE DIARIO'!D:D) -> 165370.54 | F9: =J9*D9 -> 234891.43 | G9: =+E9-F9 -> -69520.889 | H9: =ABS(G9/F9) -> 0.29597031 | I9: =E9/D9 -> 3.0172701 | J9: =(15/7)*2 -> 4.2857143 | K9: =+I9-J9 -> -1.2684442
C10: TOTAL | D10: =SUM(D6:D9) -> 93261 | E10: =SUM(E6:E9) -> 745508.72 | F10: =SUM(F6:F9) -> 1641910 | G10: =+E10-F10 -> -896401.28 | H10: =ABS(G10/F10) -> 0.54595031 | I10: =E10/D10 -> 7.9937886 | J10: =F10/D10 -> 17.605537 | K10: =I10-J10 -> -9.6117485
B12: Nota:
B13: El saldo consolidado incluye los siguientes despachos
B14: Samantha, Samantha 2, Sofia, Edith, Fernando, Olguin y Federico
