Workbook

Sheet REPORTE DIARIO
B3: COBRANZA GENERAL SAMANTHA
B4: Segmento | C4: Cuentas | D4: Recuperación
B5: Extrajudicial - 0 a 28 semanas de atraso | C5: 3161 | D5: 183525.87
B6: Extrajudicial - 29 a 39 semanas de atraso | C6: 3720 | D6: 65524.14
B7: Extrajudicial - 40 a 55 semanas de atraso | C7: 6470 | D7: 60840.19
B8: JUDICIAL | C8: 11 | D8: 0
B9: Mas 55 semanas de atraso | C9: 12657 | D9: 73506.86
B10: Total general | C10: =SUM(C5:C9) -> 26019 | D10: =SUM(D5:D9) -> 383397.06
B12: COBRANZA GENERAL EDITH
B13: Segmento | C13: Cuentas | D13: Recuperación
B14: Extrajudicial - 0 a 28 semanas de atraso | C14: 3207 | D14: 60714.7
B15: Extrajudicial - 29 a 39 semanas de atraso | C15: 1578 | D15: 16511.04
B16: Extrajudicial - 40 a 55 semanas de atraso | C16: 2081 | D16: 17291.83
B17: JUDICIAL | C17: 1 | D17: 0
B18: Mas 55 semanas de atraso | C18: 16855 | D18: 45294.01
B19: Total general | C19: =SUM(C14:C18) -> 23722 | D19: =SUM(D14:D18) -> 139811.58
B21: COBRANZA GENERAL SAMANTHA 2
B22: Segmento | C22: Cuentas | D22: Recuperación
B23: Extrajudicial - 0 a 28 semanas de atraso | C23: 2706 | D23: 76489
B24: Extrajudicial - 29 a 39 semanas de atraso | C24: 1905 | D24: 11759
B25: Extrajudicial - 40 a 55 semanas de atraso | C25: 2633 | D25: 35070
B26: JUDICIAL | C26: 0 | D26: 0
B27: Mas 55 semanas de atraso | C27: 12629 | D27: 11364
B28: Total general | C28: =SUM(C23:C27) -> 19873 | D28: =SUM(D23:D27) -> 134682
B30: COBRANZA GENERAL SOFIA
B31: Segmento | C31: Cuentas | D31: Recuperación
B32: Extrajudicial - 0 a 28 semanas de atraso | C32: 496 | D32: 29366.13
B33: Extrajudicial - 29 a 39 semanas de atraso | C33: 2858 | D33: 48886.42
B34: Extrajudicial - 40 a 55 semanas de atraso | C34: 362 | D34: 594
B35: Mas 55 semanas de atraso | C35: 4001 | D35: 1050
B36: Total general | C36: =SUM(C32:C35) -> 7717 | D36: =SUM(D32:D35) -> 79896.55
B38: COBRANZA GENERAL FEDERICO
B39: Segmento | C39: Cuentas | D39: Recuperación
B40: Extrajudicial - 0 a 28 semanas de atraso | C40: 580 | D40: 4892
B41: Extrajudicial - 29 a 39 semanas de atraso | C41: 606 | D41: 640
B42: Extrajudicial - 40 a 55 semanas de atraso | C42: 776 | D42: 16201
B43: Mas 55 semanas de atraso | C43: 2426 | D43: 2468
B44: Total general | C44: =SUM(C40:C43) -> 4388 | D44: =SUM(D40:D43) -> 24201
B46: COBRANZA GENERAL FERNANDO
B47: Segmento | C47: Cuentas | D47: Recuperación
...

Sheet DATA

Sheet EPR 17 JUN
B2: REPORTE CONSOLIDADO POR SEGMENTOS
B3: SALDO ACUMULADO SEMANA 25
B5: COORDINADOR | C5: SEGMENTO | D5: CUENTAS | E5: COBRANZA REAL | F5: CUOTA IDEAL | G5: VARIACION | H5: % VAR | I5: EPR | J5: EPR IDEAL | K5: VAR EPR
B6: Zareth | C6: Extrajudicial - 0 a 28 semanas de atraso | D6: =SUMIF('REPORTE DIARIO'!B:B,'EPR 17 JUN'!C6, 'REPORTE DIARIO'!C:C) -> 14870 | E6: =SUMIF('REPORTE DIARIO'!B:B,'EPR 17 JUN'!C6, 'REPORTE DIARIO'!D:D) -> 377333.32 | F6: =J6*D6 -> 934685.71 | G6: =+E6-F6 -> -557352.39 | H6: =ABS(G6/F6) -> 0.59629925 | I6: =E6/D6 -> 25.375475 | J6: =(220/7)*2 -> 62.857143 | K6: =+I6-J6 -> -37.481667
B7: Gabriel | C7: Extrajudicial - 29 a 39 semanas de atraso | D7: =SUMIF('REPORTE DIARIO'!B:B,'EPR 17 JUN'!C7, 'REPORTE DIARIO'!C:C) -> 12156 | E7: =SUMIF('REPORTE DIARIO'!B:B,'EPR 17 JUN'!C7, 'REPORTE DIARIO'!D:D) -> 144476.6 | F7: =J7*D7 -> 382045.71 | G7: =+E7-F7 -> -237569.11 | H7: =ABS(G7/F7) -> 0.62183426 | I7: =E7/D7 -> 11.885209 | J7: =(110/7)*2 -> 31.428571 | K7: =+I7-J7 -> -19.543362
B8: Gabriel | C8: Extrajudicial - 40 a 55 semanas de atraso | D8: =SUMIF('REPORTE DIARIO'!B:B,'EPR 17 JUN'!C8, 'REPORTE DIARIO'!C:C) -> 14336 | E8: =SUMIF('REPORTE DIARIO'!B:B,'EPR 17 JUN'!C8, 'REPORTE DIARIO'!D:D) -> 130997.02 | F8: =J8*D8 -> 184320 | G8: =+E8-F8 -> -53322.98 | H8: =ABS(G8/F8) -> 0.28929568 | I8: =E8/D8 -> 9.137627 | J8: =(45/7)*2 -> 12.857143 | K8: =+I8-J8 -> -3.7195159
B9: Fernando (Naucalpan) | C9: Mas 55 semanas de atraso | D9: =SUMIF('REPORTE DIARIO'!B:B,'EPR 17 JUN'!C9, 'REPORTE DIARIO'!C:C) -> 50432 | E9: =SUMIF('REPORTE DIARIO'!B:B,'EPR 17 JUN'!C9, 'REPORTE DIARIO'!D:D) -> 134766.87 | F9: =J9*D9 -> 216137.14 | G9: =+E9-F9 -> -81370.273 | H9: =ABS(G9/F9) -> 0.37647519 | I9: =E9/D9 -> 2.6722492 | J9: =(15/7)*2 -> 4.2857143 | K9: =+I9-J9 -> -1.6134651
C10: TOTAL | D10: =SUM(D6:D9) -> 91794 | E10: =SUM(E6:E9) -> 787573.81 | F10: =SUM(F6:F9) -> 1717188.6 | G10: =+E10-F10 -> -929614.76 | H10: =ABS(G10/F10) -> 0.54135858 | I10: =E10/D10 -> 8.5797962 | J10: =F10/D10 -> 18.706981 | K10: =I10-J10 -> -10.127184
B12: Nota:
B13: El saldo consolidado incluye los siguientes despachos
B14: Samantha, Samantha 2, Sofia, Edith, Fernando, Olguin y Federico
