Workbook

Sheet REPORTE DIARIO
B3: COBRANZA GENERAL SAMANTHA
B4: Segmento | C4: Cuentas | D4: Recuperación
B5: Extrajudicial - 0 a 28 semanas de atraso | C5: 6640 | D5: 44706.26
B6: Extrajudicial - 29 a 39 semanas de atraso | C6: 5870 | D6: 55123
B7: Extrajudicial - 40 a 55 semanas de atraso | C7: 8851 | D7: 54468
B8: JUDICIAL | C8: 21 | D8: 0
B9: Mas 55 semanas de atraso | C9: 21315 | D9: 94026.6
B10: Total general | C10: =SUM(C5:C9) -> 42697 | D10: =SUM(D5:D9) -> 248323.86
B12: COBRANZA GENERAL EDITH
B13: Segmento | C13: Cuentas | D13: Recuperación
B14: Extrajudicial - 0 a 28 semanas de atraso | C14: 2023 | D14: 107823.84
B15: Extrajudicial - 29 a 39 semanas de atraso | C15: 2166 | D15: 8515
B16: Extrajudicial - 40 a 55 semanas de atraso | C16: 935 | D16: 3501
B17: Mas 55 semanas de atraso | C17: 8971 | D17: 9423.75
B18: Total general | C18: =SUM(C14:C17) -> 14095 | D18: =SUM(D14:D17) -> 129263.59
B20: COBRANZA GENERAL SAMANTHA 2
B21: Segmento | C21: Cuentas | D21: Recuperación
B22: Extrajudicial - 0 a 28 semanas de atraso | C22: 2404 | D22: 27541.77
B23: Extrajudicial - 29 a 39 semanas de atraso | C23: 1546 | D23: 13293
B24: Extrajudicial - 40 a 55 semanas de atraso | C24: 3309 | D24: 3456
B25: JUDICIAL | C25: 2 | D25: 0
B26: Mas 55 semanas de atraso | C26: 21226 | D26: 15377
B27: Total general | C27: =SUM(C22:C26) -> 28487 | D27: =SUM(D22:D26) -> 59667.77
B29: COBRANZA GENERAL SOFIA
B30: Segmento | C30: Cuentas | D30: Recuperación
B31: Extrajudicial - 0 a 28 semanas de atraso | C31: 1361 | D31: 21405.41
B32: Extrajudicial - 29 a 39 semanas de atraso | C32: 1957 | D32: 10550
B33: Extrajudicial - 40 a 55 semanas de atraso | C33: 2828 | D33: 0
B34: Mas 55 semanas de atraso | C34: 4264 | D34: 2368
B35: Total general | C35: =SUM(C31:C34) -> 10410 | D35: =SUM(D31:D34) -> 34323.41
B37: COBRANZA GENERAL FERNANDO
B38: Segmento | C38: Cuentas | D38: Recuperación
B39: Extrajudicial - 0 a 28 semanas de atraso | C39: 2535 | D39: 9515
B40: Total general | C40: =SUM(C39:C39) -> 2535 | D40: =SUM(D39:D39) -> 9515
B42: COBRANZA GENERAL FEDERICO
B43: Segmento | C43: Cuentas | D43: Recuperación
B44: Extrajudicial - 0 a 28 semanas de atraso | C44: 39 | D44: 0
B45: Extrajudicial - 29 a 39 semanas de atraso | C45: 323 | D45: 100
B46: Extrajudicial - 40 a 55 semanas de atraso | C46: 255 | D46: 0
B47: Mas 55 semanas de atraso | C47: 1931 | D47: 1483
...

Sheet DATA

Sheet EPR 15 ABR
B2: REPORTE CONSOLIDADO POR SEGMENTOS
B3: COBRANZA 15 ABRIL
B5: COORDINADOR | C5: SEGMENTO | D5: CUENTAS | E5: COBRANZA REAL | F5: CUOTA IDEAL | G5: VARIACION | H5: % VAR | I5: EPR | J5: EPR IDEAL | K5: VAR EPR
B6: Samatha y Zareth | C6: Extrajudicial - 0 a 28 semanas de atraso | D6: =SUMIF('REPORTE DIARIO'!B:B,'EPR 15 ABR'!C6, 'REPORTE DIARIO'!C:C) -> 15002 | E6: =SUMIF('REPORTE DIARIO'!B:B,'EPR 15 ABR'!C6, 'REPORTE DIARIO'!D:D) -> 210992.28 | F6: =J6*D6 -> 428628.57 | G6: =+E6-F6 -> -217636.29 | H6: =ABS(G6/F6) -> 0.50775031 | I6: =E6/D6 -> 14.064277 | J6: =200/7 -> 28.571429 | K6: =+I6-J6 -> -14.507152
B7: Gabriel | C7: Extrajudicial - 29 a 39 semanas de atraso | D7: =SUMIF('REPORTE DIARIO'!B:B,'EPR 15 ABR'!C7, 'REPORTE DIARIO'!C:C) -> 11862 | E7: =SUMIF('REPORTE DIARIO'!B:B,'EPR 15 ABR'!C7, 'REPORTE DIARIO'!D:D) -> 87581 | F7: =J7*D7 -> 186402.86 | G7: =+E7-F7 -> -98821.857 | H7: =ABS(G7/F7) -> 0.53015205 | I7: =E7/D7 -> 7.3833249 | J7: =110/7 -> 15.714286 | K7: =+I7-J7 -> -8.3309608
B8: Gabriel | C8: Extrajudicial - 40 a 55 semanas de atraso | D8: =SUMIF('REPORTE DIARIO'!B:B,'EPR 15 ABR'!C8, 'REPORTE DIARIO'!C:C) -> 16178 | E8: =SUMIF('REPORTE DIARIO'!B:B,'EPR 15 ABR'!C8, 'REPORTE DIARIO'!D:D) -> 61425 | F8: =J8*D8 -> 104001.43 | G8: =+E8-F8 -> -42576.429 | H8: =ABS(G8/F8) -> 0.40938311 | I8: =E8/D8 -> 3.7968228 | J8: =45/7 -> 6.4285714 | K8: =+I8-J8 -> -2.6317486
B9: Fernando | C9: Mas 55 semanas de atraso | D9: =SUMIF('REPORTE DIARIO'!B:B,'EPR 15 ABR'!C9, 'REPORTE DIARIO'!C:C) -> 57707 | E9: =SUMIF('REPORTE DIARIO'!B:B,'EPR 15 ABR'!C9, 'REPORTE DIARIO'!D:D) -> 122678.35 | F9: =J9*D9 -> 123657.86 | G9: =+E9-F9 -> -979.50714 | H9: =ABS(G9/F9) -> 0.0079211072 | I9: =E9/D9 -> 2.1258833 | J9: =15/7 -> 2.1428571 | K9: =+I9-J9 -> -0.016973801
C10: TOTAL | D10: =SUM(D6:D9) -> 100749 | E10: =SUM(E6:E9) -> 482676.63 | F10: =SUM(F6:F9) -> 842690.71 | G10: =+E10-F10 -> -360014.08 | H10: =ABS(G10/F10) -> 0.42721971 | I10: =E10/D10 -> 4.7908826 | J10: =F10/D10 -> 8.3642588 | K10: =I10-J10 -> -3.5733763
B12: Nota:
B13: El saldo consolidado incluye los siguientes despachos
B14: Samantha, Samantha 2, Sofia, Edith, Fernando y Federico
