Workbook

Sheet REPORTE DIARIO
B3: COBRANZA GENERAL SAMANTHA
B4: Segmento | C4: Cuentas | D4: Recuperación
B5: Extrajudicial - 0 a 28 semanas de atraso | C5: 7441 | D5: 257038.99
B6: Extrajudicial - 29 a 39 semanas de atraso | C6: 8213 | D6: 113016.44
B7: Extrajudicial - 40 a 55 semanas de atraso | C7: 10068 | D7: 118910.51
B8: JUDICIAL | C8: 21 | D8: 0
B9: Mas 55 semanas de atraso | C9: 29554 | D9: 62319.25
B10: Total general | C10: =SUM(C5:C9) -> 55297 | D10: =SUM(D5:D9) -> 551285.19
B12: COBRANZA GENERAL SAMANTHA 2
B13: Segmento | C13: Cuentas | D13: Recuperación
B14: Extrajudicial - 0 a 28 semanas de atraso | C14: 3353 | D14: 110231.34
B15: Extrajudicial - 29 a 39 semanas de atraso | C15: 1816 | D15: 18284
B16: Extrajudicial - 40 a 55 semanas de atraso | C16: 3338 | D16: 9044
B17: JUDICIAL | C17: 2 | D17: 0
B18: Mas 55 semanas de atraso | C18: 21216 | D18: 99055.38
B19: Total general | C19: =SUM(C14:C18) -> 29725 | D19: =SUM(D14:D18) -> 236614.72
B21: COBRANZA GENERAL EDITH
B22: Segmento | C22: Cuentas | D22: Recuperación
B23: Extrajudicial - 0 a 28 semanas de atraso | C23: 1459 | D23: 62534.31
B24: Extrajudicial - 29 a 39 semanas de atraso | C24: 1427 | D24: 83407.51
B25: Extrajudicial - 40 a 55 semanas de atraso | C25: 293 | D25: 4994
B26: Mas 55 semanas de atraso | C26: 8411 | D26: -9401.49
B27: Total general | C27: =SUM(C23:C26) -> 11590 | D27: =SUM(D23:D26) -> 141534.33
B29: COBRANZA GENERAL SOFIA
B30: Segmento | C30: Cuentas | D30: Recuperación
B31: Extrajudicial - 0 a 28 semanas de atraso | C31: 1205 | D31: 63932.37
B32: Extrajudicial - 29 a 39 semanas de atraso | C32: 1167 | D32: 2798
B33: Extrajudicial - 40 a 55 semanas de atraso | C33: 3061 | D33: -6087
B34: Mas 55 semanas de atraso | C34: 1901 | D34: 5823
B35: Total general | C35: =SUM(C31:C34) -> 7334 | D35: =SUM(D31:D34) -> 66466.37
B37: COBRANZA GENERAL FERNANDO
B38: Segmento | C38: Cuentas | D38: Recuperación
B39: Extrajudicial - 0 a 28 semanas de atraso | C39: 3067 | D39: 48322
B40: Total general | C40: =SUM(C39:C39) -> 3067 | D40: =SUM(D39:D39) -> 48322
B42: COBRANZA GENERAL OLGUIN
B43: Segmento | C43: Cuentas | D43: Recuperación
B44: Extrajudicial - 0 a 28 semanas de atraso | C44: 68 | D44: 5605.16
B45: Extrajudicial - 29 a 39 semanas de atraso | C45: 122 | D45: 0
B46: Extrajudicial - 40 a 55 semanas de atraso | C46: 14 | D46: 0
B47: Mas 55 semanas de atraso | C47: 10 | D47: 0
...

Sheet DATA

Sheet EPR 26 MAR
B2: REPORTE CONSOLIDADO POR SEGMENTOS
B3: SALDO ACUMULADO SEMANA 13
B5: COORDINADOR | C5: SEGMENTO | D5: CUENTAS | E5: COBRANZA REAL | F5: CUOTA IDEAL | G5: VARIACION | H5: % VAR | I5: EPR | J5: EPR IDEAL | K5: VAR EPR
B6: Samatha y Zareth | C6: Extrajudicial - 0 a 28 semanas de atraso | D6: =SUMIF('REPORTE DIARIO'!B:B,'EPR 26 MAR'!C6, 'REPORTE DIARIO'!C:C) -> 16593 | E6: =SUMIF('REPORTE DIARIO'!B:B,'EPR 26 MAR'!C6, 'REPORTE DIARIO'!D:D) -> 547664.17 | F6: =J6*D6 -> 1422257.1 | G6: =+E6-F6 -> -874592.97 | H6: =ABS(G6/F6) -> 0.61493309 | I6: =E6/D6 -> 33.005736 | J6: =(200/7)*3 -> 85.714286 | K6: =+I6-J6 -> -52.70855
B7: Gabriel | C7: Extrajudicial - 29 a 39 semanas de atraso | D7: =SUMIF('REPORTE DIARIO'!B:B,'EPR 26 MAR'!C7, 'REPORTE DIARIO'!C:C) -> 12868 | E7: =SUMIF('REPORTE DIARIO'!B:B,'EPR 26 MAR'!C7, 'REPORTE DIARIO'!D:D) -> 218105.95 | F7: =J7*D7 -> 606634.29 | G7: =+E7-F7 -> -388528.34 | H7: =ABS(G7/F7) -> 0.64046551 | I7: =E7/D7 -> 16.949483 | J7: =(110/7)*3 -> 47.142857 | K7: =+I7-J7 -> -30.193374
B8: Gabriel | C8: Extrajudicial - 40 a 55 semanas de atraso | D8: =SUMIF('REPORTE DIARIO'!B:B,'EPR 26 MAR'!C8, 'REPORTE DIARIO'!C:C) -> 16938 | E8: =SUMIF('REPORTE DIARIO'!B:B,'EPR 26 MAR'!C8, 'REPORTE DIARIO'!D:D) -> 126861.51 | F8: =J8*D8 -> 326661.43 | G8: =+E8-F8 -> -199799.92 | H8: =ABS(G8/F8) -> 0.61164221 | I8: =E8/D8 -> 7.4897574 | J8: =(45/7)*3 -> 19.285714 | K8: =+I8-J8 -> -11.795957
B9: Fernando | C9: Mas 55 semanas de atraso | D9: =SUMIF('REPORTE DIARIO'!B:B,'EPR 26 MAR'!C9, 'REPORTE DIARIO'!C:C) -> 61678 | E9: =SUMIF('REPORTE DIARIO'!B:B,'EPR 26 MAR'!C9, 'REPORTE DIARIO'!D:D) -> 157796.14 | F9: =J9*D9 -> 396501.43 | G9: =+E9-F9 -> -238705.29 | H9: =ABS(G9/F9) -> 0.60202882 | I9: =E9/D9 -> 2.5583861 | J9: =(15/7)*3 -> 6.4285714 | K9: =+I9-J9 -> -3.8701853
C10: TOTAL | D10: =SUM(D6:D9) -> 108077 | E10: =SUM(E6:E9) -> 1050427.8 | F10: =SUM(F6:F9) -> 2752054.3 | G10: =+E10-F10 -> -1701626.5 | H10: =ABS(G10/F10) -> 0.61831139 | I10: =E10/D10 -> 9.7192536 | J10: =F10/D10 -> 25.463829 | K10: =I10-J10 -> -15.744576
B12: Nota:
B13: El saldo consolidado incluye los siguientes despachos
B14: Samantha, Samantha 2, Sofia, Edith, Olguin, Fernando y Federico
