Workbook

Sheet REPORTE DIARIO
B3: COBRANZA GENERAL SAMANTHA
B4: Segmento | C4: Cuentas | D4: Recuperación
B5: Extrajudicial - 0 a 28 semanas de atraso | C5: 4128 | D5: 554388.1
B6: Extrajudicial - 29 a 39 semanas de atraso | C6: 4352 | D6: 390410.19
B7: Extrajudicial - 40 a 55 semanas de atraso | C7: 4267 | D7: 381155.6
B8: JUDICIAL | C8: 12 | D8: 803.56
B9: Mas 55 semanas de atraso | C9: 11330 | D9: 501862.33
B10: Total general | C10: =SUM(C5:C9) -> 24089 | D10: =SUM(D5:D9) -> 1828619.8
B12: COBRANZA GENERAL EDITH
B13: Segmento | C13: Cuentas | D13: Recuperación
B14: Extrajudicial - 0 a 28 semanas de atraso | C14: 3345 | D14: 339474.34
B15: Extrajudicial - 29 a 39 semanas de atraso | C15: 1487 | D15: 135358.87
B16: Extrajudicial - 40 a 55 semanas de atraso | C16: 2197 | D16: 76251.34
B17: JUDICIAL | C17: 1 | D17: 39
B18: Mas 55 semanas de atraso | C18: 17193 | D18: 77202.69
B19: Total general | C19: =SUM(C14:C18) -> 24223 | D19: =SUM(D14:D18) -> 628326.24
B21: COBRANZA GENERAL SAMANTHA 2
B22: Segmento | C22: Cuentas | D22: Recuperación
B23: Extrajudicial - 0 a 28 semanas de atraso | C23: 1884 | D23: 194067
B24: Extrajudicial - 29 a 39 semanas de atraso | C24: 2025 | D24: 125398.89
B25: Extrajudicial - 40 a 55 semanas de atraso | C25: 2085 | D25: 72560
B26: JUDICIAL | C26: 2 | D26: 0
B27: Mas 55 semanas de atraso | C27: 20729 | D27: 215818.08
B28: Total general | C28: =SUM(C23:C27) -> 26725 | D28: =SUM(D23:D27) -> 607843.97
B30: COBRANZA GENERAL SOFIA
B31: Segmento | C31: Cuentas | D31: Recuperación
B32: Extrajudicial - 0 a 28 semanas de atraso | C32: 230 | D32: 100576.07
B33: Extrajudicial - 29 a 39 semanas de atraso | C33: 3184 | D33: 272191.69
B34: Extrajudicial - 40 a 55 semanas de atraso | C34: 640 | D34: 29181.33
B35: Mas 55 semanas de atraso | C35: 3965 | D35: 7896
B36: Total general | C36: =SUM(C32:C35) -> 8019 | D36: =SUM(D32:D35) -> 409845.09
B38: COBRANZA GENERAL FERNANDO
B39: Segmento | C39: Cuentas | D39: Recuperación
B40: Extrajudicial - 0 a 28 semanas de atraso | C40: 1936 | D40: 71766
B41: Total general | C41: =SUM(C40:C40) -> 1936 | D41: =SUM(D40:D40) -> 71766
B43: COBRANZA GENERAL OLGUIN
B44: Segmento | C44: Cuentas | D44: Recuperación
B45: Extrajudicial - 0 a 28 semanas de atraso | C45: 475 | D45: 4687
B46: Extrajudicial - 29 a 39 semanas de atraso | C46: 641 | D46: 4074
B47: Extrajudicial - 40 a 55 semanas de atraso | C47: 1101 | D47: 51144
...

Sheet DATA

Sheet EPR 18 MAYO
B2: REPORTE CONSOLIDADO POR SEGMENTOS
B3: SALDO ACUMULADO SEMANA 20
B5: COORDINADOR | C5: SEGMENTO | D5: CUENTAS | E5: COBRANZA REAL | F5: CUOTA IDEAL | G5: VARIACION | H5: % VAR | I5: EPR | J5: EPR IDEAL | K5: VAR EPR
B6: Zareth | C6: Extrajudicial - 0 a 28 semanas de atraso | D6: =SUMIF('REPORTE DIARIO'!B:B,'EPR 18 MAYO'!C6, 'REPORTE DIARIO'!C:C) -> 12430 | E6: =SUMIF('REPORTE DIARIO'!B:B,'EPR 18 MAYO'!C6, 'REPORTE DIARIO'!D:D) -> 1278789.5 | F6: =J6*D6 -> 2734600 | G6: =+E6-F6 -> -1455810.5 | H6: =ABS(G6/F6) -> 0.53236689 | I6: =E6/D6 -> 102.87928 | J6: =(220/7)*7 -> 220 | K6: =+I6-J6 -> -117.12072
B7: Gabriel | C7: Extrajudicial - 29 a 39 semanas de atraso | D7: =SUMIF('REPORTE DIARIO'!B:B,'EPR 18 MAYO'!C7, 'REPORTE DIARIO'!C:C) -> 12496 | E7: =SUMIF('REPORTE DIARIO'!B:B,'EPR 18 MAYO'!C7, 'REPORTE DIARIO'!D:D) -> 936080.64 | F7: =J7*D7 -> 1374560 | G7: =+E7-F7 -> -438479.36 | H7: =ABS(G7/F7) -> 0.31899616 | I7: =E7/D7 -> 74.910423 | J7: =(110/7)*7 -> 110 | K7: =+I7-J7 -> -35.089577
B8: Gabriel | C8: Extrajudicial - 40 a 55 semanas de atraso | D8: =SUMIF('REPORTE DIARIO'!B:B,'EPR 18 MAYO'!C8, 'REPORTE DIARIO'!C:C) -> 10986 | E8: =SUMIF('REPORTE DIARIO'!B:B,'EPR 18 MAYO'!C8, 'REPORTE DIARIO'!D:D) -> 612424.27 | F8: =J8*D8 -> 494370 | G8: =+E8-F8 -> 118054.27 | H8: =ABS(G8/F8) -> 0.2387974 | I8: =E8/D8 -> 55.745883 | J8: =(45/7)*7 -> 45 | K8: =+I8-J8 -> 10.745883
B9: Fernando (Naucalpan) | C9: Mas 55 semanas de atraso | D9: =SUMIF('REPORTE DIARIO'!B:B,'EPR 18 MAYO'!C9, 'REPORTE DIARIO'!C:C) -> 56880 | E9: =SUMIF('REPORTE DIARIO'!B:B,'EPR 18 MAYO'!C9, 'REPORTE DIARIO'!D:D) -> 843101.1 | F9: =J9*D9 -> 853200 | G9: =+E9-F9 -> -10098.9 | H9: =ABS(G9/F9) -> 0.011836498 | I9: =E9/D9 -> 14.822453 | J9: =(15/7)*7 -> 15 | K9: =+I9-J9 -> -0.17754747
C10: TOTAL | D10: =SUM(D6:D9) -> 92792 | E10: =SUM(E6:E9) -> 3670395.5 | F10: =SUM(F6:F9) -> 5456730 | G10: =+E10-F10 -> -1786334.5 | H10: =ABS(G10/F10) -> 0.32736355 | I10: =E10/D10 -> 39.555086 | J10: =F10/D10 -> 58.806039 | K10: =I10-J10 -> -19.250954
B12: Nota:
B13: El saldo consolidado incluye los siguientes despachos
B14: Samantha, Samantha 2, Sofia, Edith, Fernando, Olguin y Federico
