Workbook

Sheet REPORTE DIARIO
B3: COBRANZA GENERAL SAMANTHA
B4: Segmento | C4: Cuentas | D4: Recuperación
B5: Extrajudicial - 0 a 28 semanas de atraso | C5: 4069 | D5: 296214.73
B6: Extrajudicial - 29 a 39 semanas de atraso | C6: 4243 | D6: 217324.7
B7: Extrajudicial - 40 a 55 semanas de atraso | C7: 4271 | D7: 100932.45
B8: JUDICIAL | C8: 11 | D8: 0
B9: Mas 55 semanas de atraso | C9: 11352 | D9: 198032.07
B10: Total general | C10: =SUM(C5:C9) -> 23946 | D10: =SUM(D5:D9) -> 812503.95
B12: COBRANZA GENERAL SAMANTHA 2
B13: Segmento | C13: Cuentas | D13: Recuperación
B14: Extrajudicial - 0 a 28 semanas de atraso | C14: 2322 | D14: 136976.32
B15: Extrajudicial - 29 a 39 semanas de atraso | C15: 2140 | D15: 77507.23
B16: Extrajudicial - 40 a 55 semanas de atraso | C16: 2212 | D16: 79893.34
B17: JUDICIAL | C17: 2 | D17: 0
B18: Mas 55 semanas de atraso | C18: 20851 | D18: 58092.99
B19: Total general | C19: =SUM(C14:C18) -> 27527 | D19: =SUM(D14:D18) -> 352469.88
B21: COBRANZA GENERAL SOFIA
B22: Segmento | C22: Cuentas | D22: Recuperación
B23: Extrajudicial - 0 a 28 semanas de atraso | C23: 221 | D23: 39421.84
B24: Extrajudicial - 29 a 39 semanas de atraso | C24: 3362 | D24: 234824.49
B25: Extrajudicial - 40 a 55 semanas de atraso | C25: 610 | D25: 43726
B26: Mas 55 semanas de atraso | C26: 3969 | D26: 4813.68
B27: Total general | C27: =SUM(C23:C26) -> 8162 | D27: =SUM(D23:D26) -> 322786.01
B29: COBRANZA GENERAL EDITH
B30: Segmento | C30: Cuentas | D30: Recuperación
B31: Extrajudicial - 0 a 28 semanas de atraso | C31: 3329 | D31: 228248.38
B32: Extrajudicial - 29 a 39 semanas de atraso | C32: 1484 | D32: 33638.7
B33: Extrajudicial - 40 a 55 semanas de atraso | C33: 2158 | D33: 31134.68
B34: JUDICIAL | C34: 1 | D34: 39
B35: Mas 55 semanas de atraso | C35: 17193 | D35: 37521.2
B36: Total general | C36: =SUM(C31:C35) -> 24165 | D36: =SUM(D31:D35) -> 330581.96
B38: COBRANZA GENERAL FEDERICO
B39: Segmento | C39: Cuentas | D39: Recuperación
B40: Extrajudicial - 0 a 28 semanas de atraso | C40: 576 | D40: 14600
B41: Extrajudicial - 29 a 39 semanas de atraso | C41: 866 | D41: 9133
B42: Extrajudicial - 40 a 55 semanas de atraso | C42: 788 | D42: 1052
B43: Mas 55 semanas de atraso | C43: 2429 | D43: 62944
B44: Total general | C44: =SUM(C40:C43) -> 4659 | D44: =SUM(D40:D43) -> 87729
B46: COBRANZA GENERAL FERNANDO
B47: Segmento | C47: Cuentas | D47: Recuperación
...

Sheet DATA

Sheet EPR 23 MAYO
B2: REPORTE CONSOLIDADO POR SEGMENTOS
B3: SALDO ACUMULADO SEMANA 21
B5: COORDINADOR | C5: SEGMENTO | D5: CUENTAS | E5: COBRANZA REAL | F5: CUOTA IDEAL | G5: VARIACION | H5: % VAR | I5: EPR | J5: EPR IDEAL | K5: VAR EPR
B6: Zareth | C6: Extrajudicial - 0 a 28 semanas de atraso | D6: =SUMIF('REPORTE DIARIO'!B:B,'EPR 23 MAYO'!C6, 'REPORTE DIARIO'!C:C) -> 13833 | E6: =SUMIF('REPORTE DIARIO'!B:B,'EPR 23 MAYO'!C6, 'REPORTE DIARIO'!D:D) -> 777269.53 | F6: =J6*D6 -> 2173757.1 | G6: =+E6-F6 -> -1396487.6 | H6: =ABS(G6/F6) -> 0.64243037 | I6: =E6/D6 -> 56.189513 | J6: =(220/7)*5 -> 157.14286 | K6: =+I6-J6 -> -100.95334
B7: Gabriel | C7: Extrajudicial - 29 a 39 semanas de atraso | D7: =SUMIF('REPORTE DIARIO'!B:B,'EPR 23 MAYO'!C7, 'REPORTE DIARIO'!C:C) -> 12968 | E7: =SUMIF('REPORTE DIARIO'!B:B,'EPR 23 MAYO'!C7, 'REPORTE DIARIO'!D:D) -> 576565.12 | F7: =J7*D7 -> 1018914.3 | G7: =+E7-F7 -> -442349.17 | H7: =ABS(G7/F7) -> 0.43413776 | I7: =E7/D7 -> 44.460605 | J7: =(110/7)*5 -> 78.571429 | K7: =+I7-J7 -> -34.110824
B8: Gabriel | C8: Extrajudicial - 40 a 55 semanas de atraso | D8: =SUMIF('REPORTE DIARIO'!B:B,'EPR 23 MAYO'!C8, 'REPORTE DIARIO'!C:C) -> 11348 | E8: =SUMIF('REPORTE DIARIO'!B:B,'EPR 23 MAYO'!C8, 'REPORTE DIARIO'!D:D) -> 261049.47 | F8: =J8*D8 -> 364757.14 | G8: =+E8-F8 -> -103707.67 | H8: =ABS(G8/F8) -> 0.28431979 | I8: =E8/D8 -> 23.004007 | J8: =(45/7)*5 -> 32.142857 | K8: =+I8-J8 -> -9.1388503
B9: Fernando (Naucalpan) | C9: Mas 55 semanas de atraso | D9: =SUMIF('REPORTE DIARIO'!B:B,'EPR 23 MAYO'!C9, 'REPORTE DIARIO'!C:C) -> 57157 | E9: =SUMIF('REPORTE DIARIO'!B:B,'EPR 23 MAYO'!C9, 'REPORTE DIARIO'!D:D) -> 363848.94 | F9: =J9*D9 -> 612396.43 | G9: =+E9-F9 -> -248547.49 | H9: =ABS(G9/F9) -> 0.40586045 | I9: =E9/D9 -> 6.3657809 | J9: =(15/7)*5 -> 10.714286 | K9: =+I9-J9 -> -4.3485048
C10: TOTAL | D10: =SUM(D6:D9) -> 95306 | E10: =SUM(E6:E9) -> 1978733.1 | F10: =SUM(F6:F9) -> 4169825 | G10: =+E10-F10 -> -2191091.9 | H10: =ABS(G10/F10) -> 0.52546376 | I10: =E10/D10 -> 20.761894 | J10: =F10/D10 -> 43.751967 | K10: =I10-J10 -> -22.990073
B12: Nota:
B13: El saldo consolidado incluye los siguientes despachos
B14: Samantha, Samantha 2, Sofia, Edith, Fernando, Olguin y Federico
