Workbook

Sheet REPORTE DIARIO
B3: COBRANZA GENERAL SAMANTHA
B4: Segmento | C4: Cuentas | D4: Recuperación
B5: Extrajudicial - 0 a 28 semanas de atraso | C5: 2538 | D5: 518214.5
B6: Extrajudicial - 29 a 39 semanas de atraso | C6: 3126 | D6: 343753.92
B7: Extrajudicial - 40 a 55 semanas de atraso | C7: 4936 | D7: 286464.22
B8: JUDICIAL | C8: 1980 | D8: 1063.06
B9: Mas 55 semanas de atraso | C9: 11341 | D9: 431921.68
B10: Total general | C10: =SUM(C5:C9) -> 23921 | D10: =SUM(D5:D9) -> 1581417.4
B12: COBRANZA GENERAL SAMANTHA 2
B13: Segmento | C13: Cuentas | D13: Recuperación
B14: Extrajudicial - 0 a 28 semanas de atraso | C14: 2700 | D14: 243108.7
B15: Extrajudicial - 29 a 39 semanas de atraso | C15: 2215 | D15: 127186.71
B16: Extrajudicial - 40 a 55 semanas de atraso | C16: 2622 | D16: 78488.31
B17: JUDICIAL | C17: 2 | D17: 0
B18: Mas 55 semanas de atraso | C18: 17759 | D18: 211949.76
B19: Total general | C19: =SUM(C14:C18) -> 25298 | D19: =SUM(D14:D18) -> 660733.48
B21: COBRANZA GENERAL EDITH
B22: Segmento | C22: Cuentas | D22: Recuperación
B23: Extrajudicial - 0 a 28 semanas de atraso | C23: 3224 | D23: 304158.59
B24: Extrajudicial - 29 a 39 semanas de atraso | C24: 1156 | D24: 75576.89
B25: Extrajudicial - 40 a 55 semanas de atraso | C25: 2152 | D25: 59026.82
B26: JUDICIAL | C26: 1 | D26: 39
B27: Mas 55 semanas de atraso | C27: 17177 | D27: 128035.23
B28: Total general | C28: =SUM(C23:C27) -> 23710 | D28: =SUM(D23:D27) -> 566836.53
B30: COBRANZA GENERAL SOFIA
B31: Segmento | C31: Cuentas | D31: Recuperación
B32: Extrajudicial - 0 a 28 semanas de atraso | C32: 55 | D32: 28296.06
B33: Extrajudicial - 29 a 39 semanas de atraso | C33: 3357 | D33: 270330.52
B34: Extrajudicial - 40 a 55 semanas de atraso | C34: 282 | D34: 9881.67
B35: Mas 55 semanas de atraso | C35: 3972 | D35: 9209
B36: Total general | C36: =SUM(C32:C35) -> 7666 | D36: =SUM(D32:D35) -> 317717.25
B38: COBRANZA GENERAL OLGUIN
B39: Segmento | C39: Cuentas | D39: Recuperación
B40: Extrajudicial - 0 a 28 semanas de atraso | C40: 1960 | D40: 83576.79
B41: Extrajudicial - 29 a 39 semanas de atraso | C41: 1197 | D41: 29942.3
B42: Extrajudicial - 40 a 55 semanas de atraso | C42: 1986 | D42: 10203
B43: Mas 55 semanas de atraso | C43: 2026 | D43: 12859
B44: Total general | C44: =SUM(C40:C43) -> 7169 | D44: =SUM(D40:D43) -> 136581.09
B46: COBRANZA GENERAL FERNANDO
B47: Segmento | C47: Cuentas | D47: Recuperación
...

Sheet DATA

Sheet EPR 01 JUN
B2: REPORTE CONSOLIDADO POR SEGMENTOS
B3: SALDO ACUMULADO SEMANA 22
B5: COORDINADOR | C5: SEGMENTO | D5: CUENTAS | E5: COBRANZA REAL | F5: CUOTA IDEAL | G5: VARIACION | H5: % VAR | I5: EPR | J5: EPR IDEAL | K5: VAR EPR
B6: Zareth | C6: Extrajudicial - 0 a 28 semanas de atraso | D6: =SUMIF('REPORTE DIARIO'!B:B,'EPR 01 JUN'!C6, 'REPORTE DIARIO'!C:C) -> 13905 | E6: =SUMIF('REPORTE DIARIO'!B:B,'EPR 01 JUN'!C6, 'REPORTE DIARIO'!D:D) -> 1325809.4 | F6: =J6*D6 -> 3059100 | G6: =+E6-F6 -> -1733290.6 | H6: =ABS(G6/F6) -> 0.56660147 | I6: =E6/D6 -> 95.347676 | J6: =(220/7)*7 -> 220 | K6: =+I6-J6 -> -124.65232
B7: Gabriel | C7: Extrajudicial - 29 a 39 semanas de atraso | D7: =SUMIF('REPORTE DIARIO'!B:B,'EPR 01 JUN'!C7, 'REPORTE DIARIO'!C:C) -> 11756 | E7: =SUMIF('REPORTE DIARIO'!B:B,'EPR 01 JUN'!C7, 'REPORTE DIARIO'!D:D) -> 864718.15 | F7: =J7*D7 -> 1293160 | G7: =+E7-F7 -> -428441.85 | H7: =ABS(G7/F7) -> 0.33131387 | I7: =E7/D7 -> 73.555474 | J7: =(110/7)*7 -> 110 | K7: =+I7-J7 -> -36.444526
B8: Gabriel | C8: Extrajudicial - 40 a 55 semanas de atraso | D8: =SUMIF('REPORTE DIARIO'!B:B,'EPR 01 JUN'!C8, 'REPORTE DIARIO'!C:C) -> 12789 | E8: =SUMIF('REPORTE DIARIO'!B:B,'EPR 01 JUN'!C8, 'REPORTE DIARIO'!D:D) -> 449365.02 | F8: =J8*D8 -> 575505 | G8: =+E8-F8 -> -126139.98 | H8: =ABS(G8/F8) -> 0.21918138 | I8: =E8/D8 -> 35.136838 | J8: =(45/7)*7 -> 45 | K8: =+I8-J8 -> -9.8631621
B9: Fernando (Naucalpan) | C9: Mas 55 semanas de atraso | D9: =SUMIF('REPORTE DIARIO'!B:B,'EPR 01 JUN'!C9, 'REPORTE DIARIO'!C:C) -> 54747 | E9: =SUMIF('REPORTE DIARIO'!B:B,'EPR 01 JUN'!C9, 'REPORTE DIARIO'!D:D) -> 800126.67 | F9: =J9*D9 -> 821205 | G9: =+E9-F9 -> -21078.33 | H9: =ABS(G9/F9) -> 0.025667562 | I9: =E9/D9 -> 14.614987 | J9: =(15/7)*7 -> 15 | K9: =+I9-J9 -> -0.38501343
C10: TOTAL | D10: =SUM(D6:D9) -> 93197 | E10: =SUM(E6:E9) -> 3440019.3 | F10: =SUM(F6:F9) -> 5748970 | G10: =+E10-F10 -> -2308950.7 | H10: =ABS(G10/F10) -> 0.40162859 | I10: =E10/D10 -> 36.911266 | J10: =F10/D10 -> 61.686213 | K10: =I10-J10 -> -24.774947
B12: Nota:
B13: El saldo consolidado incluye los siguientes despachos
B14: Samantha, Samantha 2, Sofia, Edith, Fernando, Olguin y Federico
