Workbook

Sheet REPORTE DIARIO
B3: COBRANZA GENERAL SAMANTHA
B4: Segmento | C4: Cuentas | D4: Recuperación
B5: Extrajudicial - 0 a 28 semanas de atraso | C5: 3157 | D5: 757130.89
B6: Extrajudicial - 29 a 39 semanas de atraso | C6: 3692 | D6: 332917.82
B7: Extrajudicial - 40 a 55 semanas de atraso | C7: 6337 | D7: 366826.73
B8: JUDICIAL | C8: 1980 | D8: 300
B9: Mas 55 semanas de atraso | C9: 12534 | D9: 442378.9
B10: Total general | C10: =SUM(C5:C9) -> 27700 | D10: =SUM(D5:D9) -> 1899554.3
B12: COBRANZA GENERAL EDITH
B13: Segmento | C13: Cuentas | D13: Recuperación
B14: Extrajudicial - 0 a 28 semanas de atraso | C14: 3229 | D14: 343475.03
B15: Extrajudicial - 29 a 39 semanas de atraso | C15: 1584 | D15: 55488.34
B16: Extrajudicial - 40 a 55 semanas de atraso | C16: 2075 | D16: 125505.81
B17: JUDICIAL | C17: 1 | D17: 39
B18: Mas 55 semanas de atraso | C18: 16855 | D18: 80926.69
B19: Total general | C19: =SUM(C14:C18) -> 23744 | D19: =SUM(D14:D18) -> 605434.87
B21: COBRANZA GENERAL SAMANTHA 2
B22: Segmento | C22: Cuentas | D22: Recuperación
B23: Extrajudicial - 0 a 28 semanas de atraso | C23: 2789 | D23: 203945.44
B24: Extrajudicial - 29 a 39 semanas de atraso | C24: 1956 | D24: 99638.85
B25: Extrajudicial - 40 a 55 semanas de atraso | C25: 2583 | D25: 100926
B26: JUDICIAL | C26: 0 | D26: 0
B27: Mas 55 semanas de atraso | C27: 12612 | D27: 172231.89
B28: Total general | C28: =SUM(C23:C27) -> 19940 | D28: =SUM(D23:D27) -> 576742.18
B30: COBRANZA GENERAL SOFIA
B31: Segmento | C31: Cuentas | D31: Recuperación
B32: Extrajudicial - 0 a 28 semanas de atraso | C32: 472 | D32: 121039.51
B33: Extrajudicial - 29 a 39 semanas de atraso | C33: 2865 | D33: 127035
B34: Extrajudicial - 40 a 55 semanas de atraso | C34: 345 | D34: 6482
B35: Mas 55 semanas de atraso | C35: 3986 | D35: 39591.4
B36: Total general | C36: =SUM(C32:C35) -> 7668 | D36: =SUM(D32:D35) -> 294147.91
B38: COBRANZA GENERAL OLGUIN
B39: Segmento | C39: Cuentas | D39: Recuperación
B40: Extrajudicial - 0 a 28 semanas de atraso | C40: 2277 | D40: 97333.52
B41: Extrajudicial - 29 a 39 semanas de atraso | C41: 1475 | D41: 46889
B42: Extrajudicial - 40 a 55 semanas de atraso | C42: 1995 | D42: 18830
B43: Mas 55 semanas de atraso | C43: 1842 | D43: 18327
B44: Total general | C44: =SUM(C40:C43) -> 7589 | D44: =SUM(D40:D43) -> 181379.52
B46: COBRANZA GENERAL FERNANDO
B47: Segmento | C47: Cuentas | D47: Recuperación
...

Sheet DATA

Sheet EPR 15 JUN
B2: REPORTE CONSOLIDADO POR SEGMENTOS
B3: SALDO ACUMULADO SEMANA 24
B5: COORDINADOR | C5: SEGMENTO | D5: CUENTAS | E5: COBRANZA REAL | F5: CUOTA IDEAL | G5: VARIACION | H5: % VAR | I5: EPR | J5: EPR IDEAL | K5: VAR EPR
B6: Zareth | C6: Extrajudicial - 0 a 28 semanas de atraso | D6: =SUMIF('REPORTE DIARIO'!B:B,'EPR 15 JUN'!C6, 'REPORTE DIARIO'!C:C) -> 15111 | E6: =SUMIF('REPORTE DIARIO'!B:B,'EPR 15 JUN'!C6, 'REPORTE DIARIO'!D:D) -> 1616300 | F6: =J6*D6 -> 3324420 | G6: =+E6-F6 -> -1708120 | H6: =ABS(G6/F6) -> 0.51380994 | I6: =E6/D6 -> 106.96181 | J6: =(220/7)*7 -> 220 | K6: =+I6-J6 -> -113.03819
B7: Gabriel | C7: Extrajudicial - 29 a 39 semanas de atraso | D7: =SUMIF('REPORTE DIARIO'!B:B,'EPR 15 JUN'!C7, 'REPORTE DIARIO'!C:C) -> 12178 | E7: =SUMIF('REPORTE DIARIO'!B:B,'EPR 15 JUN'!C7, 'REPORTE DIARIO'!D:D) -> 669235.01 | F7: =J7*D7 -> 1339580 | G7: =+E7-F7 -> -670344.99 | H7: =ABS(G7/F7) -> 0.5004143 | I7: =E7/D7 -> 54.954427 | J7: =(110/7)*7 -> 110 | K7: =+I7-J7 -> -55.045573
B8: Gabriel | C8: Extrajudicial - 40 a 55 semanas de atraso | D8: =SUMIF('REPORTE DIARIO'!B:B,'EPR 15 JUN'!C8, 'REPORTE DIARIO'!C:C) -> 14111 | E8: =SUMIF('REPORTE DIARIO'!B:B,'EPR 15 JUN'!C8, 'REPORTE DIARIO'!D:D) -> 621341.54 | F8: =J8*D8 -> 634995 | G8: =+E8-F8 -> -13653.46 | H8: =ABS(G8/F8) -> 0.021501681 | I8: =E8/D8 -> 44.032424 | J8: =(45/7)*7 -> 45 | K8: =+I8-J8 -> -0.96757565
B9: Fernando (Naucalpan) | C9: Mas 55 semanas de atraso | D9: =SUMIF('REPORTE DIARIO'!B:B,'EPR 15 JUN'!C9, 'REPORTE DIARIO'!C:C) -> 50256 | E9: =SUMIF('REPORTE DIARIO'!B:B,'EPR 15 JUN'!C9, 'REPORTE DIARIO'!D:D) -> 765629.88 | F9: =J9*D9 -> 753840 | G9: =+E9-F9 -> 11789.88 | H9: =ABS(G9/F9) -> 0.015639764 | I9: =E9/D9 -> 15.234596 | J9: =(15/7)*7 -> 15 | K9: =+I9-J9 -> 0.23459647
C10: TOTAL | D10: =SUM(D6:D9) -> 91656 | E10: =SUM(E6:E9) -> 3672506.4 | F10: =SUM(F6:F9) -> 6052835 | G10: =+E10-F10 -> -2380328.6 | H10: =ABS(G10/F10) -> 0.39325847 | I10: =E10/D10 -> 40.068369 | J10: =F10/D10 -> 66.038612 | K10: =I10-J10 -> -25.970243
B12: Nota:
B13: El saldo consolidado incluye los siguientes despachos
B14: Samantha, Samantha 2, Sofia, Edith, Fernando, Olguin y Federico
