Workbook

Sheet REPORTE DIARIO
B3: COBRANZA GENERAL SAMANTHA
B4: Segmento | C4: Cuentas | D4: Recuperación
B5: Extrajudicial - 0 a 28 semanas de atraso | C5: 4161 | D5: 633319.02
B6: Extrajudicial - 29 a 39 semanas de atraso | C6: 4381 | D6: 349795.39
B7: Extrajudicial - 40 a 55 semanas de atraso | C7: 6023 | D7: 316924.62
B8: JUDICIAL | C8: 10 | D8: 0
B9: Mas 55 semanas de atraso | C9: 13324 | D9: 433932.1
B10: Total general | C10: =SUM(C5:C9) -> 27899 | D10: =SUM(D5:D9) -> 1733971.1
B12: COBRANZA GENERAL EDITH
B13: Segmento | C13: Cuentas | D13: Recuperación
B14: Extrajudicial - 0 a 28 semanas de atraso | C14: 3397 | D14: 395717.48
B15: Extrajudicial - 29 a 39 semanas de atraso | C15: 1958 | D15: 164830
B16: Extrajudicial - 40 a 55 semanas de atraso | C16: 2240 | D16: 43602.48
B17: Mas 55 semanas de atraso | C17: 9835 | D17: 96291.81
B18: Total general | C18: =SUM(C14:C17) -> 17430 | D18: =SUM(D14:D17) -> 700441.77
B20: COBRANZA GENERAL SAMANTHA 2
B21: Segmento | C21: Cuentas | D21: Recuperación
B22: Extrajudicial - 0 a 28 semanas de atraso | C22: 1932 | D22: 228482.34
B23: Extrajudicial - 29 a 39 semanas de atraso | C23: 1826 | D23: 104752
B24: Extrajudicial - 40 a 55 semanas de atraso | C24: 3118 | D24: 119728
B25: JUDICIAL | C25: 2 | D25: 0
B26: Mas 55 semanas de atraso | C26: 20810 | D26: 171694.37
B27: Total general | C27: =SUM(C22:C26) -> 27688 | D27: =SUM(D22:D26) -> 624656.71
B29: COBRANZA GENERAL SOFIA
B30: Segmento | C30: Cuentas | D30: Recuperación
B31: Extrajudicial - 0 a 28 semanas de atraso | C31: 282 | D31: 65687.97
B32: Extrajudicial - 29 a 39 semanas de atraso | C32: 2023 | D32: 116494.71
B33: Extrajudicial - 40 a 55 semanas de atraso | C33: 2233 | D33: 38041.99
B34: Mas 55 semanas de atraso | C34: 4229 | D34: 5658
B35: Total general | C35: =SUM(C31:C34) -> 8767 | D35: =SUM(D31:D34) -> 225882.67
B37: COBRANZA GENERAL FEDERICO
B38: Segmento | C38: Cuentas | D38: Recuperación
B39: Extrajudicial - 0 a 28 semanas de atraso | C39: 144 | D39: 177376
B40: Extrajudicial - 29 a 39 semanas de atraso | C40: 642 | D40: 9536
B41: Extrajudicial - 40 a 55 semanas de atraso | C41: 511 | D41: 1320
B42: Mas 55 semanas de atraso | C42: 2181 | D42: 31522
B43: Total general | C43: =SUM(C39:C42) -> 3478 | D43: =SUM(D39:D42) -> 219754
B45: COBRANZA GENERAL OLGUIN
B46: Segmento | C46: Cuentas | D46: Recuperación
B47: Extrajudicial - 0 a 28 semanas de atraso | C47: 183 | D47: 15372
...

Sheet DATA

Sheet EPR 11 MAYO
B2: REPORTE CONSOLIDADO POR SEGMENTOS
B3: SALDO ACUMULADO SEMANA 19
B5: COORDINADOR | C5: SEGMENTO | D5: CUENTAS | E5: COBRANZA REAL | F5: CUOTA IDEAL | G5: VARIACION | H5: % VAR | I5: EPR | J5: EPR IDEAL | K5: VAR EPR
B6: Zareth | C6: Extrajudicial - 0 a 28 semanas de atraso | D6: =SUMIF('REPORTE DIARIO'!B:B,'EPR 11 MAYO'!C6, 'REPORTE DIARIO'!C:C) -> 12131 | E6: =SUMIF('REPORTE DIARIO'!B:B,'EPR 11 MAYO'!C6, 'REPORTE DIARIO'!D:D) -> 1553451.8 | F6: =J6*D6 -> 2668820 | G6: =+E6-F6 -> -1115368.2 | H6: =ABS(G6/F6) -> 0.4179256 | I6: =E6/D6 -> 128.05637 | J6: =(220/7)*7 -> 220 | K6: =+I6-J6 -> -91.943631
B7: Gabriel | C7: Extrajudicial - 29 a 39 semanas de atraso | D7: =SUMIF('REPORTE DIARIO'!B:B,'EPR 11 MAYO'!C7, 'REPORTE DIARIO'!C:C) -> 11297 | E7: =SUMIF('REPORTE DIARIO'!B:B,'EPR 11 MAYO'!C7, 'REPORTE DIARIO'!D:D) -> 821462.1 | F7: =J7*D7 -> 1242670 | G7: =+E7-F7 -> -421207.9 | H7: =ABS(G7/F7) -> 0.33895395 | I7: =E7/D7 -> 72.715066 | J7: =(110/7)*7 -> 110 | K7: =+I7-J7 -> -37.284934
B8: Gabriel | C8: Extrajudicial - 40 a 55 semanas de atraso | D8: =SUMIF('REPORTE DIARIO'!B:B,'EPR 11 MAYO'!C8, 'REPORTE DIARIO'!C:C) -> 14947 | E8: =SUMIF('REPORTE DIARIO'!B:B,'EPR 11 MAYO'!C8, 'REPORTE DIARIO'!D:D) -> 521806.09 | F8: =J8*D8 -> 672615 | G8: =+E8-F8 -> -150808.91 | H8: =ABS(G8/F8) -> 0.22421283 | I8: =E8/D8 -> 34.910423 | J8: =(45/7)*7 -> 45 | K8: =+I8-J8 -> -10.089577
B9: Fernando (Naucalpan) | C9: Mas 55 semanas de atraso | D9: =SUMIF('REPORTE DIARIO'!B:B,'EPR 11 MAYO'!C9, 'REPORTE DIARIO'!C:C) -> 51466 | E9: =SUMIF('REPORTE DIARIO'!B:B,'EPR 11 MAYO'!C9, 'REPORTE DIARIO'!D:D) -> 743459.28 | F9: =J9*D9 -> 771990 | G9: =+E9-F9 -> -28530.72 | H9: =ABS(G9/F9) -> 0.03695737 | I9: =E9/D9 -> 14.445639 | J9: =(15/7)*7 -> 15 | K9: =+I9-J9 -> -0.55436055
C10: TOTAL | D10: =SUM(D6:D9) -> 89841 | E10: =SUM(E6:E9) -> 3640179.3 | F10: =SUM(F6:F9) -> 5356095 | G10: =+E10-F10 -> -1715915.7 | H10: =ABS(G10/F10) -> 0.32036693 | I10: =E10/D10 -> 40.518018 | J10: =F10/D10 -> 59.617491 | K10: =I10-J10 -> -19.099473
B12: Nota:
B13: El saldo consolidado incluye los siguientes despachos
B14: Samantha, Samantha 2, Sofia, Edith, Fernando, Olguin y Federico
