Workbook

Sheet REPORTE DIARIO
B3: COBRANZA GENERAL SAMANTHA
B4: Segmento | C4: Cuentas | D4: Recuperación
B5: Extrajudicial - 0 a 28 semanas de atraso | C5: 4211 | D5: 58568.04
B6: Extrajudicial - 29 a 39 semanas de atraso | C6: 4322 | D6: 20205
B7: Extrajudicial - 40 a 55 semanas de atraso | C7: 6109 | D7: 16781.6
B8: JUDICIAL | C8: 12 | D8: 0
B9: Mas 55 semanas de atraso | C9: 13177 | D9: 37187
B10: Total general | C10: =SUM(C5:C9) -> 27831 | D10: =SUM(D5:D9) -> 132741.64
B12: COBRANZA GENERAL EDITH
B13: Segmento | C13: Cuentas | D13: Recuperación
B14: Extrajudicial - 0 a 28 semanas de atraso | C14: 3343 | D14: 63517.8
B15: Extrajudicial - 29 a 39 semanas de atraso | C15: 1733 | D15: 4754
B16: Extrajudicial - 40 a 55 semanas de atraso | C16: 2267 | D16: 1062
B17: JUDICIAL | C17: 1 | D17: 0
B18: Mas 55 semanas de atraso | C18: 17376 | D18: 6184
B19: Total general | C19: =SUM(C14:C18) -> 24720 | D19: =SUM(D14:D18) -> 75517.8
B21: COBRANZA GENERAL SAMANTHA 2
B22: Segmento | C22: Cuentas | D22: Recuperación
B23: Extrajudicial - 0 a 28 semanas de atraso | C23: 1998 | D23: 30148.6
B24: Extrajudicial - 29 a 39 semanas de atraso | C24: 1926 | D24: 9246
B25: Extrajudicial - 40 a 55 semanas de atraso | C25: 3214 | D25: 3494
B26: JUDICIAL | C26: 2 | D26: 0
B27: Mas 55 semanas de atraso | C27: 20623 | D27: 22187.8
B28: Total general | C28: =SUM(C23:C27) -> 27763 | D28: =SUM(D23:D27) -> 65076.4
B30: COBRANZA GENERAL OLGUIN
B31: Segmento | C31: Cuentas | D31: Recuperación
B32: Extrajudicial - 0 a 28 semanas de atraso | C32: 342 | D32: 1
B33: Extrajudicial - 29 a 39 semanas de atraso | C33: 546 | D33: 1200
B34: Extrajudicial - 40 a 55 semanas de atraso | C34: 935 | D34: 0
B35: Mas 55 semanas de atraso | C35: 1153 | D35: 49629
B36: Total general | C36: =SUM(C32:C35) -> 2976 | D36: =SUM(D32:D35) -> 50830
B38: COBRANZA GENERAL SOFIA
B39: Segmento | C39: Cuentas | D39: Recuperación
B40: Extrajudicial - 0 a 28 semanas de atraso | C40: 247 | D40: 6372.18
B41: Extrajudicial - 29 a 39 semanas de atraso | C41: 2813 | D41: 24101.29
B42: Extrajudicial - 40 a 55 semanas de atraso | C42: 1864 | D42: 1680
B43: Mas 55 semanas de atraso | C43: 4230 | D43: 530
B44: Total general | C44: =SUM(C40:C43) -> 9154 | D44: =SUM(D40:D43) -> 32683.47
B46: COBRANZA GENERAL FERNANDO
B47: Segmento | C47: Cuentas | D47: Recuperación
...

Sheet DATA

Sheet EPR 14 MAYO
B2: REPORTE CONSOLIDADO POR SEGMENTOS
B3: COBRANZA 14 MAYO
B5: COORDINADOR | C5: SEGMENTO | D5: CUENTAS | E5: COBRANZA REAL | F5: CUOTA IDEAL | G5: VARIACION | H5: % VAR | I5: EPR | J5: EPR IDEAL | K5: VAR EPR
B6: Zareth | C6: Extrajudicial - 0 a 28 semanas de atraso | D6: =SUMIF('REPORTE DIARIO'!B:B,'EPR 14 MAYO'!C6, 'REPORTE DIARIO'!C:C) -> 12447 | E6: =SUMIF('REPORTE DIARIO'!B:B,'EPR 14 MAYO'!C6, 'REPORTE DIARIO'!D:D) -> 160197.62 | F6: =J6*D6 -> 391191.43 | G6: =+E6-F6 -> -230993.81 | H6: =ABS(G6/F6) -> 0.59048791 | I6: =E6/D6 -> 12.87038 | J6: =220/7 -> 31.428571 | K6: =+I6-J6 -> -18.558191
B7: Gabriel | C7: Extrajudicial - 29 a 39 semanas de atraso | D7: =SUMIF('REPORTE DIARIO'!B:B,'EPR 14 MAYO'!C7, 'REPORTE DIARIO'!C:C) -> 12056 | E7: =SUMIF('REPORTE DIARIO'!B:B,'EPR 14 MAYO'!C7, 'REPORTE DIARIO'!D:D) -> 60006.29 | F7: =J7*D7 -> 189451.43 | G7: =+E7-F7 -> -129445.14 | H7: =ABS(G7/F7) -> 0.68326293 | I7: =E7/D7 -> 4.9772968 | J7: =110/7 -> 15.714286 | K7: =+I7-J7 -> -10.736989
B8: Gabriel | C8: Extrajudicial - 40 a 55 semanas de atraso | D8: =SUMIF('REPORTE DIARIO'!B:B,'EPR 14 MAYO'!C8, 'REPORTE DIARIO'!C:C) -> 15008 | E8: =SUMIF('REPORTE DIARIO'!B:B,'EPR 14 MAYO'!C8, 'REPORTE DIARIO'!D:D) -> 23017.6 | F8: =J8*D8 -> 96480 | G8: =+E8-F8 -> -73462.4 | H8: =ABS(G8/F8) -> 0.7614262 | I8: =E8/D8 -> 1.5336887 | J8: =45/7 -> 6.4285714 | K8: =+I8-J8 -> -4.8948827
B9: Fernando (Naucalpan) | C9: Mas 55 semanas de atraso | D9: =SUMIF('REPORTE DIARIO'!B:B,'EPR 14 MAYO'!C9, 'REPORTE DIARIO'!C:C) -> 58829 | E9: =SUMIF('REPORTE DIARIO'!B:B,'EPR 14 MAYO'!C9, 'REPORTE DIARIO'!D:D) -> 115717.8 | F9: =J9*D9 -> 126062.14 | G9: =+E9-F9 -> -10344.343 | H9: =ABS(G9/F9) -> 0.082057489 | I9: =E9/D9 -> 1.9670197 | J9: =15/7 -> 2.1428571 | K9: =+I9-J9 -> -0.17583748
C10: TOTAL | D10: =SUM(D6:D9) -> 98340 | E10: =SUM(E6:E9) -> 358939.31 | F10: =SUM(F6:F9) -> 803185 | G10: =+E10-F10 -> -444245.69 | H10: =ABS(G10/F10) -> 0.55310506 | I10: =E10/D10 -> 3.6499828 | J10: =F10/D10 -> 8.1674293 | K10: =I10-J10 -> -4.5174465
B12: Nota:
B13: El saldo consolidado incluye los siguientes despachos
B14: Samantha, Samantha 2, Sofia, Edith, Fernando, Olguin y Federico
