Workbook

Sheet REPORTE DIARIO
B3: COBRANZA GENERAL SAMANTHA
B4: Segmento | C4: Cuentas | D4: Recuperación
B5: Extrajudicial - 0 a 28 semanas de atraso | C5: 4292 | D5: 257198.6
B6: Extrajudicial - 29 a 39 semanas de atraso | C6: 4408 | D6: 46267
B7: Extrajudicial - 40 a 55 semanas de atraso | C7: 6300 | D7: 68328
B8: JUDICIAL | C8: 10 | D8: 0
B9: Mas 55 semanas de atraso | C9: 13527 | D9: 121451
B10: Total general | C10: =SUM(C5:C9) -> 28537 | D10: =SUM(D5:D9) -> 493244.6
B12: COBRANZA GENERAL EDITH
B13: Segmento | C13: Cuentas | D13: Recuperación
B14: Extrajudicial - 0 a 28 semanas de atraso | C14: 3764 | D14: 103804.96
B15: Extrajudicial - 29 a 39 semanas de atraso | C15: 2127 | D15: 22882.62
B16: Extrajudicial - 40 a 55 semanas de atraso | C16: 2196 | D16: 12488
B17: Mas 55 semanas de atraso | C17: 9654 | D17: 24097.8
B18: Total general | C18: =SUM(C14:C17) -> 17741 | D18: =SUM(D14:D17) -> 163273.38
B20: COBRANZA GENERAL SAMANTHA 2
B21: Segmento | C21: Cuentas | D21: Recuperación
B22: Extrajudicial - 0 a 28 semanas de atraso | C22: 1995 | D22: 44091
B23: Extrajudicial - 29 a 39 semanas de atraso | C23: 1757 | D23: 20996
B24: Extrajudicial - 40 a 55 semanas de atraso | C24: 3100 | D24: 19430
B25: JUDICIAL | C25: 2 | D25: 0
B26: Mas 55 semanas de atraso | C26: 21729 | D26: 51833.42
B27: Total general | C27: =SUM(C22:C26) -> 28583 | D27: =SUM(D22:D26) -> 136350.42
B29: COBRANZA GENERAL SOFIA
B30: Segmento | C30: Cuentas | D30: Recuperación
B31: Extrajudicial - 0 a 28 semanas de atraso | C31: 316 | D31: 28419.94
B32: Extrajudicial - 29 a 39 semanas de atraso | C32: 1407 | D32: 29205.92
B33: Extrajudicial - 40 a 55 semanas de atraso | C33: 2361 | D33: 6900.78
B34: Mas 55 semanas de atraso | C34: 4259 | D34: 2157
B35: Total general | C35: =SUM(C31:C34) -> 8343 | D35: =SUM(D31:D34) -> 66683.64
B37: COBRANZA GENERAL FERNANDO
B38: Segmento | C38: Cuentas | D38: Recuperación
B39: Extrajudicial - 0 a 28 semanas de atraso | C39: 2087 | D39: 20505
B40: Total general | C40: =SUM(C39:C39) -> 2087 | D40: =SUM(D39:D39) -> 20505
B42: COBRANZA GENERAL FEDERICO
B43: Segmento | C43: Cuentas | D43: Recuperación
B44: Extrajudicial - 0 a 28 semanas de atraso | C44: 112 | D44: 2323
B45: Extrajudicial - 29 a 39 semanas de atraso | C45: 559 | D45: 1923
B46: Extrajudicial - 40 a 55 semanas de atraso | C46: 412 | D46: 0
B47: Mas 55 semanas de atraso | C47: 2112 | D47: 4506
...

Sheet DATA

Sheet EPR 06 MAYO
B2: REPORTE CONSOLIDADO POR SEGMENTOS
B3: SALDO ACUMULADO SEMANA 19
B5: COORDINADOR | C5: SEGMENTO | D5: CUENTAS | E5: COBRANZA REAL | F5: CUOTA IDEAL | G5: VARIACION | H5: % VAR | I5: EPR | J5: EPR IDEAL | K5: VAR EPR
B6: Samatha y Zareth | C6: Extrajudicial - 0 a 28 semanas de atraso | D6: =SUMIF('REPORTE DIARIO'!B:B,'EPR 06 MAYO'!C6, 'REPORTE DIARIO'!C:C) -> 12716 | E6: =SUMIF('REPORTE DIARIO'!B:B,'EPR 06 MAYO'!C6, 'REPORTE DIARIO'!D:D) -> 456342.5 | F6: =J6*D6 -> 799291.43 | G6: =+E6-F6 -> -342948.93 | H6: =ABS(G6/F6) -> 0.42906619 | I6: =E6/D6 -> 35.887268 | J6: =(220/7)*2 -> 62.857143 | K6: =+I6-J6 -> -26.969875
B7: Gabriel | C7: Extrajudicial - 29 a 39 semanas de atraso | D7: =SUMIF('REPORTE DIARIO'!B:B,'EPR 06 MAYO'!C7, 'REPORTE DIARIO'!C:C) -> 10641 | E7: =SUMIF('REPORTE DIARIO'!B:B,'EPR 06 MAYO'!C7, 'REPORTE DIARIO'!D:D) -> 122514.54 | F7: =J7*D7 -> 334431.43 | G7: =+E7-F7 -> -211916.89 | H7: =ABS(G7/F7) -> 0.6336632 | I7: =E7/D7 -> 11.513442 | J7: =(110/7)*2 -> 31.428571 | K7: =+I7-J7 -> -19.915129
B8: Gabriel | C8: Extrajudicial - 40 a 55 semanas de atraso | D8: =SUMIF('REPORTE DIARIO'!B:B,'EPR 06 MAYO'!C8, 'REPORTE DIARIO'!C:C) -> 15091 | E8: =SUMIF('REPORTE DIARIO'!B:B,'EPR 06 MAYO'!C8, 'REPORTE DIARIO'!D:D) -> 108735.78 | F8: =J8*D8 -> 194027.14 | G8: =+E8-F8 -> -85291.363 | H8: =ABS(G8/F8) -> 0.4395847 | I8: =E8/D8 -> 7.2053396 | J8: =(45/7)*2 -> 12.857143 | K8: =+I8-J8 -> -5.6518033
B9: Fernando | C9: Mas 55 semanas de atraso | D9: =SUMIF('REPORTE DIARIO'!B:B,'EPR 06 MAYO'!C9, 'REPORTE DIARIO'!C:C) -> 52282 | E9: =SUMIF('REPORTE DIARIO'!B:B,'EPR 06 MAYO'!C9, 'REPORTE DIARIO'!D:D) -> 207306.22 | F9: =J9*D9 -> 224065.71 | G9: =+E9-F9 -> -16759.494 | H9: =ABS(G9/F9) -> 0.074797228 | I9: =E9/D9 -> 3.9651547 | J9: =(15/7)*2 -> 4.2857143 | K9: =+I9-J9 -> -0.32055955
C10: TOTAL | D10: =SUM(D6:D9) -> 90730 | E10: =SUM(E6:E9) -> 894899.04 | F10: =SUM(F6:F9) -> 1551815.7 | G10: =+E10-F10 -> -656916.67 | H10: =ABS(G10/F10) -> 0.42332132 | I10: =E10/D10 -> 9.8633202 | J10: =F10/D10 -> 17.103667 | K10: =I10-J10 -> -7.2403469
B12: Nota:
B13: El saldo consolidado incluye los siguientes despachos
B14: Samantha, Samantha 2, Sofia, Edith, Fernando, Olguin y Federico
