Workbook

Sheet REPORTE DIARIO
B3: COBRANZA GENERAL SAMANTHA
B4: Segmento | C4: Cuentas | D4: Recuperación
B5: Extrajudicial - 0 a 28 semanas de atraso | C5: 4241 | D5: 38531
B6: Extrajudicial - 29 a 39 semanas de atraso | C6: 4568 | D6: 40021
B7: Extrajudicial - 40 a 55 semanas de atraso | C7: 6226 | D7: 20196
B8: JUDICIAL | C8: 10 | D8: 0
B9: Mas 55 semanas de atraso | C9: 5442 | D9: 2188
B10: Total general | C10: =SUM(C5:C9) -> 20487 | D10: =SUM(D5:D9) -> 100936
B12: COBRANZA GENERAL EDITH
B13: Segmento | C13: Cuentas | D13: Recuperación
B14: Extrajudicial - 0 a 28 semanas de atraso | C14: 3877 | D14: 49208.89
B15: Extrajudicial - 29 a 39 semanas de atraso | C15: 2278 | D15: 16022
B16: Extrajudicial - 40 a 55 semanas de atraso | C16: 1841 | D16: 3019
B17: Mas 55 semanas de atraso | C17: 0 | D17: 0
B18: Total general | C18: =SUM(C14:C17) -> 7996 | D18: =SUM(D14:D17) -> 68249.89
B20: COBRANZA GENERAL SAMANTHA 2
B21: Segmento | C21: Cuentas | D21: Recuperación
B22: Extrajudicial - 0 a 28 semanas de atraso | C22: 1985 | D22: 13017
B23: Extrajudicial - 29 a 39 semanas de atraso | C23: 1735 | D23: 83611
B24: Extrajudicial - 40 a 55 semanas de atraso | C24: 3083 | D24: 10060
B25: JUDICIAL | C25: 2 | D25: 0
B26: Mas 55 semanas de atraso | C26: 19737 | D26: 9807
B27: Total general | C27: =SUM(C22:C26) -> 26542 | D27: =SUM(D22:D26) -> 116495
B29: COBRANZA GENERAL SOFIA
B30: Segmento | C30: Cuentas | D30: Recuperación
B31: Extrajudicial - 0 a 28 semanas de atraso | C31: 323 | D31: 8223
B32: Extrajudicial - 29 a 39 semanas de atraso | C32: 1307 | D32: 4288
B33: Extrajudicial - 40 a 55 semanas de atraso | C33: 2374 | D33: 698
B34: Mas 55 semanas de atraso | C34: 0 | D34: 0
B35: Total general | C35: =SUM(C31:C34) -> 4004 | D35: =SUM(D31:D34) -> 13209
B37: COBRANZA GENERAL FERNANDO
B38: Segmento | C38: Cuentas | D38: Recuperación
B39: Extrajudicial - 0 a 28 semanas de atraso | C39: 2049 | D39: 5783
B40: Total general | C40: =SUM(C39:C39) -> 2049 | D40: =SUM(D39:D39) -> 5783
B42: COBRANZA GENERAL OLGUIN
B43: Segmento | C43: Cuentas | D43: Recuperación
B44: Extrajudicial - 0 a 28 semanas de atraso | C44: 75 | D44: 10
B45: Extrajudicial - 29 a 39 semanas de atraso | C45: 305 | D45: 0
B46: Extrajudicial - 40 a 55 semanas de atraso | C46: 649 | D46: 0
B47: Mas 55 semanas de atraso | C47: 878 | D47: 0
...

Sheet DATA

Sheet EPR 29 ABR
B2: REPORTE CONSOLIDADO POR SEGMENTOS
B3: COBRANZA 01 MAYO
B5: COORDINADOR | C5: SEGMENTO | D5: CUENTAS | E5: COBRANZA REAL | F5: CUOTA IDEAL | G5: VARIACION | H5: % VAR | I5: EPR | J5: EPR IDEAL | K5: VAR EPR
B6: Zareth | C6: Extrajudicial - 0 a 28 semanas de atraso | D6: =SUMIF('REPORTE DIARIO'!B:B,'EPR 29 ABR'!C6, 'REPORTE DIARIO'!C:C) -> 12587 | E6: =SUMIF('REPORTE DIARIO'!B:B,'EPR 29 ABR'!C6, 'REPORTE DIARIO'!D:D) -> 114772.89 | F6: =J6*D6 -> 395591.43 | G6: =+E6-F6 -> -280818.54 | H6: =ABS(G6/F6) -> 0.70987013 | I6: =E6/D6 -> 9.1183674 | J6: =220/7 -> 31.428571 | K6: =+I6-J6 -> -22.310204
B7: Gabriel | C7: Extrajudicial - 29 a 39 semanas de atraso | D7: =SUMIF('REPORTE DIARIO'!B:B,'EPR 29 ABR'!C7, 'REPORTE DIARIO'!C:C) -> 10674 | E7: =SUMIF('REPORTE DIARIO'!B:B,'EPR 29 ABR'!C7, 'REPORTE DIARIO'!D:D) -> 143942 | F7: =J7*D7 -> 167734.29 | G7: =+E7-F7 -> -23792.286 | H7: =ABS(G7/F7) -> 0.1418451 | I7: =E7/D7 -> 13.485291 | J7: =110/7 -> 15.714286 | K7: =+I7-J7 -> -2.2289944
B8: Gabriel | C8: Extrajudicial - 40 a 55 semanas de atraso | D8: =SUMIF('REPORTE DIARIO'!B:B,'EPR 29 ABR'!C8, 'REPORTE DIARIO'!C:C) -> 14512 | E8: =SUMIF('REPORTE DIARIO'!B:B,'EPR 29 ABR'!C8, 'REPORTE DIARIO'!D:D) -> 33973 | F8: =J8*D8 -> 93291.429 | G8: =+E8-F8 -> -59318.429 | H8: =ABS(G8/F8) -> 0.63584007 | I8: =E8/D8 -> 2.3410281 | J8: =45/7 -> 6.4285714 | K8: =+I8-J8 -> -4.0875433
B9: Fernando (Naucalpan) | C9: Mas 55 semanas de atraso | D9: =SUMIF('REPORTE DIARIO'!B:B,'EPR 29 ABR'!C9, 'REPORTE DIARIO'!C:C) -> 27720 | E9: =SUMIF('REPORTE DIARIO'!B:B,'EPR 29 ABR'!C9, 'REPORTE DIARIO'!D:D) -> 15270 | F9: =J9*D9 -> 47520 | G9: =+E9-F9 -> -32250 | H9: =ABS(G9/F9) -> 0.67866162 | I9: =E9/D9 -> 0.5508658 | J9: =12/7 -> 1.7142857 | K9: =+I9-J9 -> -1.1634199
C10: TOTAL | D10: =SUM(D6:D9) -> 65493 | E10: =SUM(E6:E9) -> 307957.89 | F10: =SUM(F6:F9) -> 704137.14 | G10: =+E10-F10 -> -396179.25 | H10: =ABS(G10/F10) -> 0.56264501 | I10: =E10/D10 -> 4.7021497 | J10: =F10/D10 -> 10.751334 | K10: =I10-J10 -> -6.0491847
B12: Nota:
B13: El saldo consolidado incluye los siguientes despachos
B14: Samantha, Samantha 2, Sofia, Edith, Fernando, Olguin y Federico
