Workbook

Sheet REPORTE DIARIO
B3: COBRANZA GENERAL SAMANTHA
B4: Segmento | C4: Cuentas | D4: Recuperación
B5: Extrajudicial - 0 a 28 semanas de atraso | C5: 4549 | D5: 654679.85
B6: Extrajudicial - 29 a 39 semanas de atraso | C6: 4585 | D6: 442716.92
B7: Extrajudicial - 40 a 55 semanas de atraso | C7: 6196 | D7: 284767.84
B8: JUDICIAL | C8: 8 | D8: 0
B9: Mas 55 semanas de atraso | C9: 13440 | D9: 441254.47
B10: Total general | C10: =SUM(C5:C9) -> 28778 | D10: =SUM(D5:D9) -> 1823419.1
B12: COBRANZA GENERAL EDITH
B13: Segmento | C13: Cuentas | D13: Recuperación
B14: Extrajudicial - 0 a 28 semanas de atraso | C14: 3999 | D14: 462231.27
B15: Extrajudicial - 29 a 39 semanas de atraso | C15: 2325 | D15: 194708.8
B16: Extrajudicial - 40 a 55 semanas de atraso | C16: 1808 | D16: 63833.43
B17: Mas 55 semanas de atraso | C17: 9599 | D17: 55882.4
B18: Total general | C18: =SUM(C14:C17) -> 17731 | D18: =SUM(D14:D17) -> 776655.9
B20: COBRANZA GENERAL SAMANTHA 2
B21: Segmento | C21: Cuentas | D21: Recuperación
B22: Extrajudicial - 0 a 28 semanas de atraso | C22: 2164 | D22: 235378.08
B23: Extrajudicial - 29 a 39 semanas de atraso | C23: 1629 | D23: 136789.39
B24: Extrajudicial - 40 a 55 semanas de atraso | C24: 3098 | D24: 107077.6
B25: JUDICIAL | C25: 2 | D25: 0
B26: Mas 55 semanas de atraso | C26: 21854 | D26: 181649.82
B27: Total general | C27: =SUM(C22:C26) -> 28747 | D27: =SUM(D22:D26) -> 660894.89
B29: COBRANZA GENERAL SOFIA
B30: Segmento | C30: Cuentas | D30: Recuperación
B31: Extrajudicial - 0 a 28 semanas de atraso | C31: 336 | D31: 209902.61
B32: Extrajudicial - 29 a 39 semanas de atraso | C32: 1314 | D32: 155431.27
B33: Extrajudicial - 40 a 55 semanas de atraso | C33: 2383 | D33: 59693.33
B34: Mas 55 semanas de atraso | C34: 4264 | D34: 7082.51
B35: Total general | C35: =SUM(C31:C34) -> 8297 | D35: =SUM(D31:D34) -> 432109.72
B37: COBRANZA GENERAL FERNANDO
B38: Segmento | C38: Cuentas | D38: Recuperación
B39: Extrajudicial - 0 a 28 semanas de atraso | C39: 2039 | D39: 57505
B40: Total general | C40: =SUM(C39:C39) -> 2039 | D40: =SUM(D39:D39) -> 57505
B42: COBRANZA GENERAL FEDERICO
B43: Segmento | C43: Cuentas | D43: Recuperación
B44: Extrajudicial - 0 a 28 semanas de atraso | C44: 39 | D44: 2302
B45: Extrajudicial - 29 a 39 semanas de atraso | C45: 347 | D45: 5886
B46: Extrajudicial - 40 a 55 semanas de atraso | C46: 292 | D46: 1320
B47: Mas 55 semanas de atraso | C47: 1951 | D47: 24200.71
...

Sheet DATA

Sheet EPR 27 ABR
B2: REPORTE CONSOLIDADO POR SEGMENTOS
B3: SALDO ACUMULADO SEMANA 17
B5: COORDINADOR | C5: SEGMENTO | D5: CUENTAS | E5: COBRANZA REAL | F5: CUOTA IDEAL | G5: VARIACION | H5: % VAR | I5: EPR | J5: EPR IDEAL | K5: VAR EPR
B6: Samatha y Zareth | C6: Extrajudicial - 0 a 28 semanas de atraso | D6: =SUMIF('REPORTE DIARIO'!B:B,'EPR 27 ABR'!C6, 'REPORTE DIARIO'!C:C) -> 13211 | E6: =SUMIF('REPORTE DIARIO'!B:B,'EPR 27 ABR'!C6, 'REPORTE DIARIO'!D:D) -> 1623033.3 | F6: =J6*D6 -> 2642200 | G6: =+E6-F6 -> -1019166.7 | H6: =ABS(G6/F6) -> 0.38572657 | I6: =E6/D6 -> 122.85469 | J6: =(200/7)*7 -> 200 | K6: =+I6-J6 -> -77.145314
B7: Gabriel | C7: Extrajudicial - 29 a 39 semanas de atraso | D7: =SUMIF('REPORTE DIARIO'!B:B,'EPR 27 ABR'!C7, 'REPORTE DIARIO'!C:C) -> 10369 | E7: =SUMIF('REPORTE DIARIO'!B:B,'EPR 27 ABR'!C7, 'REPORTE DIARIO'!D:D) -> 937032.38 | F7: =J7*D7 -> 1140590 | G7: =+E7-F7 -> -203557.62 | H7: =ABS(G7/F7) -> 0.17846695 | I7: =E7/D7 -> 90.368635 | J7: =(110/7)*7 -> 110 | K7: =+I7-J7 -> -19.631365
B8: Gabriel | C8: Extrajudicial - 40 a 55 semanas de atraso | D8: =SUMIF('REPORTE DIARIO'!B:B,'EPR 27 ABR'!C8, 'REPORTE DIARIO'!C:C) -> 14376 | E8: =SUMIF('REPORTE DIARIO'!B:B,'EPR 27 ABR'!C8, 'REPORTE DIARIO'!D:D) -> 517692.2 | F8: =J8*D8 -> 646920 | G8: =+E8-F8 -> -129227.8 | H8: =ABS(G8/F8) -> 0.19975855 | I8: =E8/D8 -> 36.010865 | J8: =(45/7)*7 -> 45 | K8: =+I8-J8 -> -8.9891347
B9: Fernando | C9: Mas 55 semanas de atraso | D9: =SUMIF('REPORTE DIARIO'!B:B,'EPR 27 ABR'!C9, 'REPORTE DIARIO'!C:C) -> 51950 | E9: =SUMIF('REPORTE DIARIO'!B:B,'EPR 27 ABR'!C9, 'REPORTE DIARIO'!D:D) -> 714155.91 | F9: =J9*D9 -> 779250 | G9: =+E9-F9 -> -65094.09 | H9: =ABS(G9/F9) -> 0.083534283 | I9: =E9/D9 -> 13.746986 | J9: =(15/7)*7 -> 15 | K9: =+I9-J9 -> -1.2530142
C10: TOTAL | D10: =SUM(D6:D9) -> 89906 | E10: =SUM(E6:E9) -> 3791913.8 | F10: =SUM(F6:F9) -> 5208960 | G10: =+E10-F10 -> -1417046.2 | H10: =ABS(G10/F10) -> 0.27204015 | I10: =E10/D10 -> 42.176426 | J10: =F10/D10 -> 57.937846 | K10: =I10-J10 -> -15.76142
B12: Nota:
B13: El saldo consolidado incluye los siguientes despachos
B14: Samantha, Samantha 2, Sofia, Edith, Fernando, Olguin y Federico
