Workbook

Sheet REPORTE DIARIO
B3: COBRANZA GENERAL SAMANTHA
B4: Segmento | C4: Cuentas | D4: Recuperación
B5: Extrajudicial - 0 a 28 semanas de atraso | C5: 2626 | D5: 32234.47
B6: Extrajudicial - 29 a 39 semanas de atraso | C6: 2960 | D6: 35646
B7: Extrajudicial - 40 a 55 semanas de atraso | C7: 5515 | D7: 25708
B8: JUDICIAL | C8: 11 | D8: 0
B9: Mas 55 semanas de atraso | C9: 11575 | D9: 67988.69
B10: Total general | C10: =SUM(C5:C9) -> 22687 | D10: =SUM(D5:D9) -> 161577.16
B12: COBRANZA GENERAL SAMANTHA 2
B13: Segmento | C13: Cuentas | D13: Recuperación
B14: Extrajudicial - 0 a 28 semanas de atraso | C14: 2880 | D14: 34192
B15: Extrajudicial - 29 a 39 semanas de atraso | C15: 2114 | D15: 33455
B16: Extrajudicial - 40 a 55 semanas de atraso | C16: 2743 | D16: 6910
B17: JUDICIAL | C17: 2 | D17: 0
B18: Mas 55 semanas de atraso | C18: 17881 | D18: 15599.73
B19: Total general | C19: =SUM(C14:C18) -> 25620 | D19: =SUM(D14:D18) -> 90156.73
B21: COBRANZA GENERAL EDITH
B22: Segmento | C22: Cuentas | D22: Recuperación
B23: Extrajudicial - 0 a 28 semanas de atraso | C23: 3218 | D23: 56506.84
B24: Extrajudicial - 29 a 39 semanas de atraso | C24: 1015 | D24: 942
B25: Extrajudicial - 40 a 55 semanas de atraso | C25: 2120 | D25: 1038
B26: JUDICIAL | C26: 1 | D26: 0
B27: Mas 55 semanas de atraso | C27: 16874 | D27: 2053.01
B28: Total general | C28: =SUM(C23:C27) -> 23228 | D28: =SUM(D23:D27) -> 60539.85
B30: COBRANZA GENERAL OLGUIN
B31: Segmento | C31: Cuentas | D31: Recuperación
B32: Extrajudicial - 0 a 28 semanas de atraso | C32: 2196 | D32: 8794
B33: Extrajudicial - 29 a 39 semanas de atraso | C33: 1346 | D33: 1663
B34: Extrajudicial - 40 a 55 semanas de atraso | C34: 2200 | D34: 1000
B35: Mas 55 semanas de atraso | C35: 2186 | D35: 45111.75
B36: Total general | C36: =SUM(C32:C35) -> 7928 | D36: =SUM(D32:D35) -> 56568.75
B38: COBRANZA GENERAL FERNANDO
B39: Segmento | C39: Cuentas | D39: Recuperación
B40: Extrajudicial - 0 a 28 semanas de atraso | C40: 2837 | D40: 41811
B41: Total general | C41: =SUM(C40:C40) -> 2837 | D41: =SUM(D40:D40) -> 41811
B43: COBRANZA GENERAL SOFIA
B44: Segmento | C44: Cuentas | D44: Recuperación
B45: Extrajudicial - 0 a 28 semanas de atraso | C45: 52 | D45: 1801
B46: Extrajudicial - 29 a 39 semanas de atraso | C46: 3312 | D46: 25052.26
B47: Extrajudicial - 40 a 55 semanas de atraso | C47: 286 | D47: 0
...

Sheet DATA

Sheet EPR 04 JUN
B2: REPORTE CONSOLIDADO POR SEGMENTOS
B3: COBRANZA 04 JUNIO
B5: COORDINADOR | C5: SEGMENTO | D5: CUENTAS | E5: COBRANZA REAL | F5: CUOTA IDEAL | G5: VARIACION | H5: % VAR | I5: EPR | J5: EPR IDEAL | K5: VAR EPR
B6: Zareth | C6: Extrajudicial - 0 a 28 semanas de atraso | D6: =SUMIF('REPORTE DIARIO'!B:B,'EPR 04 JUN'!C6, 'REPORTE DIARIO'!C:C) -> 14394 | E6: =SUMIF('REPORTE DIARIO'!B:B,'EPR 04 JUN'!C6, 'REPORTE DIARIO'!D:D) -> 176759.31 | F6: =J6*D6 -> 452382.86 | G6: =+E6-F6 -> -275623.55 | H6: =ABS(G6/F6) -> 0.60927054 | I6: =E6/D6 -> 12.280069 | J6: =220/7 -> 31.428571 | K6: =+I6-J6 -> -19.148503
B7: Gabriel | C7: Extrajudicial - 29 a 39 semanas de atraso | D7: =SUMIF('REPORTE DIARIO'!B:B,'EPR 04 JUN'!C7, 'REPORTE DIARIO'!C:C) -> 11389 | E7: =SUMIF('REPORTE DIARIO'!B:B,'EPR 04 JUN'!C7, 'REPORTE DIARIO'!D:D) -> 97758.26 | F7: =J7*D7 -> 178970 | G7: =+E7-F7 -> -81211.74 | H7: =ABS(G7/F7) -> 0.45377292 | I7: =E7/D7 -> 8.5835684 | J7: =110/7 -> 15.714286 | K7: =+I7-J7 -> -7.1307174
B8: Gabriel | C8: Extrajudicial - 40 a 55 semanas de atraso | D8: =SUMIF('REPORTE DIARIO'!B:B,'EPR 04 JUN'!C8, 'REPORTE DIARIO'!C:C) -> 13669 | E8: =SUMIF('REPORTE DIARIO'!B:B,'EPR 04 JUN'!C8, 'REPORTE DIARIO'!D:D) -> 34656 | F8: =J8*D8 -> 87872.143 | G8: =+E8-F8 -> -53216.143 | H8: =ABS(G8/F8) -> 0.6056088 | I8: =E8/D8 -> 2.535372 | J8: =45/7 -> 6.4285714 | K8: =+I8-J8 -> -3.8931994
B9: Fernando (Naucalpan) | C9: Mas 55 semanas de atraso | D9: =SUMIF('REPORTE DIARIO'!B:B,'EPR 04 JUN'!C9, 'REPORTE DIARIO'!C:C) -> 54938 | E9: =SUMIF('REPORTE DIARIO'!B:B,'EPR 04 JUN'!C9, 'REPORTE DIARIO'!D:D) -> 133390.18 | F9: =J9*D9 -> 117724.29 | G9: =+E9-F9 -> 15665.894 | H9: =ABS(G9/F9) -> 0.13307275 | I9: =E9/D9 -> 2.428013 | J9: =15/7 -> 2.1428571 | K9: =+I9-J9 -> 0.28515589
C10: TOTAL | D10: =SUM(D6:D9) -> 94390 | E10: =SUM(E6:E9) -> 442563.75 | F10: =SUM(F6:F9) -> 836949.29 | G10: =+E10-F10 -> -394385.54 | H10: =ABS(G10/F10) -> 0.47121796 | I10: =E10/D10 -> 4.688672 | J10: =F10/D10 -> 8.8669275 | K10: =I10-J10 -> -4.1782555
B12: Nota:
B13: El saldo consolidado incluye los siguientes despachos
B14: Samantha, Samantha 2, Sofia, Edith, Fernando, Olguin y Federico
