Workbook

Sheet REPORTE DIARIO
B3: COBRANZA GENERAL SAMANTHA
B4: Segmento | C4: Cuentas | D4: Recuperación
B5: Extrajudicial - 0 a 28 semanas de atraso | C5: 6750 | D5: 37428.73
B6: Extrajudicial - 29 a 39 semanas de atraso | C6: 5523 | D6: 28165.89
B7: Extrajudicial - 40 a 55 semanas de atraso | C7: 8481 | D7: 39972.77
B8: JUDICIAL | C8: 21 | D8: 0
B9: Mas 55 semanas de atraso | C9: 21089 | D9: 35543
B10: Total general | C10: =SUM(C5:C9) -> 41864 | D10: =SUM(D5:D9) -> 141110.39
B12: COBRANZA GENERAL SAMANTHA 2
B13: Segmento | C13: Cuentas | D13: Recuperación
B14: Extrajudicial - 0 a 28 semanas de atraso | C14: 2409 | D14: 83307.7
B15: Extrajudicial - 29 a 39 semanas de atraso | C15: 1515 | D15: 2749
B16: Extrajudicial - 40 a 55 semanas de atraso | C16: 3355 | D16: 4913
B17: JUDICIAL | C17: 2 | D17: 0
B18: Mas 55 semanas de atraso | C18: 21327 | D18: 11761
B19: Total general | C19: =SUM(C14:C18) -> 28608 | D19: =SUM(D14:D18) -> 102730.7
B21: COBRANZA GENERAL EDITH
B22: Segmento | C22: Cuentas | D22: Recuperación
B23: Extrajudicial - 0 a 28 semanas de atraso | C23: 2058 | D23: 33093.67
B24: Extrajudicial - 29 a 39 semanas de atraso | C24: 2170 | D24: 9629.29
B25: Extrajudicial - 40 a 55 semanas de atraso | C25: 990 | D25: 1598
B26: Mas 55 semanas de atraso | C26: 9105 | D26: 9303
B27: Total general | C27: =SUM(C23:C26) -> 14323 | D27: =SUM(D23:D26) -> 53623.96
B29: COBRANZA GENERAL SOFIA
B30: Segmento | C30: Cuentas | D30: Recuperación
B31: Extrajudicial - 0 a 28 semanas de atraso | C31: 1355 | D31: 15030.46
B32: Extrajudicial - 29 a 39 semanas de atraso | C32: 1942 | D32: 33455.63
B33: Extrajudicial - 40 a 55 semanas de atraso | C33: 2795 | D33: 0
B34: Mas 55 semanas de atraso | C34: 4265 | D34: 139
B35: Total general | C35: =SUM(C31:C34) -> 10357 | D35: =SUM(D31:D34) -> 48625.09
B37: COBRANZA GENERAL FEDERICO
B38: Segmento | C38: Cuentas | D38: Recuperación
B39: Extrajudicial - 0 a 28 semanas de atraso | C39: 39 | D39: 210
B40: Extrajudicial - 29 a 39 semanas de atraso | C40: 322 | D40: 400
B41: Extrajudicial - 40 a 55 semanas de atraso | C41: 255 | D41: 546
B42: Mas 55 semanas de atraso | C42: 1930 | D42: 3131
B43: Total general | C43: =SUM(C39:C42) -> 2546 | D43: =SUM(D39:D42) -> 4287
B45: COBRANZA GENERAL FERNANDO
B46: Segmento | C46: Cuentas | D46: Recuperación
B47: Extrajudicial - 0 a 28 semanas de atraso | C47: 1333 | D47: 2305
...

Sheet DATA

Sheet EPR 17 ABR
B2: REPORTE CONSOLIDADO POR SEGMENTOS
B3: COBRANZA 17 ABRIL
B5: COORDINADOR | C5: SEGMENTO | D5: CUENTAS | E5: COBRANZA REAL | F5: CUOTA IDEAL | G5: VARIACION | H5: % VAR | I5: EPR | J5: EPR IDEAL | K5: VAR EPR
B6: Samatha y Zareth | C6: Extrajudicial - 0 a 28 semanas de atraso | D6: =SUMIF('REPORTE DIARIO'!B:B,'EPR 17 ABR'!C6, 'REPORTE DIARIO'!C:C) -> 13944 | E6: =SUMIF('REPORTE DIARIO'!B:B,'EPR 17 ABR'!C6, 'REPORTE DIARIO'!D:D) -> 171375.56 | F6: =J6*D6 -> 398400 | G6: =+E6-F6 -> -227024.44 | H6: =ABS(G6/F6) -> 0.56984046 | I6: =E6/D6 -> 12.290273 | J6: =200/7 -> 28.571429 | K6: =+I6-J6 -> -16.281156
B7: Gabriel | C7: Extrajudicial - 29 a 39 semanas de atraso | D7: =SUMIF('REPORTE DIARIO'!B:B,'EPR 17 ABR'!C7, 'REPORTE DIARIO'!C:C) -> 11472 | E7: =SUMIF('REPORTE DIARIO'!B:B,'EPR 17 ABR'!C7, 'REPORTE DIARIO'!D:D) -> 74399.81 | F7: =J7*D7 -> 180274.29 | G7: =+E7-F7 -> -105874.48 | H7: =ABS(G7/F7) -> 0.5872966 | I7: =E7/D7 -> 6.4853391 | J7: =110/7 -> 15.714286 | K7: =+I7-J7 -> -9.2289466
B8: Gabriel | C8: Extrajudicial - 40 a 55 semanas de atraso | D8: =SUMIF('REPORTE DIARIO'!B:B,'EPR 17 ABR'!C8, 'REPORTE DIARIO'!C:C) -> 15876 | E8: =SUMIF('REPORTE DIARIO'!B:B,'EPR 17 ABR'!C8, 'REPORTE DIARIO'!D:D) -> 47029.77 | F8: =J8*D8 -> 102060 | G8: =+E8-F8 -> -55030.23 | H8: =ABS(G8/F8) -> 0.53919489 | I8: =E8/D8 -> 2.9623186 | J8: =45/7 -> 6.4285714 | K8: =+I8-J8 -> -3.4662528
B9: Fernando | C9: Mas 55 semanas de atraso | D9: =SUMIF('REPORTE DIARIO'!B:B,'EPR 17 ABR'!C9, 'REPORTE DIARIO'!C:C) -> 57716 | E9: =SUMIF('REPORTE DIARIO'!B:B,'EPR 17 ABR'!C9, 'REPORTE DIARIO'!D:D) -> 59877 | F9: =J9*D9 -> 123677.14 | G9: =+E9-F9 -> -63800.143 | H9: =ABS(G9/F9) -> 0.51586042 | I9: =E9/D9 -> 1.037442 | J9: =15/7 -> 2.1428571 | K9: =+I9-J9 -> -1.1054152
C10: TOTAL | D10: =SUM(D6:D9) -> 99008 | E10: =SUM(E6:E9) -> 352682.14 | F10: =SUM(F6:F9) -> 804411.43 | G10: =+E10-F10 -> -451729.29 | H10: =ABS(G10/F10) -> 0.56156498 | I10: =E10/D10 -> 3.562158 | J10: =F10/D10 -> 8.1247114 | K10: =I10-J10 -> -4.5625534
B12: Nota:
B13: El saldo consolidado incluye los siguientes despachos
B14: Samantha, Samantha 2, Sofia, Edith, Fernando y Federico
