Workbook

Sheet REPORTE DIARIO
B3: COBRANZA GENERAL SAMANTHA
B4: Segmento | C4: Cuentas | D4: Recuperación
B5: Extrajudicial - 0 a 28 semanas de atraso | C5: 7393 | D5: 83284
B6: Extrajudicial - 29 a 39 semanas de atraso | C6: 7932 | D6: 61323.86
B7: Extrajudicial - 40 a 55 semanas de atraso | C7: 10188 | D7: 109869
B8: JUDICIAL | C8: 21 | D8: 0
B9: Mas 55 semanas de atraso | C9: 29562 | D9: 62636.51
B10: Total general | C10: =SUM(C5:C9) -> 55096 | D10: =SUM(D5:D9) -> 317113.37
B12: COBRANZA GENERAL SAMANTHA 2
B13: Segmento | C13: Cuentas | D13: Recuperación
B14: Extrajudicial - 0 a 28 semanas de atraso | C14: 3256 | D14: 22615.23
B15: Extrajudicial - 29 a 39 semanas de atraso | C15: 1803 | D15: 14130
B16: Extrajudicial - 40 a 55 semanas de atraso | C16: 3456 | D16: 7601
B17: JUDICIAL | C17: 2 | D17: 0
B18: Mas 55 semanas de atraso | C18: 21206 | D18: 49154
B19: Total general | C19: =SUM(C14:C18) -> 29723 | D19: =SUM(D14:D18) -> 93500.23
B21: COBRANZA GENERAL EDITH
B22: Segmento | C22: Cuentas | D22: Recuperación
B23: Extrajudicial - 0 a 28 semanas de atraso | C23: 1491 | D23: 25633.8
B24: Extrajudicial - 29 a 39 semanas de atraso | C24: 1404 | D24: 14171
B25: Extrajudicial - 40 a 55 semanas de atraso | C25: 735 | D25: 379
B26: Mas 55 semanas de atraso | C26: 8472 | D26: 5804
B27: Total general | C27: =SUM(C23:C26) -> 12102 | D27: =SUM(D23:D26) -> 45987.8
B29: COBRANZA GENERAL SOFIA
B30: Segmento | C30: Cuentas | D30: Recuperación
B31: Extrajudicial - 0 a 28 semanas de atraso | C31: 1247 | D31: 27170.14
B32: Extrajudicial - 29 a 39 semanas de atraso | C32: 1169 | D32: 1695.08
B33: Extrajudicial - 40 a 55 semanas de atraso | C33: 2996 | D33: 1992
B34: Mas 55 semanas de atraso | C34: 1900 | D34: 2141
B35: Total general | C35: =SUM(C31:C34) -> 7312 | D35: =SUM(D31:D34) -> 32998.22
B37: COBRANZA GENERAL FERNANDO
B38: Segmento | C38: Cuentas | D38: Recuperación
B39: Extrajudicial - 0 a 28 semanas de atraso | C39: 2746 | D39: 8977
B40: Total general | C40: =SUM(C39:C39) -> 2746 | D40: =SUM(D39:D39) -> 8977
B42: COBRANZA GENERAL FEDERICO
B43: Segmento | C43: Cuentas | D43: Recuperación
B44: Extrajudicial - 0 a 28 semanas de atraso | C44: 0 | D44: 0
B45: Extrajudicial - 29 a 39 semanas de atraso | C45: 123 | D45: 0
B46: Extrajudicial - 40 a 55 semanas de atraso | C46: 164 | D46: 0
B47: Mas 55 semanas de atraso | C47: 959 | D47: 1443
...

Sheet DATA

Sheet EPR 30 MAR
B2: REPORTE CONSOLIDADO POR SEGMENTOS
B3: COBRANZA 30 MARZO
B5: COORDINADOR | C5: SEGMENTO | D5: CUENTAS | E5: COBRANZA REAL | F5: CUOTA IDEAL | G5: VARIACION | H5: % VAR | I5: EPR | J5: EPR IDEAL | K5: VAR EPR
B6: Samatha y Zareth | C6: Extrajudicial - 0 a 28 semanas de atraso | D6: =SUMIF('REPORTE DIARIO'!B:B,'EPR 30 MAR'!C6, 'REPORTE DIARIO'!C:C) -> 16201 | E6: =SUMIF('REPORTE DIARIO'!B:B,'EPR 30 MAR'!C6, 'REPORTE DIARIO'!D:D) -> 167680.17 | F6: =J6*D6 -> 462885.71 | G6: =+E6-F6 -> -295205.54 | H6: =ABS(G6/F6) -> 0.63775039 | I6: =E6/D6 -> 10.349989 | J6: =200/7 -> 28.571429 | K6: =+I6-J6 -> -18.22144
B7: Gabriel | C7: Extrajudicial - 29 a 39 semanas de atraso | D7: =SUMIF('REPORTE DIARIO'!B:B,'EPR 30 MAR'!C7, 'REPORTE DIARIO'!C:C) -> 12572 | E7: =SUMIF('REPORTE DIARIO'!B:B,'EPR 30 MAR'!C7, 'REPORTE DIARIO'!D:D) -> 91319.94 | F7: =J7*D7 -> 197560 | G7: =+E7-F7 -> -106240.06 | H7: =ABS(G7/F7) -> 0.53776098 | I7: =E7/D7 -> 7.263756 | J7: =110/7 -> 15.714286 | K7: =+I7-J7 -> -8.4505297
B8: Gabriel | C8: Extrajudicial - 40 a 55 semanas de atraso | D8: =SUMIF('REPORTE DIARIO'!B:B,'EPR 30 MAR'!C8, 'REPORTE DIARIO'!C:C) -> 17554 | E8: =SUMIF('REPORTE DIARIO'!B:B,'EPR 30 MAR'!C8, 'REPORTE DIARIO'!D:D) -> 119841 | F8: =J8*D8 -> 112847.14 | G8: =+E8-F8 -> 6993.8571 | H8: =ABS(G8/F8) -> 0.061976378 | I8: =E8/D8 -> 6.826991 | J8: =45/7 -> 6.4285714 | K8: =+I8-J8 -> 0.39841957
B9: Fernando | C9: Mas 55 semanas de atraso | D9: =SUMIF('REPORTE DIARIO'!B:B,'EPR 30 MAR'!C9, 'REPORTE DIARIO'!C:C) -> 62109 | E9: =SUMIF('REPORTE DIARIO'!B:B,'EPR 30 MAR'!C9, 'REPORTE DIARIO'!D:D) -> 121178.51 | F9: =J9*D9 -> 133090.71 | G9: =+E9-F9 -> -11912.204 | H9: =ABS(G9/F9) -> 0.089504398 | I9: =E9/D9 -> 1.951062 | J9: =15/7 -> 2.1428571 | K9: =+I9-J9 -> -0.19179514
C10: TOTAL | D10: =SUM(D6:D9) -> 108436 | E10: =SUM(E6:E9) -> 500019.62 | F10: =SUM(F6:F9) -> 906383.57 | G10: =+E10-F10 -> -406363.95 | H10: =ABS(G10/F10) -> 0.44833552 | I10: =E10/D10 -> 4.6111957 | J10: =F10/D10 -> 8.3586961 | K10: =I10-J10 -> -3.7475004
B12: Nota:
B13: El saldo consolidado incluye los siguientes despachos
B14: Samantha, Samantha 2, Sofia, Edith, Olguin, Fernando y Federico
