Workbook

Sheet REPORTE DIARIO
B3: COBRANZA GENERAL SAMANTHA
B4: Segmento | C4: Cuentas | D4: Recuperación
B5: Extrajudicial - 0 a 28 semanas de atraso | C5: 2752 | D5: 111319.87
B6: Extrajudicial - 29 a 39 semanas de atraso | C6: 3095 | D6: 45554
B7: Extrajudicial - 40 a 55 semanas de atraso | C7: 6031 | D7: 61182
B8: JUDICIAL | C8: 11 | D8: 0
B9: Mas 55 semanas de atraso | C9: 12028 | D9: 81909.24
B10: Total general | C10: =SUM(C5:C9) -> 23917 | D10: =SUM(D5:D9) -> 299965.11
B12: COBRANZA GENERAL EDITH
B13: Segmento | C13: Cuentas | D13: Recuperación
B14: Extrajudicial - 0 a 28 semanas de atraso | C14: 3796 | D14: 110271.06
B15: Extrajudicial - 29 a 39 semanas de atraso | C15: 926 | D15: 7898
B16: Extrajudicial - 40 a 55 semanas de atraso | C16: 2113 | D16: 5709
B17: JUDICIAL | C17: 1 | D17: 0
B18: Mas 55 semanas de atraso | C18: 16873 | D18: 26345
B19: Total general | C19: =SUM(C14:C18) -> 23709 | D19: =SUM(D14:D18) -> 150223.06
B21: COBRANZA GENERAL SAMANTHA 2
B22: Segmento | C22: Cuentas | D22: Recuperación
B23: Extrajudicial - 0 a 28 semanas de atraso | C23: 2916 | D23: 26617
B24: Extrajudicial - 29 a 39 semanas de atraso | C24: 2040 | D24: 4743
B25: Extrajudicial - 40 a 55 semanas de atraso | C25: 2825 | D25: 20966
B26: JUDICIAL | C26: 2 | D26: 0
B27: Mas 55 semanas de atraso | C27: 13268 | D27: 17964
B28: Total general | C28: =SUM(C23:C27) -> 21051 | D28: =SUM(D23:D27) -> 70290
B30: COBRANZA GENERAL SOFIA
B31: Segmento | C31: Cuentas | D31: Recuperación
B32: Extrajudicial - 0 a 28 semanas de atraso | C32: 49 | D32: 704
B33: Extrajudicial - 29 a 39 semanas de atraso | C33: 3229 | D33: 19685
B34: Extrajudicial - 40 a 55 semanas de atraso | C34: 285 | D34: 626
B35: Mas 55 semanas de atraso | C35: 3954 | D35: 102
B36: Total general | C36: =SUM(C32:C35) -> 7517 | D36: =SUM(D32:D35) -> 21117
B38: COBRANZA GENERAL OLGUIN
B39: Segmento | C39: Cuentas | D39: Recuperación
B40: Extrajudicial - 0 a 28 semanas de atraso | C40: 2274 | D40: 3632
B41: Extrajudicial - 29 a 39 semanas de atraso | C41: 1412 | D41: 5176
B42: Extrajudicial - 40 a 55 semanas de atraso | C42: 2310 | D42: 1000
B43: Mas 55 semanas de atraso | C43: 2008 | D43: 2192
B44: Total general | C44: =SUM(C40:C43) -> 8004 | D44: =SUM(D40:D43) -> 12000
B46: COBRANZA GENERAL FEDERICO
B47: Segmento | C47: Cuentas | D47: Recuperación
...

Sheet DATA

Sheet EPR 08 JUN
B2: REPORTE CONSOLIDADO POR SEGMENTOS
B3: COBRANZA 08 JUNIO
B5: COORDINADOR | C5: SEGMENTO | D5: CUENTAS | E5: COBRANZA REAL | F5: CUOTA IDEAL | G5: VARIACION | H5: % VAR | I5: EPR | J5: EPR IDEAL | K5: VAR EPR
B6: Zareth | C6: Extrajudicial - 0 a 28 semanas de atraso | D6: =SUMIF('REPORTE DIARIO'!B:B,'EPR 08 JUN'!C6, 'REPORTE DIARIO'!C:C) -> 15119 | E6: =SUMIF('REPORTE DIARIO'!B:B,'EPR 08 JUN'!C6, 'REPORTE DIARIO'!D:D) -> 258980.93 | F6: =J6*D6 -> 475168.57 | G6: =+E6-F6 -> -216187.64 | H6: =ABS(G6/F6) -> 0.45497041 | I6: =E6/D6 -> 17.129501 | J6: =220/7 -> 31.428571 | K6: =+I6-J6 -> -14.29907
B7: Gabriel | C7: Extrajudicial - 29 a 39 semanas de atraso | D7: =SUMIF('REPORTE DIARIO'!B:B,'EPR 08 JUN'!C7, 'REPORTE DIARIO'!C:C) -> 11313 | E7: =SUMIF('REPORTE DIARIO'!B:B,'EPR 08 JUN'!C7, 'REPORTE DIARIO'!D:D) -> 83056 | F7: =J7*D7 -> 177775.71 | G7: =+E7-F7 -> -94719.714 | H7: =ABS(G7/F7) -> 0.53280458 | I7: =E7/D7 -> 7.3416424 | J7: =110/7 -> 15.714286 | K7: =+I7-J7 -> -8.3726434
B8: Gabriel | C8: Extrajudicial - 40 a 55 semanas de atraso | D8: =SUMIF('REPORTE DIARIO'!B:B,'EPR 08 JUN'!C8, 'REPORTE DIARIO'!C:C) -> 14369 | E8: =SUMIF('REPORTE DIARIO'!B:B,'EPR 08 JUN'!C8, 'REPORTE DIARIO'!D:D) -> 89483 | F8: =J8*D8 -> 92372.143 | G8: =+E8-F8 -> -2889.1429 | H8: =ABS(G8/F8) -> 0.031277209 | I8: =E8/D8 -> 6.2275037 | J8: =45/7 -> 6.4285714 | K8: =+I8-J8 -> -0.20106777
B9: Fernando (Naucalpan) | C9: Mas 55 semanas de atraso | D9: =SUMIF('REPORTE DIARIO'!B:B,'EPR 08 JUN'!C9, 'REPORTE DIARIO'!C:C) -> 50600 | E9: =SUMIF('REPORTE DIARIO'!B:B,'EPR 08 JUN'!C9, 'REPORTE DIARIO'!D:D) -> 136241.24 | F9: =J9*D9 -> 108428.57 | G9: =+E9-F9 -> 27812.669 | H9: =ABS(G9/F9) -> 0.25650682 | I9: =E9/D9 -> 2.6925146 | J9: =15/7 -> 2.1428571 | K9: =+I9-J9 -> 0.54965748
C10: TOTAL | D10: =SUM(D6:D9) -> 91401 | E10: =SUM(E6:E9) -> 567761.17 | F10: =SUM(F6:F9) -> 853745 | G10: =+E10-F10 -> -285983.83 | H10: =ABS(G10/F10) -> 0.3349757 | I10: =E10/D10 -> 6.211761 | J10: =F10/D10 -> 9.3406527 | K10: =I10-J10 -> -3.1288917
B12: Nota:
B13: El saldo consolidado incluye los siguientes despachos
B14: Samantha, Samantha 2, Sofia, Edith, Fernando, Olguin y Federico
