Workbook

Sheet REPORTE DIARIO
B3: COBRANZA GENERAL SAMANTHA
B4: Segmento | C4: Cuentas | D4: Recuperación
B5: Extrajudicial - 0 a 28 semanas de atraso | C5: 4080 | D5: 60355.31
B6: Extrajudicial - 29 a 39 semanas de atraso | C6: 4214 | D6: 44167.7
B7: Extrajudicial - 40 a 55 semanas de atraso | C7: 4191 | D7: 87267.16
B8: JUDICIAL | C8: 11 | D8: 0
B9: Mas 55 semanas de atraso | C9: 11351 | D9: 74116.23
B10: Total general | C10: =SUM(C5:C9) -> 23847 | D10: =SUM(D5:D9) -> 265906.4
B12: COBRANZA GENERAL EDITH
B13: Segmento | C13: Cuentas | D13: Recuperación
B14: Extrajudicial - 0 a 28 semanas de atraso | C14: 3329 | D14: 59021.79
B15: Extrajudicial - 29 a 39 semanas de atraso | C15: 1482 | D15: 10110
B16: Extrajudicial - 40 a 55 semanas de atraso | C16: 2154 | D16: 9601.61
B17: JUDICIAL | C17: 1 | D17: 0
B18: Mas 55 semanas de atraso | C18: 17188 | D18: 5028.2
B19: Total general | C19: =SUM(C14:C18) -> 24154 | D19: =SUM(D14:D18) -> 83761.6
B21: COBRANZA GENERAL SOFIA
B22: Segmento | C22: Cuentas | D22: Recuperación
B23: Extrajudicial - 0 a 28 semanas de atraso | C23: 221 | D23: 15481
B24: Extrajudicial - 29 a 39 semanas de atraso | C24: 3355 | D24: 49539.62
B25: Extrajudicial - 40 a 55 semanas de atraso | C25: 604 | D25: 7991
B26: Mas 55 semanas de atraso | C26: 3968 | D26: 1153.92
B27: Total general | C27: =SUM(C23:C26) -> 8148 | D27: =SUM(D23:D26) -> 74165.54
B29: COBRANZA GENERAL FERNANDO
B30: Segmento | C30: Cuentas | D30: Recuperación
B31: Extrajudicial - 0 a 28 semanas de atraso | C31: 2546 | D31: 52350
B32: Total general | C32: =SUM(C31:C31) -> 2546 | D32: =SUM(D31:D31) -> 52350
B34: COBRANZA GENERAL SAMANTHA 2
B35: Segmento | C35: Cuentas | D35: Recuperación
B36: Extrajudicial - 0 a 28 semanas de atraso | C36: 2338 | D36: 42018.49
B37: Extrajudicial - 29 a 39 semanas de atraso | C37: 2126 | D37: 7058
B38: Extrajudicial - 40 a 55 semanas de atraso | C38: 2062 | D38: 4310
B39: JUDICIAL | C39: 2 | D39: 0
B40: Mas 55 semanas de atraso | C40: 20878 | D40: 15410
B41: Total general | C41: =SUM(C36:C40) -> 27406 | D41: =SUM(D36:D40) -> 68796.49
B43: COBRANZA GENERAL FEDERICO
B44: Segmento | C44: Cuentas | D44: Recuperación
B45: Extrajudicial - 0 a 28 semanas de atraso | C45: 580 | D45: 0
B46: Extrajudicial - 29 a 39 semanas de atraso | C46: 860 | D46: 0
B47: Extrajudicial - 40 a 55 semanas de atraso | C47: 785 | D47: 2320
...

Sheet DATA

Sheet EPR 22 MAYO
B2: REPORTE CONSOLIDADO POR SEGMENTOS
B3: COBRANZA 23 MAYO
B5: COORDINADOR | C5: SEGMENTO | D5: CUENTAS | E5: COBRANZA REAL | F5: CUOTA IDEAL | G5: VARIACION | H5: % VAR | I5: EPR | J5: EPR IDEAL | K5: VAR EPR
B6: Zareth | C6: Extrajudicial - 0 a 28 semanas de atraso | D6: =SUMIF('REPORTE DIARIO'!B:B,'EPR 22 MAYO'!C6, 'REPORTE DIARIO'!C:C) -> 13896 | E6: =SUMIF('REPORTE DIARIO'!B:B,'EPR 22 MAYO'!C6, 'REPORTE DIARIO'!D:D) -> 231581.59 | F6: =J6*D6 -> 436731.43 | G6: =+E6-F6 -> -205149.84 | H6: =ABS(G6/F6) -> 0.46973912 | I6: =E6/D6 -> 16.665342 | J6: =220/7 -> 31.428571 | K6: =+I6-J6 -> -14.76323
B7: Gabriel | C7: Extrajudicial - 29 a 39 semanas de atraso | D7: =SUMIF('REPORTE DIARIO'!B:B,'EPR 22 MAYO'!C7, 'REPORTE DIARIO'!C:C) -> 12914 | E7: =SUMIF('REPORTE DIARIO'!B:B,'EPR 22 MAYO'!C7, 'REPORTE DIARIO'!D:D) -> 111746.32 | F7: =J7*D7 -> 202934.29 | G7: =+E7-F7 -> -91187.966 | H7: =ABS(G7/F7) -> 0.44934726 | I7: =E7/D7 -> 8.6531144 | J7: =110/7 -> 15.714286 | K7: =+I7-J7 -> -7.0611713
B8: Gabriel | C8: Extrajudicial - 40 a 55 semanas de atraso | D8: =SUMIF('REPORTE DIARIO'!B:B,'EPR 22 MAYO'!C8, 'REPORTE DIARIO'!C:C) -> 11114 | E8: =SUMIF('REPORTE DIARIO'!B:B,'EPR 22 MAYO'!C8, 'REPORTE DIARIO'!D:D) -> 112494.77 | F8: =J8*D8 -> 71447.143 | G8: =+E8-F8 -> 41047.627 | H8: =ABS(G8/F8) -> 0.57451741 | I8: =E8/D8 -> 10.121898 | J8: =45/7 -> 6.4285714 | K8: =+I8-J8 -> 3.6933262
B9: Fernando (Naucalpan) | C9: Mas 55 semanas de atraso | D9: =SUMIF('REPORTE DIARIO'!B:B,'EPR 22 MAYO'!C9, 'REPORTE DIARIO'!C:C) -> 57227 | E9: =SUMIF('REPORTE DIARIO'!B:B,'EPR 22 MAYO'!C9, 'REPORTE DIARIO'!D:D) -> 101705.35 | F9: =J9*D9 -> 122629.29 | G9: =+E9-F9 -> -20923.936 | H9: =ABS(G9/F9) -> 0.17062756 | I9: =E9/D9 -> 1.7772267 | J9: =15/7 -> 2.1428571 | K9: =+I9-J9 -> -0.36563048
C10: TOTAL | D10: =SUM(D6:D9) -> 95151 | E10: =SUM(E6:E9) -> 557528.03 | F10: =SUM(F6:F9) -> 833742.14 | G10: =+E10-F10 -> -276214.11 | H10: =ABS(G10/F10) -> 0.33129441 | I10: =E10/D10 -> 5.8594027 | J10: =F10/D10 -> 8.7623056 | K10: =I10-J10 -> -2.9029029
B12: Nota:
B13: El saldo consolidado incluye los siguientes despachos
B14: Samantha, Samantha 2, Sofia, Edith, Fernando, Olguin y Federico
