Workbook

Sheet REPORTE DIARIO
B3: COBRANZA GENERAL SAMANTHA
B4: Segmento | C4: Cuentas | D4: Recuperación
B5: Extrajudicial - 0 a 28 semanas de atraso | C5: 5985 | D5: 38392
B6: Extrajudicial - 29 a 39 semanas de atraso | C6: 6706 | D6: 27378
B7: Extrajudicial - 40 a 55 semanas de atraso | C7: 9944 | D7: 15138
B8: JUDICIAL | C8: 21 | D8: 0
B9: Mas 55 semanas de atraso | C9: 28940 | D9: 25607
B10: Total general | C10: =SUM(C5:C9) -> 51596 | D10: =SUM(D5:D9) -> 106515
B12: COBRANZA GENERAL EDITH
B13: Segmento | C13: Cuentas | D13: Recuperación
B14: Extrajudicial - 0 a 28 semanas de atraso | C14: 1707 | D14: 8388
B15: Extrajudicial - 29 a 39 semanas de atraso | C15: 1519 | D15: 16307
B16: Extrajudicial - 40 a 55 semanas de atraso | C16: 857 | D16: 1730
B17: Mas 55 semanas de atraso | C17: 8833 | D17: 132
B18: Total general | C18: =SUM(C14:C17) -> 12916 | D18: =SUM(D14:D17) -> 26557
B20: COBRANZA GENERAL SAMANTHA 2
B21: Segmento | C21: Cuentas | D21: Recuperación
B22: Extrajudicial - 0 a 28 semanas de atraso | C22: 2622 | D22: 9653
B23: Extrajudicial - 29 a 39 semanas de atraso | C23: 1407 | D23: 2804
B24: Extrajudicial - 40 a 55 semanas de atraso | C24: 3317 | D24: 1158
B25: JUDICIAL | C25: 2 | D25: 0
B26: Mas 55 semanas de atraso | C26: 21156 | D26: 9451
B27: Total general | C27: =SUM(C22:C26) -> 28504 | D27: =SUM(D22:D26) -> 23066
B29: COBRANZA GENERAL FERNANDO
B30: Segmento | C30: Cuentas | D30: Recuperación
B31: Extrajudicial - 0 a 28 semanas de atraso | C31: 2752 | D31: 7131
B32: Total general | C32: =SUM(C31:C31) -> 2752 | D32: =SUM(D31:D31) -> 7131
B34: COBRANZA GENERAL SOFIA
B35: Segmento | C35: Cuentas | D35: Recuperación
B36: Extrajudicial - 0 a 28 semanas de atraso | C36: 1412 | D36: 3366
B37: Extrajudicial - 29 a 39 semanas de atraso | C37: 1310 | D37: 1510
B38: Extrajudicial - 40 a 55 semanas de atraso | C38: 2925 | D38: 0
B39: Mas 55 semanas de atraso | C39: 1828 | D39: 0
B40: Total general | C40: =SUM(C36:C39) -> 7475 | D40: =SUM(D36:D39) -> 4876
B42: COBRANZA GENERAL FEDERICO
B43: Segmento | C43: Cuentas | D43: Recuperación
B44: Extrajudicial - 0 a 28 semanas de atraso | C44: 39 | D44: 0
B45: Extrajudicial - 29 a 39 semanas de atraso | C45: 185 | D45: 0
B46: Extrajudicial - 40 a 55 semanas de atraso | C46: 194 | D46: 0
B47: Mas 55 semanas de atraso | C47: 1857 | D47: 0
...

Sheet DATA

Sheet EPR 8 ABR
B2: REPORTE CONSOLIDADO POR SEGMENTOS
B3: COBRANZA 08 ABRIL
B5: COORDINADOR | C5: SEGMENTO | D5: CUENTAS | E5: COBRANZA REAL | F5: CUOTA IDEAL | G5: VARIACION | H5: % VAR | I5: EPR | J5: EPR IDEAL | K5: VAR EPR
B6: Samatha y Zareth | C6: Extrajudicial - 0 a 28 semanas de atraso | D6: =SUMIF('REPORTE DIARIO'!B:B,'EPR 8 ABR'!C6, 'REPORTE DIARIO'!C:C) -> 14586 | E6: =SUMIF('REPORTE DIARIO'!B:B,'EPR 8 ABR'!C6, 'REPORTE DIARIO'!D:D) -> 66930 | F6: =J6*D6 -> 416742.86 | G6: =+E6-F6 -> -349812.86 | H6: =ABS(G6/F6) -> 0.83939737 | I6: =E6/D6 -> 4.5886466 | J6: =200/7 -> 28.571429 | K6: =+I6-J6 -> -23.982782
B7: Gabriel | C7: Extrajudicial - 29 a 39 semanas de atraso | D7: =SUMIF('REPORTE DIARIO'!B:B,'EPR 8 ABR'!C7, 'REPORTE DIARIO'!C:C) -> 11189 | E7: =SUMIF('REPORTE DIARIO'!B:B,'EPR 8 ABR'!C7, 'REPORTE DIARIO'!D:D) -> 47999 | F7: =J7*D7 -> 175827.14 | G7: =+E7-F7 -> -127828.14 | H7: =ABS(G7/F7) -> 0.72701029 | I7: =E7/D7 -> 4.2898382 | J7: =110/7 -> 15.714286 | K7: =+I7-J7 -> -11.424447
B8: Gabriel | C8: Extrajudicial - 40 a 55 semanas de atraso | D8: =SUMIF('REPORTE DIARIO'!B:B,'EPR 8 ABR'!C8, 'REPORTE DIARIO'!C:C) -> 17250 | E8: =SUMIF('REPORTE DIARIO'!B:B,'EPR 8 ABR'!C8, 'REPORTE DIARIO'!D:D) -> 18026 | F8: =J8*D8 -> 110892.86 | G8: =+E8-F8 -> -92866.857 | H8: =ABS(G8/F8) -> 0.8374467 | I8: =E8/D8 -> 1.0449855 | J8: =45/7 -> 6.4285714 | K8: =+I8-J8 -> -5.3835859
B9: Fernando | C9: Mas 55 semanas de atraso | D9: =SUMIF('REPORTE DIARIO'!B:B,'EPR 8 ABR'!C9, 'REPORTE DIARIO'!C:C) -> 62623 | E9: =SUMIF('REPORTE DIARIO'!B:B,'EPR 8 ABR'!C9, 'REPORTE DIARIO'!D:D) -> 35190 | F9: =J9*D9 -> 134192.14 | G9: =+E9-F9 -> -99002.143 | H9: =ABS(G9/F9) -> 0.73776408 | I9: =E9/D9 -> 0.56193411 | J9: =15/7 -> 2.1428571 | K9: =+I9-J9 -> -1.580923
C10: TOTAL | D10: =SUM(D6:D9) -> 105648 | E10: =SUM(E6:E9) -> 168145 | F10: =SUM(F6:F9) -> 837655 | G10: =+E10-F10 -> -669510 | H10: =ABS(G10/F10) -> 0.799267 | I10: =E10/D10 -> 1.5915588 | J10: =F10/D10 -> 7.928735 | K10: =I10-J10 -> -6.3371763
B12: Nota:
B13: El saldo consolidado incluye los siguientes despachos
B14: Samantha, Samantha 2, Sofia, Edith, Olguin, Fernando y Federico
