Workbook

Sheet REPORTE DIARIO
B3: COBRANZA GENERAL SAMANTHA
B4: Segmento | C4: Cuentas | D4: Recuperación
B5: Extrajudicial - 0 a 28 semanas de atraso | C5: 4324 | D5: 497600.99
B6: Extrajudicial - 29 a 39 semanas de atraso | C6: 4442 | D6: 328453.41
B7: Extrajudicial - 40 a 55 semanas de atraso | C7: 6378 | D7: 253215.59
B8: JUDICIAL | C8: 10 | D8: 0
B9: Mas 55 semanas de atraso | C9: 13434 | D9: 399374.97
B10: Total general | C10: =SUM(C5:C9) -> 28588 | D10: =SUM(D5:D9) -> 1478645
B12: COBRANZA GENERAL SAMANTHA 2
B13: Segmento | C13: Cuentas | D13: Recuperación
B14: Extrajudicial - 0 a 28 semanas de atraso | C14: 2048 | D14: 235903.81
B15: Extrajudicial - 29 a 39 semanas de atraso | C15: 1688 | D15: 201496.8
B16: Extrajudicial - 40 a 55 semanas de atraso | C16: 3095 | D16: 57416.55
B17: JUDICIAL | C17: 2 | D17: 0
B18: Mas 55 semanas de atraso | C18: 21621 | D18: 228450.57
B19: Total general | C19: =SUM(C14:C18) -> 28454 | D19: =SUM(D14:D18) -> 723267.73
B21: COBRANZA GENERAL EDITH
B22: Segmento | C22: Cuentas | D22: Recuperación
B23: Extrajudicial - 0 a 28 semanas de atraso | C23: 3907 | D23: 353985.91
B24: Extrajudicial - 29 a 39 semanas de atraso | C24: 2145 | D24: 145370.84
B25: Extrajudicial - 40 a 55 semanas de atraso | C25: 2158 | D25: 41651.38
B26: Mas 55 semanas de atraso | C26: 9602 | D26: 34740.04
B27: Total general | C27: =SUM(C23:C26) -> 17812 | D27: =SUM(D23:D26) -> 575748.17
B29: COBRANZA GENERAL SOFIA
B30: Segmento | C30: Cuentas | D30: Recuperación
B31: Extrajudicial - 0 a 28 semanas de atraso | C31: 320 | D31: 85965.99
B32: Extrajudicial - 29 a 39 semanas de atraso | C32: 1225 | D32: 97680.38
B33: Extrajudicial - 40 a 55 semanas de atraso | C33: 2376 | D33: 13332.15
B34: Mas 55 semanas de atraso | C34: 4259 | D34: 30552
B35: Total general | C35: =SUM(C31:C34) -> 8180 | D35: =SUM(D31:D34) -> 227530.52
B37: COBRANZA GENERAL FERNANDO
B38: Segmento | C38: Cuentas | D38: Recuperación
B39: Extrajudicial - 0 a 28 semanas de atraso | C39: 2126 | D39: 61120
B40: Total general | C40: =SUM(C39:C39) -> 2126 | D40: =SUM(D39:D39) -> 61120
B42: COBRANZA GENERAL FEDERICO
B43: Segmento | C43: Cuentas | D43: Recuperación
B44: Extrajudicial - 0 a 28 semanas de atraso | C44: 112 | D44: 8053.72
B45: Extrajudicial - 29 a 39 semanas de atraso | C45: 485 | D45: 10386
B46: Extrajudicial - 40 a 55 semanas de atraso | C46: 355 | D46: 1920
B47: Mas 55 semanas de atraso | C47: 1994 | D47: 14001
...

Sheet DATA

Sheet EPR 04 MAYO
B2: REPORTE CONSOLIDADO POR SEGMENTOS
B3: SALDO ACUMULADO SEMANA 18
B5: COORDINADOR | C5: SEGMENTO | D5: CUENTAS | E5: COBRANZA REAL | F5: CUOTA IDEAL | G5: VARIACION | H5: % VAR | I5: EPR | J5: EPR IDEAL | K5: VAR EPR
B6: Samatha y Zareth | C6: Extrajudicial - 0 a 28 semanas de atraso | D6: =SUMIF('REPORTE DIARIO'!B:B,'EPR 04 MAYO'!C6, 'REPORTE DIARIO'!C:C) -> 12987 | E6: =SUMIF('REPORTE DIARIO'!B:B,'EPR 04 MAYO'!C6, 'REPORTE DIARIO'!D:D) -> 1245267.4 | F6: =J6*D6 -> 2857140 | G6: =+E6-F6 -> -1611872.6 | H6: =ABS(G6/F6) -> 0.56415597 | I6: =E6/D6 -> 95.885687 | J6: =(220/7)*7 -> 220 | K6: =+I6-J6 -> -124.11431
B7: Gabriel | C7: Extrajudicial - 29 a 39 semanas de atraso | D7: =SUMIF('REPORTE DIARIO'!B:B,'EPR 04 MAYO'!C7, 'REPORTE DIARIO'!C:C) -> 10294 | E7: =SUMIF('REPORTE DIARIO'!B:B,'EPR 04 MAYO'!C7, 'REPORTE DIARIO'!D:D) -> 786516.43 | F7: =J7*D7 -> 1132340 | G7: =+E7-F7 -> -345823.57 | H7: =ABS(G7/F7) -> 0.30540612 | I7: =E7/D7 -> 76.405326 | J7: =(110/7)*7 -> 110 | K7: =+I7-J7 -> -33.594674
B8: Gabriel | C8: Extrajudicial - 40 a 55 semanas de atraso | D8: =SUMIF('REPORTE DIARIO'!B:B,'EPR 04 MAYO'!C8, 'REPORTE DIARIO'!C:C) -> 15027 | E8: =SUMIF('REPORTE DIARIO'!B:B,'EPR 04 MAYO'!C8, 'REPORTE DIARIO'!D:D) -> 370335.67 | F8: =J8*D8 -> 676215 | G8: =+E8-F8 -> -305879.33 | H8: =ABS(G8/F8) -> 0.45234035 | I8: =E8/D8 -> 24.644684 | J8: =(45/7)*7 -> 45 | K8: =+I8-J8 -> -20.355316
B9: Fernando | C9: Mas 55 semanas de atraso | D9: =SUMIF('REPORTE DIARIO'!B:B,'EPR 04 MAYO'!C9, 'REPORTE DIARIO'!C:C) -> 51797 | E9: =SUMIF('REPORTE DIARIO'!B:B,'EPR 04 MAYO'!C9, 'REPORTE DIARIO'!D:D) -> 709903.58 | F9: =J9*D9 -> 776955 | G9: =+E9-F9 -> -67051.42 | H9: =ABS(G9/F9) -> 0.086300262 | I9: =E9/D9 -> 13.705496 | J9: =(15/7)*7 -> 15 | K9: =+I9-J9 -> -1.2945039
C10: TOTAL | D10: =SUM(D6:D9) -> 90105 | E10: =SUM(E6:E9) -> 3112023.1 | F10: =SUM(F6:F9) -> 5442650 | G10: =+E10-F10 -> -2330626.9 | H10: =ABS(G10/F10) -> 0.42821546 | I10: =E10/D10 -> 34.53774 | J10: =F10/D10 -> 60.403418 | K10: =I10-J10 -> -25.865678
B12: Nota:
B13: El saldo consolidado incluye los siguientes despachos
B14: Samantha, Samantha 2, Sofia, Edith, Fernando, Olguin y Federico
