Workbook

Sheet REPORTE DIARIO
B3: COBRANZA GENERAL SAMANTHA
B4: Segmento | C4: Cuentas | D4: Recuperación
B5: Extrajudicial - 0 a 28 semanas de atraso | C5: 3222 | D5: 890252.87
B6: Extrajudicial - 29 a 39 semanas de atraso | C6: 3760 | D6: 533381.64
B7: Extrajudicial - 40 a 55 semanas de atraso | C7: 5799 | D7: 322067.13
B8: JUDICIAL | C8: 11 | D8: 0
B9: Mas 55 semanas de atraso | C9: 14659 | D9: 428718.96
B10: Total general | C10: =SUM(C5:C9) -> 27451 | D10: =SUM(D5:D9) -> 2174420.6
B12: COBRANZA GENERAL EDITH
B13: Segmento | C13: Cuentas | D13: Recuperación
B14: Extrajudicial - 0 a 28 semanas de atraso | C14: 3083 | D14: 406265.52
B15: Extrajudicial - 29 a 39 semanas de atraso | C15: 1573 | D15: 199888.32
B16: Extrajudicial - 40 a 55 semanas de atraso | C16: 2135 | D16: 49082.68
B17: JUDICIAL | C17: 1 | D17: 39
B18: Mas 55 semanas de atraso | C18: 17300 | D18: 107023.74
B19: Total general | C19: =SUM(C14:C18) -> 24092 | D19: =SUM(D14:D18) -> 762299.26
B21: COBRANZA GENERAL SAMANTHA 2
B22: Segmento | C22: Cuentas | D22: Recuperación
B23: Extrajudicial - 0 a 28 semanas de atraso | C23: 2552 | D23: 258214.37
B24: Extrajudicial - 29 a 39 semanas de atraso | C24: 1588 | D24: 63827
B25: Extrajudicial - 40 a 55 semanas de atraso | C25: 2161 | D25: 113073
B26: JUDICIAL | C26: 0 | D26: 0
B27: Mas 55 semanas de atraso | C27: 12688 | D27: 116494.44
B28: Total general | C28: =SUM(C23:C27) -> 18989 | D28: =SUM(D23:D27) -> 551608.81
B30: COBRANZA GENERAL SOFIA
B31: Segmento | C31: Cuentas | D31: Recuperación
B32: Extrajudicial - 0 a 28 semanas de atraso | C32: 488 | D32: 124166.44
B33: Extrajudicial - 29 a 39 semanas de atraso | C33: 3042 | D33: 219201.95
B34: Extrajudicial - 40 a 55 semanas de atraso | C34: 479 | D34: 15224
B35: Mas 55 semanas de atraso | C35: 4018 | D35: 31428.26
B36: Total general | C36: =SUM(C32:C35) -> 8027 | D36: =SUM(D32:D35) -> 390020.65
B38: COBRANZA GENERAL OLGUIN
B39: Segmento | C39: Cuentas | D39: Recuperación
B40: Extrajudicial - 0 a 28 semanas de atraso | C40: 2225 | D40: 125372.93
B41: Extrajudicial - 29 a 39 semanas de atraso | C41: 1278 | D41: 69678.83
B42: Extrajudicial - 40 a 55 semanas de atraso | C42: 1672 | D42: 25297
B43: Mas 55 semanas de atraso | C43: 1866 | D43: 15102
B44: Total general | C44: =SUM(C40:C43) -> 7041 | D44: =SUM(D40:D43) -> 235450.76
B46: COBRANZA GENERAL FEDERICO
B47: Segmento | C47: Cuentas | D47: Recuperación
...

Sheet DATA

Sheet EPR 22 JUN
B2: REPORTE CONSOLIDADO POR SEGMENTOS
B3: SALDO ACUMULADO SEMANA 25
B5: COORDINADOR | C5: SEGMENTO | D5: CUENTAS | E5: COBRANZA REAL | F5: CUOTA IDEAL | G5: VARIACION | H5: % VAR | I5: EPR | J5: EPR IDEAL | K5: VAR EPR
B6: Zareth | C6: Extrajudicial - 0 a 28 semanas de atraso | D6: =SUMIF('REPORTE DIARIO'!B:B,'EPR 22 JUN'!C6, 'REPORTE DIARIO'!C:C) -> 14075 | E6: =SUMIF('REPORTE DIARIO'!B:B,'EPR 22 JUN'!C6, 'REPORTE DIARIO'!D:D) -> 1888341.1 | F6: =J6*D6 -> 3096500 | G6: =+E6-F6 -> -1208158.9 | H6: =ABS(G6/F6) -> 0.39016918 | I6: =E6/D6 -> 134.16278 | J6: =(220/7)*7 -> 220 | K6: =+I6-J6 -> -85.83722
B7: Gabriel | C7: Extrajudicial - 29 a 39 semanas de atraso | D7: =SUMIF('REPORTE DIARIO'!B:B,'EPR 22 JUN'!C7, 'REPORTE DIARIO'!C:C) -> 11649 | E7: =SUMIF('REPORTE DIARIO'!B:B,'EPR 22 JUN'!C7, 'REPORTE DIARIO'!D:D) -> 1092652.7 | F7: =J7*D7 -> 1281390 | G7: =+E7-F7 -> -188737.26 | H7: =ABS(G7/F7) -> 0.14729104 | I7: =E7/D7 -> 93.797986 | J7: =(110/7)*7 -> 110 | K7: =+I7-J7 -> -16.202014
B8: Gabriel | C8: Extrajudicial - 40 a 55 semanas de atraso | D8: =SUMIF('REPORTE DIARIO'!B:B,'EPR 22 JUN'!C8, 'REPORTE DIARIO'!C:C) -> 12863 | E8: =SUMIF('REPORTE DIARIO'!B:B,'EPR 22 JUN'!C8, 'REPORTE DIARIO'!D:D) -> 544043.81 | F8: =J8*D8 -> 578835 | G8: =+E8-F8 -> -34791.19 | H8: =ABS(G8/F8) -> 0.06010554 | I8: =E8/D8 -> 42.295251 | J8: =(45/7)*7 -> 45 | K8: =+I8-J8 -> -2.7047493
B9: Fernando (Naucalpan) | C9: Mas 55 semanas de atraso | D9: =SUMIF('REPORTE DIARIO'!B:B,'EPR 22 JUN'!C9, 'REPORTE DIARIO'!C:C) -> 52957 | E9: =SUMIF('REPORTE DIARIO'!B:B,'EPR 22 JUN'!C9, 'REPORTE DIARIO'!D:D) -> 718431.88 | F9: =J9*D9 -> 794355 | G9: =+E9-F9 -> -75923.12 | H9: =ABS(G9/F9) -> 0.095578325 | I9: =E9/D9 -> 13.566325 | J9: =(15/7)*7 -> 15 | K9: =+I9-J9 -> -1.4336749
C10: TOTAL | D10: =SUM(D6:D9) -> 91544 | E10: =SUM(E6:E9) -> 4243469.6 | F10: =SUM(F6:F9) -> 5751080 | G10: =+E10-F10 -> -1507610.4 | H10: =ABS(G10/F10) -> 0.26214388 | I10: =E10/D10 -> 46.354426 | J10: =F10/D10 -> 62.823123 | K10: =I10-J10 -> -16.468697
B12: Nota:
B13: El saldo consolidado incluye los siguientes despachos
B14: Samantha, Samantha 2, Sofia, Edith, Fernando, Olguin y Federico
