Workbook

Sheet REPORTE DIARIO
B3: COBRANZA GENERAL SAMANTHA
B4: Segmento | C4: Cuentas | D4: Recuperación
B5: Extrajudicial - 0 a 28 semanas de atraso | C5: 7416 | D5: 301375.46
B6: Extrajudicial - 29 a 39 semanas de atraso | C6: 8003 | D6: 161466
B7: Extrajudicial - 40 a 55 semanas de atraso | C7: 10187 | D7: 65545
B8: JUDICIAL | C8: 21 | D8: 0
B9: Mas 55 semanas de atraso | C9: 29545 | D9: 503299
B10: Total general | C10: =SUM(C5:C9) -> 55172 | D10: =SUM(D5:D9) -> 1031685.5
B12: COBRANZA GENERAL SOFIA
B13: Segmento | C13: Cuentas | D13: Recuperación
B14: Extrajudicial - 0 a 28 semanas de atraso | C14: 1237 | D14: 95282.8
B15: Extrajudicial - 29 a 39 semanas de atraso | C15: 1161 | D15: 85630
B16: Extrajudicial - 40 a 55 semanas de atraso | C16: 3045 | D16: 94601
B17: Mas 55 semanas de atraso | C17: 1901 | D17: 3306
B18: Total general | C18: =SUM(C14:C17) -> 7344 | D18: =SUM(D14:D17) -> 278819.8
B20: COBRANZA GENERAL SAMANTHA 2
B21: Segmento | C21: Cuentas | D21: Recuperación
B22: Extrajudicial - 0 a 28 semanas de atraso | C22: 3315 | D22: 172283.04
B23: Extrajudicial - 29 a 39 semanas de atraso | C23: 1806 | D23: 14933
B24: Extrajudicial - 40 a 55 semanas de atraso | C24: 3436 | D24: 14761
B25: JUDICIAL | C25: 2 | D25: 0
B26: Mas 55 semanas de atraso | C26: 21213 | D26: 56738.76
B27: Total general | C27: =SUM(C22:C26) -> 29772 | D27: =SUM(D22:D26) -> 258715.8
B29: COBRANZA GENERAL EDITH
B30: Segmento | C30: Cuentas | D30: Recuperación
B31: Extrajudicial - 0 a 28 semanas de atraso | C31: 1484 | D31: 84568.18
B32: Extrajudicial - 29 a 39 semanas de atraso | C32: 1398 | D32: 10812
B33: Extrajudicial - 40 a 55 semanas de atraso | C33: 724 | D33: 2447
B34: Mas 55 semanas de atraso | C34: 8414 | D34: 23228.24
B35: Total general | C35: =SUM(C31:C34) -> 12020 | D35: =SUM(D31:D34) -> 121055.42
B37: COBRANZA GENERAL FERNANDO
B38: Segmento | C38: Cuentas | D38: Recuperación
B39: Extrajudicial - 0 a 28 semanas de atraso | C39: 3088 | D39: 17644
B40: Total general | C40: =SUM(C39:C39) -> 3088 | D40: =SUM(D39:D39) -> 17644
B42: COBRANZA GENERAL OLGUIN
B43: Segmento | C43: Cuentas | D43: Recuperación
B44: Extrajudicial - 0 a 28 semanas de atraso | C44: 68 | D44: 8038
B45: Extrajudicial - 29 a 39 semanas de atraso | C45: 131 | D45: 0
B46: Extrajudicial - 40 a 55 semanas de atraso | C46: 15 | D46: 0
B47: Mas 55 semanas de atraso | C47: 10 | D47: 0
...

Sheet DATA

Sheet EPR 28 MAR
B2: REPORTE CONSOLIDADO POR SEGMENTOS
B3: COBRANZA 28 MARZO
B5: COORDINADOR | C5: SEGMENTO | D5: CUENTAS | E5: COBRANZA REAL | F5: CUOTA IDEAL | G5: VARIACION | H5: % VAR | I5: EPR | J5: EPR IDEAL | K5: VAR EPR
B6: Samatha y Zareth | C6: Extrajudicial - 0 a 28 semanas de atraso | D6: =SUMIF('REPORTE DIARIO'!B:B,'EPR 28 MAR'!C6, 'REPORTE DIARIO'!C:C) -> 16608 | E6: =SUMIF('REPORTE DIARIO'!B:B,'EPR 28 MAR'!C6, 'REPORTE DIARIO'!D:D) -> 679191.48 | F6: =J6*D6 -> 474514.29 | G6: =+E6-F6 -> 204677.19 | H6: =ABS(G6/F6) -> 0.43134043 | I6: =E6/D6 -> 40.895441 | J6: =200/7 -> 28.571429 | K6: =+I6-J6 -> 12.324012
B7: Gabriel | C7: Extrajudicial - 29 a 39 semanas de atraso | D7: =SUMIF('REPORTE DIARIO'!B:B,'EPR 28 MAR'!C7, 'REPORTE DIARIO'!C:C) -> 12622 | E7: =SUMIF('REPORTE DIARIO'!B:B,'EPR 28 MAR'!C7, 'REPORTE DIARIO'!D:D) -> 273641 | F7: =J7*D7 -> 198345.71 | G7: =+E7-F7 -> 75295.286 | H7: =ABS(G7/F7) -> 0.3796164 | I7: =E7/D7 -> 21.679686 | J7: =110/7 -> 15.714286 | K7: =+I7-J7 -> 5.9654005
B8: Gabriel | C8: Extrajudicial - 40 a 55 semanas de atraso | D8: =SUMIF('REPORTE DIARIO'!B:B,'EPR 28 MAR'!C8, 'REPORTE DIARIO'!C:C) -> 17571 | E8: =SUMIF('REPORTE DIARIO'!B:B,'EPR 28 MAR'!C8, 'REPORTE DIARIO'!D:D) -> 177354 | F8: =J8*D8 -> 112956.43 | G8: =+E8-F8 -> 64397.571 | H8: =ABS(G8/F8) -> 0.57010984 | I8: =E8/D8 -> 10.093563 | J8: =45/7 -> 6.4285714 | K8: =+I8-J8 -> 3.6649918
B9: Fernando | C9: Mas 55 semanas de atraso | D9: =SUMIF('REPORTE DIARIO'!B:B,'EPR 28 MAR'!C9, 'REPORTE DIARIO'!C:C) -> 61771 | E9: =SUMIF('REPORTE DIARIO'!B:B,'EPR 28 MAR'!C9, 'REPORTE DIARIO'!D:D) -> 587686 | F9: =J9*D9 -> 132366.43 | G9: =+E9-F9 -> 455319.57 | H9: =ABS(G9/F9) -> 3.4398418 | I9: =E9/D9 -> 9.5139467 | J9: =15/7 -> 2.1428571 | K9: =+I9-J9 -> 7.3710895
C10: TOTAL | D10: =SUM(D6:D9) -> 108572 | E10: =SUM(E6:E9) -> 1717872.5 | F10: =SUM(F6:F9) -> 918182.86 | G10: =+E10-F10 -> 799689.62 | H10: =ABS(G10/F10) -> 0.87094811 | I10: =E10/D10 -> 15.822426 | J10: =F10/D10 -> 8.4569029 | K10: =I10-J10 -> 7.3655235
B12: Nota:
B13: El saldo consolidado incluye los siguientes despachos
B14: Samantha, Samantha 2, Sofia, Edith, Olguin, Fernando y Federico
