Workbook

Sheet REPORTE DIARIO
B3: COBRANZA GENERAL SAMANTHA
B4: Segmento | C4: Cuentas | D4: Recuperación
B5: Extrajudicial - 0 a 28 semanas de atraso | C5: 6574 | D5: 376464
B6: Extrajudicial - 29 a 39 semanas de atraso | C6: 5393 | D6: 336994.89
B7: Extrajudicial - 40 a 55 semanas de atraso | C7: 7275 | D7: 185219.31
B8: JUDICIAL | C8: 21 | D8: 0
B9: Mas 55 semanas de atraso | C9: 21098 | D9: 301823.65
B10: Total general | C10: =SUM(C5:C9) -> 40361 | D10: =SUM(D5:D9) -> 1200501.8
B12: COBRANZA GENERAL EDITH
B13: Segmento | C13: Cuentas | D13: Recuperación
B14: Extrajudicial - 0 a 28 semanas de atraso | C14: 2061 | D14: 284428.16
B15: Extrajudicial - 29 a 39 semanas de atraso | C15: 2169 | D15: 196598.32
B16: Extrajudicial - 40 a 55 semanas de atraso | C16: 944 | D16: 27920.92
B17: Mas 55 semanas de atraso | C17: 9405 | D17: 36944.25
B18: Total general | C18: =SUM(C14:C17) -> 14579 | D18: =SUM(D14:D17) -> 545891.65
B20: COBRANZA GENERAL SAMANTHA 2
B21: Segmento | C21: Cuentas | D21: Recuperación
B22: Extrajudicial - 0 a 28 semanas de atraso | C22: 2417 | D22: 207894.61
B23: Extrajudicial - 29 a 39 semanas de atraso | C23: 1517 | D23: 58940.68
B24: Extrajudicial - 40 a 55 semanas de atraso | C24: 3294 | D24: 30712
B25: JUDICIAL | C25: 2 | D25: 0
B26: Mas 55 semanas de atraso | C26: 21610 | D26: 91656.61
B27: Total general | C27: =SUM(C22:C26) -> 28840 | D27: =SUM(D22:D26) -> 389203.9
B29: COBRANZA GENERAL SOFIA
B30: Segmento | C30: Cuentas | D30: Recuperación
B31: Extrajudicial - 0 a 28 semanas de atraso | C31: 1354 | D31: 116158.66
B32: Extrajudicial - 29 a 39 semanas de atraso | C32: 1940 | D32: 76357.69
B33: Extrajudicial - 40 a 55 semanas de atraso | C33: 2423 | D33: 4574
B34: Mas 55 semanas de atraso | C34: 4264 | D34: 5237.29
B35: Total general | C35: =SUM(C31:C34) -> 9981 | D35: =SUM(D31:D34) -> 202327.64
B37: COBRANZA GENERAL FERNANDO
B38: Segmento | C38: Cuentas | D38: Recuperación
B39: Extrajudicial - 0 a 28 semanas de atraso | C39: 1332 | D39: 54834.63
B40: Total general | C40: =SUM(C39:C39) -> 1332 | D40: =SUM(D39:D39) -> 54834.63
B42: COBRANZA GENERAL FEDERICO
B43: Segmento | C43: Cuentas | D43: Recuperación
B44: Extrajudicial - 0 a 28 semanas de atraso | C44: 39 | D44: 2323
B45: Extrajudicial - 29 a 39 semanas de atraso | C45: 322 | D45: 14900
B46: Extrajudicial - 40 a 55 semanas de atraso | C46: 255 | D46: 546
B47: Mas 55 semanas de atraso | C47: 1930 | D47: 12038
...

Sheet DATA

Sheet EPR 19 ABR
B2: REPORTE CONSOLIDADO POR SEGMENTOS
B3: SALDO ACUMULADO SEMANA 16
B5: COORDINADOR | C5: SEGMENTO | D5: CUENTAS | E5: COBRANZA REAL | F5: CUOTA IDEAL | G5: VARIACION | H5: % VAR | I5: EPR | J5: EPR IDEAL | K5: VAR EPR
B6: Samatha y Zareth | C6: Extrajudicial - 0 a 28 semanas de atraso | D6: =SUMIF('REPORTE DIARIO'!B:B,'EPR 19 ABR'!C6, 'REPORTE DIARIO'!C:C) -> 13813 | E6: =SUMIF('REPORTE DIARIO'!B:B,'EPR 19 ABR'!C6, 'REPORTE DIARIO'!D:D) -> 1042103.1 | F6: =J6*D6 -> 2367942.9 | G6: =+E6-F6 -> -1325839.8 | H6: =ABS(G6/F6) -> 0.55991207 | I6: =E6/D6 -> 75.443644 | J6: =(200/7)*6 -> 171.42857 | K6: =+I6-J6 -> -95.984927
B7: Gabriel | C7: Extrajudicial - 29 a 39 semanas de atraso | D7: =SUMIF('REPORTE DIARIO'!B:B,'EPR 19 ABR'!C7, 'REPORTE DIARIO'!C:C) -> 11401 | E7: =SUMIF('REPORTE DIARIO'!B:B,'EPR 19 ABR'!C7, 'REPORTE DIARIO'!D:D) -> 684791.58 | F7: =J7*D7 -> 1074951.4 | G7: =+E7-F7 -> -390159.85 | H7: =ABS(G7/F7) -> 0.36295579 | I7: =E7/D7 -> 60.064168 | J7: =(110/7)*6 -> 94.285714 | K7: =+I7-J7 -> -34.221546
B8: Gabriel | C8: Extrajudicial - 40 a 55 semanas de atraso | D8: =SUMIF('REPORTE DIARIO'!B:B,'EPR 19 ABR'!C8, 'REPORTE DIARIO'!C:C) -> 14430 | E8: =SUMIF('REPORTE DIARIO'!B:B,'EPR 19 ABR'!C8, 'REPORTE DIARIO'!D:D) -> 248972.23 | F8: =J8*D8 -> 556585.71 | G8: =+E8-F8 -> -307613.48 | H8: =ABS(G8/F8) -> 0.55267945 | I8: =E8/D8 -> 17.253793 | J8: =(45/7)*6 -> 38.571429 | K8: =+I8-J8 -> -21.317636
B9: Fernando | C9: Mas 55 semanas de atraso | D9: =SUMIF('REPORTE DIARIO'!B:B,'EPR 19 ABR'!C9, 'REPORTE DIARIO'!C:C) -> 58563 | E9: =SUMIF('REPORTE DIARIO'!B:B,'EPR 19 ABR'!C9, 'REPORTE DIARIO'!D:D) -> 447699.8 | F9: =J9*D9 -> 752952.86 | G9: =+E9-F9 -> -305253.06 | H9: =ABS(G9/F9) -> 0.40540793 | I9: =E9/D9 -> 7.6447552 | J9: =(15/7)*6 -> 12.857143 | K9: =+I9-J9 -> -5.2123876
C10: TOTAL | D10: =SUM(D6:D9) -> 98207 | E10: =SUM(E6:E9) -> 2423566.7 | F10: =SUM(F6:F9) -> 4752432.9 | G10: =+E10-F10 -> -2328866.2 | H10: =ABS(G10/F10) -> 0.49003663 | I10: =E10/D10 -> 24.678146 | J10: =F10/D10 -> 48.391997 | K10: =I10-J10 -> -23.713851
B12: Nota:
B13: El saldo consolidado incluye los siguientes despachos
B14: Samantha, Samantha 2, Sofia, Edith, Fernando, Olguin y Federico
