Workbook

Sheet REPORTE DIARIO
B3: COBRANZA GENERAL SAMANTHA
B4: Segmento | C4: Cuentas | D4: Recuperación
B5: Extrajudicial - 0 a 28 semanas de atraso | C5: 6139 | D5: 402739.6
B6: Extrajudicial - 29 a 39 semanas de atraso | C6: 5777 | D6: 186675.18
B7: Extrajudicial - 40 a 55 semanas de atraso | C7: 8670 | D7: 141223
B8: JUDICIAL | C8: 21 | D8: 0
B9: Mas 55 semanas de atraso | C9: 21144 | D9: 256500.74
B10: Total general | C10: =SUM(C5:C9) -> 41751 | D10: =SUM(D5:D9) -> 987138.52
B12: COBRANZA GENERAL SAMANTHA 2
B13: Segmento | C13: Cuentas | D13: Recuperación
B14: Extrajudicial - 0 a 28 semanas de atraso | C14: 2498 | D14: 137460.75
B15: Extrajudicial - 29 a 39 semanas de atraso | C15: 1444 | D15: 76290.01
B16: Extrajudicial - 40 a 55 semanas de atraso | C16: 3283 | D16: 38401.62
B17: JUDICIAL | C17: 2 | D17: 0
B18: Mas 55 semanas de atraso | C18: 21186 | D18: 116217
B19: Total general | C19: =SUM(C14:C18) -> 28413 | D19: =SUM(D14:D18) -> 368369.38
B21: COBRANZA GENERAL EDITH
B22: Segmento | C22: Cuentas | D22: Recuperación
B23: Extrajudicial - 0 a 28 semanas de atraso | C23: 1757 | D23: 135828.5
B24: Extrajudicial - 29 a 39 semanas de atraso | C24: 2122 | D24: 88988.8
B25: Extrajudicial - 40 a 55 semanas de atraso | C25: 872 | D25: 23147
B26: Mas 55 semanas de atraso | C26: 8901 | D26: 22137.88
B27: Total general | C27: =SUM(C23:C26) -> 13652 | D27: =SUM(D23:D26) -> 270102.18
B29: COBRANZA GENERAL SOFIA
B30: Segmento | C30: Cuentas | D30: Recuperación
B31: Extrajudicial - 0 a 28 semanas de atraso | C31: 1364 | D31: 74451.24
B32: Extrajudicial - 29 a 39 semanas de atraso | C32: 1929 | D32: 68577.28
B33: Extrajudicial - 40 a 55 semanas de atraso | C33: 2775 | D33: 5066.22
B34: Mas 55 semanas de atraso | C34: 4264 | D34: 1477
B35: Total general | C35: =SUM(C31:C34) -> 10332 | D35: =SUM(D31:D34) -> 149571.74
B37: COBRANZA GENERAL FERNANDO
B38: Segmento | C38: Cuentas | D38: Recuperación
B39: Extrajudicial - 0 a 28 semanas de atraso | C39: 2630 | D39: 147335
B40: Total general | C40: =SUM(C39:C39) -> 2630 | D40: =SUM(D39:D39) -> 147335
B42: COBRANZA GENERAL FEDERICO
B43: Segmento | C43: Cuentas | D43: Recuperación
B44: Extrajudicial - 0 a 28 semanas de atraso | C44: 39 | D44: 25813
B45: Extrajudicial - 29 a 39 semanas de atraso | C45: 219 | D45: 1010
B46: Extrajudicial - 40 a 55 semanas de atraso | C46: 213 | D46: 546
B47: Mas 55 semanas de atraso | C47: 1891 | D47: 6573
...

Sheet DATA

Sheet EPR 12 ABR
B2: REPORTE CONSOLIDADO POR SEGMENTOS
B3: SALDO ACUMULADO SEMANA 15
B5: COORDINADOR | C5: SEGMENTO | D5: CUENTAS | E5: COBRANZA REAL | F5: CUOTA IDEAL | G5: VARIACION | H5: % VAR | I5: EPR | J5: EPR IDEAL | K5: VAR EPR
B6: Samatha y Zareth | C6: Extrajudicial - 0 a 28 semanas de atraso | D6: =SUMIF('REPORTE DIARIO'!B:B,'EPR 12 ABR'!C6, 'REPORTE DIARIO'!C:C) -> 14428 | E6: =SUMIF('REPORTE DIARIO'!B:B,'EPR 12 ABR'!C6, 'REPORTE DIARIO'!D:D) -> 923628.09 | F6: =J6*D6 -> 2473371.4 | G6: =+E6-F6 -> -1549743.3 | H6: =ABS(G6/F6) -> 0.62657121 | I6: =E6/D6 -> 64.016363 | J6: =(200/7)*6 -> 171.42857 | K6: =+I6-J6 -> -107.41221
B7: Gabriel | C7: Extrajudicial - 29 a 39 semanas de atraso | D7: =SUMIF('REPORTE DIARIO'!B:B,'EPR 12 ABR'!C7, 'REPORTE DIARIO'!C:C) -> 11491 | E7: =SUMIF('REPORTE DIARIO'!B:B,'EPR 12 ABR'!C7, 'REPORTE DIARIO'!D:D) -> 421541.27 | F7: =J7*D7 -> 1083437.1 | G7: =+E7-F7 -> -661895.87 | H7: =ABS(G7/F7) -> 0.61092226 | I7: =E7/D7 -> 36.684472 | J7: =(110/7)*6 -> 94.285714 | K7: =+I7-J7 -> -57.601242
B8: Gabriel | C8: Extrajudicial - 40 a 55 semanas de atraso | D8: =SUMIF('REPORTE DIARIO'!B:B,'EPR 12 ABR'!C8, 'REPORTE DIARIO'!C:C) -> 15813 | E8: =SUMIF('REPORTE DIARIO'!B:B,'EPR 12 ABR'!C8, 'REPORTE DIARIO'!D:D) -> 208383.84 | F8: =J8*D8 -> 609930 | G8: =+E8-F8 -> -401546.16 | H8: =ABS(G8/F8) -> 0.65834794 | I8: =E8/D8 -> 13.178008 | J8: =(45/7)*6 -> 38.571429 | K8: =+I8-J8 -> -25.393421
B9: Fernando | C9: Mas 55 semanas de atraso | D9: =SUMIF('REPORTE DIARIO'!B:B,'EPR 12 ABR'!C9, 'REPORTE DIARIO'!C:C) -> 57388 | E9: =SUMIF('REPORTE DIARIO'!B:B,'EPR 12 ABR'!C9, 'REPORTE DIARIO'!D:D) -> 402905.62 | F9: =J9*D9 -> 737845.71 | G9: =+E9-F9 -> -334940.09 | H9: =ABS(G9/F9) -> 0.45394327 | I9: =E9/D9 -> 7.0207294 | J9: =(15/7)*6 -> 12.857143 | K9: =+I9-J9 -> -5.8364134
C10: TOTAL | D10: =SUM(D6:D9) -> 99120 | E10: =SUM(E6:E9) -> 1956458.8 | F10: =SUM(F6:F9) -> 4904584.3 | G10: =+E10-F10 -> -2948125.5 | H10: =ABS(G10/F10) -> 0.60109589 | I10: =E10/D10 -> 19.738285 | J10: =F10/D10 -> 49.481278 | K10: =I10-J10 -> -29.742993
B12: Nota:
B13: El saldo consolidado incluye los siguientes despachos
B14: Samantha, Samantha 2, Sofia, Edith, Olguin, Fernando y Federico
