Workbook

Sheet REPORTE DIARIO
B3: COBRANZA GENERAL SAMANTHA
B4: Segmento | C4: Cuentas | D4: Recuperación
B5: Extrajudicial - 0 a 28 semanas de atraso | C5: 3379 | D5: 769355.89
B6: Extrajudicial - 29 a 39 semanas de atraso | C6: 2758 | D6: 313282.05
B7: Extrajudicial - 40 a 55 semanas de atraso | C7: 6004 | D7: 270665.64
B8: JUDICIAL | C8: 11 | D8: 0
B9: Mas 55 semanas de atraso | C9: 19903 | D9: 781926.83
B10: Total general | C10: =SUM(C5:C9) -> 32055 | D10: =SUM(D5:D9) -> 2135230.4
B12: COBRANZA GENERAL ANDREA
B13: Segmento | C13: Cuentas | D13: Recuperación
B14: Extrajudicial - 0 a 28 semanas de atraso | C14: 2084 | D14: 256255.77
B15: Extrajudicial - 29 a 39 semanas de atraso | C15: 1449 | D15: 68839.27
B16: Extrajudicial - 40 a 55 semanas de atraso | C16: 3606 | D16: 155134.51
B17: JUDICIAL | C17: 0 | D17: 0
B18: Mas 55 semanas de atraso | C18: 18144 | D18: 172252.92
B19: Total general | C19: =SUM(C14:C18) -> 25283 | D19: =SUM(D14:D18) -> 652482.47
B21: COBRANZA GENERAL EDITH
B22: Segmento | C22: Cuentas | D22: Recuperación
B23: Extrajudicial - 0 a 28 semanas de atraso | C23: 1677 | D23: 332816.44
B24: Extrajudicial - 29 a 39 semanas de atraso | C24: 272 | D24: 100065.25
B25: Extrajudicial - 40 a 55 semanas de atraso | C25: 1353 | D25: 48767.73
B26: JUDICIAL | C26: 1 | D26: 84
B27: Mas 55 semanas de atraso | C27: 17454 | D27: 136655.22
B28: Total general | C28: =SUM(C23:C27) -> 20757 | D28: =SUM(D23:D27) -> 618388.64
B30: COBRANZA GENERAL SOFIA
B31: Segmento | C31: Cuentas | D31: Recuperación
B32: Extrajudicial - 0 a 28 semanas de atraso | C32: 700 | D32: 103788.2
B33: Extrajudicial - 29 a 39 semanas de atraso | C33: 633 | D33: 165580.55
B34: Extrajudicial - 40 a 55 semanas de atraso | C34: 809 | D34: 38701
B35: Mas 55 semanas de atraso | C35: 4323 | D35: 13794
B36: Total general | C36: =SUM(C32:C35) -> 6465 | D36: =SUM(D32:D35) -> 321863.75
B38: COBRANZA GENERAL OLGUIN
B39: Segmento | C39: Cuentas | D39: Recuperación
B40: Extrajudicial - 0 a 28 semanas de atraso | C40: 805 | D40: 125573.08
B41: Extrajudicial - 29 a 39 semanas de atraso | C41: 696 | D41: 50560.9
B42: Extrajudicial - 40 a 55 semanas de atraso | C42: 1003 | D42: 37448.97
B43: Mas 55 semanas de atraso | C43: 418 | D43: 4527
B44: Total general | C44: =SUM(C40:C43) -> 2922 | D44: =SUM(D40:D43) -> 218109.95
B46: COBRANZA GENERAL FERNANDO
B47: Segmento | C47: Cuentas | D47: Recuperación
...

Sheet CDC-OLGUIN
B3: COBRANZA GENERAL CDC 100
B4: Segmento | C4: Cuentas | D4: Recuperación
B5: Extrajudicial - 0 a 28 semanas de atraso | C5: 9478 | D5: 263172.64
B6: Extrajudicial - 29 a 39 semanas de atraso | C6: 5632 | D6: 24283.39
B7: Extrajudicial - 40 a 55 semanas de atraso | C7: 8641 | D7: 33605.39
B8: JUDICIAL | C8: 2739 | D8: 250
B9: Mas 55 semanas de atraso | C9: 112881 | D9: 22753
B10: Total general | C10: =SUM(C5:C9) -> 139371 | D10: =SUM(D5:D9) -> 344064.42
B12: COBRANZA GENERAL OLGUIN
B13: Segmento | C13: Cuentas | D13: Recuperación
B14: Extrajudicial - 0 a 28 semanas de atraso | C14: 805 | D14: 125573.08
B15: Extrajudicial - 29 a 39 semanas de atraso | C15: 696 | D15: 50560.9
B16: Extrajudicial - 40 a 55 semanas de atraso | C16: 1003 | D16: 37448.97
B17: Mas 55 semanas de atraso | C17: 418 | D17: 4527
B18: Total general | C18: =SUM(C14:C17) -> 2922 | D18: =SUM(D14:D17) -> 218109.95
B20: Cobranza Total | C20: =SUMIF(B:B, "Total general", C:C) -> 142293 | D20: =SUMIF(B:B, "Total general", D:D) -> 562174.37

Sheet DATA

Sheet EPR 26 JUN
B2: REPORTE CONSOLIDADO POR SEGMENTOS
B3: SALDO ACUMULADO SEMANA 26
B5: COORDINADOR | C5: SEGMENTO | D5: CUENTAS | E5: COBRANZA REAL | F5: CUOTA IDEAL | G5: VARIACION | H5: % VAR | I5: EPR | J5: EPR IDEAL | K5: VAR EPR
B6: Zareth | C6: Extrajudicial - 0 a 28 semanas de atraso | D6: =SUMIF('REPORTE DIARIO'!B:B,'EPR 26 JUN'!C6, 'REPORTE DIARIO'!C:C) -> 10697 | E6: =SUMIF('REPORTE DIARIO'!B:B,'EPR 26 JUN'!C6, 'REPORTE DIARIO'!D:D) -> 1713427.8 | F6: =J6*D6 -> 672382.86 | G6: =+E6-F6 -> 1041044.9 | H6: =ABS(G6/F6) -> 1.5482919 | I6: =E6/D6 -> 160.17835 | J6: =(220/7)*2 -> 62.857143 | K6: =+I6-J6 -> 97.321204
B7: Gabriel | C7: Extrajudicial - 29 a 39 semanas de atraso | D7: =SUMIF('REPORTE DIARIO'!B:B,'EPR 26 JUN'!C7, 'REPORTE DIARIO'!C:C) -> 5815 | E7: =SUMIF('REPORTE DIARIO'!B:B,'EPR 26 JUN'!C7, 'REPORTE DIARIO'!D:D) -> 700254.02 | F7: =J7*D7 -> 182757.14 | G7: =+E7-F7 -> 517496.88 | H7: =ABS(G7/F7) -> 2.8316096 | I7: =E7/D7 -> 120.42202 | J7: =(110/7)*2 -> 31.428571 | K7: =+I7-J7 -> 88.993444
B8: Gabriel | C8: Extrajudicial - 40 a 55 semanas de atraso | D8: =SUMIF('REPORTE DIARIO'!B:B,'EPR 26 JUN'!C8, 'REPORTE DIARIO'!C:C) -> 13318 | E8: =SUMIF('REPORTE DIARIO'!B:B,'EPR 26 JUN'!C8, 'REPORTE DIARIO'!D:D) -> 554740.85 | F8: =J8*D8 -> 171231.43 | G8: =+E8-F8 -> 383509.42 | H8: =ABS(G8/F8) -> 2.239714 | I8: =E8/D8 -> 41.653465 | J8: =(45/7)*2 -> 12.857143 | K8: =+I8-J8 -> 28.796322
B9: Fernando (Naucalpan) | C9: Mas 55 semanas de atraso | D9: =SUMIF('REPORTE DIARIO'!B:B,'EPR 26 JUN'!C9, 'REPORTE DIARIO'!C:C) -> 62538 | E9: =SUMIF('REPORTE DIARIO'!B:B,'EPR 26 JUN'!C9, 'REPORTE DIARIO'!D:D) -> 1116125 | F9: =J9*D9 -> 268020 | G9: =+E9-F9 -> 848104.97 | H9: =ABS(G9/F9) -> 3.1643346 | I9: =E9/D9 -> 17.847148 | J9: =(15/7)*2 -> 4.2857143 | K9: =+I9-J9 -> 13.561434
C10: TOTAL | D10: =SUM(D6:D9) -> 92368 | E10: =SUM(E6:E9) -> 4084547.6 | F10: =SUM(F6:F9) -> 1294391.4 | G10: =+E10-F10 -> 2790156.2 | H10: =ABS(G10/F10) -> 2.1555738 | I10: =E10/D10 -> 44.220375 | J10: =F10/D10 -> 14.013418 | K10: =I10-J10 -> 30.206957
B12: Nota:
B13: El saldo consolidado incluye los siguientes despachos
B14: Samantha, Samantha 2, Sofia, Edith, Fernando, Olguin y Federico
