Workbook

Sheet REPORTE DIARIO
B3: COBRANZA GENERAL SAMANTHA
B4: Segmento | C4: Cuentas | D4: Recuperación
B5: Extrajudicial - 0 a 28 semanas de atraso | C5: 6366 | D5: 556284.16
B6: Extrajudicial - 29 a 39 semanas de atraso | C6: 5807 | D6: 270120.5
B7: Extrajudicial - 40 a 55 semanas de atraso | C7: 8694 | D7: 231510
B8: JUDICIAL | C8: 21 | D8: 0
B9: Mas 55 semanas de atraso | C9: 21212 | D9: 338695.99
B10: Total general | C10: =SUM(C5:C9) -> 42100 | D10: =SUM(D5:D9) -> 1396610.7
B12: COBRANZA GENERAL SAMANTHA 2
B13: Segmento | C13: Cuentas | D13: Recuperación
B14: Extrajudicial - 0 a 28 semanas de atraso | C14: 2474 | D14: 178915.75
B15: Extrajudicial - 29 a 39 semanas de atraso | C15: 1485 | D15: 92818.01
B16: Extrajudicial - 40 a 55 semanas de atraso | C16: 3279 | D16: 51333.62
B17: JUDICIAL | C17: 2 | D17: 0
B18: Mas 55 semanas de atraso | C18: 21194 | D18: 145715
B19: Total general | C19: =SUM(C14:C18) -> 28434 | D19: =SUM(D14:D18) -> 468782.38
B21: COBRANZA GENERAL EDITH
B22: Segmento | C22: Cuentas | D22: Recuperación
B23: Extrajudicial - 0 a 28 semanas de atraso | C23: 1986 | D23: 258091
B24: Extrajudicial - 29 a 39 semanas de atraso | C24: 2125 | D24: 111952.2
B25: Extrajudicial - 40 a 55 semanas de atraso | C25: 880 | D25: 24596
B26: Mas 55 semanas de atraso | C26: 8907 | D26: 29698.58
B27: Total general | C27: =SUM(C23:C26) -> 13898 | D27: =SUM(D23:D26) -> 424337.78
B29: COBRANZA GENERAL SOFIA
B30: Segmento | C30: Cuentas | D30: Recuperación
B31: Extrajudicial - 0 a 28 semanas de atraso | C31: 1363 | D31: 91203.94
B32: Extrajudicial - 29 a 39 semanas de atraso | C32: 1932 | D32: 75406.28
B33: Extrajudicial - 40 a 55 semanas de atraso | C33: 2776 | D33: 5730.22
B34: Mas 55 semanas de atraso | C34: 4264 | D34: 2617
B35: Total general | C35: =SUM(C31:C34) -> 10335 | D35: =SUM(D31:D34) -> 174957.44
B37: COBRANZA GENERAL FERNANDO
B38: Segmento | C38: Cuentas | D38: Recuperación
B39: Extrajudicial - 0 a 28 semanas de atraso | C39: 2584 | D39: 160711
B40: Total general | C40: =SUM(C39:C39) -> 2584 | D40: =SUM(D39:D39) -> 160711
B42: COBRANZA GENERAL FEDERICO
B43: Segmento | C43: Cuentas | D43: Recuperación
B44: Extrajudicial - 0 a 28 semanas de atraso | C44: 39 | D44: 25813
B45: Extrajudicial - 29 a 39 semanas de atraso | C45: 263 | D45: 1010
B46: Extrajudicial - 40 a 55 semanas de atraso | C46: 220 | D46: 546
B47: Mas 55 semanas de atraso | C47: 1902 | D47: 11692
...

Sheet DATA

Sheet EPR 13 ABR
B2: REPORTE CONSOLIDADO POR SEGMENTOS
B3: SALDO ACUMULADO SEMANA 15
B5: COORDINADOR | C5: SEGMENTO | D5: CUENTAS | E5: COBRANZA REAL | F5: CUOTA IDEAL | G5: VARIACION | H5: % VAR | I5: EPR | J5: EPR IDEAL | K5: VAR EPR
B6: Samatha y Zareth | C6: Extrajudicial - 0 a 28 semanas de atraso | D6: =SUMIF('REPORTE DIARIO'!B:B,'EPR 13 ABR'!C6, 'REPORTE DIARIO'!C:C) -> 14812 | E6: =SUMIF('REPORTE DIARIO'!B:B,'EPR 13 ABR'!C6, 'REPORTE DIARIO'!D:D) -> 1271018.9 | F6: =J6*D6 -> 2962400 | G6: =+E6-F6 -> -1691381.1 | H6: =ABS(G6/F6) -> 0.57094962 | I6: =E6/D6 -> 85.810076 | J6: =(200/7)*7 -> 200 | K6: =+I6-J6 -> -114.18992
B7: Gabriel | C7: Extrajudicial - 29 a 39 semanas de atraso | D7: =SUMIF('REPORTE DIARIO'!B:B,'EPR 13 ABR'!C7, 'REPORTE DIARIO'!C:C) -> 11612 | E7: =SUMIF('REPORTE DIARIO'!B:B,'EPR 13 ABR'!C7, 'REPORTE DIARIO'!D:D) -> 551306.99 | F7: =J7*D7 -> 1277320 | G7: =+E7-F7 -> -726013.01 | H7: =ABS(G7/F7) -> 0.56838773 | I7: =E7/D7 -> 47.47735 | J7: =(110/7)*7 -> 110 | K7: =+I7-J7 -> -62.52265
B8: Gabriel | C8: Extrajudicial - 40 a 55 semanas de atraso | D8: =SUMIF('REPORTE DIARIO'!B:B,'EPR 13 ABR'!C8, 'REPORTE DIARIO'!C:C) -> 15849 | E8: =SUMIF('REPORTE DIARIO'!B:B,'EPR 13 ABR'!C8, 'REPORTE DIARIO'!D:D) -> 313715.84 | F8: =J8*D8 -> 713205 | G8: =+E8-F8 -> -399489.16 | H8: =ABS(G8/F8) -> 0.5601323 | I8: =E8/D8 -> 19.794046 | J8: =(45/7)*7 -> 45 | K8: =+I8-J8 -> -25.205954
B9: Fernando | C9: Mas 55 semanas de atraso | D9: =SUMIF('REPORTE DIARIO'!B:B,'EPR 13 ABR'!C9, 'REPORTE DIARIO'!C:C) -> 57479 | E9: =SUMIF('REPORTE DIARIO'!B:B,'EPR 13 ABR'!C9, 'REPORTE DIARIO'!D:D) -> 528418.57 | F9: =J9*D9 -> 862185 | G9: =+E9-F9 -> -333766.43 | H9: =ABS(G9/F9) -> 0.38711695 | I9: =E9/D9 -> 9.1932457 | J9: =(15/7)*7 -> 15 | K9: =+I9-J9 -> -5.8067543
C10: TOTAL | D10: =SUM(D6:D9) -> 99752 | E10: =SUM(E6:E9) -> 2664460.2 | F10: =SUM(F6:F9) -> 5815110 | G10: =+E10-F10 -> -3150649.8 | H10: =ABS(G10/F10) -> 0.54180398 | I10: =E10/D10 -> 26.710845 | J10: =F10/D10 -> 58.295673 | K10: =I10-J10 -> -31.584828
B12: Nota:
B13: El saldo consolidado incluye los siguientes despachos
B14: Samantha, Samantha 2, Sofia, Edith, Fernando y Federico
