Workbook

Sheet REPORTE DIARIO
B3: COBRANZA GENERAL SAMANTHA
B4: Segmento | C4: Cuentas | D4: Recuperación
B5: Extrajudicial - 0 a 28 semanas de atraso | C5: 7434 | D5: 221704.08
B6: Extrajudicial - 29 a 39 semanas de atraso | C6: 8029 | D6: 110678.46
B7: Extrajudicial - 40 a 55 semanas de atraso | C7: 10048 | D7: 97918.51
B8: JUDICIAL | C8: 21 | D8: 0
B9: Mas 55 semanas de atraso | C9: 29554 | D9: 172421.48
B10: Total general | C10: =SUM(C5:C9) -> 55086 | D10: =SUM(D5:D9) -> 602722.53
B12: COBRANZA GENERAL SAMANTHA 2
B13: Segmento | C13: Cuentas | D13: Recuperación
B14: Extrajudicial - 0 a 28 semanas de atraso | C14: 3337 | D14: 96952.02
B15: Extrajudicial - 29 a 39 semanas de atraso | C15: 1783 | D15: 17621
B16: Extrajudicial - 40 a 55 semanas de atraso | C16: 3334 | D16: 7711
B17: JUDICIAL | C17: 2 | D17: 0
B18: Mas 55 semanas de atraso | C18: 21215 | D18: 68744.19
B19: Total general | C19: =SUM(C14:C18) -> 29671 | D19: =SUM(D14:D18) -> 191028.21
B21: COBRANZA GENERAL EDITH
B22: Segmento | C22: Cuentas | D22: Recuperación
B23: Extrajudicial - 0 a 28 semanas de atraso | C23: 1455 | D23: 71493.73
B24: Extrajudicial - 29 a 39 semanas de atraso | C24: 1388 | D24: 64437.51
B25: Extrajudicial - 40 a 55 semanas de atraso | C25: 292 | D25: 3571
B26: Mas 55 semanas de atraso | C26: 8408 | D26: 10187.51
B27: Total general | C27: =SUM(C23:C26) -> 11543 | D27: =SUM(D23:D26) -> 149689.75
B29: COBRANZA GENERAL SOFIA
B30: Segmento | C30: Cuentas | D30: Recuperación
B31: Extrajudicial - 0 a 28 semanas de atraso | C31: 1204 | D31: 58197.56
B32: Extrajudicial - 29 a 39 semanas de atraso | C32: 1155 | D32: 8035
B33: Extrajudicial - 40 a 55 semanas de atraso | C33: 3051 | D33: 1433
B34: Mas 55 semanas de atraso | C34: 1901 | D34: 3219
B35: Total general | C35: =SUM(C31:C34) -> 7311 | D35: =SUM(D31:D34) -> 70884.56
B37: COBRANZA GENERAL FERNANDO
B38: Segmento | C38: Cuentas | D38: Recuperación
B39: Extrajudicial - 0 a 28 semanas de atraso | C39: 3066 | D39: 34484
B40: Total general | C40: =SUM(C39:C39) -> 3066 | D40: =SUM(D39:D39) -> 34484
B42: COBRANZA GENERAL OLGUIN
B43: Segmento | C43: Cuentas | D43: Recuperación
B44: Extrajudicial - 0 a 28 semanas de atraso | C44: 68 | D44: 5605.16
B45: Extrajudicial - 29 a 39 semanas de atraso | C45: 122 | D45: 0
B46: Extrajudicial - 40 a 55 semanas de atraso | C46: 14 | D46: 0
B47: Mas 55 semanas de atraso | C47: 10 | D47: 0
...

Sheet DATA

Sheet EPR 27 MAR
B2: REPORTE CONSOLIDADO POR SEGMENTOS
B3: SALDO ACUMULADO SEMANA 13
B5: COORDINADOR | C5: SEGMENTO | D5: CUENTAS | E5: COBRANZA REAL | F5: CUOTA IDEAL | G5: VARIACION | H5: % VAR | I5: EPR | J5: EPR IDEAL | K5: VAR EPR
B6: Samatha y Zareth | C6: Extrajudicial - 0 a 28 semanas de atraso | D6: =SUMIF('REPORTE DIARIO'!B:B,'EPR 27 MAR'!C6, 'REPORTE DIARIO'!C:C) -> 16564 | E6: =SUMIF('REPORTE DIARIO'!B:B,'EPR 27 MAR'!C6, 'REPORTE DIARIO'!D:D) -> 488436.55 | F6: =J6*D6 -> 1893028.6 | G6: =+E6-F6 -> -1404592 | H6: =ABS(G6/F6) -> 0.74198142 | I6: =E6/D6 -> 29.487838 | J6: =(200/7)*4 -> 114.28571 | K6: =+I6-J6 -> -84.797876
B7: Gabriel | C7: Extrajudicial - 29 a 39 semanas de atraso | D7: =SUMIF('REPORTE DIARIO'!B:B,'EPR 27 MAR'!C7, 'REPORTE DIARIO'!C:C) -> 12599 | E7: =SUMIF('REPORTE DIARIO'!B:B,'EPR 27 MAR'!C7, 'REPORTE DIARIO'!D:D) -> 201371.97 | F7: =J7*D7 -> 791937.14 | G7: =+E7-F7 -> -590565.17 | H7: =ABS(G7/F7) -> 0.74572228 | I7: =E7/D7 -> 15.983171 | J7: =(110/7)*4 -> 62.857143 | K7: =+I7-J7 -> -46.873972
B8: Gabriel | C8: Extrajudicial - 40 a 55 semanas de atraso | D8: =SUMIF('REPORTE DIARIO'!B:B,'EPR 27 MAR'!C8, 'REPORTE DIARIO'!C:C) -> 16903 | E8: =SUMIF('REPORTE DIARIO'!B:B,'EPR 27 MAR'!C8, 'REPORTE DIARIO'!D:D) -> 110633.51 | F8: =J8*D8 -> 434648.57 | G8: =+E8-F8 -> -324015.06 | H8: =ABS(G8/F8) -> 0.74546446 | I8: =E8/D8 -> 6.5451997 | J8: =(45/7)*4 -> 25.714286 | K8: =+I8-J8 -> -19.169086
B9: Fernando | C9: Mas 55 semanas de atraso | D9: =SUMIF('REPORTE DIARIO'!B:B,'EPR 27 MAR'!C9, 'REPORTE DIARIO'!C:C) -> 61657 | E9: =SUMIF('REPORTE DIARIO'!B:B,'EPR 27 MAR'!C9, 'REPORTE DIARIO'!D:D) -> 254572.18 | F9: =J9*D9 -> 528488.57 | G9: =+E9-F9 -> -273916.39 | H9: =ABS(G9/F9) -> 0.51830145 | I9: =E9/D9 -> 4.1288447 | J9: =(15/7)*4 -> 8.5714286 | K9: =+I9-J9 -> -4.4425838
C10: TOTAL | D10: =SUM(D6:D9) -> 107723 | E10: =SUM(E6:E9) -> 1055014.2 | F10: =SUM(F6:F9) -> 3648102.9 | G10: =+E10-F10 -> -2593088.6 | H10: =ABS(G10/F10) -> 0.7108047 | I10: =E10/D10 -> 9.7937693 | J10: =F10/D10 -> 33.865589 | K10: =I10-J10 -> -24.07182
B12: Nota:
B13: El saldo consolidado incluye los siguientes despachos
B14: Samantha, Samantha 2, Sofia, Edith, Olguin, Fernando y Federico
