Workbook

Sheet REPORTE DIARIO
B3: COBRANZA GENERAL SAMANTHA
B4: Segmento | C4: Cuentas | D4: Recuperación
B5: Extrajudicial - 0 a 28 semanas de atraso | C5: 4660 | D5: 275765.8
B6: Extrajudicial - 29 a 39 semanas de atraso | C6: 4717 | D6: 48143.97
B7: Extrajudicial - 40 a 55 semanas de atraso | C7: 6050 | D7: 22131.73
B8: JUDICIAL | C8: 21 | D8: 0
B9: Mas 55 semanas de atraso | C9: 13416 | D9: 91761.77
B10: Total general | C10: =SUM(C5:C9) -> 28864 | D10: =SUM(D5:D9) -> 437803.27
B12: COBRANZA GENERAL SAMANTHA 2
B13: Segmento | C13: Cuentas | D13: Recuperación
B14: Extrajudicial - 0 a 28 semanas de atraso | C14: 2330 | D14: 47468.67
B15: Extrajudicial - 29 a 39 semanas de atraso | C15: 1682 | D15: 58061
B16: Extrajudicial - 40 a 55 semanas de atraso | C16: 3082 | D16: 57953
B17: JUDICIAL | C17: 2 | D17: 0
B18: Mas 55 semanas de atraso | C18: 21844 | D18: 75913.43
B19: Total general | C19: =SUM(C14:C18) -> 28940 | D19: =SUM(D14:D18) -> 239396.1
B21: COBRANZA GENERAL EDITH
B22: Segmento | C22: Cuentas | D22: Recuperación
B23: Extrajudicial - 0 a 28 semanas de atraso | C23: 4108 | D23: 117945.34
B24: Extrajudicial - 29 a 39 semanas de atraso | C24: 2411 | D24: 13161.66
B25: Extrajudicial - 40 a 55 semanas de atraso | C25: 1027 | D25: 7572
B26: Mas 55 semanas de atraso | C26: 9590 | D26: 10321.07
B27: Total general | C27: =SUM(C23:C26) -> 17136 | D27: =SUM(D23:D26) -> 149000.07
B29: COBRANZA GENERAL SOFIA
B30: Segmento | C30: Cuentas | D30: Recuperación
B31: Extrajudicial - 0 a 28 semanas de atraso | C31: 339 | D31: 36639.05
B32: Extrajudicial - 29 a 39 semanas de atraso | C32: 1903 | D32: 16965.53
B33: Extrajudicial - 40 a 55 semanas de atraso | C33: 2383 | D33: 1294
B34: Mas 55 semanas de atraso | C34: 4264 | D34: 1971
B35: Total general | C35: =SUM(C31:C34) -> 8889 | D35: =SUM(D31:D34) -> 56869.58
B37: COBRANZA GENERAL FEDERICO
B38: Segmento | C38: Cuentas | D38: Recuperación
B39: Extrajudicial - 0 a 28 semanas de atraso | C39: 39 | D39: 0
B40: Extrajudicial - 29 a 39 semanas de atraso | C40: 327 | D40: 0
B41: Extrajudicial - 40 a 55 semanas de atraso | C41: 258 | D41: 1320
B42: Mas 55 semanas de atraso | C42: 1940 | D42: 4933.71
B43: Total general | C43: =SUM(C39:C42) -> 2564 | D43: =SUM(D39:D42) -> 6253.71
B45: COBRANZA GENERAL FERNANDO
B46: Segmento | C46: Cuentas | D46: Recuperación
B47: Extrajudicial - 0 a 28 semanas de atraso | C47: 2036 | D47: 6066
...

Sheet DATA

Sheet EPR 24 ABR
B2: REPORTE CONSOLIDADO POR SEGMENTOS
B3: COBRANZA 25 ABRIL
B5: COORDINADOR | C5: SEGMENTO | D5: CUENTAS | E5: COBRANZA REAL | F5: CUOTA IDEAL | G5: VARIACION | H5: % VAR | I5: EPR | J5: EPR IDEAL | K5: VAR EPR
B6: Samatha y Zareth | C6: Extrajudicial - 0 a 28 semanas de atraso | D6: =SUMIF('REPORTE DIARIO'!B:B,'EPR 24 ABR'!C6, 'REPORTE DIARIO'!C:C) -> 13598 | E6: =SUMIF('REPORTE DIARIO'!B:B,'EPR 24 ABR'!C6, 'REPORTE DIARIO'!D:D) -> 483884.86 | F6: =J6*D6 -> 388514.29 | G6: =+E6-F6 -> 95370.574 | H6: =ABS(G6/F6) -> 0.24547508 | I6: =E6/D6 -> 35.585002 | J6: =200/7 -> 28.571429 | K6: =+I6-J6 -> 7.0135736
B7: Gabriel | C7: Extrajudicial - 29 a 39 semanas de atraso | D7: =SUMIF('REPORTE DIARIO'!B:B,'EPR 24 ABR'!C7, 'REPORTE DIARIO'!C:C) -> 11189 | E7: =SUMIF('REPORTE DIARIO'!B:B,'EPR 24 ABR'!C7, 'REPORTE DIARIO'!D:D) -> 137832.16 | F7: =J7*D7 -> 175827.14 | G7: =+E7-F7 -> -37994.983 | H7: =ABS(G7/F7) -> 0.21609282 | I7: =E7/D7 -> 12.318541 | J7: =110/7 -> 15.714286 | K7: =+I7-J7 -> -3.3957443
B8: Gabriel | C8: Extrajudicial - 40 a 55 semanas de atraso | D8: =SUMIF('REPORTE DIARIO'!B:B,'EPR 24 ABR'!C8, 'REPORTE DIARIO'!C:C) -> 13363 | E8: =SUMIF('REPORTE DIARIO'!B:B,'EPR 24 ABR'!C8, 'REPORTE DIARIO'!D:D) -> 90270.73 | F8: =J8*D8 -> 85905 | G8: =+E8-F8 -> 4365.73 | H8: =ABS(G8/F8) -> 0.050820441 | I8: =E8/D8 -> 6.7552743 | J8: =45/7 -> 6.4285714 | K8: =+I8-J8 -> 0.32670284
B9: Fernando | C9: Mas 55 semanas de atraso | D9: =SUMIF('REPORTE DIARIO'!B:B,'EPR 24 ABR'!C9, 'REPORTE DIARIO'!C:C) -> 51883 | E9: =SUMIF('REPORTE DIARIO'!B:B,'EPR 24 ABR'!C9, 'REPORTE DIARIO'!D:D) -> 184900.98 | F9: =J9*D9 -> 111177.86 | G9: =+E9-F9 -> 73723.123 | H9: =ABS(G9/F9) -> 0.66310977 | I9: =E9/D9 -> 3.5638066 | J9: =15/7 -> 2.1428571 | K9: =+I9-J9 -> 1.4209495
C10: TOTAL | D10: =SUM(D6:D9) -> 90033 | E10: =SUM(E6:E9) -> 896888.73 | F10: =SUM(F6:F9) -> 761424.29 | G10: =+E10-F10 -> 135464.44 | H10: =ABS(G10/F10) -> 0.17790928 | I10: =E10/D10 -> 9.9617777 | J10: =F10/D10 -> 8.4571689 | K10: =I10-J10 -> 1.5046088
B12: Nota:
B13: El saldo consolidado incluye los siguientes despachos
B14: Samantha, Samantha 2, Sofia, Edith, Fernando, Olguin y Federico
