Workbook

Sheet REPORTE DIARIO
B3: COBRANZA GENERAL SAMANTHA
B4: Segmento | C4: Cuentas | D4: Recuperación
B5: Extrajudicial - 0 a 28 semanas de atraso | C5: 4660 | D5: 570509.87
B6: Extrajudicial - 29 a 39 semanas de atraso | C6: 4717 | D6: 258782.73
B7: Extrajudicial - 40 a 55 semanas de atraso | C7: 6050 | D7: 188694.27
B8: JUDICIAL | C8: 21 | D8: 0
B9: Mas 55 semanas de atraso | C9: 13416 | D9: 274163
B10: Total general | C10: =SUM(C5:C9) -> 28864 | D10: =SUM(D5:D9) -> 1292149.9
B12: COBRANZA GENERAL EDITH
B13: Segmento | C13: Cuentas | D13: Recuperación
B14: Extrajudicial - 0 a 28 semanas de atraso | C14: 4108 | D14: 329615.57
B15: Extrajudicial - 29 a 39 semanas de atraso | C15: 2411 | D15: 127916.25
B16: Extrajudicial - 40 a 55 semanas de atraso | C16: 1027 | D16: 52139.42
B17: Mas 55 semanas de atraso | C17: 9590 | D17: 28910.07
B18: Total general | C18: =SUM(C14:C17) -> 17136 | D18: =SUM(D14:D17) -> 538581.31
B20: COBRANZA GENERAL SAMANTHA 2
B21: Segmento | C21: Cuentas | D21: Recuperación
B22: Extrajudicial - 0 a 28 semanas de atraso | C22: 2330 | D22: 160334.75
B23: Extrajudicial - 29 a 39 semanas de atraso | C23: 1682 | D23: 96720.79
B24: Extrajudicial - 40 a 55 semanas de atraso | C24: 3082 | D24: 79835.6
B25: JUDICIAL | C25: 2 | D25: 0
B26: Mas 55 semanas de atraso | C26: 21844 | D26: 134595.81
B27: Total general | C27: =SUM(C22:C26) -> 28940 | D27: =SUM(D22:D26) -> 471486.95
B29: COBRANZA GENERAL SOFIA
B30: Segmento | C30: Cuentas | D30: Recuperación
B31: Extrajudicial - 0 a 28 semanas de atraso | C31: 339 | D31: 171690.23
B32: Extrajudicial - 29 a 39 semanas de atraso | C32: 1903 | D32: 116324.78
B33: Extrajudicial - 40 a 55 semanas de atraso | C33: 2383 | D33: 52053.52
B34: Mas 55 semanas de atraso | C34: 4264 | D34: 4658.51
B35: Total general | C35: =SUM(C31:C34) -> 8889 | D35: =SUM(D31:D34) -> 344727.04
B37: COBRANZA GENERAL FERNANDO
B38: Segmento | C38: Cuentas | D38: Recuperación
B39: Extrajudicial - 0 a 28 semanas de atraso | C39: 2036 | D39: 36404
B40: Total general | C40: =SUM(C39:C39) -> 2036 | D40: =SUM(D39:D39) -> 36404
B42: COBRANZA GENERAL FEDERICO
B43: Segmento | C43: Cuentas | D43: Recuperación
B44: Extrajudicial - 0 a 28 semanas de atraso | C44: 39 | D44: 1354
B45: Extrajudicial - 29 a 39 semanas de atraso | C45: 327 | D45: 3323
B46: Extrajudicial - 40 a 55 semanas de atraso | C46: 258 | D46: 1320
B47: Mas 55 semanas de atraso | C47: 1940 | D47: 19719.71
...

Sheet DATA

Sheet EPR 25 ABR
B2: REPORTE CONSOLIDADO POR SEGMENTOS
B3: SALDO ACUMULADO SEMANA 17
B5: COORDINADOR | C5: SEGMENTO | D5: CUENTAS | E5: COBRANZA REAL | F5: CUOTA IDEAL | G5: VARIACION | H5: % VAR | I5: EPR | J5: EPR IDEAL | K5: VAR EPR
B6: Samatha y Zareth | C6: Extrajudicial - 0 a 28 semanas de atraso | D6: =SUMIF('REPORTE DIARIO'!B:B,'EPR 25 ABR'!C6, 'REPORTE DIARIO'!C:C) -> 13598 | E6: =SUMIF('REPORTE DIARIO'!B:B,'EPR 25 ABR'!C6, 'REPORTE DIARIO'!D:D) -> 1270942.9 | F6: =J6*D6 -> 1942571.4 | G6: =+E6-F6 -> -671628.56 | H6: =ABS(G6/F6) -> 0.34574201 | I6: =E6/D6 -> 93.465427 | J6: =(200/7)*5 -> 142.85714 | K6: =+I6-J6 -> -49.391716
B7: Gabriel | C7: Extrajudicial - 29 a 39 semanas de atraso | D7: =SUMIF('REPORTE DIARIO'!B:B,'EPR 25 ABR'!C7, 'REPORTE DIARIO'!C:C) -> 11189 | E7: =SUMIF('REPORTE DIARIO'!B:B,'EPR 25 ABR'!C7, 'REPORTE DIARIO'!D:D) -> 604567.55 | F7: =J7*D7 -> 879135.71 | G7: =+E7-F7 -> -274568.16 | H7: =ABS(G7/F7) -> 0.31231602 | I7: =E7/D7 -> 54.032313 | J7: =(110/7)*5 -> 78.571429 | K7: =+I7-J7 -> -24.539116
B8: Gabriel | C8: Extrajudicial - 40 a 55 semanas de atraso | D8: =SUMIF('REPORTE DIARIO'!B:B,'EPR 25 ABR'!C8, 'REPORTE DIARIO'!C:C) -> 13363 | E8: =SUMIF('REPORTE DIARIO'!B:B,'EPR 25 ABR'!C8, 'REPORTE DIARIO'!D:D) -> 374042.81 | F8: =J8*D8 -> 429525 | G8: =+E8-F8 -> -55482.19 | H8: =ABS(G8/F8) -> 0.12917104 | I8: =E8/D8 -> 27.990931 | J8: =(45/7)*5 -> 32.142857 | K8: =+I8-J8 -> -4.1519262
B9: Fernando | C9: Mas 55 semanas de atraso | D9: =SUMIF('REPORTE DIARIO'!B:B,'EPR 25 ABR'!C9, 'REPORTE DIARIO'!C:C) -> 51883 | E9: =SUMIF('REPORTE DIARIO'!B:B,'EPR 25 ABR'!C9, 'REPORTE DIARIO'!D:D) -> 464633.1 | F9: =J9*D9 -> 555889.29 | G9: =+E9-F9 -> -91256.186 | H9: =ABS(G9/F9) -> 0.16416252 | I9: =E9/D9 -> 8.9554016 | J9: =(15/7)*5 -> 10.714286 | K9: =+I9-J9 -> -1.7588841
C10: TOTAL | D10: =SUM(D6:D9) -> 90033 | E10: =SUM(E6:E9) -> 2714186.3 | F10: =SUM(F6:F9) -> 3807121.4 | G10: =+E10-F10 -> -1092935.1 | H10: =ABS(G10/F10) -> 0.2870765 | I10: =E10/D10 -> 30.146572 | J10: =F10/D10 -> 42.285844 | K10: =I10-J10 -> -12.139272
B12: Nota:
B13: El saldo consolidado incluye los siguientes despachos
B14: Samantha, Samantha 2, Sofia, Edith, Fernando, Olguin y Federico
