Workbook

Sheet REPORTE DIARIO
B3: COBRANZA GENERAL SAMANTHA
B4: Segmento | C4: Cuentas | D4: Recuperación
B5: Extrajudicial - 0 a 28 semanas de atraso | C5: 4042 | D5: 119138.12
B6: Extrajudicial - 29 a 39 semanas de atraso | C6: 4295 | D6: 58610.03
B7: Extrajudicial - 40 a 55 semanas de atraso | C7: 6053 | D7: 90911
B8: JUDICIAL | C8: 10 | D8: 803.56
B9: Mas 55 semanas de atraso | C9: 13337 | D9: 67074.15
B10: Total general | C10: =SUM(C5:C9) -> 27737 | D10: =SUM(D5:D9) -> 336536.86
B12: COBRANZA GENERAL SOFIA
B13: Segmento | C13: Cuentas | D13: Recuperación
B14: Extrajudicial - 0 a 28 semanas de atraso | C14: 259 | D14: 20007.99
B15: Extrajudicial - 29 a 39 semanas de atraso | C15: 2030 | D15: 80939.78
B16: Extrajudicial - 40 a 55 semanas de atraso | C16: 2233 | D16: 2381
B17: Mas 55 semanas de atraso | C17: 4232 | D17: 0
B18: Total general | C18: =SUM(C14:C17) -> 8754 | D18: =SUM(D14:D17) -> 103328.77
B20: COBRANZA GENERAL EDITH
B21: Segmento | C21: Cuentas | D21: Recuperación
B22: Extrajudicial - 0 a 28 semanas de atraso | C22: 3082 | D22: 15564.77
B23: Extrajudicial - 29 a 39 semanas de atraso | C23: 1955 | D23: 20449
B24: Extrajudicial - 40 a 55 semanas de atraso | C24: 2249 | D24: 12968
B25: Mas 55 semanas de atraso | C25: 9845 | D25: 8052
B26: Total general | C26: =SUM(C22:C25) -> 17131 | D26: =SUM(D22:D25) -> 57033.77
B28: COBRANZA GENERAL SAMANTHA 2
B29: Segmento | C29: Cuentas | D29: Recuperación
B30: Extrajudicial - 0 a 28 semanas de atraso | C30: 1921 | D30: 16811
B31: Extrajudicial - 29 a 39 semanas de atraso | C31: 1833 | D31: 18115
B32: Extrajudicial - 40 a 55 semanas de atraso | C32: 3131 | D32: 8420
B33: JUDICIAL | C33: 2 | D33: 0
B34: Mas 55 semanas de atraso | C34: 20831 | D34: 11655
B35: Total general | C35: =SUM(C30:C34) -> 27718 | D35: =SUM(D30:D34) -> 55001
B37: COBRANZA GENERAL FERNANDO
B38: Segmento | C38: Cuentas | D38: Recuperación
B39: Extrajudicial - 0 a 28 semanas de atraso | C39: 2040 | D39: 10957
B40: Total general | C40: =SUM(C39:C39) -> 2040 | D40: =SUM(D39:D39) -> 10957
B42: COBRANZA GENERAL FEDERICO
B43: Segmento | C43: Cuentas | D43: Recuperación
B44: Extrajudicial - 0 a 28 semanas de atraso | C44: 191 | D44: 3456
B45: Extrajudicial - 29 a 39 semanas de atraso | C45: 645 | D45: 100
B46: Extrajudicial - 40 a 55 semanas de atraso | C46: 523 | D46: 500
B47: Mas 55 semanas de atraso | C47: 2202 | D47: 1783
...

Sheet DATA

Sheet EPR 13 MAYO
B2: REPORTE CONSOLIDADO POR SEGMENTOS
B3: SALDO ACUMULADO SEMANA 20
B5: COORDINADOR | C5: SEGMENTO | D5: CUENTAS | E5: COBRANZA REAL | F5: CUOTA IDEAL | G5: VARIACION | H5: % VAR | I5: EPR | J5: EPR IDEAL | K5: VAR EPR
B6: Zareth | C6: Extrajudicial - 0 a 28 semanas de atraso | D6: =SUMIF('REPORTE DIARIO'!B:B,'EPR 13 MAYO'!C6, 'REPORTE DIARIO'!C:C) -> 11768 | E6: =SUMIF('REPORTE DIARIO'!B:B,'EPR 13 MAYO'!C6, 'REPORTE DIARIO'!D:D) -> 185934.88 | F6: =J6*D6 -> 739702.86 | G6: =+E6-F6 -> -553767.98 | H6: =ABS(G6/F6) -> 0.74863571 | I6: =E6/D6 -> 15.800041 | J6: =(220/7)*2 -> 62.857143 | K6: =+I6-J6 -> -47.057102
B7: Gabriel | C7: Extrajudicial - 29 a 39 semanas de atraso | D7: =SUMIF('REPORTE DIARIO'!B:B,'EPR 13 MAYO'!C7, 'REPORTE DIARIO'!C:C) -> 11230 | E7: =SUMIF('REPORTE DIARIO'!B:B,'EPR 13 MAYO'!C7, 'REPORTE DIARIO'!D:D) -> 179713.81 | F7: =J7*D7 -> 352942.86 | G7: =+E7-F7 -> -173229.05 | H7: =ABS(G7/F7) -> 0.4908133 | I7: =E7/D7 -> 16.003011 | J7: =(110/7)*2 -> 31.428571 | K7: =+I7-J7 -> -15.425561
B8: Gabriel | C8: Extrajudicial - 40 a 55 semanas de atraso | D8: =SUMIF('REPORTE DIARIO'!B:B,'EPR 13 MAYO'!C8, 'REPORTE DIARIO'!C:C) -> 15025 | E8: =SUMIF('REPORTE DIARIO'!B:B,'EPR 13 MAYO'!C8, 'REPORTE DIARIO'!D:D) -> 115180 | F8: =J8*D8 -> 193178.57 | G8: =+E8-F8 -> -77998.571 | H8: =ABS(G8/F8) -> 0.4037641 | I8: =E8/D8 -> 7.6658902 | J8: =(45/7)*2 -> 12.857143 | K8: =+I8-J8 -> -5.1912527
B9: Fernando (Naucalpan) | C9: Mas 55 semanas de atraso | D9: =SUMIF('REPORTE DIARIO'!B:B,'EPR 13 MAYO'!C9, 'REPORTE DIARIO'!C:C) -> 51556 | E9: =SUMIF('REPORTE DIARIO'!B:B,'EPR 13 MAYO'!C9, 'REPORTE DIARIO'!D:D) -> 88992.15 | F9: =J9*D9 -> 220954.29 | G9: =+E9-F9 -> -131962.14 | H9: =ABS(G9/F9) -> 0.59723728 | I9: =E9/D9 -> 1.726126 | J9: =(15/7)*2 -> 4.2857143 | K9: =+I9-J9 -> -2.5595883
C10: TOTAL | D10: =SUM(D6:D9) -> 89579 | E10: =SUM(E6:E9) -> 569820.84 | F10: =SUM(F6:F9) -> 1506778.6 | G10: =+E10-F10 -> -936957.73 | H10: =ABS(G10/F10) -> 0.62182842 | I10: =E10/D10 -> 6.3610985 | J10: =F10/D10 -> 16.820667 | K10: =I10-J10 -> -10.459569
B12: Nota:
B13: El saldo consolidado incluye los siguientes despachos
B14: Samantha, Samantha 2, Sofia, Edith, Fernando, Olguin y Federico
