Workbook

Sheet REPORTE DIARIO
B3: COBRANZA GENERAL SAMANTHA
B4: Segmento | C4: Cuentas | D4: Recuperación
B5: Extrajudicial - 0 a 28 semanas de atraso | C5: 4078 | D5: 447154.75
B6: Extrajudicial - 29 a 39 semanas de atraso | C6: 4181 | D6: 333760.7
B7: Extrajudicial - 40 a 55 semanas de atraso | C7: 4226 | D7: 248083.94
B8: JUDICIAL | C8: 11 | D8: 0
B9: Mas 55 semanas de atraso | C9: 11356 | D9: 374064.92
B10: Total general | C10: =SUM(C5:C9) -> 23852 | D10: =SUM(D5:D9) -> 1403064.3
B12: COBRANZA GENERAL SAMANTHA 2
B13: Segmento | C13: Cuentas | D13: Recuperación
B14: Extrajudicial - 0 a 28 semanas de atraso | C14: 2370 | D14: 284022.26
B15: Extrajudicial - 29 a 39 semanas de atraso | C15: 2110 | D15: 130786.23
B16: Extrajudicial - 40 a 55 semanas de atraso | C16: 2115 | D16: 131573.34
B17: JUDICIAL | C17: 2 | D17: 0
B18: Mas 55 semanas de atraso | C18: 20883 | D18: 95193.01
B19: Total general | C19: =SUM(C14:C18) -> 27480 | D19: =SUM(D14:D18) -> 641574.84
B21: COBRANZA GENERAL EDITH
B22: Segmento | C22: Cuentas | D22: Recuperación
B23: Extrajudicial - 0 a 28 semanas de atraso | C23: 3335 | D23: 423431.78
B24: Extrajudicial - 29 a 39 semanas de atraso | C24: 1481 | D24: 52857.55
B25: Extrajudicial - 40 a 55 semanas de atraso | C25: 2153 | D25: 47342.29
B26: JUDICIAL | C26: 1 | D26: 39
B27: Mas 55 semanas de atraso | C27: 17183 | D27: 59104.97
B28: Total general | C28: =SUM(C23:C27) -> 24153 | D28: =SUM(D23:D27) -> 582775.59
B30: COBRANZA GENERAL SOFIA
B31: Segmento | C31: Cuentas | D31: Recuperación
B32: Extrajudicial - 0 a 28 semanas de atraso | C32: 220 | D32: 63589.28
B33: Extrajudicial - 29 a 39 semanas de atraso | C33: 3353 | D33: 308731.32
B34: Extrajudicial - 40 a 55 semanas de atraso | C34: 539 | D34: 93286.25
B35: Mas 55 semanas de atraso | C35: 3967 | D35: 45883.15
B36: Total general | C36: =SUM(C32:C35) -> 8079 | D36: =SUM(D32:D35) -> 511490
B38: COBRANZA GENERAL FEDERICO
B39: Segmento | C39: Cuentas | D39: Recuperación
B40: Extrajudicial - 0 a 28 semanas de atraso | C40: 586 | D40: 14601
B41: Extrajudicial - 29 a 39 semanas de atraso | C41: 861 | D41: 10946
B42: Extrajudicial - 40 a 55 semanas de atraso | C42: 797 | D42: 37081
B43: Mas 55 semanas de atraso | C43: 2435 | D43: 73326
B44: Total general | C44: =SUM(C40:C43) -> 4679 | D44: =SUM(D40:D43) -> 135954
B46: COBRANZA GENERAL FERNANDO
B47: Segmento | C47: Cuentas | D47: Recuperación
...

Sheet DATA

Sheet EPR 24 MAYO
B2: REPORTE CONSOLIDADO POR SEGMENTOS
B3: SALDO ACUMULADO SEMANA 21
B5: COORDINADOR | C5: SEGMENTO | D5: CUENTAS | E5: COBRANZA REAL | F5: CUOTA IDEAL | G5: VARIACION | H5: % VAR | I5: EPR | J5: EPR IDEAL | K5: VAR EPR
B6: Zareth | C6: Extrajudicial - 0 a 28 semanas de atraso | D6: =SUMIF('REPORTE DIARIO'!B:B,'EPR 24 MAYO'!C6, 'REPORTE DIARIO'!C:C) -> 14071 | E6: =SUMIF('REPORTE DIARIO'!B:B,'EPR 24 MAYO'!C6, 'REPORTE DIARIO'!D:D) -> 1441501.3 | F6: =J6*D6 -> 2653388.6 | G6: =+E6-F6 -> -1211887.2 | H6: =ABS(G6/F6) -> 0.45673191 | I6: =E6/D6 -> 102.44484 | J6: =(220/7)*6 -> 188.57143 | K6: =+I6-J6 -> -86.12659
B7: Gabriel | C7: Extrajudicial - 29 a 39 semanas de atraso | D7: =SUMIF('REPORTE DIARIO'!B:B,'EPR 24 MAYO'!C7, 'REPORTE DIARIO'!C:C) -> 12907 | E7: =SUMIF('REPORTE DIARIO'!B:B,'EPR 24 MAYO'!C7, 'REPORTE DIARIO'!D:D) -> 847436.8 | F7: =J7*D7 -> 1216945.7 | G7: =+E7-F7 -> -369508.91 | H7: =ABS(G7/F7) -> 0.30363632 | I7: =E7/D7 -> 65.657147 | J7: =(110/7)*6 -> 94.285714 | K7: =+I7-J7 -> -28.628567
B8: Gabriel | C8: Extrajudicial - 40 a 55 semanas de atraso | D8: =SUMIF('REPORTE DIARIO'!B:B,'EPR 24 MAYO'!C8, 'REPORTE DIARIO'!C:C) -> 11267 | E8: =SUMIF('REPORTE DIARIO'!B:B,'EPR 24 MAYO'!C8, 'REPORTE DIARIO'!D:D) -> 564398.82 | F8: =J8*D8 -> 434584.29 | G8: =+E8-F8 -> 129814.53 | H8: =ABS(G8/F8) -> 0.29870968 | I8: =E8/D8 -> 50.093088 | J8: =(45/7)*6 -> 38.571429 | K8: =+I8-J8 -> 11.521659
B9: Fernando (Naucalpan) | C9: Mas 55 semanas de atraso | D9: =SUMIF('REPORTE DIARIO'!B:B,'EPR 24 MAYO'!C9, 'REPORTE DIARIO'!C:C) -> 57312 | E9: =SUMIF('REPORTE DIARIO'!B:B,'EPR 24 MAYO'!C9, 'REPORTE DIARIO'!D:D) -> 651463.05 | F9: =J9*D9 -> 736868.57 | G9: =+E9-F9 -> -85405.521 | H9: =ABS(G9/F9) -> 0.11590333 | I9: =E9/D9 -> 11.366957 | J9: =(15/7)*6 -> 12.857143 | K9: =+I9-J9 -> -1.4901857
C10: TOTAL | D10: =SUM(D6:D9) -> 95557 | E10: =SUM(E6:E9) -> 3504800 | F10: =SUM(F6:F9) -> 5041787.1 | G10: =+E10-F10 -> -1536987.1 | H10: =ABS(G10/F10) -> 0.30484967 | I10: =E10/D10 -> 36.677585 | J10: =F10/D10 -> 52.762091 | K10: =I10-J10 -> -16.084506
B12: Nota:
B13: El saldo consolidado incluye los siguientes despachos
B14: Samantha, Samantha 2, Sofia, Edith, Fernando, Olguin y Federico
