Workbook

Sheet REPORTE DIARIO
B3: COBRANZA GENERAL SAMANTHA
B4: Segmento | C4: Cuentas | D4: Recuperación
B5: Extrajudicial - 0 a 28 semanas de atraso | C5: 4312 | D5: 111927.26
B6: Extrajudicial - 29 a 39 semanas de atraso | C6: 4555 | D6: 104051.69
B7: Extrajudicial - 40 a 55 semanas de atraso | C7: 6210 | D7: 117227
B8: JUDICIAL | C8: 10 | D8: 0
B9: Mas 55 semanas de atraso | C9: 13408 | D9: 107201.32
B10: Total general | C10: =SUM(C5:C9) -> 28495 | D10: =SUM(D5:D9) -> 440407.27
B12: COBRANZA GENERAL SAMANTHA 2
B13: Segmento | C13: Cuentas | D13: Recuperación
B14: Extrajudicial - 0 a 28 semanas de atraso | C14: 2000 | D14: 73929.23
B15: Extrajudicial - 29 a 39 semanas de atraso | C15: 1705 | D15: 65966.78
B16: Extrajudicial - 40 a 55 semanas de atraso | C16: 3071 | D16: 10775
B17: JUDICIAL | C17: 2 | D17: 0
B18: Mas 55 semanas de atraso | C18: 21626 | D18: 88351.01
B19: Total general | C19: =SUM(C14:C18) -> 28404 | D19: =SUM(D14:D18) -> 239022.02
B21: COBRANZA GENERAL EDITH
B22: Segmento | C22: Cuentas | D22: Recuperación
B23: Extrajudicial - 0 a 28 semanas de atraso | C23: 3897 | D23: 93634.26
B24: Extrajudicial - 29 a 39 semanas de atraso | C24: 2284 | D24: 49461.83
B25: Extrajudicial - 40 a 55 semanas de atraso | C25: 1825 | D25: 14345.69
B26: Mas 55 semanas de atraso | C26: 9604 | D26: 11821.04
B27: Total general | C27: =SUM(C23:C26) -> 17610 | D27: =SUM(D23:D26) -> 169262.82
B29: COBRANZA GENERAL SOFIA
B30: Segmento | C30: Cuentas | D30: Recuperación
B31: Extrajudicial - 0 a 28 semanas de atraso | C31: 323 | D31: 19756
B32: Extrajudicial - 29 a 39 semanas de atraso | C32: 1283 | D32: 12189.15
B33: Extrajudicial - 40 a 55 semanas de atraso | C33: 2376 | D33: 3455.71
B34: Mas 55 semanas de atraso | C34: 4260 | D34: 3250
B35: Total general | C35: =SUM(C31:C34) -> 8242 | D35: =SUM(D31:D34) -> 38650.86
B37: COBRANZA GENERAL FERNANDO
B38: Segmento | C38: Cuentas | D38: Recuperación
B39: Extrajudicial - 0 a 28 semanas de atraso | C39: 2043 | D39: 19863
B40: Total general | C40: =SUM(C39:C39) -> 2043 | D40: =SUM(D39:D39) -> 19863
B42: COBRANZA GENERAL FEDERICO
B43: Segmento | C43: Cuentas | D43: Recuperación
B44: Extrajudicial - 0 a 28 semanas de atraso | C44: 37 | D44: 2323
B45: Extrajudicial - 29 a 39 semanas de atraso | C45: 449 | D45: 2523
B46: Extrajudicial - 40 a 55 semanas de atraso | C46: 325 | D46: 600
B47: Mas 55 semanas de atraso | C47: 1974 | D47: 1787
...

Sheet DATA

Sheet EPR 30 ABR
B2: REPORTE CONSOLIDADO POR SEGMENTOS
B3: SALDO ACUMULADO SEMANA 18
B5: COORDINADOR | C5: SEGMENTO | D5: CUENTAS | E5: COBRANZA REAL | F5: CUOTA IDEAL | G5: VARIACION | H5: % VAR | I5: EPR | J5: EPR IDEAL | K5: VAR EPR
B6: Samatha y Zareth | C6: Extrajudicial - 0 a 28 semanas de atraso | D6: =SUMIF('REPORTE DIARIO'!B:B,'EPR 30 ABR'!C6, 'REPORTE DIARIO'!C:C) -> 12687 | E6: =SUMIF('REPORTE DIARIO'!B:B,'EPR 30 ABR'!C6, 'REPORTE DIARIO'!D:D) -> 321432.75 | F6: =J6*D6 -> 724971.43 | G6: =+E6-F6 -> -403538.68 | H6: =ABS(G6/F6) -> 0.55662701 | I6: =E6/D6 -> 25.335599 | J6: =(200/7)*2 -> 57.142857 | K6: =+I6-J6 -> -31.807258
B7: Gabriel | C7: Extrajudicial - 29 a 39 semanas de atraso | D7: =SUMIF('REPORTE DIARIO'!B:B,'EPR 30 ABR'!C7, 'REPORTE DIARIO'!C:C) -> 10549 | E7: =SUMIF('REPORTE DIARIO'!B:B,'EPR 30 ABR'!C7, 'REPORTE DIARIO'!D:D) -> 235821.45 | F7: =J7*D7 -> 331540 | G7: =+E7-F7 -> -95718.55 | H7: =ABS(G7/F7) -> 0.2887089 | I7: =E7/D7 -> 22.354863 | J7: =(110/7)*2 -> 31.428571 | K7: =+I7-J7 -> -9.0737084
B8: Gabriel | C8: Extrajudicial - 40 a 55 semanas de atraso | D8: =SUMIF('REPORTE DIARIO'!B:B,'EPR 30 ABR'!C8, 'REPORTE DIARIO'!C:C) -> 14442 | E8: =SUMIF('REPORTE DIARIO'!B:B,'EPR 30 ABR'!C8, 'REPORTE DIARIO'!D:D) -> 146403.4 | F8: =J8*D8 -> 185682.86 | G8: =+E8-F8 -> -39279.457 | H8: =ABS(G8/F8) -> 0.21154057 | I8: =E8/D8 -> 10.137336 | J8: =(45/7)*2 -> 12.857143 | K8: =+I8-J8 -> -2.7198073
B9: Fernando | C9: Mas 55 semanas de atraso | D9: =SUMIF('REPORTE DIARIO'!B:B,'EPR 30 ABR'!C9, 'REPORTE DIARIO'!C:C) -> 51745 | E9: =SUMIF('REPORTE DIARIO'!B:B,'EPR 30 ABR'!C9, 'REPORTE DIARIO'!D:D) -> 214195.37 | F9: =J9*D9 -> 221764.29 | G9: =+E9-F9 -> -7568.9157 | H9: =ABS(G9/F9) -> 0.034130454 | I9: =E9/D9 -> 4.1394409 | J9: =(15/7)*2 -> 4.2857143 | K9: =+I9-J9 -> -0.14627337
C10: TOTAL | D10: =SUM(D6:D9) -> 89423 | E10: =SUM(E6:E9) -> 917852.97 | F10: =SUM(F6:F9) -> 1463958.6 | G10: =+E10-F10 -> -546105.6 | H10: =ABS(G10/F10) -> 0.37303351 | I10: =E10/D10 -> 10.264171 | J10: =F10/D10 -> 16.371164 | K10: =I10-J10 -> -6.1069926
B12: Nota:
B13: El saldo consolidado incluye los siguientes despachos
B14: Samantha, Samantha 2, Sofia, Edith, Fernando, Olguin y Federico
