Workbook

Sheet REPORTE DIARIO
B3: COBRANZA GENERAL SAMANTHA
B4: Segmento | C4: Cuentas | D4: Recuperación
B5: Extrajudicial - 0 a 28 semanas de atraso | C5: 7267 | D5: 125036.07
B6: Extrajudicial - 29 a 39 semanas de atraso | C6: 7825 | D6: 163349.56
B7: Extrajudicial - 40 a 55 semanas de atraso | C7: 10275 | D7: 39447.45
B8: JUDICIAL | C8: 21 | D8: 0
B9: Mas 55 semanas de atraso | C9: 29569 | D9: 158399.87
B10: Total general | C10: =SUM(C5:C9) -> 54957 | D10: =SUM(D5:D9) -> 486232.95
B12: COBRANZA GENERAL SAMANTHA 2
B13: Segmento | C13: Cuentas | D13: Recuperación
B14: Extrajudicial - 0 a 28 semanas de atraso | C14: 3099 | D14: 64214.83
B15: Extrajudicial - 29 a 39 semanas de atraso | C15: 1708 | D15: 17594.01
B16: Extrajudicial - 40 a 55 semanas de atraso | C16: 3496 | D16: 8795.63
B17: JUDICIAL | C17: 2 | D17: 0
B18: Mas 55 semanas de atraso | C18: 21196 | D18: 44087.01
B19: Total general | C19: =SUM(C14:C18) -> 29501 | D19: =SUM(D14:D18) -> 134691.48
B21: COBRANZA GENERAL EDITH
B22: Segmento | C22: Cuentas | D22: Recuperación
B23: Extrajudicial - 0 a 28 semanas de atraso | C23: 1492 | D23: 45194.42
B24: Extrajudicial - 29 a 39 semanas de atraso | C24: 1413 | D24: 55142.59
B25: Extrajudicial - 40 a 55 semanas de atraso | C25: 753 | D25: 3257
B26: Mas 55 semanas de atraso | C26: 8486 | D26: 10294
B27: Total general | C27: =SUM(C23:C26) -> 12144 | D27: =SUM(D23:D26) -> 113888.01
B29: COBRANZA GENERAL SOFIA
B30: Segmento | C30: Cuentas | D30: Recuperación
B31: Extrajudicial - 0 a 28 semanas de atraso | C31: 1248 | D31: 48983.84
B32: Extrajudicial - 29 a 39 semanas de atraso | C32: 1184 | D32: 18040.73
B33: Extrajudicial - 40 a 55 semanas de atraso | C33: 2996 | D33: 1000
B34: Mas 55 semanas de atraso | C34: 1900 | D34: 652
B35: Total general | C35: =SUM(C31:C34) -> 7328 | D35: =SUM(D31:D34) -> 68676.57
B37: COBRANZA GENERAL FERNANDO
B38: Segmento | C38: Cuentas | D38: Recuperación
B39: Extrajudicial - 0 a 28 semanas de atraso | C39: 2807 | D39: 13940
B40: Total general | C40: =SUM(C39:C39) -> 2807 | D40: =SUM(D39:D39) -> 13940
B42: COBRANZA GENERAL OLGUIN
B43: Segmento | C43: Cuentas | D43: Recuperación
B44: Extrajudicial - 0 a 28 semanas de atraso | C44: 68 | D44: 2000
B45: Extrajudicial - 29 a 39 semanas de atraso | C45: 167 | D45: 0
B46: Extrajudicial - 40 a 55 semanas de atraso | C46: 34 | D46: 0
B47: Mas 55 semanas de atraso | C47: 10 | D47: 0
...

Sheet DATA

Sheet EPR 1 ABR
B2: REPORTE CONSOLIDADO POR SEGMENTOS
B3: SALDO ACUMULADO SEMANA 14
B5: COORDINADOR | C5: SEGMENTO | D5: CUENTAS | E5: COBRANZA REAL | F5: CUOTA IDEAL | G5: VARIACION | H5: % VAR | I5: EPR | J5: EPR IDEAL | K5: VAR EPR
B6: Samatha y Zareth | C6: Extrajudicial - 0 a 28 semanas de atraso | D6: =SUMIF('REPORTE DIARIO'!B:B,'EPR 1 ABR'!C6, 'REPORTE DIARIO'!C:C) -> 15981 | E6: =SUMIF('REPORTE DIARIO'!B:B,'EPR 1 ABR'!C6, 'REPORTE DIARIO'!D:D) -> 299369.16 | F6: =J6*D6 -> 913200 | G6: =+E6-F6 -> -613830.84 | H6: =ABS(G6/F6) -> 0.67217569 | I6: =E6/D6 -> 18.732818 | J6: =(200/7)*2 -> 57.142857 | K6: =+I6-J6 -> -38.410039
B7: Gabriel | C7: Extrajudicial - 29 a 39 semanas de atraso | D7: =SUMIF('REPORTE DIARIO'!B:B,'EPR 1 ABR'!C7, 'REPORTE DIARIO'!C:C) -> 12418 | E7: =SUMIF('REPORTE DIARIO'!B:B,'EPR 1 ABR'!C7, 'REPORTE DIARIO'!D:D) -> 254126.89 | F7: =J7*D7 -> 390280 | G7: =+E7-F7 -> -136153.11 | H7: =ABS(G7/F7) -> 0.34886007 | I7: =E7/D7 -> 20.464398 | J7: =(110/7)*2 -> 31.428571 | K7: =+I7-J7 -> -10.964174
B8: Gabriel | C8: Extrajudicial - 40 a 55 semanas de atraso | D8: =SUMIF('REPORTE DIARIO'!B:B,'EPR 1 ABR'!C8, 'REPORTE DIARIO'!C:C) -> 17718 | E8: =SUMIF('REPORTE DIARIO'!B:B,'EPR 1 ABR'!C8, 'REPORTE DIARIO'!D:D) -> 52500.08 | F8: =J8*D8 -> 227802.86 | G8: =+E8-F8 -> -175302.78 | H8: =ABS(G8/F8) -> 0.76953722 | I8: =E8/D8 -> 2.9630929 | J8: =(45/7)*2 -> 12.857143 | K8: =+I8-J8 -> -9.89405
B9: Fernando | C9: Mas 55 semanas de atraso | D9: =SUMIF('REPORTE DIARIO'!B:B,'EPR 1 ABR'!C9, 'REPORTE DIARIO'!C:C) -> 62258 | E9: =SUMIF('REPORTE DIARIO'!B:B,'EPR 1 ABR'!C9, 'REPORTE DIARIO'!D:D) -> 215287.88 | F9: =J9*D9 -> 266820 | G9: =+E9-F9 -> -51532.12 | H9: =ABS(G9/F9) -> 0.1931344 | I9: =E9/D9 -> 3.4579954 | J9: =(15/7)*2 -> 4.2857143 | K9: =+I9-J9 -> -0.82771885
C10: TOTAL | D10: =SUM(D6:D9) -> 108375 | E10: =SUM(E6:E9) -> 821284.01 | F10: =SUM(F6:F9) -> 1798102.9 | G10: =+E10-F10 -> -976818.85 | H10: =ABS(G10/F10) -> 0.54324971 | I10: =E10/D10 -> 7.5781685 | J10: =F10/D10 -> 16.591491 | K10: =I10-J10 -> -9.0133227
B12: Nota:
B13: El saldo consolidado incluye los siguientes despachos
B14: Samantha, Samantha 2, Sofia, Edith, Olguin, Fernando y Federico
