Workbook

Sheet REPORTE DIARIO
B3: COBRANZA GENERAL SAMANTHA
B4: Segmento | C4: Cuentas | D4: Recuperación
B5: Extrajudicial - 0 a 28 semanas de atraso | C5: 4201 | D5: 355806.45
B6: Extrajudicial - 29 a 39 semanas de atraso | C6: 4314 | D6: 123095.25
B7: Extrajudicial - 40 a 55 semanas de atraso | C7: 6057 | D7: 171421.62
B8: JUDICIAL | C8: 10 | D8: 0
B9: Mas 55 semanas de atraso | C9: 13193 | D9: 164544.58
B10: Total general | C10: =SUM(C5:C9) -> 27775 | D10: =SUM(D5:D9) -> 814867.9
B12: COBRANZA GENERAL SAMANTHA 2
B13: Segmento | C13: Cuentas | D13: Recuperación
B14: Extrajudicial - 0 a 28 semanas de atraso | C14: 1930 | D14: 128882.34
B15: Extrajudicial - 29 a 39 semanas de atraso | C15: 1797 | D15: 50175
B16: Extrajudicial - 40 a 55 semanas de atraso | C16: 3080 | D16: 85526
B17: JUDICIAL | C17: 2 | D17: 0
B18: Mas 55 semanas de atraso | C18: 20751 | D18: 103850.42
B19: Total general | C19: =SUM(C14:C18) -> 27560 | D19: =SUM(D14:D18) -> 368433.76
B21: COBRANZA GENERAL EDITH
B22: Segmento | C22: Cuentas | D22: Recuperación
B23: Extrajudicial - 0 a 28 semanas de atraso | C23: 3665 | D23: 188534.38
B24: Extrajudicial - 29 a 39 semanas de atraso | C24: 1963 | D24: 31341.65
B25: Extrajudicial - 40 a 55 semanas de atraso | C25: 2221 | D25: 18912.48
B26: Mas 55 semanas de atraso | C26: 9734 | D26: 98036.8
B27: Total general | C27: =SUM(C23:C26) -> 17583 | D27: =SUM(D23:D26) -> 336825.31
B29: COBRANZA GENERAL SOFIA
B30: Segmento | C30: Cuentas | D30: Recuperación
B31: Extrajudicial - 0 a 28 semanas de atraso | C31: 293 | D31: 41181.55
B32: Extrajudicial - 29 a 39 semanas de atraso | C32: 1534 | D32: 46101.73
B33: Extrajudicial - 40 a 55 semanas de atraso | C33: 2304 | D33: 8731.78
B34: Mas 55 semanas de atraso | C34: 4229 | D34: 2157
B35: Total general | C35: =SUM(C31:C34) -> 8360 | D35: =SUM(D31:D34) -> 98172.06
B37: COBRANZA GENERAL OLGUIN
B38: Segmento | C38: Cuentas | D38: Recuperación
B39: Extrajudicial - 0 a 28 semanas de atraso | C39: 150 | D39: 14872
B40: Extrajudicial - 29 a 39 semanas de atraso | C40: 444 | D40: 76054
B41: Extrajudicial - 40 a 55 semanas de atraso | C41: 773 | D41: 1589
B42: Mas 55 semanas de atraso | C42: 1014 | D42: 3261
B43: Total general | C43: =SUM(C39:C42) -> 2381 | D43: =SUM(D39:D42) -> 95776
B45: COBRANZA GENERAL FEDERICO
B46: Segmento | C46: Cuentas | D46: Recuperación
B47: Extrajudicial - 0 a 28 semanas de atraso | C47: 110 | D47: 2323
...

Sheet DATA

Sheet EPR 08 MAYO
B2: REPORTE CONSOLIDADO POR SEGMENTOS
B3: SALDO ACUMULADO SEMANA 19
B5: COORDINADOR | C5: SEGMENTO | D5: CUENTAS | E5: COBRANZA REAL | F5: CUOTA IDEAL | G5: VARIACION | H5: % VAR | I5: EPR | J5: EPR IDEAL | K5: VAR EPR
B6: Zareth | C6: Extrajudicial - 0 a 28 semanas de atraso | D6: =SUMIF('REPORTE DIARIO'!B:B,'EPR 08 MAYO'!C6, 'REPORTE DIARIO'!C:C) -> 12361 | E6: =SUMIF('REPORTE DIARIO'!B:B,'EPR 08 MAYO'!C6, 'REPORTE DIARIO'!D:D) -> 755042.72 | F6: =J6*D6 -> 1553954.3 | G6: =+E6-F6 -> -798911.57 | H6: =ABS(G6/F6) -> 0.51411523 | I6: =E6/D6 -> 61.082657 | J6: =(220/7)*4 -> 125.71429 | K6: =+I6-J6 -> -64.631629
B7: Gabriel | C7: Extrajudicial - 29 a 39 semanas de atraso | D7: =SUMIF('REPORTE DIARIO'!B:B,'EPR 08 MAYO'!C7, 'REPORTE DIARIO'!C:C) -> 10670 | E7: =SUMIF('REPORTE DIARIO'!B:B,'EPR 08 MAYO'!C7, 'REPORTE DIARIO'!D:D) -> 329190.63 | F7: =J7*D7 -> 670685.71 | G7: =+E7-F7 -> -341495.08 | H7: =ABS(G7/F7) -> 0.50917304 | I7: =E7/D7 -> 30.85198 | J7: =(110/7)*4 -> 62.857143 | K7: =+I7-J7 -> -32.005163
B8: Gabriel | C8: Extrajudicial - 40 a 55 semanas de atraso | D8: =SUMIF('REPORTE DIARIO'!B:B,'EPR 08 MAYO'!C8, 'REPORTE DIARIO'!C:C) -> 14897 | E8: =SUMIF('REPORTE DIARIO'!B:B,'EPR 08 MAYO'!C8, 'REPORTE DIARIO'!D:D) -> 287500.88 | F8: =J8*D8 -> 383065.71 | G8: =+E8-F8 -> -95564.834 | H8: =ABS(G8/F8) -> 0.24947373 | I8: =E8/D8 -> 19.299247 | J8: =(45/7)*4 -> 25.714286 | K8: =+I8-J8 -> -6.4150389
B9: Fernando (Naucalpan) | C9: Mas 55 semanas de atraso | D9: =SUMIF('REPORTE DIARIO'!B:B,'EPR 08 MAYO'!C9, 'REPORTE DIARIO'!C:C) -> 51027 | E9: =SUMIF('REPORTE DIARIO'!B:B,'EPR 08 MAYO'!C9, 'REPORTE DIARIO'!D:D) -> 396081.8 | F9: =J9*D9 -> 437374.29 | G9: =+E9-F9 -> -41292.486 | H9: =ABS(G9/F9) -> 0.094409953 | I9: =E9/D9 -> 7.7622004 | J9: =(15/7)*4 -> 8.5714286 | K9: =+I9-J9 -> -0.80922817
C10: TOTAL | D10: =SUM(D6:D9) -> 88955 | E10: =SUM(E6:E9) -> 1767816 | F10: =SUM(F6:F9) -> 3045080 | G10: =+E10-F10 -> -1277264 | H10: =ABS(G10/F10) -> 0.4194517 | I10: =E10/D10 -> 19.87315 | J10: =F10/D10 -> 34.23169 | K10: =I10-J10 -> -14.35854
B12: Nota:
B13: El saldo consolidado incluye los siguientes despachos
B14: Samantha, Samantha 2, Sofia, Edith, Fernando, Olguin y Federico
