Workbook

Sheet REPORTE DIARIO
B3: COBRANZA GENERAL SAMANTHA
B4: Segmento | C4: Cuentas | D4: Recuperación
B5: Extrajudicial - 0 a 28 semanas de atraso | C5: 6568 | D5: 311088.08
B6: Extrajudicial - 29 a 39 semanas de atraso | C6: 5381 | D6: 301181.89
B7: Extrajudicial - 40 a 55 semanas de atraso | C7: 7275 | D7: 158866.31
B8: JUDICIAL | C8: 21 | D8: 0
B9: Mas 55 semanas de atraso | C9: 21087 | D9: 253767.65
B10: Total general | C10: =SUM(C5:C9) -> 40332 | D10: =SUM(D5:D9) -> 1024903.9
B12: COBRANZA GENERAL EDITH
B13: Segmento | C13: Cuentas | D13: Recuperación
B14: Extrajudicial - 0 a 28 semanas de atraso | C14: 2053 | D14: 240613.21
B15: Extrajudicial - 29 a 39 semanas de atraso | C15: 2168 | D15: 161971.42
B16: Extrajudicial - 40 a 55 semanas de atraso | C16: 944 | D16: 25034.92
B17: Mas 55 semanas de atraso | C17: 9105 | D17: 31237.25
B18: Total general | C18: =SUM(C14:C17) -> 14270 | D18: =SUM(D14:D17) -> 458856.8
B20: COBRANZA GENERAL SAMANTHA 2
B21: Segmento | C21: Cuentas | D21: Recuperación
B22: Extrajudicial - 0 a 28 semanas de atraso | C22: 2407 | D22: 190531.61
B23: Extrajudicial - 29 a 39 semanas de atraso | C23: 1513 | D23: 51406.05
B24: Extrajudicial - 40 a 55 semanas de atraso | C24: 3294 | D24: 24323
B25: JUDICIAL | C25: 2 | D25: 0
B26: Mas 55 semanas de atraso | C26: 21318 | D26: 81225.61
B27: Total general | C27: =SUM(C22:C26) -> 28534 | D27: =SUM(D22:D26) -> 347486.27
B29: COBRANZA GENERAL SOFIA
B30: Segmento | C30: Cuentas | D30: Recuperación
B31: Extrajudicial - 0 a 28 semanas de atraso | C31: 1354 | D31: 104255.66
B32: Extrajudicial - 29 a 39 semanas de atraso | C32: 1940 | D32: 64239.69
B33: Extrajudicial - 40 a 55 semanas de atraso | C33: 2423 | D33: 2876
B34: Mas 55 semanas de atraso | C34: 4264 | D34: 4507.29
B35: Total general | C35: =SUM(C31:C34) -> 9981 | D35: =SUM(D31:D34) -> 175878.64
B37: COBRANZA GENERAL FERNANDO
B38: Segmento | C38: Cuentas | D38: Recuperación
B39: Extrajudicial - 0 a 28 semanas de atraso | C39: 1332 | D39: 50214.63
B40: Total general | C40: =SUM(C39:C39) -> 1332 | D40: =SUM(D39:D39) -> 50214.63
B42: COBRANZA GENERAL FEDERICO
B43: Segmento | C43: Cuentas | D43: Recuperación
B44: Extrajudicial - 0 a 28 semanas de atraso | C44: 39 | D44: 2323
B45: Extrajudicial - 29 a 39 semanas de atraso | C45: 318 | D45: 13700
B46: Extrajudicial - 40 a 55 semanas de atraso | C46: 255 | D46: 546
B47: Mas 55 semanas de atraso | C47: 1930 | D47: 11004
...

Sheet DATA

Sheet EPR 18 ABR
L1: =TODAY() -> 45765
B2: REPORTE CONSOLIDADO POR SEGMENTOS | L2: =WEEKDAY(L1,2) -> 5
B3: SALDO ACUMULADO SEMANA 16
B5: COORDINADOR | C5: SEGMENTO | D5: CUENTAS | E5: COBRANZA REAL | F5: CUOTA IDEAL | G5: VARIACION | H5: % VAR | I5: EPR | J5: EPR IDEAL | K5: VAR EPR
B6: Samatha y Zareth | C6: Extrajudicial - 0 a 28 semanas de atraso | D6: =SUMIF('REPORTE DIARIO'!B:B,'EPR 18 ABR'!C6, 'REPORTE DIARIO'!C:C) -> 13753 | E6: =SUMIF('REPORTE DIARIO'!B:B,'EPR 18 ABR'!C6, 'REPORTE DIARIO'!D:D) -> 899026.19 | F6: =J6*D6 -> 1964714.3 | G6: =+E6-F6 -> -1065688.1 | H6: =ABS(G6/F6) -> 0.54241378 | I6: =E6/D6 -> 65.36946 | J6: =(200/7)*L2 -> 142.85714 | K6: =+I6-J6 -> -77.487682
B7: Gabriel | C7: Extrajudicial - 29 a 39 semanas de atraso | D7: =SUMIF('REPORTE DIARIO'!B:B,'EPR 18 ABR'!C7, 'REPORTE DIARIO'!C:C) -> 11320 | E7: =SUMIF('REPORTE DIARIO'!B:B,'EPR 18 ABR'!C7, 'REPORTE DIARIO'!D:D) -> 592499.05 | F7: =J7*D7 -> 889428.57 | G7: =+E7-F7 -> -296929.52 | H7: =ABS(G7/F7) -> 0.33384302 | I7: =E7/D7 -> 52.340905 | J7: =(110/7)*L2 -> 78.571429 | K7: =+I7-J7 -> -26.230523
B8: Gabriel | C8: Extrajudicial - 40 a 55 semanas de atraso | D8: =SUMIF('REPORTE DIARIO'!B:B,'EPR 18 ABR'!C8, 'REPORTE DIARIO'!C:C) -> 14191 | E8: =SUMIF('REPORTE DIARIO'!B:B,'EPR 18 ABR'!C8, 'REPORTE DIARIO'!D:D) -> 211646.23 | F8: =J8*D8 -> 456139.29 | G8: =+E8-F8 -> -244493.06 | H8: =ABS(G8/F8) -> 0.53600526 | I8: =E8/D8 -> 14.914117 | J8: =(45/7)*L2 -> 32.142857 | K8: =+I8-J8 -> -17.22874
B9: Fernando | C9: Mas 55 semanas de atraso | D9: =SUMIF('REPORTE DIARIO'!B:B,'EPR 18 ABR'!C9, 'REPORTE DIARIO'!C:C) -> 57704 | E9: =SUMIF('REPORTE DIARIO'!B:B,'EPR 18 ABR'!C9, 'REPORTE DIARIO'!D:D) -> 381741.8 | F9: =J9*D9 -> 618257.14 | G9: =+E9-F9 -> -236515.34 | H9: =ABS(G9/F9) -> 0.38255174 | I9: =E9/D9 -> 6.6155171 | J9: =(15/7)*L2 -> 10.714286 | K9: =+I9-J9 -> -4.0987686
C10: TOTAL | D10: =SUM(D6:D9) -> 96968 | E10: =SUM(E6:E9) -> 2084913.3 | F10: =SUM(F6:F9) -> 3928539.3 | G10: =+E10-F10 -> -1843626 | H10: =ABS(G10/F10) -> 0.46929046 | I10: =E10/D10 -> 21.501044 | J10: =F10/D10 -> 40.51377 | K10: =I10-J10 -> -19.012726
B12: Nota:
B13: El saldo consolidado incluye los siguientes despachos
B14: Samantha, Samantha 2, Sofia, Edith, Fernando y Federico
