Workbook

Sheet REPORTE DIARIO
B3: COBRANZA GENERAL SAMANTHA
B4: Segmento | C4: Cuentas | D4: Recuperación
B5: Extrajudicial - 0 a 28 semanas de atraso | C5: 1 | D5: 199627.32
B6: Extrajudicial - 29 a 39 semanas de atraso | C6: 8979 | D6: 1114029.1
B7: Extrajudicial - 40 a 55 semanas de atraso | C7: 7284 | D7: 412663.55
B8: JUDICIAL | C8: 1244 | D8: 1000
B9: Mas 55 semanas de atraso | C9: 33618 | D9: 544592.38
B10: Total general | C10: =SUM(C5:C9) -> 51126 | D10: =SUM(D5:D9) -> 2271912.3
B12: COBRANZA GENERAL EDITH
B13: Segmento | C13: Cuentas | D13: Recuperación
B14: Extrajudicial - 0 a 28 semanas de atraso | C14: 9 | D14: 71486.23
B15: Extrajudicial - 29 a 39 semanas de atraso | C15: 2882 | D15: 350357.52
B16: Extrajudicial - 40 a 55 semanas de atraso | C16: 788 | D16: 85747.8
B17: JUDICIAL | C17: 1 | D17: 39
B18: Mas 55 semanas de atraso | C18: 12551 | D18: 110080.31
B19: Total general | C19: =SUM(C14:C18) -> 16231 | D19: =SUM(D14:D18) -> 617710.86
B21: COBRANZA GENERAL ANDREA
B22: Segmento | C22: Cuentas | D22: Recuperación
B23: Extrajudicial - 0 a 28 semanas de atraso | C23: 0 | D23: 9186
B24: Extrajudicial - 29 a 39 semanas de atraso | C24: 2591 | D24: 207677.03
B25: Extrajudicial - 40 a 55 semanas de atraso | C25: 3486 | D25: 128712.2
B26: JUDICIAL | C26: 0 | D26: 0
B27: Mas 55 semanas de atraso | C27: 18217 | D27: 222786
B28: Total general | C28: =SUM(C23:C27) -> 24294 | D28: =SUM(D23:D27) -> 568361.23
B30: COBRANZA GENERAL SOFIA
B31: Segmento | C31: Cuentas | D31: Recuperación
B32: Extrajudicial - 0 a 28 semanas de atraso | C32: 1 | D32: 16598.01
B33: Extrajudicial - 29 a 39 semanas de atraso | C33: 1307 | D33: 179545.97
B34: Extrajudicial - 40 a 55 semanas de atraso | C34: 895 | D34: 59521.7
B35: Mas 55 semanas de atraso | C35: 1970 | D35: 24774.32
B36: Total general | C36: =SUM(C32:C35) -> 4173 | D36: =SUM(D32:D35) -> 280440
B38: COBRANZA GENERAL OLGUIN
B39: Segmento | C39: Cuentas | D39: Recuperación
B40: Extrajudicial - 0 a 28 semanas de atraso | C40: 364 | D40: 7907.1
B41: Extrajudicial - 29 a 39 semanas de atraso | C41: 2159 | D41: 88446.86
B42: Extrajudicial - 40 a 55 semanas de atraso | C42: 1377 | D42: 67140.87
B43: Mas 55 semanas de atraso | C43: 368 | D43: 6445
B44: Total general | C44: =SUM(C40:C43) -> 4268 | D44: =SUM(D40:D43) -> 169939.83
B46: COBRANZA GENERAL FEDERICO
B47: Segmento | C47: Cuentas | D47: Recuperación
...

Sheet CDC-OLGUIN
B1: ETIQUETA PROYECTO CDC
B3: COBRANZA GENERAL CDC 100
B4: Segmento | C4: Cuentas | D4: Recuperación
B5: Extrajudicial - 0 a 28 semanas de atraso | C5: 6 | D5: 76668
B6: Extrajudicial - 29 a 39 semanas de atraso | C6: 15538 | D6: 413095.22
B7: Extrajudicial - 40 a 55 semanas de atraso | C7: 9359 | D7: 31342
B8: JUDICIAL | C8: 2739 | D8: 1000
B9: Mas 55 semanas de atraso | C9: 61792 | D9: 26423.52
B10: Total general | C10: =SUM(C5:C9) -> 89434 | D10: =SUM(D5:D9) -> 548528.74
B12: COBRANZA GENERAL OLGUIN
B13: Segmento | C13: Cuentas | D13: Recuperación
B14: Extrajudicial - 0 a 28 semanas de atraso | C14: 167 | D14: 7214
B15: Extrajudicial - 29 a 39 semanas de atraso | C15: 2140 | D15: 88446.86
B16: Extrajudicial - 40 a 55 semanas de atraso | C16: 1225 | D16: 66040.87
B17: Mas 55 semanas de atraso | C17: 367 | D17: 6445
B18: Total general | C18: =SUM(C14:C17) -> 3899 | D18: =SUM(D14:D17) -> 168146.73
B20: COBRANZA GENERAL FERNANDO
B21: Segmento | C21: Cuentas | D21: Recuperación
B22: Extrajudicial - 0 a 28 semanas de atraso | C22: 164 | D22: 13227
B23: Extrajudicial - 29 a 39 semanas de atraso | C23: 652 | D23: 15179.83
B24: Extrajudicial - 40 a 55 semanas de atraso | C24: 223 | D24: 0
B25: Total general | C25: =SUM(C22:C24) -> 1039 | D25: =SUM(D22:D24) -> 28406.83
B27: COBRANZA GENERAL SAMANTHA
B28: Segmento | C28: Cuentas | D28: Recuperación
B29: Extrajudicial - 0 a 28 semanas de atraso | C29: 0 | D29: 744
B30: Extrajudicial - 29 a 39 semanas de atraso | C30: 20 | D30: 5981
B31: Extrajudicial - 40 a 55 semanas de atraso | C31: 78 | D31: 3007
B32: JUDICIAL | C32: 1 | D32: 0
B33: Mas 55 semanas de atraso | C33: 304 | D33: 11697.04
B34: Total general | C34: =SUM(C29:C33) -> 403 | D34: =SUM(D29:D33) -> 21429.04
B36: COBRANZA GENERAL ANDREA
B37: Segmento | C37: Cuentas | D37: Recuperación
B38: Extrajudicial - 0 a 28 semanas de atraso | C38: 0 | D38: 0
B39: Extrajudicial - 29 a 39 semanas de atraso | C39: 6 | D39: 2290
B40: Extrajudicial - 40 a 55 semanas de atraso | C40: 44 | D40: 0
B41: JUDICIAL | C41: 0 | D41: 0
B42: Mas 55 semanas de atraso | C42: 333 | D42: 12275
B43: Total general | C43: =SUM(C38:C42) -> 383 | D43: =SUM(D38:D42) -> 14565
B45: COBRANZA GENERAL EDITH
B46: Segmento | C46: Cuentas | D46: Recuperación
...

Sheet COBRANZA CDC
B1: ETIQUETA PROYECTO CDC
B2: Segmento | C2: Cuentas | D2: Recuperación
B3: Extrajudicial - 0 a 28 semanas de atraso | C3: =SUMIF('CDC-OLGUIN'!B:B, "Extrajudicial - 0 a 28 semanas de atraso", 'CDC-OLGUIN'!C:C) -> 338 | D3: 98228.82
B4: Extrajudicial - 29 a 39 semanas de atraso | C4: =SUMIF('CDC-OLGUIN'!B:B, "Extrajudicial - 29 a 39 semanas de atraso", 'CDC-OLGUIN'!C:C) -> 18365 | D4: 525524.91
B5: Extrajudicial - 40 a 55 semanas de atraso | C5: =SUMIF('CDC-OLGUIN'!B:B, "Extrajudicial - 40 a 55 semanas de atraso", 'CDC-OLGUIN'!C:C) -> 10957 | D5: 103287.87
B6: JUDICIAL | C6: =SUMIF('CDC-OLGUIN'!B:B, "JUDICIAL", 'CDC-OLGUIN'!C:C) -> 2740 | D6: 1000
B7: Mas 55 semanas de atraso | C7: =SUMIF('CDC-OLGUIN'!B:B, "Mas 55 semanas de atraso", 'CDC-OLGUIN'!C:C) -> 63089 | D7: 59383.56
B8: Total general | C8: =SUM(C3:C7) -> 95489 | D8: =SUM(D3:D7) -> 787425.16

Sheet EPR 26 JUN
B2: REPORTE CONSOLIDADO POR SEGMENTOS
B3: SALDO ACUMULADO SEMANA 26
B5: COORDINADOR | C5: SEGMENTO | D5: CUENTAS | E5: COBRANZA REAL | F5: CUOTA IDEAL | G5: VARIACION | H5: % VAR | I5: EPR | J5: EPR IDEAL | K5: VAR EPR
B6: Zareth | C6: Extrajudicial - 0 a 28 semanas de atraso | D6: =SUMIF('REPORTE DIARIO'!B:B,'EPR 26 JUN'!C6, 'REPORTE DIARIO'!C:C) -> 732 | E6: =SUMIF('REPORTE DIARIO'!B:B,'EPR 26 JUN'!C6, 'REPORTE DIARIO'!D:D) -> 340367.66 | F6: =J6*D6 -> 46011.429 | G6: =+E6-F6 -> 294356.23 | H6: =ABS(G6/F6) -> 6.3974591 | I6: =E6/D6 -> 464.98314 | J6: =(220/7)*2 -> 62.857143 | K6: =+I6-J6 -> 402.126
B7: Gabriel | C7: Extrajudicial - 29 a 39 semanas de atraso | D7: =SUMIF('REPORTE DIARIO'!B:B,'EPR 26 JUN'!C7, 'REPORTE DIARIO'!C:C) -> 22677 | E7: =SUMIF('REPORTE DIARIO'!B:B,'EPR 26 JUN'!C7, 'REPORTE DIARIO'!D:D) -> 2112064.8 | F7: =J7*D7 -> 712705.71 | G7: =+E7-F7 -> 1399359.1 | H7: =ABS(G7/F7) -> 1.9634459 | I7: =E7/D7 -> 93.136872 | J7: =(110/7)*2 -> 31.428571 | K7: =+I7-J7 -> 61.7083
B8: Gabriel | C8: Extrajudicial - 40 a 55 semanas de atraso | D8: =SUMIF('REPORTE DIARIO'!B:B,'EPR 26 JUN'!C8, 'REPORTE DIARIO'!C:C) -> 14723 | E8: =SUMIF('REPORTE DIARIO'!B:B,'EPR 26 JUN'!C8, 'REPORTE DIARIO'!D:D) -> 762671.12 | F8: =J8*D8 -> 189295.71 | G8: =+E8-F8 -> 573375.41 | H8: =ABS(G8/F8) -> 3.0289931 | I8: =E8/D8 -> 51.801339 | J8: =(45/7)*2 -> 12.857143 | K8: =+I8-J8 -> 38.944197
B9: Fernando (Naucalpan) | C9: Mas 55 semanas de atraso | D9: =SUMIF('REPORTE DIARIO'!B:B,'EPR 26 JUN'!C9, 'REPORTE DIARIO'!C:C) -> 69020 | E9: =SUMIF('REPORTE DIARIO'!B:B,'EPR 26 JUN'!C9, 'REPORTE DIARIO'!D:D) -> 922521.01 | F9: =J9*D9 -> 295800 | G9: =+E9-F9 -> 626721.01 | H9: =ABS(G9/F9) -> 2.1187323 | I9: =E9/D9 -> 13.365996 | J9: =(15/7)*2 -> 4.2857143 | K9: =+I9-J9 -> 9.0802812
C10: TOTAL | D10: =SUM(D6:D9) -> 107152 | E10: =SUM(E6:E9) -> 4137624.6 | F10: =SUM(F6:F9) -> 1243812.9 | G10: =+E10-F10 -> 2893811.8 | H10: =ABS(G10/F10) -> 2.3265653 | I10: =E10/D10 -> 38.614535 | J10: =F10/D10 -> 11.607929 | K10: =I10-J10 -> 27.006605
B12: Nota:
B13: El saldo consolidado incluye los siguientes despachos
B14: Samantha, Samantha 2, Sofia, Edith, Fernando, Olguin y Federico
