Workbook

Sheet REPORTE DIARIO
B3: COBRANZA GENERAL SAMANTHA
B4: Segmento | C4: Cuentas | D4: Recuperación
B5: Extrajudicial - 0 a 28 semanas de atraso | C5: 2808 | D5: 321600.6
B6: Extrajudicial - 29 a 39 semanas de atraso | C6: 3066 | D6: 326650.9
B7: Extrajudicial - 40 a 55 semanas de atraso | C7: 5633 | D7: 207585.51
B8: JUDICIAL | C8: 11 | D8: 500
B9: Mas 55 semanas de atraso | C9: 11844 | D9: 315821.85
B10: Total general | C10: =SUM(C5:C9) -> 23362 | D10: =SUM(D5:D9) -> 1172158.9
B12: COBRANZA GENERAL SAMANTHA 2
B13: Segmento | C13: Cuentas | D13: Recuperación
B14: Extrajudicial - 0 a 28 semanas de atraso | C14: 2906 | D14: 253181.1
B15: Extrajudicial - 29 a 39 semanas de atraso | C15: 2081 | D15: 93860.94
B16: Extrajudicial - 40 a 55 semanas de atraso | C16: 2796 | D16: 135483.17
B17: JUDICIAL | C17: 2 | D17: 0
B18: Mas 55 semanas de atraso | C18: 17925 | D18: 92413.17
B19: Total general | C19: =SUM(C14:C18) -> 25710 | D19: =SUM(D14:D18) -> 574938.38
B21: COBRANZA GENERAL EDITH
B22: Segmento | C22: Cuentas | D22: Recuperación
B23: Extrajudicial - 0 a 28 semanas de atraso | C23: 3805 | D23: 288010.48
B24: Extrajudicial - 29 a 39 semanas de atraso | C24: 977 | D24: 47436.11
B25: Extrajudicial - 40 a 55 semanas de atraso | C25: 2119 | D25: 32169.45
B26: JUDICIAL | C26: 1 | D26: 39
B27: Mas 55 semanas de atraso | C27: 16874 | D27: 36753.12
B28: Total general | C28: =SUM(C23:C27) -> 23776 | D28: =SUM(D23:D27) -> 404408.16
B30: COBRANZA GENERAL SOFIA
B31: Segmento | C31: Cuentas | D31: Recuperación
B32: Extrajudicial - 0 a 28 semanas de atraso | C32: 50 | D32: 23550.5
B33: Extrajudicial - 29 a 39 semanas de atraso | C33: 3273 | D33: 181052.34
B34: Extrajudicial - 40 a 55 semanas de atraso | C34: 285 | D34: 18766
B35: Mas 55 semanas de atraso | C35: 3953 | D35: 4190
B36: Total general | C36: =SUM(C32:C35) -> 7561 | D36: =SUM(D32:D35) -> 227558.84
B38: COBRANZA GENERAL OLGUIN
B39: Segmento | C39: Cuentas | D39: Recuperación
B40: Extrajudicial - 0 a 28 semanas de atraso | C40: 2245 | D40: 57501.9
B41: Extrajudicial - 29 a 39 semanas de atraso | C41: 1381 | D41: 8113
B42: Extrajudicial - 40 a 55 semanas de atraso | C42: 2249 | D42: 4056
B43: Mas 55 semanas de atraso | C43: 2230 | D43: 57779.21
B44: Total general | C44: =SUM(C40:C43) -> 8105 | D44: =SUM(D40:D43) -> 127450.11
B46: COBRANZA GENERAL FEDERICO
B47: Segmento | C47: Cuentas | D47: Recuperación
...

Sheet DATA

Sheet EPR 06 JUN
B2: REPORTE CONSOLIDADO POR SEGMENTOS
B3: SALDO ACUMULADO SEMANA 23
B5: COORDINADOR | C5: SEGMENTO | D5: CUENTAS | E5: COBRANZA REAL | F5: CUOTA IDEAL | G5: VARIACION | H5: % VAR | I5: EPR | J5: EPR IDEAL | K5: VAR EPR
B6: Zareth | C6: Extrajudicial - 0 a 28 semanas de atraso | D6: =SUMIF('REPORTE DIARIO'!B:B,'EPR 06 JUN'!C6, 'REPORTE DIARIO'!C:C) -> 15222 | E6: =SUMIF('REPORTE DIARIO'!B:B,'EPR 06 JUN'!C6, 'REPORTE DIARIO'!D:D) -> 1085286.5 | F6: =J6*D6 -> 2392028.6 | G6: =+E6-F6 -> -1306742.1 | H6: =ABS(G6/F6) -> 0.54629032 | I6: =E6/D6 -> 71.297235 | J6: =(220/7)*5 -> 157.14286 | K6: =+I6-J6 -> -85.845622
B7: Gabriel | C7: Extrajudicial - 29 a 39 semanas de atraso | D7: =SUMIF('REPORTE DIARIO'!B:B,'EPR 06 JUN'!C7, 'REPORTE DIARIO'!C:C) -> 11406 | E7: =SUMIF('REPORTE DIARIO'!B:B,'EPR 06 JUN'!C7, 'REPORTE DIARIO'!D:D) -> 664876.29 | F7: =J7*D7 -> 896185.71 | G7: =+E7-F7 -> -231309.42 | H7: =ABS(G7/F7) -> 0.25810434 | I7: =E7/D7 -> 58.291802 | J7: =(110/7)*5 -> 78.571429 | K7: =+I7-J7 -> -20.279627
B8: Gabriel | C8: Extrajudicial - 40 a 55 semanas de atraso | D8: =SUMIF('REPORTE DIARIO'!B:B,'EPR 06 JUN'!C8, 'REPORTE DIARIO'!C:C) -> 13887 | E8: =SUMIF('REPORTE DIARIO'!B:B,'EPR 06 JUN'!C8, 'REPORTE DIARIO'!D:D) -> 400012.13 | F8: =J8*D8 -> 446367.86 | G8: =+E8-F8 -> -46355.727 | H8: =ABS(G8/F8) -> 0.10385095 | I8: =E8/D8 -> 28.804791 | J8: =(45/7)*5 -> 32.142857 | K8: =+I8-J8 -> -3.3380663
B9: Fernando (Naucalpan) | C9: Mas 55 semanas de atraso | D9: =SUMIF('REPORTE DIARIO'!B:B,'EPR 06 JUN'!C9, 'REPORTE DIARIO'!C:C) -> 55295 | E9: =SUMIF('REPORTE DIARIO'!B:B,'EPR 06 JUN'!C9, 'REPORTE DIARIO'!D:D) -> 515575.35 | F9: =J9*D9 -> 592446.43 | G9: =+E9-F9 -> -76871.079 | H9: =ABS(G9/F9) -> 0.12975195 | I9: =E9/D9 -> 9.3240863 | J9: =(15/7)*5 -> 10.714286 | K9: =+I9-J9 -> -1.3901994
C10: TOTAL | D10: =SUM(D6:D9) -> 95810 | E10: =SUM(E6:E9) -> 2665750.3 | F10: =SUM(F6:F9) -> 4327028.6 | G10: =+E10-F10 -> -1661278.3 | H10: =ABS(G10/F10) -> 0.38393051 | I10: =E10/D10 -> 27.823299 | J10: =F10/D10 -> 45.162599 | K10: =I10-J10 -> -17.3393
B12: Nota:
B13: El saldo consolidado incluye los siguientes despachos
B14: Samantha, Samantha 2, Sofia, Edith, Fernando, Olguin y Federico
