Workbook

Sheet REPORTE DIARIO
B3: COBRANZA GENERAL SAMANTHA
B4: Segmento | C4: Cuentas | D4: Recuperación
B5: Extrajudicial - 0 a 28 semanas de atraso | C5: 4119 | D5: 469644.65
B6: Extrajudicial - 29 a 39 semanas de atraso | C6: 4353 | D6: 302218.43
B7: Extrajudicial - 40 a 55 semanas de atraso | C7: 4098 | D7: 304133.6
B8: JUDICIAL | C8: 12 | D8: 803.56
B9: Mas 55 semanas de atraso | C9: 10666 | D9: 415912.32
B10: Total general | C10: =SUM(C5:C9) -> 23248 | D10: =SUM(D5:D9) -> 1492712.6
B12: COBRANZA GENERAL EDITH
B13: Segmento | C13: Cuentas | D13: Recuperación
B14: Extrajudicial - 0 a 28 semanas de atraso | C14: 3386 | D14: 297899.13
B15: Extrajudicial - 29 a 39 semanas de atraso | C15: 1508 | D15: 99075.05
B16: Extrajudicial - 40 a 55 semanas de atraso | C16: 2213 | D16: 66759.76
B17: JUDICIAL | C17: 1 | D17: 39
B18: Mas 55 semanas de atraso | C18: 17193 | D18: 64428.63
B19: Total general | C19: =SUM(C14:C18) -> 24301 | D19: =SUM(D14:D18) -> 528201.57
B21: COBRANZA GENERAL SAMANTHA 2
B22: Segmento | C22: Cuentas | D22: Recuperación
B23: Extrajudicial - 0 a 28 semanas de atraso | C23: 1910 | D23: 156424
B24: Extrajudicial - 29 a 39 semanas de atraso | C24: 1988 | D24: 79756.89
B25: Extrajudicial - 40 a 55 semanas de atraso | C25: 2035 | D25: 55668
B26: JUDICIAL | C26: 2 | D26: 0
B27: Mas 55 semanas de atraso | C27: 20634 | D27: 192876.08
B28: Total general | C28: =SUM(C23:C27) -> 26569 | D28: =SUM(D23:D27) -> 484724.97
B30: COBRANZA GENERAL SOFIA
B31: Segmento | C31: Cuentas | D31: Recuperación
B32: Extrajudicial - 0 a 28 semanas de atraso | C32: 246 | D32: 87620.09
B33: Extrajudicial - 29 a 39 semanas de atraso | C33: 2831 | D33: 228359.89
B34: Extrajudicial - 40 a 55 semanas de atraso | C34: 1282 | D34: 27032.33
B35: Mas 55 semanas de atraso | C35: 3941 | D35: 6875
B36: Total general | C36: =SUM(C32:C35) -> 8300 | D36: =SUM(D32:D35) -> 349887.31
B38: COBRANZA GENERAL OLGUIN
B39: Segmento | C39: Cuentas | D39: Recuperación
B40: Extrajudicial - 0 a 28 semanas de atraso | C40: 417 | D40: 3687
B41: Extrajudicial - 29 a 39 semanas de atraso | C41: 597 | D41: 3889
B42: Extrajudicial - 40 a 55 semanas de atraso | C42: 1031 | D42: 50144
B43: Mas 55 semanas de atraso | C43: 1174 | D43: 3937
B44: Total general | C44: =SUM(C40:C43) -> 3219 | D44: =SUM(D40:D43) -> 61657
B46: COBRANZA GENERAL FERNANDO
B47: Segmento | C47: Cuentas | D47: Recuperación
...

Sheet DATA

Sheet EPR 17 MAYO
B2: REPORTE CONSOLIDADO POR SEGMENTOS
B3: SALDO ACUMULADO SEMANA 20
B5: COORDINADOR | C5: SEGMENTO | D5: CUENTAS | E5: COBRANZA REAL | F5: CUOTA IDEAL | G5: VARIACION | H5: % VAR | I5: EPR | J5: EPR IDEAL | K5: VAR EPR
B6: Zareth | C6: Extrajudicial - 0 a 28 semanas de atraso | D6: =SUMIF('REPORTE DIARIO'!B:B,'EPR 17 MAYO'!C6, 'REPORTE DIARIO'!C:C) -> 12397 | E6: =SUMIF('REPORTE DIARIO'!B:B,'EPR 17 MAYO'!C6, 'REPORTE DIARIO'!D:D) -> 1074227.9 | F6: =J6*D6 -> 2337720 | G6: =+E6-F6 -> -1263492.1 | H6: =ABS(G6/F6) -> 0.54048052 | I6: =E6/D6 -> 86.652244 | J6: =(220/7)*6 -> 188.57143 | K6: =+I6-J6 -> -101.91918
B7: Gabriel | C7: Extrajudicial - 29 a 39 semanas de atraso | D7: =SUMIF('REPORTE DIARIO'!B:B,'EPR 17 MAYO'!C7, 'REPORTE DIARIO'!C:C) -> 12038 | E7: =SUMIF('REPORTE DIARIO'!B:B,'EPR 17 MAYO'!C7, 'REPORTE DIARIO'!D:D) -> 720383.26 | F7: =J7*D7 -> 1135011.4 | G7: =+E7-F7 -> -414628.17 | H7: =ABS(G7/F7) -> 0.36530748 | I7: =E7/D7 -> 59.842437 | J7: =(110/7)*6 -> 94.285714 | K7: =+I7-J7 -> -34.443277
B8: Gabriel | C8: Extrajudicial - 40 a 55 semanas de atraso | D8: =SUMIF('REPORTE DIARIO'!B:B,'EPR 17 MAYO'!C8, 'REPORTE DIARIO'!C:C) -> 11286 | E8: =SUMIF('REPORTE DIARIO'!B:B,'EPR 17 MAYO'!C8, 'REPORTE DIARIO'!D:D) -> 505557.69 | F8: =J8*D8 -> 435317.14 | G8: =+E8-F8 -> 70240.547 | H8: =ABS(G8/F8) -> 0.16135488 | I8: =E8/D8 -> 44.795117 | J8: =(45/7)*6 -> 38.571429 | K8: =+I8-J8 -> 6.2236884
B9: Fernando (Naucalpan) | C9: Mas 55 semanas de atraso | D9: =SUMIF('REPORTE DIARIO'!B:B,'EPR 17 MAYO'!C9, 'REPORTE DIARIO'!C:C) -> 55899 | E9: =SUMIF('REPORTE DIARIO'!B:B,'EPR 17 MAYO'!C9, 'REPORTE DIARIO'!D:D) -> 717225.03 | F9: =J9*D9 -> 718701.43 | G9: =+E9-F9 -> -1476.3986 | H9: =ABS(G9/F9) -> 0.0020542586 | I9: =E9/D9 -> 12.830731 | J9: =(15/7)*6 -> 12.857143 | K9: =+I9-J9 -> -0.026411896
C10: TOTAL | D10: =SUM(D6:D9) -> 91620 | E10: =SUM(E6:E9) -> 3017393.8 | F10: =SUM(F6:F9) -> 4626750 | G10: =+E10-F10 -> -1609356.2 | H10: =ABS(G10/F10) -> 0.34783728 | I10: =E10/D10 -> 32.93379 | J10: =F10/D10 -> 50.499345 | K10: =I10-J10 -> -17.565555
B12: Nota:
B13: El saldo consolidado incluye los siguientes despachos
B14: Samantha, Samantha 2, Sofia, Edith, Fernando, Olguin y Federico
