Workbook

Sheet REPORTE DIARIO
B3: COBRANZA GENERAL SAMANTHA
B4: Segmento | C4: Cuentas | D4: Recuperación
B5: Extrajudicial - 0 a 28 semanas de atraso | C5: 6049 | D5: 214369.45
B6: Extrajudicial - 29 a 39 semanas de atraso | C6: 6619 | D6: 97927.03
B7: Extrajudicial - 40 a 55 semanas de atraso | C7: 9986 | D7: 78053
B8: JUDICIAL | C8: 21 | D8: 0
B9: Mas 55 semanas de atraso | C9: 29008 | D9: 85235.84
B10: Total general | C10: =SUM(C5:C9) -> 51683 | D10: =SUM(D5:D9) -> 475585.32
B12: COBRANZA GENERAL SAMANTHA 2
B13: Segmento | C13: Cuentas | D13: Recuperación
B14: Extrajudicial - 0 a 28 semanas de atraso | C14: 2618 | D14: 68858.58
B15: Extrajudicial - 29 a 39 semanas de atraso | C15: 1412 | D15: 60084
B16: Extrajudicial - 40 a 55 semanas de atraso | C16: 3308 | D16: 12984
B17: JUDICIAL | C17: 2 | D17: 0
B18: Mas 55 semanas de atraso | C18: 21168 | D18: 47346.01
B19: Total general | C19: =SUM(C14:C18) -> 28508 | D19: =SUM(D14:D18) -> 189272.59
B21: COBRANZA GENERAL EDITH
B22: Segmento | C22: Cuentas | D22: Recuperación
B23: Extrajudicial - 0 a 28 semanas de atraso | C23: 1709 | D23: 69302.33
B24: Extrajudicial - 29 a 39 semanas de atraso | C24: 1508 | D24: 66143.65
B25: Extrajudicial - 40 a 55 semanas de atraso | C25: 859 | D25: 9637
B26: Mas 55 semanas de atraso | C26: 8798 | D26: 19290.88
B27: Total general | C27: =SUM(C23:C26) -> 12874 | D27: =SUM(D23:D26) -> 164373.86
B29: COBRANZA GENERAL FERNANDO
B30: Segmento | C30: Cuentas | D30: Recuperación
B31: Extrajudicial - 0 a 28 semanas de atraso | C31: 2765 | D31: 115325
B32: Total general | C32: =SUM(C31:C31) -> 2765 | D32: =SUM(D31:D31) -> 115325
B34: COBRANZA GENERAL SOFIA
B35: Segmento | C35: Cuentas | D35: Recuperación
B36: Extrajudicial - 0 a 28 semanas de atraso | C36: 1407 | D36: 48066.8
B37: Extrajudicial - 29 a 39 semanas de atraso | C37: 1309 | D37: 8778
B38: Extrajudicial - 40 a 55 semanas de atraso | C38: 2889 | D38: 3055
B39: Mas 55 semanas de atraso | C39: 4264 | D39: 297
B40: Total general | C40: =SUM(C36:C39) -> 9869 | D40: =SUM(D36:D39) -> 60196.8
B42: COBRANZA GENERAL FEDERICO
B43: Segmento | C43: Cuentas | D43: Recuperación
B44: Extrajudicial - 0 a 28 semanas de atraso | C44: 39 | D44: 25603
B45: Extrajudicial - 29 a 39 semanas de atraso | C45: 189 | D45: 600
B46: Extrajudicial - 40 a 55 semanas de atraso | C46: 200 | D46: 0
B47: Mas 55 semanas de atraso | C47: 1871 | D47: 6016
...

Sheet DATA

Sheet EPR 9 ABR
B2: REPORTE CONSOLIDADO POR SEGMENTOS
B3: SALDO ACUMULADO SEMANA 15
B5: COORDINADOR | C5: SEGMENTO | D5: CUENTAS | E5: COBRANZA REAL | F5: CUOTA IDEAL | G5: VARIACION | H5: % VAR | I5: EPR | J5: EPR IDEAL | K5: VAR EPR
B6: Samatha y Zareth | C6: Extrajudicial - 0 a 28 semanas de atraso | D6: =SUMIF('REPORTE DIARIO'!B:B,'EPR 9 ABR'!C6, 'REPORTE DIARIO'!C:C) -> 14588 | E6: =SUMIF('REPORTE DIARIO'!B:B,'EPR 9 ABR'!C6, 'REPORTE DIARIO'!D:D) -> 541525.16 | F6: =J6*D6 -> 1250400 | G6: =+E6-F6 -> -708874.84 | H6: =ABS(G6/F6) -> 0.56691846 | I6: =E6/D6 -> 37.121275 | J6: =(200/7)*3 -> 85.714286 | K6: =+I6-J6 -> -48.593011
B7: Gabriel | C7: Extrajudicial - 29 a 39 semanas de atraso | D7: =SUMIF('REPORTE DIARIO'!B:B,'EPR 9 ABR'!C7, 'REPORTE DIARIO'!C:C) -> 11037 | E7: =SUMIF('REPORTE DIARIO'!B:B,'EPR 9 ABR'!C7, 'REPORTE DIARIO'!D:D) -> 233532.68 | F7: =J7*D7 -> 520315.71 | G7: =+E7-F7 -> -286783.03 | H7: =ABS(G7/F7) -> 0.5511712 | I7: =E7/D7 -> 21.159072 | J7: =(110/7)*3 -> 47.142857 | K7: =+I7-J7 -> -25.983785
B8: Gabriel | C8: Extrajudicial - 40 a 55 semanas de atraso | D8: =SUMIF('REPORTE DIARIO'!B:B,'EPR 9 ABR'!C8, 'REPORTE DIARIO'!C:C) -> 17242 | E8: =SUMIF('REPORTE DIARIO'!B:B,'EPR 9 ABR'!C8, 'REPORTE DIARIO'!D:D) -> 103729 | F8: =J8*D8 -> 332524.29 | G8: =+E8-F8 -> -228795.29 | H8: =ABS(G8/F8) -> 0.68805587 | I8: =E8/D8 -> 6.0160654 | J8: =(45/7)*3 -> 19.285714 | K8: =+I8-J8 -> -13.269649
B9: Fernando | C9: Mas 55 semanas de atraso | D9: =SUMIF('REPORTE DIARIO'!B:B,'EPR 9 ABR'!C9, 'REPORTE DIARIO'!C:C) -> 65111 | E9: =SUMIF('REPORTE DIARIO'!B:B,'EPR 9 ABR'!C9, 'REPORTE DIARIO'!D:D) -> 158185.73 | F9: =J9*D9 -> 418570.71 | G9: =+E9-F9 -> -260384.98 | H9: =ABS(G9/F9) -> 0.62208123 | I9: =E9/D9 -> 2.4294778 | J9: =(15/7)*3 -> 6.4285714 | K9: =+I9-J9 -> -3.9990936
C10: TOTAL | D10: =SUM(D6:D9) -> 107978 | E10: =SUM(E6:E9) -> 1036972.6 | F10: =SUM(F6:F9) -> 2521810.7 | G10: =+E10-F10 -> -1484838.1 | H10: =ABS(G10/F10) -> 0.58879841 | I10: =E10/D10 -> 9.6035541 | J10: =F10/D10 -> 23.354857 | K10: =I10-J10 -> -13.751303
B12: Nota:
B13: El saldo consolidado incluye los siguientes despachos
B14: Samantha, Samantha 2, Sofia, Edith, Olguin, Fernando y Federico
