Workbook

Sheet REPORTE DIARIO
B3: COBRANZA GENERAL SAMANTHA
B4: Segmento | C4: Cuentas | D4: Recuperación
B5: Extrajudicial - 0 a 28 semanas de atraso | C5: 6527 | D5: 76685.13
B6: Extrajudicial - 29 a 39 semanas de atraso | C6: 5200 | D6: 20610.7
B7: Extrajudicial - 40 a 55 semanas de atraso | C7: 7156 | D7: 38432
B8: JUDICIAL | C8: 21 | D8: 0
B9: Mas 55 semanas de atraso | C9: 21109 | D9: 35458
B10: Total general | C10: =SUM(C5:C9) -> 40013 | D10: =SUM(D5:D9) -> 171185.83
B12: COBRANZA GENERAL SOFIA
B13: Segmento | C13: Cuentas | D13: Recuperación
B14: Extrajudicial - 0 a 28 semanas de atraso | C14: 1346 | D14: 43926.4
B15: Extrajudicial - 29 a 39 semanas de atraso | C15: 1921 | D15: 25299.96
B16: Extrajudicial - 40 a 55 semanas de atraso | C16: 2533 | D16: 2725
B17: Mas 55 semanas de atraso | C17: 4264 | D17: 0
B18: Total general | C18: =SUM(C14:C17) -> 10064 | D18: =SUM(D14:D17) -> 71951.36
B20: COBRANZA GENERAL EDITH
B21: Segmento | C21: Cuentas | D21: Recuperación
B22: Extrajudicial - 0 a 28 semanas de atraso | C22: 2046 | D22: 34629.44
B23: Extrajudicial - 29 a 39 semanas de atraso | C23: 2351 | D23: 25436.3
B24: Extrajudicial - 40 a 55 semanas de atraso | C24: 1047 | D24: 1828
B25: Mas 55 semanas de atraso | C25: 9429 | D25: 2437
B26: Total general | C26: =SUM(C22:C25) -> 14873 | D26: =SUM(D22:D25) -> 64330.74
B28: COBRANZA GENERAL SAMANTHA 2
B29: Segmento | C29: Cuentas | D29: Recuperación
B30: Extrajudicial - 0 a 28 semanas de atraso | C30: 2404 | D30: 28938.18
B31: Extrajudicial - 29 a 39 semanas de atraso | C31: 1637 | D31: 4930
B32: Extrajudicial - 40 a 55 semanas de atraso | C32: 3301 | D32: 4768
B33: JUDICIAL | C33: 2 | D33: 0
B34: Mas 55 semanas de atraso | C34: 21679 | D34: 4647.17
B35: Total general | C35: =SUM(C30:C34) -> 29023 | D35: =SUM(D30:D34) -> 43283.35
B37: COBRANZA GENERAL FERNANDO
B38: Segmento | C38: Cuentas | D38: Recuperación
B39: Extrajudicial - 0 a 28 semanas de atraso | C39: 1358 | D39: 3638
B40: Total general | C40: =SUM(C39:C39) -> 1358 | D40: =SUM(D39:D39) -> 3638
B42: COBRANZA GENERAL OLGUIN
B43: Segmento | C43: Cuentas | D43: Recuperación
B44: Extrajudicial - 0 a 28 semanas de atraso | C44: 86 | D44: 0
B45: Extrajudicial - 29 a 39 semanas de atraso | C45: 109 | D45: 0
B46: Extrajudicial - 40 a 55 semanas de atraso | C46: 470 | D46: 0
B47: Mas 55 semanas de atraso | C47: 749 | D47: 2586
...

Sheet DATA

Sheet EPR 22 ABR
B2: REPORTE CONSOLIDADO POR SEGMENTOS
B3: COBRANZA 22 ABRIL
B5: COORDINADOR | C5: SEGMENTO | D5: CUENTAS | E5: COBRANZA REAL | F5: CUOTA IDEAL | G5: VARIACION | H5: % VAR | I5: EPR | J5: EPR IDEAL | K5: VAR EPR
B6: Samatha y Zareth | C6: Extrajudicial - 0 a 28 semanas de atraso | D6: =SUMIF('REPORTE DIARIO'!B:B,'EPR 22 ABR'!C6, 'REPORTE DIARIO'!C:C) -> 13806 | E6: =SUMIF('REPORTE DIARIO'!B:B,'EPR 22 ABR'!C6, 'REPORTE DIARIO'!D:D) -> 187817.15 | F6: =J6*D6 -> 394457.14 | G6: =+E6-F6 -> -206639.99 | H6: =ABS(G6/F6) -> 0.52385917 | I6: =E6/D6 -> 13.604024 | J6: =200/7 -> 28.571429 | K6: =+I6-J6 -> -14.967405
B7: Gabriel | C7: Extrajudicial - 29 a 39 semanas de atraso | D7: =SUMIF('REPORTE DIARIO'!B:B,'EPR 22 ABR'!C7, 'REPORTE DIARIO'!C:C) -> 11540 | E7: =SUMIF('REPORTE DIARIO'!B:B,'EPR 22 ABR'!C7, 'REPORTE DIARIO'!D:D) -> 77276.96 | F7: =J7*D7 -> 181342.86 | G7: =+E7-F7 -> -104065.9 | H7: =ABS(G7/F7) -> 0.57386268 | I7: =E7/D7 -> 6.6964437 | J7: =110/7 -> 15.714286 | K7: =+I7-J7 -> -9.017842
B8: Gabriel | C8: Extrajudicial - 40 a 55 semanas de atraso | D8: =SUMIF('REPORTE DIARIO'!B:B,'EPR 22 ABR'!C8, 'REPORTE DIARIO'!C:C) -> 14762 | E8: =SUMIF('REPORTE DIARIO'!B:B,'EPR 22 ABR'!C8, 'REPORTE DIARIO'!D:D) -> 47753 | F8: =J8*D8 -> 94898.571 | G8: =+E8-F8 -> -47145.571 | H8: =ABS(G8/F8) -> 0.49679959 | I8: =E8/D8 -> 3.2348598 | J8: =45/7 -> 6.4285714 | K8: =+I8-J8 -> -3.1937117
B9: Fernando | C9: Mas 55 semanas de atraso | D9: =SUMIF('REPORTE DIARIO'!B:B,'EPR 22 ABR'!C9, 'REPORTE DIARIO'!C:C) -> 59160 | E9: =SUMIF('REPORTE DIARIO'!B:B,'EPR 22 ABR'!C9, 'REPORTE DIARIO'!D:D) -> 46179.17 | F9: =J9*D9 -> 126771.43 | G9: =+E9-F9 -> -80592.259 | H9: =ABS(G9/F9) -> 0.63572888 | I9: =E9/D9 -> 0.78058097 | J9: =15/7 -> 2.1428571 | K9: =+I9-J9 -> -1.3622762
C10: TOTAL | D10: =SUM(D6:D9) -> 99268 | E10: =SUM(E6:E9) -> 359026.28 | F10: =SUM(F6:F9) -> 797470 | G10: =+E10-F10 -> -438443.72 | H10: =ABS(G10/F10) -> 0.54979337 | I10: =E10/D10 -> 3.6167373 | J10: =F10/D10 -> 8.0335053 | K10: =I10-J10 -> -4.4167679
B12: Nota:
B13: El saldo consolidado incluye los siguientes despachos
B14: Samantha, Samantha 2, Sofia, Edith, Fernando, Olguin y Federico
