Workbook

Sheet REPORTE DIARIO
B3: COBRANZA GENERAL SAMANTHA
B4: Segmento | C4: Cuentas | D4: Recuperación
B5: Extrajudicial - 0 a 28 semanas de atraso | C5: 5952 | D5: 283181.01
B6: Extrajudicial - 29 a 39 semanas de atraso | C6: 6556 | D6: 120834.02
B7: Extrajudicial - 40 a 55 semanas de atraso | C7: 9791 | D7: 102274
B8: JUDICIAL | C8: 21 | D8: 0
B9: Mas 55 semanas de atraso | C9: 29244 | D9: 159841.86
B10: Total general | C10: =SUM(C5:C9) -> 51564 | D10: =SUM(D5:D9) -> 666130.89
B12: COBRANZA GENERAL SAMANTHA 2
B13: Segmento | C13: Cuentas | D13: Recuperación
B14: Extrajudicial - 0 a 28 semanas de atraso | C14: 2514 | D14: 87188.58
B15: Extrajudicial - 29 a 39 semanas de atraso | C15: 1411 | D15: 68258.01
B16: Extrajudicial - 40 a 55 semanas de atraso | C16: 3302 | D16: 18557.62
B17: JUDICIAL | C17: 2 | D17: 0
B18: Mas 55 semanas de atraso | C18: 21183 | D18: 70592
B19: Total general | C19: =SUM(C14:C18) -> 28412 | D19: =SUM(D14:D18) -> 244596.21
B21: COBRANZA GENERAL EDITH
B22: Segmento | C22: Cuentas | D22: Recuperación
B23: Extrajudicial - 0 a 28 semanas de atraso | C23: 1753 | D23: 101839.52
B24: Extrajudicial - 29 a 39 semanas de atraso | C24: 1503 | D24: 56470.8
B25: Extrajudicial - 40 a 55 semanas de atraso | C25: 860 | D25: 18031
B26: Mas 55 semanas de atraso | C26: 8899 | D26: 18845.88
B27: Total general | C27: =SUM(C23:C26) -> 13015 | D27: =SUM(D23:D26) -> 195187.2
B29: COBRANZA GENERAL FERNANDO
B30: Segmento | C30: Cuentas | D30: Recuperación
B31: Extrajudicial - 0 a 28 semanas de atraso | C31: 2647 | D31: 137488
B32: Total general | C32: =SUM(C31:C31) -> 2647 | D32: =SUM(D31:D31) -> 137488
B34: COBRANZA GENERAL SOFIA
B35: Segmento | C35: Cuentas | D35: Recuperación
B36: Extrajudicial - 0 a 28 semanas de atraso | C36: 1366 | D36: 58462.05
B37: Extrajudicial - 29 a 39 semanas de atraso | C37: 1308 | D37: 36465.92
B38: Extrajudicial - 40 a 55 semanas de atraso | C38: 2770 | D38: 3368.22
B39: Mas 55 semanas de atraso | C39: 4264 | D39: 297
B40: Total general | C40: =SUM(C36:C39) -> 9708 | D40: =SUM(D36:D39) -> 98593.19
B42: COBRANZA GENERAL FEDERICO
B43: Segmento | C43: Cuentas | D43: Recuperación
B44: Extrajudicial - 0 a 28 semanas de atraso | C44: 39 | D44: 25813
B45: Extrajudicial - 29 a 39 semanas de atraso | C45: 187 | D45: 1000
B46: Extrajudicial - 40 a 55 semanas de atraso | C46: 209 | D46: 0
B47: Mas 55 semanas de atraso | C47: 1887 | D47: 6016
...

Sheet DATA

Sheet EPR 10 ABR
B2: REPORTE CONSOLIDADO POR SEGMENTOS
B3: SALDO ACUMULADO SEMANA 15
B5: COORDINADOR | C5: SEGMENTO | D5: CUENTAS | E5: COBRANZA REAL | F5: CUOTA IDEAL | G5: VARIACION | H5: % VAR | I5: EPR | J5: EPR IDEAL | K5: VAR EPR
B6: Samatha y Zareth | C6: Extrajudicial - 0 a 28 semanas de atraso | D6: =SUMIF('REPORTE DIARIO'!B:B,'EPR 10 ABR'!C6, 'REPORTE DIARIO'!C:C) -> 14272 | E6: =SUMIF('REPORTE DIARIO'!B:B,'EPR 10 ABR'!C6, 'REPORTE DIARIO'!D:D) -> 693972.16 | F6: =J6*D6 -> 2038857.1 | G6: =+E6-F6 -> -1344885 | H6: =ABS(G6/F6) -> 0.65962688 | I6: =E6/D6 -> 48.624731 | J6: =(200/7)*5 -> 142.85714 | K6: =+I6-J6 -> -94.232412
B7: Gabriel | C7: Extrajudicial - 29 a 39 semanas de atraso | D7: =SUMIF('REPORTE DIARIO'!B:B,'EPR 10 ABR'!C7, 'REPORTE DIARIO'!C:C) -> 10965 | E7: =SUMIF('REPORTE DIARIO'!B:B,'EPR 10 ABR'!C7, 'REPORTE DIARIO'!D:D) -> 283028.75 | F7: =J7*D7 -> 861535.71 | G7: =+E7-F7 -> -578506.96 | H7: =ABS(G7/F7) -> 0.67148344 | I7: =E7/D7 -> 25.812016 | J7: =(110/7)*5 -> 78.571429 | K7: =+I7-J7 -> -52.759413
B8: Gabriel | C8: Extrajudicial - 40 a 55 semanas de atraso | D8: =SUMIF('REPORTE DIARIO'!B:B,'EPR 10 ABR'!C8, 'REPORTE DIARIO'!C:C) -> 16932 | E8: =SUMIF('REPORTE DIARIO'!B:B,'EPR 10 ABR'!C8, 'REPORTE DIARIO'!D:D) -> 142230.84 | F8: =J8*D8 -> 544242.86 | G8: =+E8-F8 -> -402012.02 | H8: =ABS(G8/F8) -> 0.73866292 | I8: =E8/D8 -> 8.4001205 | J8: =(45/7)*5 -> 32.142857 | K8: =+I8-J8 -> -23.742737
B9: Fernando | C9: Mas 55 semanas de atraso | D9: =SUMIF('REPORTE DIARIO'!B:B,'EPR 10 ABR'!C9, 'REPORTE DIARIO'!C:C) -> 65479 | E9: =SUMIF('REPORTE DIARIO'!B:B,'EPR 10 ABR'!C9, 'REPORTE DIARIO'!D:D) -> 255592.74 | F9: =J9*D9 -> 701560.71 | G9: =+E9-F9 -> -445967.97 | H9: =ABS(G9/F9) -> 0.6356798 | I9: =E9/D9 -> 3.9034307 | J9: =(15/7)*5 -> 10.714286 | K9: =+I9-J9 -> -6.810855
C10: TOTAL | D10: =SUM(D6:D9) -> 107648 | E10: =SUM(E6:E9) -> 1374824.5 | F10: =SUM(F6:F9) -> 4146196.4 | G10: =+E10-F10 -> -2771371.9 | H10: =ABS(G10/F10) -> 0.66841308 | I10: =E10/D10 -> 12.771482 | J10: =F10/D10 -> 38.516242 | K10: =I10-J10 -> -25.74476
B12: Nota:
B13: El saldo consolidado incluye los siguientes despachos
B14: Samantha, Samantha 2, Sofia, Edith, Olguin, Fernando y Federico
