Workbook

Sheet REPORTE DIARIO
B3: COBRANZA GENERAL SAMANTHA
B4: Segmento | C4: Cuentas | D4: Recuperación
B5: Extrajudicial - 0 a 28 semanas de atraso | C5: 5928 | D5: 331788.04
B6: Extrajudicial - 29 a 39 semanas de atraso | C6: 6641 | D6: 348037.8
B7: Extrajudicial - 40 a 55 semanas de atraso | C7: 9854 | D7: 169329.72
B8: JUDICIAL | C8: 21 | D8: 1150
B9: Mas 55 semanas de atraso | C9: 28805 | D9: 355819.3
B10: Total general | C10: =SUM(C5:C9) -> 51249 | D10: =SUM(D5:D9) -> 1206124.9
B12: COBRANZA GENERAL EDITH
B13: Segmento | C13: Cuentas | D13: Recuperación
B14: Extrajudicial - 0 a 28 semanas de atraso | C14: 1469 | D14: 169296.12
B15: Extrajudicial - 29 a 39 semanas de atraso | C15: 1491 | D15: 196409.75
B16: Extrajudicial - 40 a 55 semanas de atraso | C16: 838 | D16: 15439
B17: Mas 55 semanas de atraso | C17: 8338 | D17: 63500
B18: Total general | C18: =SUM(C14:C17) -> 12136 | D18: =SUM(D14:D17) -> 444644.87
B20: COBRANZA GENERAL SAMANTHA 2
B21: Segmento | C21: Cuentas | D21: Recuperación
B22: Extrajudicial - 0 a 28 semanas de atraso | C22: 2330 | D22: 179388.36
B23: Extrajudicial - 29 a 39 semanas de atraso | C23: 1438 | D23: 23915.57
B24: Extrajudicial - 40 a 55 semanas de atraso | C24: 3421 | D24: 25015.63
B25: JUDICIAL | C25: 2 | D25: 0
B26: Mas 55 semanas de atraso | C26: 21146 | D26: 118332.82
B27: Total general | C27: =SUM(C22:C26) -> 28337 | D27: =SUM(D22:D26) -> 346652.38
B29: COBRANZA GENERAL SOFIA
B30: Segmento | C30: Cuentas | D30: Recuperación
B31: Extrajudicial - 0 a 28 semanas de atraso | C31: 1194 | D31: 105784.53
B32: Extrajudicial - 29 a 39 semanas de atraso | C32: 1281 | D32: 88708.07
B33: Extrajudicial - 40 a 55 semanas de atraso | C33: 2933 | D33: 36627
B34: Mas 55 semanas de atraso | C34: 1828 | D34: 18275
B35: Total general | C35: =SUM(C31:C34) -> 7236 | D35: =SUM(D31:D34) -> 249394.6
B37: COBRANZA GENERAL FERNANDO
B38: Segmento | C38: Cuentas | D38: Recuperación
B39: Extrajudicial - 0 a 28 semanas de atraso | C39: 2741 | D39: 28072
B40: Total general | C40: =SUM(C39:C39) -> 2741 | D40: =SUM(D39:D39) -> 28072
B42: COBRANZA GENERAL FEDERICO
B43: Segmento | C43: Cuentas | D43: Recuperación
B44: Extrajudicial - 0 a 28 semanas de atraso | C44: 0 | D44: 0
B45: Extrajudicial - 29 a 39 semanas de atraso | C45: 102 | D45: 400
B46: Extrajudicial - 40 a 55 semanas de atraso | C46: 130 | D46: 0
B47: Mas 55 semanas de atraso | C47: 1422 | D47: 6291
...

Sheet DATA

Sheet EPR 3 ABR
B2: REPORTE CONSOLIDADO POR SEGMENTOS
B3: SALDO ACUMULADO SEMANA 14
B5: COORDINADOR | C5: SEGMENTO | D5: CUENTAS | E5: COBRANZA REAL | F5: CUOTA IDEAL | G5: VARIACION | H5: % VAR | I5: EPR | J5: EPR IDEAL | K5: VAR EPR
B6: Samatha y Zareth | C6: Extrajudicial - 0 a 28 semanas de atraso | D6: =SUMIF('REPORTE DIARIO'!B:B,'EPR 3 ABR'!C6, 'REPORTE DIARIO'!C:C) -> 13730 | E6: =SUMIF('REPORTE DIARIO'!B:B,'EPR 3 ABR'!C6, 'REPORTE DIARIO'!D:D) -> 816329.05 | F6: =J6*D6 -> 1569142.9 | G6: =+E6-F6 -> -752813.81 | H6: =ABS(G6/F6) -> 0.47976117 | I6: =E6/D6 -> 59.455867 | J6: =(200/7)*4 -> 114.28571 | K6: =+I6-J6 -> -54.829848
B7: Gabriel | C7: Extrajudicial - 29 a 39 semanas de atraso | D7: =SUMIF('REPORTE DIARIO'!B:B,'EPR 3 ABR'!C7, 'REPORTE DIARIO'!C:C) -> 11015 | E7: =SUMIF('REPORTE DIARIO'!B:B,'EPR 3 ABR'!C7, 'REPORTE DIARIO'!D:D) -> 657471.19 | F7: =J7*D7 -> 692371.43 | G7: =+E7-F7 -> -34900.239 | H7: =ABS(G7/F7) -> 0.050406815 | I7: =E7/D7 -> 59.688714 | J7: =(110/7)*4 -> 62.857143 | K7: =+I7-J7 -> -3.1684284
B8: Gabriel | C8: Extrajudicial - 40 a 55 semanas de atraso | D8: =SUMIF('REPORTE DIARIO'!B:B,'EPR 3 ABR'!C8, 'REPORTE DIARIO'!C:C) -> 17189 | E8: =SUMIF('REPORTE DIARIO'!B:B,'EPR 3 ABR'!C8, 'REPORTE DIARIO'!D:D) -> 246411.35 | F8: =J8*D8 -> 442002.86 | G8: =+E8-F8 -> -195591.51 | H8: =ABS(G8/F8) -> 0.44251186 | I8: =E8/D8 -> 14.335409 | J8: =(45/7)*4 -> 25.714286 | K8: =+I8-J8 -> -11.378876
B9: Fernando | C9: Mas 55 semanas de atraso | D9: =SUMIF('REPORTE DIARIO'!B:B,'EPR 3 ABR'!C9, 'REPORTE DIARIO'!C:C) -> 61548 | E9: =SUMIF('REPORTE DIARIO'!B:B,'EPR 3 ABR'!C9, 'REPORTE DIARIO'!D:D) -> 562218.12 | F9: =J9*D9 -> 527554.29 | G9: =+E9-F9 -> 34663.834 | H9: =ABS(G9/F9) -> 0.065706668 | I9: =E9/D9 -> 9.1346286 | J9: =(15/7)*4 -> 8.5714286 | K9: =+I9-J9 -> 0.56320001
C10: TOTAL | D10: =SUM(D6:D9) -> 103482 | E10: =SUM(E6:E9) -> 2282429.7 | F10: =SUM(F6:F9) -> 3231071.4 | G10: =+E10-F10 -> -948641.72 | H10: =ABS(G10/F10) -> 0.29359974 | I10: =E10/D10 -> 22.056297 | J10: =F10/D10 -> 31.223512 | K10: =I10-J10 -> -9.1672148
B12: Nota:
B13: El saldo consolidado incluye los siguientes despachos
B14: Samantha, Samantha 2, Sofia, Edith, Olguin, Fernando y Federico
