Workbook

Sheet REPORTE DIARIO
B3: COBRANZA GENERAL SAMANTHA
B4: Segmento | C4: Cuentas | D4: Recuperación
B5: Extrajudicial - 0 a 28 semanas de atraso | C5: 4149 | D5: 75997.04
B6: Extrajudicial - 29 a 39 semanas de atraso | C6: 4366 | D6: 20813
B7: Extrajudicial - 40 a 55 semanas de atraso | C7: 4267 | D7: 19160
B8: JUDICIAL | C8: 11 | D8: 0
B9: Mas 55 semanas de atraso | C9: 11353 | D9: 30229
B10: Total general | C10: =SUM(C5:C9) -> 24146 | D10: =SUM(D5:D9) -> 146199.04
B12: COBRANZA GENERAL SOFIA
B13: Segmento | C13: Cuentas | D13: Recuperación
B14: Extrajudicial - 0 a 28 semanas de atraso | C14: 226 | D14: 4607.83
B15: Extrajudicial - 29 a 39 semanas de atraso | C15: 3224 | D15: 98516.79
B16: Extrajudicial - 40 a 55 semanas de atraso | C16: 612 | D16: 280
B17: Mas 55 semanas de atraso | C17: 3969 | D17: 0
B18: Total general | C18: =SUM(C14:C17) -> 8031 | D18: =SUM(D14:D17) -> 103404.62
B20: COBRANZA GENERAL SAMANTHA 2
B21: Segmento | C21: Cuentas | D21: Recuperación
B22: Extrajudicial - 0 a 28 semanas de atraso | C22: 2062 | D22: 53115
B23: Extrajudicial - 29 a 39 semanas de atraso | C23: 2074 | D23: 11187.23
B24: Extrajudicial - 40 a 55 semanas de atraso | C24: 2105 | D24: 4459
B25: JUDICIAL | C25: 2 | D25: 0
B26: Mas 55 semanas de atraso | C26: 20846 | D26: 12506
B27: Total general | C27: =SUM(C22:C26) -> 27089 | D27: =SUM(D22:D26) -> 81267.23
B29: COBRANZA GENERAL EDITH
B30: Segmento | C30: Cuentas | D30: Recuperación
B31: Extrajudicial - 0 a 28 semanas de atraso | C31: 3321 | D31: 20619.01
B32: Extrajudicial - 29 a 39 semanas de atraso | C32: 1485 | D32: 1842
B33: Extrajudicial - 40 a 55 semanas de atraso | C33: 2158 | D33: 2004
B34: JUDICIAL | C34: 1 | D34: 0
B35: Mas 55 semanas de atraso | C35: 17193 | D35: 3865.2
B36: Total general | C36: =SUM(C31:C35) -> 24158 | D36: =SUM(D31:D35) -> 28330.21
B38: COBRANZA GENERAL FEDERICO
B39: Segmento | C39: Cuentas | D39: Recuperación
B40: Extrajudicial - 0 a 28 semanas de atraso | C40: 515 | D40: 2051
B41: Extrajudicial - 29 a 39 semanas de atraso | C41: 850 | D41: 1000
B42: Extrajudicial - 40 a 55 semanas de atraso | C42: 775 | D42: 0
B43: Mas 55 semanas de atraso | C43: 2427 | D43: 1260
B44: Total general | C44: =SUM(C40:C43) -> 4567 | D44: =SUM(D40:D43) -> 4311
B46: COBRANZA GENERAL FERNANDO
B47: Segmento | C47: Cuentas | D47: Recuperación
...

Sheet DATA

Sheet EPR 21 MAYO
B2: REPORTE CONSOLIDADO POR SEGMENTOS
B3: COBRANZA 21 MAYO
B5: COORDINADOR | C5: SEGMENTO | D5: CUENTAS | E5: COBRANZA REAL | F5: CUOTA IDEAL | G5: VARIACION | H5: % VAR | I5: EPR | J5: EPR IDEAL | K5: VAR EPR
B6: Zareth | C6: Extrajudicial - 0 a 28 semanas de atraso | D6: =SUMIF('REPORTE DIARIO'!B:B,'EPR 21 MAYO'!C6, 'REPORTE DIARIO'!C:C) -> 12981 | E6: =SUMIF('REPORTE DIARIO'!B:B,'EPR 21 MAYO'!C6, 'REPORTE DIARIO'!D:D) -> 160458.88 | F6: =J6*D6 -> 407974.29 | G6: =+E6-F6 -> -247515.41 | H6: =ABS(G6/F6) -> 0.60669364 | I6: =E6/D6 -> 12.361057 | J6: =220/7 -> 31.428571 | K6: =+I6-J6 -> -19.067514
B7: Gabriel | C7: Extrajudicial - 29 a 39 semanas de atraso | D7: =SUMIF('REPORTE DIARIO'!B:B,'EPR 21 MAYO'!C7, 'REPORTE DIARIO'!C:C) -> 12699 | E7: =SUMIF('REPORTE DIARIO'!B:B,'EPR 21 MAYO'!C7, 'REPORTE DIARIO'!D:D) -> 133359.02 | F7: =J7*D7 -> 199555.71 | G7: =+E7-F7 -> -66196.694 | H7: =ABS(G7/F7) -> 0.33172036 | I7: =E7/D7 -> 10.501537 | J7: =110/7 -> 15.714286 | K7: =+I7-J7 -> -5.2127486
B8: Gabriel | C8: Extrajudicial - 40 a 55 semanas de atraso | D8: =SUMIF('REPORTE DIARIO'!B:B,'EPR 21 MAYO'!C8, 'REPORTE DIARIO'!C:C) -> 11120 | E8: =SUMIF('REPORTE DIARIO'!B:B,'EPR 21 MAYO'!C8, 'REPORTE DIARIO'!D:D) -> 26492 | F8: =J8*D8 -> 71485.714 | G8: =+E8-F8 -> -44993.714 | H8: =ABS(G8/F8) -> 0.62940847 | I8: =E8/D8 -> 2.3823741 | J8: =45/7 -> 6.4285714 | K8: =+I8-J8 -> -4.0461973
B9: Fernando (Naucalpan) | C9: Mas 55 semanas de atraso | D9: =SUMIF('REPORTE DIARIO'!B:B,'EPR 21 MAYO'!C9, 'REPORTE DIARIO'!C:C) -> 57137 | E9: =SUMIF('REPORTE DIARIO'!B:B,'EPR 21 MAYO'!C9, 'REPORTE DIARIO'!D:D) -> 47860.2 | F9: =J9*D9 -> 122436.43 | G9: =+E9-F9 -> -74576.229 | H9: =ABS(G9/F9) -> 0.60910163 | I9: =E9/D9 -> 0.83763936 | J9: =15/7 -> 2.1428571 | K9: =+I9-J9 -> -1.3052178
C10: TOTAL | D10: =SUM(D6:D9) -> 93937 | E10: =SUM(E6:E9) -> 368170.1 | F10: =SUM(F6:F9) -> 801452.14 | G10: =+E10-F10 -> -433282.04 | H10: =ABS(G10/F10) -> 0.54062123 | I10: =E10/D10 -> 3.91933 | J10: =F10/D10 -> 8.5318048 | K10: =I10-J10 -> -4.6124748
B12: Nota:
B13: El saldo consolidado incluye los siguientes despachos
B14: Samantha, Samantha 2, Sofia, Edith, Fernando, Olguin y Federico
