Workbook

Sheet REPORTE DIARIO
B3: COBRANZA GENERAL SAMANTHA
B4: Segmento | C4: Cuentas | D4: Recuperación
B5: Extrajudicial - 0 a 28 semanas de atraso | C5: 6559 | D5: 478736.82
B6: Extrajudicial - 29 a 39 semanas de atraso | C6: 5198 | D6: 439573.94
B7: Extrajudicial - 40 a 55 semanas de atraso | C7: 7237 | D7: 221736.58
B8: JUDICIAL | C8: 21 | D8: 0
B9: Mas 55 semanas de atraso | C9: 21099 | D9: 379246.65
B10: Total general | C10: =SUM(C5:C9) -> 40114 | D10: =SUM(D5:D9) -> 1519294
B12: COBRANZA GENERAL EDITH
B13: Segmento | C13: Cuentas | D13: Recuperación
B14: Extrajudicial - 0 a 28 semanas de atraso | C14: 2042 | D14: 307801.81
B15: Extrajudicial - 29 a 39 semanas de atraso | C15: 2287 | D15: 213312.32
B16: Extrajudicial - 40 a 55 semanas de atraso | C16: 986 | D16: 38876.92
B17: Mas 55 semanas de atraso | C17: 9408 | D17: 43000.25
B18: Total general | C18: =SUM(C14:C17) -> 14723 | D18: =SUM(D14:D17) -> 602991.3
B20: COBRANZA GENERAL SAMANTHA 2
B21: Segmento | C21: Cuentas | D21: Recuperación
B22: Extrajudicial - 0 a 28 semanas de atraso | C22: 2401 | D22: 269105.17
B23: Extrajudicial - 29 a 39 semanas de atraso | C23: 1567 | D23: 76311.68
B24: Extrajudicial - 40 a 55 semanas de atraso | C24: 3282 | D24: 55057
B25: JUDICIAL | C25: 2 | D25: 0
B26: Mas 55 semanas de atraso | C26: 21627 | D26: 130144.61
B27: Total general | C27: =SUM(C22:C26) -> 28879 | D27: =SUM(D22:D26) -> 530618.46
B29: COBRANZA GENERAL SOFIA
B30: Segmento | C30: Cuentas | D30: Recuperación
B31: Extrajudicial - 0 a 28 semanas de atraso | C31: 1351 | D31: 131367.03
B32: Extrajudicial - 29 a 39 semanas de atraso | C32: 1929 | D32: 85601.09
B33: Extrajudicial - 40 a 55 semanas de atraso | C33: 2466 | D33: 11318
B34: Mas 55 semanas de atraso | C34: 4264 | D34: 5731.29
B35: Total general | C35: =SUM(C31:C34) -> 10010 | D35: =SUM(D31:D34) -> 234017.41
B37: COBRANZA GENERAL FERNANDO
B38: Segmento | C38: Cuentas | D38: Recuperación
B39: Extrajudicial - 0 a 28 semanas de atraso | C39: 1327 | D39: 73299.63
B40: Total general | C40: =SUM(C39:C39) -> 1327 | D40: =SUM(D39:D39) -> 73299.63
B42: COBRANZA GENERAL FEDERICO
B43: Segmento | C43: Cuentas | D43: Recuperación
B44: Extrajudicial - 0 a 28 semanas de atraso | C44: 39 | D44: 3583
B45: Extrajudicial - 29 a 39 semanas de atraso | C45: 318 | D45: 18963
B46: Extrajudicial - 40 a 55 semanas de atraso | C46: 255 | D46: 546
B47: Mas 55 semanas de atraso | C47: 1930 | D47: 15021
...

Sheet DATA

Sheet EPR 20 ABR
B2: REPORTE CONSOLIDADO POR SEGMENTOS
B3: SALDO ACUMULADO SEMANA 16
B5: COORDINADOR | C5: SEGMENTO | D5: CUENTAS | E5: COBRANZA REAL | F5: CUOTA IDEAL | G5: VARIACION | H5: % VAR | I5: EPR | J5: EPR IDEAL | K5: VAR EPR
B6: Samatha y Zareth | C6: Extrajudicial - 0 a 28 semanas de atraso | D6: =SUMIF('REPORTE DIARIO'!B:B,'EPR 20 ABR'!C6, 'REPORTE DIARIO'!C:C) -> 13763 | E6: =SUMIF('REPORTE DIARIO'!B:B,'EPR 20 ABR'!C6, 'REPORTE DIARIO'!D:D) -> 1263893.5 | F6: =J6*D6 -> 2752600 | G6: =+E6-F6 -> -1488706.5 | H6: =ABS(G6/F6) -> 0.5408365 | I6: =E6/D6 -> 91.832701 | J6: =(200/7)*7 -> 200 | K6: =+I6-J6 -> -108.1673
B7: Gabriel | C7: Extrajudicial - 29 a 39 semanas de atraso | D7: =SUMIF('REPORTE DIARIO'!B:B,'EPR 20 ABR'!C7, 'REPORTE DIARIO'!C:C) -> 11365 | E7: =SUMIF('REPORTE DIARIO'!B:B,'EPR 20 ABR'!C7, 'REPORTE DIARIO'!D:D) -> 834762.03 | F7: =J7*D7 -> 1250150 | G7: =+E7-F7 -> -415387.97 | H7: =ABS(G7/F7) -> 0.3322705 | I7: =E7/D7 -> 73.450245 | J7: =(110/7)*7 -> 110 | K7: =+I7-J7 -> -36.549755
B8: Gabriel | C8: Extrajudicial - 40 a 55 semanas de atraso | D8: =SUMIF('REPORTE DIARIO'!B:B,'EPR 20 ABR'!C8, 'REPORTE DIARIO'!C:C) -> 14483 | E8: =SUMIF('REPORTE DIARIO'!B:B,'EPR 20 ABR'!C8, 'REPORTE DIARIO'!D:D) -> 328534.5 | F8: =J8*D8 -> 651735 | G8: =+E8-F8 -> -323200.5 | H8: =ABS(G8/F8) -> 0.49590785 | I8: =E8/D8 -> 22.684147 | J8: =(45/7)*7 -> 45 | K8: =+I8-J8 -> -22.315853
B9: Fernando | C9: Mas 55 semanas de atraso | D9: =SUMIF('REPORTE DIARIO'!B:B,'EPR 20 ABR'!C9, 'REPORTE DIARIO'!C:C) -> 58711 | E9: =SUMIF('REPORTE DIARIO'!B:B,'EPR 20 ABR'!C9, 'REPORTE DIARIO'!D:D) -> 573143.8 | F9: =J9*D9 -> 880665 | G9: =+E9-F9 -> -307521.2 | H9: =ABS(G9/F9) -> 0.34919203 | I9: =E9/D9 -> 9.7621195 | J9: =(15/7)*7 -> 15 | K9: =+I9-J9 -> -5.2378805
C10: TOTAL | D10: =SUM(D6:D9) -> 98322 | E10: =SUM(E6:E9) -> 3000333.8 | F10: =SUM(F6:F9) -> 5535150 | G10: =+E10-F10 -> -2534816.2 | H10: =ABS(G10/F10) -> 0.45794896 | I10: =E10/D10 -> 30.515386 | J10: =F10/D10 -> 56.296149 | K10: =I10-J10 -> -25.780763
B12: Nota:
B13: El saldo consolidado incluye los siguientes despachos
B14: Samantha, Samantha 2, Sofia, Edith, Fernando, Olguin y Federico
