Workbook

Sheet REPORTE DIARIO
B3: COBRANZA GENERAL SAMANTHA
B4: Segmento | C4: Cuentas | D4: Recuperación
B5: Extrajudicial - 0 a 28 semanas de atraso | C5: 3996 | D5: 228640.72
B6: Extrajudicial - 29 a 39 semanas de atraso | C6: 3574 | D6: 89629.13
B7: Extrajudicial - 40 a 55 semanas de atraso | C7: 4333 | D7: 99198.93
B8: JUDICIAL | C8: 11 | D8: 0
B9: Mas 55 semanas de atraso | C9: 11408 | D9: 126478.38
B10: Total general | C10: =SUM(C5:C9) -> 23322 | D10: =SUM(D5:D9) -> 543947.16
B12: COBRANZA GENERAL EDITH
B13: Segmento | C13: Cuentas | D13: Recuperación
B14: Extrajudicial - 0 a 28 semanas de atraso | C14: 3292 | D14: 133780.35
B15: Extrajudicial - 29 a 39 semanas de atraso | C15: 1174 | D15: 40800.37
B16: Extrajudicial - 40 a 55 semanas de atraso | C16: 2145 | D16: 20122.82
B17: JUDICIAL | C17: 1 | D17: 0
B18: Mas 55 semanas de atraso | C18: 17180 | D18: 90689.15
B19: Total general | C19: =SUM(C14:C18) -> 23792 | D19: =SUM(D14:D18) -> 285392.69
B21: COBRANZA GENERAL SAMANTHA 2
B22: Segmento | C22: Cuentas | D22: Recuperación
B23: Extrajudicial - 0 a 28 semanas de atraso | C23: 2435 | D23: 59056.66
B24: Extrajudicial - 29 a 39 semanas de atraso | C24: 2063 | D24: 85195
B25: Extrajudicial - 40 a 55 semanas de atraso | C25: 2045 | D25: 18284.31
B26: JUDICIAL | C26: 2 | D26: 0
B27: Mas 55 semanas de atraso | C27: 20985 | D27: 33183.95
B28: Total general | C28: =SUM(C23:C27) -> 27530 | D28: =SUM(D23:D27) -> 195719.92
B30: COBRANZA GENERAL SOFIA
B31: Segmento | C31: Cuentas | D31: Recuperación
B32: Extrajudicial - 0 a 28 semanas de atraso | C32: 214 | D32: 22072.06
B33: Extrajudicial - 29 a 39 semanas de atraso | C33: 3344 | D33: 89474.09
B34: Extrajudicial - 40 a 55 semanas de atraso | C34: 267 | D34: 3098.68
B35: Mas 55 semanas de atraso | C35: 3972 | D35: 3550
B36: Total general | C36: =SUM(C32:C35) -> 7797 | D36: =SUM(D32:D35) -> 118194.83
B38: COBRANZA GENERAL OLGUIN
B39: Segmento | C39: Cuentas | D39: Recuperación
B40: Extrajudicial - 0 a 28 semanas de atraso | C40: 988 | D40: 62353.79
B41: Extrajudicial - 29 a 39 semanas de atraso | C41: 1034 | D41: 5895
B42: Extrajudicial - 40 a 55 semanas de atraso | C42: 1720 | D42: 1231
B43: Mas 55 semanas de atraso | C43: 1935 | D43: 4529
B44: Total general | C44: =SUM(C40:C43) -> 5677 | D44: =SUM(D40:D43) -> 74008.79
B46: COBRANZA GENERAL FERNANDO
B47: Segmento | C47: Cuentas | D47: Recuperación
...

Sheet DATA

Sheet EPR 28 MAYO
B2: REPORTE CONSOLIDADO POR SEGMENTOS
B3: SALDO ACUMULADO SEMANA 22
B5: COORDINADOR | C5: SEGMENTO | D5: CUENTAS | E5: COBRANZA REAL | F5: CUOTA IDEAL | G5: VARIACION | H5: % VAR | I5: EPR | J5: EPR IDEAL | K5: VAR EPR
B6: Zareth | C6: Extrajudicial - 0 a 28 semanas de atraso | D6: =SUMIF('REPORTE DIARIO'!B:B,'EPR 28 MAYO'!C6, 'REPORTE DIARIO'!C:C) -> 14401 | E6: =SUMIF('REPORTE DIARIO'!B:B,'EPR 28 MAYO'!C6, 'REPORTE DIARIO'!D:D) -> 559364.58 | F6: =J6*D6 -> 1357808.6 | G6: =+E6-F6 -> -798443.99 | H6: =ABS(G6/F6) -> 0.5880387 | I6: =E6/D6 -> 38.842065 | J6: =(220/7)*3 -> 94.285714 | K6: =+I6-J6 -> -55.443649
B7: Gabriel | C7: Extrajudicial - 29 a 39 semanas de atraso | D7: =SUMIF('REPORTE DIARIO'!B:B,'EPR 28 MAYO'!C7, 'REPORTE DIARIO'!C:C) -> 12059 | E7: =SUMIF('REPORTE DIARIO'!B:B,'EPR 28 MAYO'!C7, 'REPORTE DIARIO'!D:D) -> 313327.59 | F7: =J7*D7 -> 568495.71 | G7: =+E7-F7 -> -255168.12 | H7: =ABS(G7/F7) -> 0.44884793 | I7: =E7/D7 -> 25.982883 | J7: =(110/7)*3 -> 47.142857 | K7: =+I7-J7 -> -21.159974
B8: Gabriel | C8: Extrajudicial - 40 a 55 semanas de atraso | D8: =SUMIF('REPORTE DIARIO'!B:B,'EPR 28 MAYO'!C8, 'REPORTE DIARIO'!C:C) -> 11332 | E8: =SUMIF('REPORTE DIARIO'!B:B,'EPR 28 MAYO'!C8, 'REPORTE DIARIO'!D:D) -> 144465.74 | F8: =J8*D8 -> 218545.71 | G8: =+E8-F8 -> -74079.974 | H8: =ABS(G8/F8) -> 0.33896787 | I8: =E8/D8 -> 12.748477 | J8: =(45/7)*3 -> 19.285714 | K8: =+I8-J8 -> -6.5372374
B9: Fernando (Naucalpan) | C9: Mas 55 semanas de atraso | D9: =SUMIF('REPORTE DIARIO'!B:B,'EPR 28 MAYO'!C9, 'REPORTE DIARIO'!C:C) -> 57961 | E9: =SUMIF('REPORTE DIARIO'!B:B,'EPR 28 MAYO'!C9, 'REPORTE DIARIO'!D:D) -> 260847.48 | F9: =J9*D9 -> 372606.43 | G9: =+E9-F9 -> -111758.95 | H9: =ABS(G9/F9) -> 0.29993833 | I9: =E9/D9 -> 4.5003965 | J9: =(15/7)*3 -> 6.4285714 | K9: =+I9-J9 -> -1.928175
C10: TOTAL | D10: =SUM(D6:D9) -> 95753 | E10: =SUM(E6:E9) -> 1278005.4 | F10: =SUM(F6:F9) -> 2517456.4 | G10: =+E10-F10 -> -1239451 | H10: =ABS(G10/F10) -> 0.4923426 | I10: =E10/D10 -> 13.346897 | J10: =F10/D10 -> 26.291149 | K10: =I10-J10 -> -12.944253
B12: Nota:
B13: El saldo consolidado incluye los siguientes despachos
B14: Samantha, Samantha 2, Sofia, Edith, Fernando, Olguin y Federico
