Workbook

Sheet REPORTE DIARIO
B3: COBRANZA GENERAL SAMANTHA
B4: Segmento | C4: Cuentas | D4: Recuperación
B5: Extrajudicial - 0 a 28 semanas de atraso | C5: 7398 | D5: 764278.06
B6: Extrajudicial - 29 a 39 semanas de atraso | C6: 7979 | D6: 477749.33
B7: Extrajudicial - 40 a 55 semanas de atraso | C7: 10145 | D7: 358246.51
B8: JUDICIAL | C8: 21 | D8: 0
B9: Mas 55 semanas de atraso | C9: 29560 | D9: 707663.32
B10: Total general | C10: =SUM(C5:C9) -> 55103 | D10: =SUM(D5:D9) -> 2307937.2
B12: COBRANZA GENERAL SAMANTHA 2
B13: Segmento | C13: Cuentas | D13: Recuperación
B14: Extrajudicial - 0 a 28 semanas de atraso | C14: 3278 | D14: 401065.16
B15: Extrajudicial - 29 a 39 semanas de atraso | C15: 1796 | D15: 43791.8
B16: Extrajudicial - 40 a 55 semanas de atraso | C16: 3437 | D16: 27977.86
B17: JUDICIAL | C17: 2 | D17: 0
B18: Mas 55 semanas de atraso | C18: 21210 | D18: 186703.29
B19: Total general | C19: =SUM(C14:C18) -> 29723 | D19: =SUM(D14:D18) -> 659538.11
B21: COBRANZA GENERAL EDITH
B22: Segmento | C22: Cuentas | D22: Recuperación
B23: Extrajudicial - 0 a 28 semanas de atraso | C23: 1487 | D23: 267104.14
B24: Extrajudicial - 29 a 39 semanas de atraso | C24: 1399 | D24: 127994.33
B25: Extrajudicial - 40 a 55 semanas de atraso | C25: 729 | D25: 82827.67
B26: Mas 55 semanas de atraso | C26: 8470 | D26: 107072.46
B27: Total general | C27: =SUM(C23:C26) -> 12085 | D27: =SUM(D23:D26) -> 584998.6
B29: COBRANZA GENERAL SOFIA
B30: Segmento | C30: Cuentas | D30: Recuperación
B31: Extrajudicial - 0 a 28 semanas de atraso | C31: 1242 | D31: 276362.47
B32: Extrajudicial - 29 a 39 semanas de atraso | C32: 1166 | D32: 93048.71
B33: Extrajudicial - 40 a 55 semanas de atraso | C33: 2996 | D33: 66191.44
B34: Mas 55 semanas de atraso | C34: 1900 | D34: 72521.39
B35: Total general | C35: =SUM(C31:C34) -> 7304 | D35: =SUM(D31:D34) -> 508124.01
B37: COBRANZA GENERAL FERNANDO
B38: Segmento | C38: Cuentas | D38: Recuperación
B39: Extrajudicial - 0 a 28 semanas de atraso | C39: 2702 | D39: 56616
B40: Total general | C40: =SUM(C39:C39) -> 2702 | D40: =SUM(D39:D39) -> 56616
B42: COBRANZA GENERAL FEDERICO
B43: Segmento | C43: Cuentas | D43: Recuperación
B44: Extrajudicial - 0 a 28 semanas de atraso | C44: 0 | D44: 250.86
B45: Extrajudicial - 29 a 39 semanas de atraso | C45: 123 | D45: 25329
B46: Extrajudicial - 40 a 55 semanas de atraso | C46: 164 | D46: 0
B47: Mas 55 semanas de atraso | C47: 856 | D47: 3934
...

Sheet DATA

Sheet EPR 29 MAR
B2: REPORTE CONSOLIDADO POR SEGMENTOS
B3: SALDO ACUMULADO SEMANA 13
B5: COORDINADOR | C5: SEGMENTO | D5: CUENTAS | E5: COBRANZA REAL | F5: CUOTA IDEAL | G5: VARIACION | H5: % VAR | I5: EPR | J5: EPR IDEAL | K5: VAR EPR
B6: Samatha y Zareth | C6: Extrajudicial - 0 a 28 semanas de atraso | D6: =SUMIF('REPORTE DIARIO'!B:B,'EPR 29 MAR'!C6, 'REPORTE DIARIO'!C:C) -> 16175 | E6: =SUMIF('REPORTE DIARIO'!B:B,'EPR 29 MAR'!C6, 'REPORTE DIARIO'!D:D) -> 1782527 | F6: =J6*D6 -> 2772857.1 | G6: =+E6-F6 -> -990330.13 | H6: =ABS(G6/F6) -> 0.35715152 | I6: =E6/D6 -> 110.2026 | J6: =(200/7)*6 -> 171.42857 | K6: =+I6-J6 -> -61.225974
B7: Gabriel | C7: Extrajudicial - 29 a 39 semanas de atraso | D7: =SUMIF('REPORTE DIARIO'!B:B,'EPR 29 MAR'!C7, 'REPORTE DIARIO'!C:C) -> 12599 | E7: =SUMIF('REPORTE DIARIO'!B:B,'EPR 29 MAR'!C7, 'REPORTE DIARIO'!D:D) -> 767913.17 | F7: =J7*D7 -> 1187905.7 | G7: =+E7-F7 -> -419992.54 | H7: =ABS(G7/F7) -> 0.35355714 | I7: =E7/D7 -> 60.950327 | J7: =(110/7)*6 -> 94.285714 | K7: =+I7-J7 -> -33.335387
B8: Gabriel | C8: Extrajudicial - 40 a 55 semanas de atraso | D8: =SUMIF('REPORTE DIARIO'!B:B,'EPR 29 MAR'!C8, 'REPORTE DIARIO'!C:C) -> 17486 | E8: =SUMIF('REPORTE DIARIO'!B:B,'EPR 29 MAR'!C8, 'REPORTE DIARIO'!D:D) -> 535243.48 | F8: =J8*D8 -> 674460 | G8: =+E8-F8 -> -139216.52 | H8: =ABS(G8/F8) -> 0.20641183 | I8: =E8/D8 -> 30.60983 | J8: =(45/7)*6 -> 38.571429 | K8: =+I8-J8 -> -7.961599
B9: Fernando | C9: Mas 55 semanas de atraso | D9: =SUMIF('REPORTE DIARIO'!B:B,'EPR 29 MAR'!C9, 'REPORTE DIARIO'!C:C) -> 62006 | E9: =SUMIF('REPORTE DIARIO'!B:B,'EPR 29 MAR'!C9, 'REPORTE DIARIO'!D:D) -> 1078371.5 | F9: =J9*D9 -> 797220 | G9: =+E9-F9 -> 281151.46 | H9: =ABS(G9/F9) -> 0.35266484 | I9: =E9/D9 -> 17.391405 | J9: =(15/7)*6 -> 12.857143 | K9: =+I9-J9 -> 4.5342622
C10: TOTAL | D10: =SUM(D6:D9) -> 108266 | E10: =SUM(E6:E9) -> 4164055.1 | F10: =SUM(F6:F9) -> 5432442.9 | G10: =+E10-F10 -> -1268387.7 | H10: =ABS(G10/F10) -> 0.23348386 | I10: =E10/D10 -> 38.461337 | J10: =F10/D10 -> 50.176813 | K10: =I10-J10 -> -11.715476
B12: Nota:
B13: El saldo consolidado incluye los siguientes despachos
B14: Samantha, Samantha 2, Sofia, Edith, Olguin, Fernando y Federico
