Workbook

Sheet REPORTE DIARIO
B3: COBRANZA GENERAL SAMANTHA
B4: Segmento | C4: Cuentas | D4: Recuperación
B5: Extrajudicial - 0 a 28 semanas de atraso | C5: 2778 | D5: 93402
B6: Extrajudicial - 29 a 39 semanas de atraso | C6: 3104 | D6: 55923
B7: Extrajudicial - 40 a 55 semanas de atraso | C7: 5654 | D7: 67942
B8: JUDICIAL | C8: 11 | D8: 0
B9: Mas 55 semanas de atraso | C9: 11931 | D9: 107204
B10: Total general | C10: =SUM(C5:C9) -> 23478 | D10: =SUM(D5:D9) -> 324471
B12: COBRANZA GENERAL SAMANTHA 2
B13: Segmento | C13: Cuentas | D13: Recuperación
B14: Extrajudicial - 0 a 28 semanas de atraso | C14: 2908 | D14: 40348
B15: Extrajudicial - 29 a 39 semanas de atraso | C15: 2090 | D15: 7853
B16: Extrajudicial - 40 a 55 semanas de atraso | C16: 2808 | D16: 43593
B17: JUDICIAL | C17: 2 | D17: 0
B18: Mas 55 semanas de atraso | C18: 17928 | D18: 20127
B19: Total general | C19: =SUM(C14:C18) -> 25736 | D19: =SUM(D14:D18) -> 111921
B21: COBRANZA GENERAL EDITH
B22: Segmento | C22: Cuentas | D22: Recuperación
B23: Extrajudicial - 0 a 28 semanas de atraso | C23: 3795 | D23: 48970.98
B24: Extrajudicial - 29 a 39 semanas de atraso | C24: 976 | D24: 6978
B25: Extrajudicial - 40 a 55 semanas de atraso | C25: 2118 | D25: 6706
B26: JUDICIAL | C26: 1 | D26: 0
B27: Mas 55 semanas de atraso | C27: 16874 | D27: 26451.6
B28: Total general | C28: =SUM(C23:C27) -> 23764 | D28: =SUM(D23:D27) -> 89106.58
B30: COBRANZA GENERAL SOFIA
B31: Segmento | C31: Cuentas | D31: Recuperación
B32: Extrajudicial - 0 a 28 semanas de atraso | C32: 49 | D32: 163
B33: Extrajudicial - 29 a 39 semanas de atraso | C33: 3270 | D33: 22488
B34: Extrajudicial - 40 a 55 semanas de atraso | C34: 285 | D34: 857
B35: Mas 55 semanas de atraso | C35: 3954 | D35: 11698
B36: Total general | C36: =SUM(C32:C35) -> 7558 | D36: =SUM(D32:D35) -> 35206
B38: COBRANZA GENERAL FERNANDO
B39: Segmento | C39: Cuentas | D39: Recuperación
B40: Extrajudicial - 0 a 28 semanas de atraso | C40: 2804 | D40: 23632
B41: Total general | C41: =SUM(C40:C40) -> 2804 | D41: =SUM(D40:D40) -> 23632
B43: COBRANZA GENERAL OLGUIN
B44: Segmento | C44: Cuentas | D44: Recuperación
B45: Extrajudicial - 0 a 28 semanas de atraso | C45: 2256 | D45: 8138
B46: Extrajudicial - 29 a 39 semanas de atraso | C46: 1396 | D46: 5608
B47: Extrajudicial - 40 a 55 semanas de atraso | C47: 2259 | D47: 3430
...

Sheet DATA

Sheet EPR 07 JUN
B2: REPORTE CONSOLIDADO POR SEGMENTOS
B3: COBRANZA 07 JUNIO
B5: COORDINADOR | C5: SEGMENTO | D5: CUENTAS | E5: COBRANZA REAL | F5: CUOTA IDEAL | G5: VARIACION | H5: % VAR | I5: EPR | J5: EPR IDEAL | K5: VAR EPR
B6: Zareth | C6: Extrajudicial - 0 a 28 semanas de atraso | D6: =SUMIF('REPORTE DIARIO'!B:B,'EPR 07 JUN'!C6, 'REPORTE DIARIO'!C:C) -> 15174 | E6: =SUMIF('REPORTE DIARIO'!B:B,'EPR 07 JUN'!C6, 'REPORTE DIARIO'!D:D) -> 217008.98 | F6: =J6*D6 -> 476897.14 | G6: =+E6-F6 -> -259888.16 | H6: =ABS(G6/F6) -> 0.54495643 | I6: =E6/D6 -> 14.301369 | J6: =220/7 -> 31.428571 | K6: =+I6-J6 -> -17.127202
B7: Gabriel | C7: Extrajudicial - 29 a 39 semanas de atraso | D7: =SUMIF('REPORTE DIARIO'!B:B,'EPR 07 JUN'!C7, 'REPORTE DIARIO'!C:C) -> 11458 | E7: =SUMIF('REPORTE DIARIO'!B:B,'EPR 07 JUN'!C7, 'REPORTE DIARIO'!D:D) -> 100663 | F7: =J7*D7 -> 180054.29 | G7: =+E7-F7 -> -79391.286 | H7: =ABS(G7/F7) -> 0.44092972 | I7: =E7/D7 -> 8.7853901 | J7: =110/7 -> 15.714286 | K7: =+I7-J7 -> -6.9288956
B8: Gabriel | C8: Extrajudicial - 40 a 55 semanas de atraso | D8: =SUMIF('REPORTE DIARIO'!B:B,'EPR 07 JUN'!C8, 'REPORTE DIARIO'!C:C) -> 13929 | E8: =SUMIF('REPORTE DIARIO'!B:B,'EPR 07 JUN'!C8, 'REPORTE DIARIO'!D:D) -> 124175 | F8: =J8*D8 -> 89543.571 | G8: =+E8-F8 -> 34631.429 | H8: =ABS(G8/F8) -> 0.38675505 | I8: =E8/D8 -> 8.9148539 | J8: =45/7 -> 6.4285714 | K8: =+I8-J8 -> 2.4862825
B9: Fernando (Naucalpan) | C9: Mas 55 semanas de atraso | D9: =SUMIF('REPORTE DIARIO'!B:B,'EPR 07 JUN'!C9, 'REPORTE DIARIO'!C:C) -> 55394 | E9: =SUMIF('REPORTE DIARIO'!B:B,'EPR 07 JUN'!C9, 'REPORTE DIARIO'!D:D) -> 168928.6 | F9: =J9*D9 -> 118701.43 | G9: =+E9-F9 -> 50227.171 | H9: =ABS(G9/F9) -> 0.42313873 | I9: =E9/D9 -> 3.049583 | J9: =15/7 -> 2.1428571 | K9: =+I9-J9 -> 0.90672584
C10: TOTAL | D10: =SUM(D6:D9) -> 95955 | E10: =SUM(E6:E9) -> 610775.58 | F10: =SUM(F6:F9) -> 865196.43 | G10: =+E10-F10 -> -254420.85 | H10: =ABS(G10/F10) -> 0.29406137 | I10: =E10/D10 -> 6.3652293 | J10: =F10/D10 -> 9.0166894 | K10: =I10-J10 -> -2.65146
B12: Nota:
B13: El saldo consolidado incluye los siguientes despachos
B14: Samantha, Samantha 2, Sofia, Edith, Fernando, Olguin y Federico
