Workbook

Sheet REPORTE DIARIO
B3: COBRANZA GENERAL SAMANTHA
B4: Segmento | C4: Cuentas | D4: Recuperación
B5: Extrajudicial - 0 a 28 semanas de atraso | C5: 4653 | D5: 486894.44
B6: Extrajudicial - 29 a 39 semanas de atraso | C6: 4676 | D6: 266845.08
B7: Extrajudicial - 40 a 55 semanas de atraso | C7: 6102 | D7: 202748.84
B8: JUDICIAL | C8: 8 | D8: 0
B9: Mas 55 semanas de atraso | C9: 13432 | D9: 283244.1
B10: Total general | C10: =SUM(C5:C9) -> 28871 | D10: =SUM(D5:D9) -> 1239732.5
B12: COBRANZA GENERAL EDITH
B13: Segmento | C13: Cuentas | D13: Recuperación
B14: Extrajudicial - 0 a 28 semanas de atraso | C14: 4102 | D14: 351833.28
B15: Extrajudicial - 29 a 39 semanas de atraso | C15: 2390 | D15: 133791.28
B16: Extrajudicial - 40 a 55 semanas de atraso | C16: 1214 | D16: 52298.43
B17: Mas 55 semanas de atraso | C17: 9597 | D17: 30355.4
B18: Total general | C18: =SUM(C14:C17) -> 17303 | D18: =SUM(D14:D17) -> 568278.39
B20: COBRANZA GENERAL SAMANTHA 2
B21: Segmento | C21: Cuentas | D21: Recuperación
B22: Extrajudicial - 0 a 28 semanas de atraso | C22: 2318 | D22: 162808.45
B23: Extrajudicial - 29 a 39 semanas de atraso | C23: 1677 | D23: 98977.79
B24: Extrajudicial - 40 a 55 semanas de atraso | C24: 3065 | D24: 80677.6
B25: JUDICIAL | C25: 2 | D25: 0
B26: Mas 55 semanas de atraso | C26: 21852 | D26: 136246.82
B27: Total general | C27: =SUM(C22:C26) -> 28914 | D27: =SUM(D22:D26) -> 478710.66
B29: COBRANZA GENERAL SOFIA
B30: Segmento | C30: Cuentas | D30: Recuperación
B31: Extrajudicial - 0 a 28 semanas de atraso | C31: 339 | D31: 184459.86
B32: Extrajudicial - 29 a 39 semanas de atraso | C32: 1752 | D32: 119436.47
B33: Extrajudicial - 40 a 55 semanas de atraso | C33: 2383 | D33: 55054.33
B34: Mas 55 semanas de atraso | C34: 4264 | D34: 4839.51
B35: Total general | C35: =SUM(C31:C34) -> 8738 | D35: =SUM(D31:D34) -> 363790.17
B37: COBRANZA GENERAL FERNANDO
B38: Segmento | C38: Cuentas | D38: Recuperación
B39: Extrajudicial - 0 a 28 semanas de atraso | C39: 2061 | D39: 36525
B40: Total general | C40: =SUM(C39:C39) -> 2061 | D40: =SUM(D39:D39) -> 36525
B42: COBRANZA GENERAL FEDERICO
B43: Segmento | C43: Cuentas | D43: Recuperación
B44: Extrajudicial - 0 a 28 semanas de atraso | C44: 39 | D44: 1354
B45: Extrajudicial - 29 a 39 semanas de atraso | C45: 330 | D45: 3323
B46: Extrajudicial - 40 a 55 semanas de atraso | C46: 261 | D46: 1320
B47: Mas 55 semanas de atraso | C47: 1947 | D47: 21212.71
...

Sheet DATA

Sheet EPR 26 ABR
B2: REPORTE CONSOLIDADO POR SEGMENTOS
B3: SALDO ACUMULADO SEMANA 17
B5: COORDINADOR | C5: SEGMENTO | D5: CUENTAS | E5: COBRANZA REAL | F5: CUOTA IDEAL | G5: VARIACION | H5: % VAR | I5: EPR | J5: EPR IDEAL | K5: VAR EPR
B6: Samatha y Zareth | C6: Extrajudicial - 0 a 28 semanas de atraso | D6: =SUMIF('REPORTE DIARIO'!B:B,'EPR 26 ABR'!C6, 'REPORTE DIARIO'!C:C) -> 13597 | E6: =SUMIF('REPORTE DIARIO'!B:B,'EPR 26 ABR'!C6, 'REPORTE DIARIO'!D:D) -> 1224909.5 | F6: =J6*D6 -> 2330914.3 | G6: =+E6-F6 -> -1106004.8 | H6: =ABS(G6/F6) -> 0.47449398 | I6: =E6/D6 -> 90.086746 | J6: =(200/7)*6 -> 171.42857 | K6: =+I6-J6 -> -81.341826
B7: Gabriel | C7: Extrajudicial - 29 a 39 semanas de atraso | D7: =SUMIF('REPORTE DIARIO'!B:B,'EPR 26 ABR'!C7, 'REPORTE DIARIO'!C:C) -> 10977 | E7: =SUMIF('REPORTE DIARIO'!B:B,'EPR 26 ABR'!C7, 'REPORTE DIARIO'!D:D) -> 623873.62 | F7: =J7*D7 -> 1034974.3 | G7: =+E7-F7 -> -411100.67 | H7: =ABS(G7/F7) -> 0.39720858 | I7: =E7/D7 -> 56.83462 | J7: =(110/7)*6 -> 94.285714 | K7: =+I7-J7 -> -37.451095
B8: Gabriel | C8: Extrajudicial - 40 a 55 semanas de atraso | D8: =SUMIF('REPORTE DIARIO'!B:B,'EPR 26 ABR'!C8, 'REPORTE DIARIO'!C:C) -> 13591 | E8: =SUMIF('REPORTE DIARIO'!B:B,'EPR 26 ABR'!C8, 'REPORTE DIARIO'!D:D) -> 392099.2 | F8: =J8*D8 -> 524224.29 | G8: =+E8-F8 -> -132125.09 | H8: =ABS(G8/F8) -> 0.25203923 | I8: =E8/D8 -> 28.849915 | J8: =(45/7)*6 -> 38.571429 | K8: =+I8-J8 -> -9.7215132
B9: Fernando | C9: Mas 55 semanas de atraso | D9: =SUMIF('REPORTE DIARIO'!B:B,'EPR 26 ABR'!C9, 'REPORTE DIARIO'!C:C) -> 51929 | E9: =SUMIF('REPORTE DIARIO'!B:B,'EPR 26 ABR'!C9, 'REPORTE DIARIO'!D:D) -> 478484.54 | F9: =J9*D9 -> 667658.57 | G9: =+E9-F9 -> -189174.03 | H9: =ABS(G9/F9) -> 0.28333948 | I9: =E9/D9 -> 9.2142067 | J9: =(15/7)*6 -> 12.857143 | K9: =+I9-J9 -> -3.6429362
C10: TOTAL | D10: =SUM(D6:D9) -> 90094 | E10: =SUM(E6:E9) -> 2719366.8 | F10: =SUM(F6:F9) -> 4557771.4 | G10: =+E10-F10 -> -1838404.6 | H10: =ABS(G10/F10) -> 0.40335603 | I10: =E10/D10 -> 30.183662 | J10: =F10/D10 -> 50.589067 | K10: =I10-J10 -> -20.405405
B12: Nota:
B13: El saldo consolidado incluye los siguientes despachos
B14: Samantha, Samantha 2, Sofia, Edith, Fernando, Olguin y Federico
