Workbook

Sheet REPORTE DIARIO
B3: COBRANZA GENERAL SAMANTHA
B4: Segmento | C4: Cuentas | D4: Recuperación
B5: Extrajudicial - 0 a 28 semanas de atraso | C5: 3212 | D5: 256160.05
B6: Extrajudicial - 29 a 39 semanas de atraso | C6: 3812 | D6: 111457.74
B7: Extrajudicial - 40 a 55 semanas de atraso | C7: 6151 | D7: 68492.05
B8: JUDICIAL | C8: 11 | D8: 0
B9: Mas 55 semanas de atraso | C9: 14919 | D9: 90160.32
B10: Total general | C10: =SUM(C5:C9) -> 28105 | D10: =SUM(D5:D9) -> 526270.16
B12: COBRANZA GENERAL SAMANTHA 2
B13: Segmento | C13: Cuentas | D13: Recuperación
B14: Extrajudicial - 0 a 28 semanas de atraso | C14: 2569 | D14: 31056.6
B15: Extrajudicial - 29 a 39 semanas de atraso | C15: 1592 | D15: 53698.82
B16: Extrajudicial - 40 a 55 semanas de atraso | C16: 2161 | D16: 22326
B17: JUDICIAL | C17: 0 | D17: 0
B18: Mas 55 semanas de atraso | C18: 12703 | D18: 13384
B19: Total general | C19: =SUM(C14:C18) -> 19025 | D19: =SUM(D14:D18) -> 120465.42
B21: COBRANZA GENERAL EDITH
B22: Segmento | C22: Cuentas | D22: Recuperación
B23: Extrajudicial - 0 a 28 semanas de atraso | C23: 3083 | D23: 33075.51
B24: Extrajudicial - 29 a 39 semanas de atraso | C24: 1553 | D24: 22817.52
B25: Extrajudicial - 40 a 55 semanas de atraso | C25: 2135 | D25: 17623.01
B26: JUDICIAL | C26: 1 | D26: 0
B27: Mas 55 semanas de atraso | C27: 17311 | D27: 31673.08
B28: Total general | C28: =SUM(C23:C27) -> 24083 | D28: =SUM(D23:D27) -> 105189.12
B30: COBRANZA GENERAL SOFIA
B31: Segmento | C31: Cuentas | D31: Recuperación
B32: Extrajudicial - 0 a 28 semanas de atraso | C32: 493 | D32: 7313.39
B33: Extrajudicial - 29 a 39 semanas de atraso | C33: 3048 | D33: 56621.05
B34: Extrajudicial - 40 a 55 semanas de atraso | C34: 486 | D34: 2326
B35: Mas 55 semanas de atraso | C35: 4018 | D35: 1159
B36: Total general | C36: =SUM(C32:C35) -> 8045 | D36: =SUM(D32:D35) -> 67419.44
B38: COBRANZA GENERAL OLGUIN
B39: Segmento | C39: Cuentas | D39: Recuperación
B40: Extrajudicial - 0 a 28 semanas de atraso | C40: 2188 | D40: 9420
B41: Extrajudicial - 29 a 39 semanas de atraso | C41: 1276 | D41: 30371
B42: Extrajudicial - 40 a 55 semanas de atraso | C42: 1671 | D42: 0
B43: Mas 55 semanas de atraso | C43: 1865 | D43: 4039.88
B44: Total general | C44: =SUM(C40:C43) -> 7000 | D44: =SUM(D40:D43) -> 43830.88
B46: COBRANZA GENERAL FERNANDO
B47: Segmento | C47: Cuentas | D47: Recuperación
...

Sheet DATA

Sheet EPR 24 JUN
B2: REPORTE CONSOLIDADO POR SEGMENTOS
B3: SALDO ACUMULADO SEMANA 26
B5: COORDINADOR | C5: SEGMENTO | D5: CUENTAS | E5: COBRANZA REAL | F5: CUOTA IDEAL | G5: VARIACION | H5: % VAR | I5: EPR | J5: EPR IDEAL | K5: VAR EPR
B6: Zareth | C6: Extrajudicial - 0 a 28 semanas de atraso | D6: =SUMIF('REPORTE DIARIO'!B:B,'EPR 24 JUN'!C6, 'REPORTE DIARIO'!C:C) -> 14017 | E6: =SUMIF('REPORTE DIARIO'!B:B,'EPR 24 JUN'!C6, 'REPORTE DIARIO'!D:D) -> 348182.55 | F6: =J6*D6 -> 881068.57 | G6: =+E6-F6 -> -532886.02 | H6: =ABS(G6/F6) -> 0.60481788 | I6: =E6/D6 -> 24.840019 | J6: =(220/7)*2 -> 62.857143 | K6: =+I6-J6 -> -38.017124
B7: Gabriel | C7: Extrajudicial - 29 a 39 semanas de atraso | D7: =SUMIF('REPORTE DIARIO'!B:B,'EPR 24 JUN'!C7, 'REPORTE DIARIO'!C:C) -> 11685 | E7: =SUMIF('REPORTE DIARIO'!B:B,'EPR 24 JUN'!C7, 'REPORTE DIARIO'!D:D) -> 276566.13 | F7: =J7*D7 -> 367242.86 | G7: =+E7-F7 -> -90676.727 | H7: =ABS(G7/F7) -> 0.24691216 | I7: =E7/D7 -> 23.668475 | J7: =(110/7)*2 -> 31.428571 | K7: =+I7-J7 -> -7.7600965
B8: Gabriel | C8: Extrajudicial - 40 a 55 semanas de atraso | D8: =SUMIF('REPORTE DIARIO'!B:B,'EPR 24 JUN'!C8, 'REPORTE DIARIO'!C:C) -> 13221 | E8: =SUMIF('REPORTE DIARIO'!B:B,'EPR 24 JUN'!C8, 'REPORTE DIARIO'!D:D) -> 110767.06 | F8: =J8*D8 -> 169984.29 | G8: =+E8-F8 -> -59217.226 | H8: =ABS(G8/F8) -> 0.34836882 | I8: =E8/D8 -> 8.3781151 | J8: =(45/7)*2 -> 12.857143 | K8: =+I8-J8 -> -4.4790277
B9: Fernando (Naucalpan) | C9: Mas 55 semanas de atraso | D9: =SUMIF('REPORTE DIARIO'!B:B,'EPR 24 JUN'!C9, 'REPORTE DIARIO'!C:C) -> 53239 | E9: =SUMIF('REPORTE DIARIO'!B:B,'EPR 24 JUN'!C9, 'REPORTE DIARIO'!D:D) -> 141703.28 | F9: =J9*D9 -> 228167.14 | G9: =+E9-F9 -> -86463.863 | H9: =ABS(G9/F9) -> 0.37894967 | I9: =E9/D9 -> 2.6616443 | J9: =(15/7)*2 -> 4.2857143 | K9: =+I9-J9 -> -1.62407
C10: TOTAL | D10: =SUM(D6:D9) -> 92162 | E10: =SUM(E6:E9) -> 877219.02 | F10: =SUM(F6:F9) -> 1646462.9 | G10: =+E10-F10 -> -769243.84 | H10: =ABS(G10/F10) -> 0.46720995 | I10: =E10/D10 -> 9.518229 | J10: =F10/D10 -> 17.864878 | K10: =I10-J10 -> -8.3466487
B12: Nota:
B13: El saldo consolidado incluye los siguientes despachos
B14: Samantha, Samantha 2, Sofia, Edith, Fernando, Olguin y Federico
