Workbook

Sheet REPORTE DIARIO
B3: COBRANZA GENERAL SAMANTHA
B4: Segmento | C4: Cuentas | D4: Recuperación
B5: Extrajudicial - 0 a 28 semanas de atraso | C5: 4201 | D5: 372633.65
B6: Extrajudicial - 29 a 39 semanas de atraso | C6: 4314 | D6: 128497.25
B7: Extrajudicial - 40 a 55 semanas de atraso | C7: 6057 | D7: 174165.62
B8: JUDICIAL | C8: 10 | D8: 0
B9: Mas 55 semanas de atraso | C9: 13193 | D9: 170290.58
B10: Total general | C10: =SUM(C5:C9) -> 27775 | D10: =SUM(D5:D9) -> 845587.1
B12: COBRANZA GENERAL SAMANTHA 2
B13: Segmento | C13: Cuentas | D13: Recuperación
B14: Extrajudicial - 0 a 28 semanas de atraso | C14: 1930 | D14: 132096.34
B15: Extrajudicial - 29 a 39 semanas de atraso | C15: 1797 | D15: 52662
B16: Extrajudicial - 40 a 55 semanas de atraso | C16: 3080 | D16: 86641
B17: JUDICIAL | C17: 2 | D17: 0
B18: Mas 55 semanas de atraso | C18: 20751 | D18: 114238.04
B19: Total general | C19: =SUM(C14:C18) -> 27560 | D19: =SUM(D14:D18) -> 385637.38
B21: COBRANZA GENERAL EDITH
B22: Segmento | C22: Cuentas | D22: Recuperación
B23: Extrajudicial - 0 a 28 semanas de atraso | C23: 3665 | D23: 192112.38
B24: Extrajudicial - 29 a 39 semanas de atraso | C24: 1963 | D24: 32493.69
B25: Extrajudicial - 40 a 55 semanas de atraso | C25: 2221 | D25: 20203.48
B26: Mas 55 semanas de atraso | C26: 9734 | D26: 68536.8
B27: Total general | C27: =SUM(C23:C26) -> 17583 | D27: =SUM(D23:D26) -> 313346.35
B29: COBRANZA GENERAL SOFIA
B30: Segmento | C30: Cuentas | D30: Recuperación
B31: Extrajudicial - 0 a 28 semanas de atraso | C31: 293 | D31: 38359.97
B32: Extrajudicial - 29 a 39 semanas de atraso | C32: 1534 | D32: 46073.1
B33: Extrajudicial - 40 a 55 semanas de atraso | C33: 2304 | D33: 20361.78
B34: Mas 55 semanas de atraso | C34: 4229 | D34: 2157
B35: Total general | C35: =SUM(C31:C34) -> 8360 | D35: =SUM(D31:D34) -> 106951.85
B37: COBRANZA GENERAL OLGUIN
B38: Segmento | C38: Cuentas | D38: Recuperación
B39: Extrajudicial - 0 a 28 semanas de atraso | C39: 150 | D39: 14872
B40: Extrajudicial - 29 a 39 semanas de atraso | C40: 444 | D40: 76054
B41: Extrajudicial - 40 a 55 semanas de atraso | C41: 773 | D41: 1589
B42: Mas 55 semanas de atraso | C42: 1014 | D42: 3261
B43: Total general | C43: =SUM(C39:C42) -> 2381 | D43: =SUM(D39:D42) -> 95776
B45: COBRANZA GENERAL FEDERICO
B46: Segmento | C46: Cuentas | D46: Recuperación
B47: Extrajudicial - 0 a 28 semanas de atraso | C47: 110 | D47: 2323
...

Sheet DATA

Sheet EPR 09 MAYO
B2: REPORTE CONSOLIDADO POR SEGMENTOS
B3: SALDO ACUMULADO SEMANA 19
B5: COORDINADOR | C5: SEGMENTO | D5: CUENTAS | E5: COBRANZA REAL | F5: CUOTA IDEAL | G5: VARIACION | H5: % VAR | I5: EPR | J5: EPR IDEAL | K5: VAR EPR
B6: Zareth | C6: Extrajudicial - 0 a 28 semanas de atraso | D6: =SUMIF('REPORTE DIARIO'!B:B,'EPR 09 MAYO'!C6, 'REPORTE DIARIO'!C:C) -> 12361 | E6: =SUMIF('REPORTE DIARIO'!B:B,'EPR 09 MAYO'!C6, 'REPORTE DIARIO'!D:D) -> 776160.34 | F6: =J6*D6 -> 1942442.9 | G6: =+E6-F6 -> -1166282.5 | H6: =ABS(G6/F6) -> 0.6004205 | I6: =E6/D6 -> 62.791064 | J6: =(220/7)*5 -> 157.14286 | K6: =+I6-J6 -> -94.351793
B7: Gabriel | C7: Extrajudicial - 29 a 39 semanas de atraso | D7: =SUMIF('REPORTE DIARIO'!B:B,'EPR 09 MAYO'!C7, 'REPORTE DIARIO'!C:C) -> 10670 | E7: =SUMIF('REPORTE DIARIO'!B:B,'EPR 09 MAYO'!C7, 'REPORTE DIARIO'!D:D) -> 338203.04 | F7: =J7*D7 -> 838357.14 | G7: =+E7-F7 -> -500154.1 | H7: =ABS(G7/F7) -> 0.59658835 | I7: =E7/D7 -> 31.69663 | J7: =(110/7)*5 -> 78.571429 | K7: =+I7-J7 -> -46.874799
B8: Gabriel | C8: Extrajudicial - 40 a 55 semanas de atraso | D8: =SUMIF('REPORTE DIARIO'!B:B,'EPR 09 MAYO'!C8, 'REPORTE DIARIO'!C:C) -> 14897 | E8: =SUMIF('REPORTE DIARIO'!B:B,'EPR 09 MAYO'!C8, 'REPORTE DIARIO'!D:D) -> 304280.88 | F8: =J8*D8 -> 478832.14 | G8: =+E8-F8 -> -174551.26 | H8: =ABS(G8/F8) -> 0.36453539 | I8: =E8/D8 -> 20.425648 | J8: =(45/7)*5 -> 32.142857 | K8: =+I8-J8 -> -11.717209
B9: Fernando (Naucalpan) | C9: Mas 55 semanas de atraso | D9: =SUMIF('REPORTE DIARIO'!B:B,'EPR 09 MAYO'!C9, 'REPORTE DIARIO'!C:C) -> 51027 | E9: =SUMIF('REPORTE DIARIO'!B:B,'EPR 09 MAYO'!C9, 'REPORTE DIARIO'!D:D) -> 382715.42 | F9: =J9*D9 -> 546717.86 | G9: =+E9-F9 -> -164002.44 | H9: =ABS(G9/F9) -> 0.29997637 | I9: =E9/D9 -> 7.5002532 | J9: =(15/7)*5 -> 10.714286 | K9: =+I9-J9 -> -3.2140325
C10: TOTAL | D10: =SUM(D6:D9) -> 88955 | E10: =SUM(E6:E9) -> 1801359.7 | F10: =SUM(F6:F9) -> 3806350 | G10: =+E10-F10 -> -2004990.3 | H10: =ABS(G10/F10) -> 0.52674881 | I10: =E10/D10 -> 20.250235 | J10: =F10/D10 -> 42.789613 | K10: =I10-J10 -> -22.539377
B12: Nota:
B13: El saldo consolidado incluye los siguientes despachos
B14: Samantha, Samantha 2, Sofia, Edith, Fernando, Olguin y Federico
