Workbook

Sheet REPORTE DIARIO
B3: COBRANZA GENERAL SAMANTHA
B4: Segmento | C4: Cuentas | D4: Recuperación
B5: Extrajudicial - 0 a 28 semanas de atraso | C5: 4096 | D5: 507590.49
B6: Extrajudicial - 29 a 39 semanas de atraso | C6: 3563 | D6: 243222.94
B7: Extrajudicial - 40 a 55 semanas de atraso | C7: 6844 | D7: 310500.48
B8: JUDICIAL | C8: 1977 | D8: 874
B9: Mas 55 semanas de atraso | C9: 15786 | D9: 384199.99
B10: Total general | C10: =SUM(C5:C9) -> 32266 | D10: =SUM(D5:D9) -> 1446387.9
B12: COBRANZA GENERAL EDITH
B13: Segmento | C13: Cuentas | D13: Recuperación
B14: Extrajudicial - 0 a 28 semanas de atraso | C14: 2592 | D14: 310497.64
B15: Extrajudicial - 29 a 39 semanas de atraso | C15: 827 | D15: 35360.69
B16: Extrajudicial - 40 a 55 semanas de atraso | C16: 2347 | D16: 55895.45
B17: JUDICIAL | C17: 1 | D17: 0
B18: Mas 55 semanas de atraso | C18: 17261 | D18: 96722.08
B19: Total general | C19: =SUM(C14:C18) -> 23028 | D19: =SUM(D14:D18) -> 498475.86
B21: COBRANZA GENERAL SAMANTHA 2
B22: Segmento | C22: Cuentas | D22: Recuperación
B23: Extrajudicial - 0 a 28 semanas de atraso | C23: 4515 | D23: 212237.83
B24: Extrajudicial - 29 a 39 semanas de atraso | C24: 2486 | D24: 45687.08
B25: Extrajudicial - 40 a 55 semanas de atraso | C25: 3775 | D25: 78532.23
B26: JUDICIAL | C26: 0 | D26: 0
B27: Mas 55 semanas de atraso | C27: 14377 | D27: 130689.56
B28: Total general | C28: =SUM(C23:C27) -> 25153 | D28: =SUM(D23:D27) -> 467146.7
B30: COBRANZA GENERAL SOFIA
B31: Segmento | C31: Cuentas | D31: Recuperación
B32: Extrajudicial - 0 a 28 semanas de atraso | C32: 474 | D32: 120005.02
B33: Extrajudicial - 29 a 39 semanas de atraso | C33: 1523 | D33: 145414.66
B34: Extrajudicial - 40 a 55 semanas de atraso | C34: 805 | D34: 30483.02
B35: Mas 55 semanas de atraso | C35: 4323 | D35: 9505
B36: Total general | C36: =SUM(C32:C35) -> 7125 | D36: =SUM(D32:D35) -> 305407.7
B38: COBRANZA GENERAL OLGUIN
B39: Segmento | C39: Cuentas | D39: Recuperación
B40: Extrajudicial - 0 a 28 semanas de atraso | C40: 630 | D40: 76388.18
B41: Extrajudicial - 29 a 39 semanas de atraso | C41: 269 | D41: 5691
B42: Extrajudicial - 40 a 55 semanas de atraso | C42: 367 | D42: 8854
B43: Mas 55 semanas de atraso | C43: 419 | D43: 18827
B44: Total general | C44: =SUM(C40:C43) -> 1685 | D44: =SUM(D40:D43) -> 109760.18
B46: COBRANZA GENERAL FERNANDO
B47: Segmento | C47: Cuentas | D47: Recuperación
...

Sheet DATA

Sheet EPR 26 JUN
B2: REPORTE CONSOLIDADO POR SEGMENTOS
B3: SALDO ACUMULADO SEMANA 26
B5: COORDINADOR | C5: SEGMENTO | D5: CUENTAS | E5: COBRANZA REAL | F5: CUOTA IDEAL | G5: VARIACION | H5: % VAR | I5: EPR | J5: EPR IDEAL | K5: VAR EPR
B6: Zareth | C6: Extrajudicial - 0 a 28 semanas de atraso | D6: =SUMIF('REPORTE DIARIO'!B:B,'EPR 26 JUN'!C6, 'REPORTE DIARIO'!C:C) -> 14848 | E6: =SUMIF('REPORTE DIARIO'!B:B,'EPR 26 JUN'!C6, 'REPORTE DIARIO'!D:D) -> 1372000.5 | F6: =J6*D6 -> 933302.86 | G6: =+E6-F6 -> 438697.66 | H6: =ABS(G6/F6) -> 0.47004856 | I6: =E6/D6 -> 92.403052 | J6: =(220/7)*2 -> 62.857143 | K6: =+I6-J6 -> 29.545909
B7: Gabriel | C7: Extrajudicial - 29 a 39 semanas de atraso | D7: =SUMIF('REPORTE DIARIO'!B:B,'EPR 26 JUN'!C7, 'REPORTE DIARIO'!C:C) -> 8844 | E7: =SUMIF('REPORTE DIARIO'!B:B,'EPR 26 JUN'!C7, 'REPORTE DIARIO'!D:D) -> 475876.37 | F7: =J7*D7 -> 277954.29 | G7: =+E7-F7 -> 197922.08 | H7: =ABS(G7/F7) -> 0.71206704 | I7: =E7/D7 -> 53.807821 | J7: =(110/7)*2 -> 31.428571 | K7: =+I7-J7 -> 22.37925
B8: Gabriel | C8: Extrajudicial - 40 a 55 semanas de atraso | D8: =SUMIF('REPORTE DIARIO'!B:B,'EPR 26 JUN'!C8, 'REPORTE DIARIO'!C:C) -> 14738 | E8: =SUMIF('REPORTE DIARIO'!B:B,'EPR 26 JUN'!C8, 'REPORTE DIARIO'!D:D) -> 490724.18 | F8: =J8*D8 -> 189488.57 | G8: =+E8-F8 -> 301235.61 | H8: =ABS(G8/F8) -> 1.5897297 | I8: =E8/D8 -> 33.296525 | J8: =(45/7)*2 -> 12.857143 | K8: =+I8-J8 -> 20.439382
B9: Fernando (Naucalpan) | C9: Mas 55 semanas de atraso | D9: =SUMIF('REPORTE DIARIO'!B:B,'EPR 26 JUN'!C9, 'REPORTE DIARIO'!C:C) -> 54575 | E9: =SUMIF('REPORTE DIARIO'!B:B,'EPR 26 JUN'!C9, 'REPORTE DIARIO'!D:D) -> 648130.63 | F9: =J9*D9 -> 233892.86 | G9: =+E9-F9 -> 414237.77 | H9: =ABS(G9/F9) -> 1.7710578 | I9: =E9/D9 -> 11.875962 | J9: =(15/7)*2 -> 4.2857143 | K9: =+I9-J9 -> 7.5902478
C10: TOTAL | D10: =SUM(D6:D9) -> 93005 | E10: =SUM(E6:E9) -> 2986731.7 | F10: =SUM(F6:F9) -> 1634638.6 | G10: =+E10-F10 -> 1352093.1 | H10: =ABS(G10/F10) -> 0.82715112 | I10: =E10/D10 -> 32.113668 | J10: =F10/D10 -> 17.575814 | K10: =I10-J10 -> 14.537854
B12: Nota:
B13: El saldo consolidado incluye los siguientes despachos
B14: Samantha, Samantha 2, Sofia, Edith, Fernando, Olguin y Federico
