Workbook

Sheet REPORTE DIARIO
B3: COBRANZA GENERAL SAMANTHA
B4: Segmento | C4: Cuentas | D4: Recuperación
B5: Extrajudicial - 0 a 28 semanas de atraso | C5: 6527 | D5: 171797.05
B6: Extrajudicial - 29 a 39 semanas de atraso | C6: 5200 | D6: 165085.26
B7: Extrajudicial - 40 a 55 semanas de atraso | C7: 7156 | D7: 91999.02
B8: JUDICIAL | C8: 21 | D8: 0
B9: Mas 55 semanas de atraso | C9: 21109 | D9: 103174.7
B10: Total general | C10: =SUM(C5:C9) -> 40013 | D10: =SUM(D5:D9) -> 532056.03
B12: COBRANZA GENERAL SOFIA
B13: Segmento | C13: Cuentas | D13: Recuperación
B14: Extrajudicial - 0 a 28 semanas de atraso | C14: 1346 | D14: 77211.2
B15: Extrajudicial - 29 a 39 semanas de atraso | C15: 1921 | D15: 57044.72
B16: Extrajudicial - 40 a 55 semanas de atraso | C16: 2533 | D16: 38728.52
B17: Mas 55 semanas de atraso | C17: 4264 | D17: 1909
B18: Total general | C18: =SUM(C14:C17) -> 10064 | D18: =SUM(D14:D17) -> 174893.44
B20: COBRANZA GENERAL EDITH
B21: Segmento | C21: Cuentas | D21: Recuperación
B22: Extrajudicial - 0 a 28 semanas de atraso | C22: 2046 | D22: 72635.18
B23: Extrajudicial - 29 a 39 semanas de atraso | C23: 2351 | D23: 56338.3
B24: Extrajudicial - 40 a 55 semanas de atraso | C24: 1047 | D24: 6183
B25: Mas 55 semanas de atraso | C25: 9429 | D25: 7526
B26: Total general | C26: =SUM(C22:C25) -> 14873 | D26: =SUM(D22:D25) -> 142682.48
B28: COBRANZA GENERAL SAMANTHA 2
B29: Segmento | C29: Cuentas | D29: Recuperación
B30: Extrajudicial - 0 a 28 semanas de atraso | C30: 2404 | D30: 77450.18
B31: Extrajudicial - 29 a 39 semanas de atraso | C31: 1637 | D31: 19615
B32: Extrajudicial - 40 a 55 semanas de atraso | C32: 3301 | D32: 14821
B33: JUDICIAL | C33: 2 | D33: 0
B34: Mas 55 semanas de atraso | C34: 21679 | D34: 23511.88
B35: Total general | C35: =SUM(C30:C34) -> 29023 | D35: =SUM(D30:D34) -> 135398.06
B37: COBRANZA GENERAL FERNANDO
B38: Segmento | C38: Cuentas | D38: Recuperación
B39: Extrajudicial - 0 a 28 semanas de atraso | C39: 1358 | D39: 21334
B40: Total general | C40: =SUM(C39:C39) -> 1358 | D40: =SUM(D39:D39) -> 21334
B42: COBRANZA GENERAL FEDERICO
B43: Segmento | C43: Cuentas | D43: Recuperación
B44: Extrajudicial - 0 a 28 semanas de atraso | C44: 39 | D44: 1144
B45: Extrajudicial - 29 a 39 semanas de atraso | C45: 322 | D45: 2923
B46: Extrajudicial - 40 a 55 semanas de atraso | C46: 255 | D46: 0
B47: Mas 55 semanas de atraso | C47: 1930 | D47: 3035
...

Sheet DATA

Sheet EPR 23 ABR
B2: REPORTE CONSOLIDADO POR SEGMENTOS
B3: SALDO ACUMULADO SEMANA 17
B5: COORDINADOR | C5: SEGMENTO | D5: CUENTAS | E5: COBRANZA REAL | F5: CUOTA IDEAL | G5: VARIACION | H5: % VAR | I5: EPR | J5: EPR IDEAL | K5: VAR EPR
B6: Samatha y Zareth | C6: Extrajudicial - 0 a 28 semanas de atraso | D6: =SUMIF('REPORTE DIARIO'!B:B,'EPR 23 ABR'!C6, 'REPORTE DIARIO'!C:C) -> 13806 | E6: =SUMIF('REPORTE DIARIO'!B:B,'EPR 23 ABR'!C6, 'REPORTE DIARIO'!D:D) -> 421571.61 | F6: =J6*D6 -> 1183371.4 | G6: =+E6-F6 -> -761799.82 | H6: =ABS(G6/F6) -> 0.64375377 | I6: =E6/D6 -> 30.535391 | J6: =(200/7)*3 -> 85.714286 | K6: =+I6-J6 -> -55.178895
B7: Gabriel | C7: Extrajudicial - 29 a 39 semanas de atraso | D7: =SUMIF('REPORTE DIARIO'!B:B,'EPR 23 ABR'!C7, 'REPORTE DIARIO'!C:C) -> 11540 | E7: =SUMIF('REPORTE DIARIO'!B:B,'EPR 23 ABR'!C7, 'REPORTE DIARIO'!D:D) -> 301006.28 | F7: =J7*D7 -> 544028.57 | G7: =+E7-F7 -> -243022.29 | H7: =ABS(G7/F7) -> 0.44670869 | I7: =E7/D7 -> 26.083733 | J7: =(110/7)*3 -> 47.142857 | K7: =+I7-J7 -> -21.059124
B8: Gabriel | C8: Extrajudicial - 40 a 55 semanas de atraso | D8: =SUMIF('REPORTE DIARIO'!B:B,'EPR 23 ABR'!C8, 'REPORTE DIARIO'!C:C) -> 14762 | E8: =SUMIF('REPORTE DIARIO'!B:B,'EPR 23 ABR'!C8, 'REPORTE DIARIO'!D:D) -> 151731.54 | F8: =J8*D8 -> 284695.71 | G8: =+E8-F8 -> -132964.17 | H8: =ABS(G8/F8) -> 0.46703961 | I8: =E8/D8 -> 10.278522 | J8: =(45/7)*3 -> 19.285714 | K8: =+I8-J8 -> -9.0071924
B9: Fernando | C9: Mas 55 semanas de atraso | D9: =SUMIF('REPORTE DIARIO'!B:B,'EPR 23 ABR'!C9, 'REPORTE DIARIO'!C:C) -> 59160 | E9: =SUMIF('REPORTE DIARIO'!B:B,'EPR 23 ABR'!C9, 'REPORTE DIARIO'!D:D) -> 141742.58 | F9: =J9*D9 -> 380314.29 | G9: =+E9-F9 -> -238571.71 | H9: =ABS(G9/F9) -> 0.62730146 | I9: =E9/D9 -> 2.3959192 | J9: =(15/7)*3 -> 6.4285714 | K9: =+I9-J9 -> -4.0326522
C10: TOTAL | D10: =SUM(D6:D9) -> 99268 | E10: =SUM(E6:E9) -> 1016052 | F10: =SUM(F6:F9) -> 2392410 | G10: =+E10-F10 -> -1376358 | H10: =ABS(G10/F10) -> 0.57530189 | I10: =E10/D10 -> 10.235444 | J10: =F10/D10 -> 24.100516 | K10: =I10-J10 -> -13.865072
B12: Nota:
B13: El saldo consolidado incluye los siguientes despachos
B14: Samantha, Samantha 2, Sofia, Edith, Fernando, Olguin y Federico
