Workbook

Sheet REPORTE DIARIO
B3: COBRANZA GENERAL SAMANTHA
B4: Segmento | C4: Cuentas | D4: Recuperación
B5: Extrajudicial - 0 a 28 semanas de atraso | C5: 2814 | D5: 154476.43
B6: Extrajudicial - 29 a 39 semanas de atraso | C6: 3087 | D6: 67035
B7: Extrajudicial - 40 a 55 semanas de atraso | C7: 6049 | D7: 45669.46
B8: JUDICIAL | C8: 11 | D8: 0
B9: Mas 55 semanas de atraso | C9: 12425 | D9: 79776
B10: Total general | C10: =SUM(C5:C9) -> 24386 | D10: =SUM(D5:D9) -> 346956.89
B12: COBRANZA GENERAL EDITH
B13: Segmento | C13: Cuentas | D13: Recuperación
B14: Extrajudicial - 0 a 28 semanas de atraso | C14: 3794 | D14: 56485.9
B15: Extrajudicial - 29 a 39 semanas de atraso | C15: 928 | D15: 9465.5
B16: Extrajudicial - 40 a 55 semanas de atraso | C16: 2079 | D16: 8924
B17: JUDICIAL | C17: 1 | D17: 0
B18: Mas 55 semanas de atraso | C18: 16872 | D18: 23774
B19: Total general | C19: =SUM(C14:C18) -> 23674 | D19: =SUM(D14:D18) -> 98649.4
B21: COBRANZA GENERAL SAMANTHA 2
B22: Segmento | C22: Cuentas | D22: Recuperación
B23: Extrajudicial - 0 a 28 semanas de atraso | C23: 2918 | D23: 21149
B24: Extrajudicial - 29 a 39 semanas de atraso | C24: 1941 | D24: 14628.91
B25: Extrajudicial - 40 a 55 semanas de atraso | C25: 2519 | D25: 19820
B26: JUDICIAL | C26: 2 | D26: 0
B27: Mas 55 semanas de atraso | C27: 12927 | D27: 8332
B28: Total general | C28: =SUM(C23:C27) -> 20307 | D28: =SUM(D23:D27) -> 63929.91
B30: COBRANZA GENERAL SOFIA
B31: Segmento | C31: Cuentas | D31: Recuperación
B32: Extrajudicial - 0 a 28 semanas de atraso | C32: 48 | D32: 1659
B33: Extrajudicial - 29 a 39 semanas de atraso | C33: 3226 | D33: 13384.5
B34: Extrajudicial - 40 a 55 semanas de atraso | C34: 283 | D34: 94
B35: Mas 55 semanas de atraso | C35: 3955 | D35: 6800
B36: Total general | C36: =SUM(C32:C35) -> 7512 | D36: =SUM(D32:D35) -> 21937.5
B38: COBRANZA GENERAL OLGUIN
B39: Segmento | C39: Cuentas | D39: Recuperación
B40: Extrajudicial - 0 a 28 semanas de atraso | C40: 2260 | D40: 1491
B41: Extrajudicial - 29 a 39 semanas de atraso | C41: 1372 | D41: 5182
B42: Extrajudicial - 40 a 55 semanas de atraso | C42: 1998 | D42: 8245
B43: Mas 55 semanas de atraso | C43: 1786 | D43: 2352
B44: Total general | C44: =SUM(C40:C43) -> 7416 | D44: =SUM(D40:D43) -> 17270
B46: COBRANZA GENERAL FERNANDO
B47: Segmento | C47: Cuentas | D47: Recuperación
...

Sheet DATA

Sheet EPR 10 JUN
B2: REPORTE CONSOLIDADO POR SEGMENTOS
B3: SALDO ACUMULADO SEMANA 24
B5: COORDINADOR | C5: SEGMENTO | D5: CUENTAS | E5: COBRANZA REAL | F5: CUOTA IDEAL | G5: VARIACION | H5: % VAR | I5: EPR | J5: EPR IDEAL | K5: VAR EPR
B6: Zareth | C6: Extrajudicial - 0 a 28 semanas de atraso | D6: =SUMIF('REPORTE DIARIO'!B:B,'EPR 10 JUN'!C6, 'REPORTE DIARIO'!C:C) -> 15156 | E6: =SUMIF('REPORTE DIARIO'!B:B,'EPR 10 JUN'!C6, 'REPORTE DIARIO'!D:D) -> 249170.33 | F6: =J6*D6 -> 952662.86 | G6: =+E6-F6 -> -703492.53 | H6: =ABS(G6/F6) -> 0.73844857 | I6: =E6/D6 -> 16.440375 | J6: =(220/7)*2 -> 62.857143 | K6: =+I6-J6 -> -46.416767
B7: Gabriel | C7: Extrajudicial - 29 a 39 semanas de atraso | D7: =SUMIF('REPORTE DIARIO'!B:B,'EPR 10 JUN'!C7, 'REPORTE DIARIO'!C:C) -> 11164 | E7: =SUMIF('REPORTE DIARIO'!B:B,'EPR 10 JUN'!C7, 'REPORTE DIARIO'!D:D) -> 111325.91 | F7: =J7*D7 -> 350868.57 | G7: =+E7-F7 -> -239542.66 | H7: =ABS(G7/F7) -> 0.68271336 | I7: =E7/D7 -> 9.9718658 | J7: =(110/7)*2 -> 31.428571 | K7: =+I7-J7 -> -21.456706
B8: Gabriel | C8: Extrajudicial - 40 a 55 semanas de atraso | D8: =SUMIF('REPORTE DIARIO'!B:B,'EPR 10 JUN'!C8, 'REPORTE DIARIO'!C:C) -> 13733 | E8: =SUMIF('REPORTE DIARIO'!B:B,'EPR 10 JUN'!C8, 'REPORTE DIARIO'!D:D) -> 82752.46 | F8: =J8*D8 -> 176567.14 | G8: =+E8-F8 -> -93814.683 | H8: =ABS(G8/F8) -> 0.53132583 | I8: =E8/D8 -> 6.0258108 | J8: =(45/7)*2 -> 12.857143 | K8: =+I8-J8 -> -6.831332
B9: Fernando (Naucalpan) | C9: Mas 55 semanas de atraso | D9: =SUMIF('REPORTE DIARIO'!B:B,'EPR 10 JUN'!C9, 'REPORTE DIARIO'!C:C) -> 50434 | E9: =SUMIF('REPORTE DIARIO'!B:B,'EPR 10 JUN'!C9, 'REPORTE DIARIO'!D:D) -> 121734 | F9: =J9*D9 -> 216145.71 | G9: =+E9-F9 -> -94411.714 | H9: =ABS(G9/F9) -> 0.43679661 | I9: =E9/D9 -> 2.4137288 | J9: =(15/7)*2 -> 4.2857143 | K9: =+I9-J9 -> -1.8719855
C10: TOTAL | D10: =SUM(D6:D9) -> 90487 | E10: =SUM(E6:E9) -> 564982.7 | F10: =SUM(F6:F9) -> 1696244.3 | G10: =+E10-F10 -> -1131261.6 | H10: =ABS(G10/F10) -> 0.66692138 | I10: =E10/D10 -> 6.2437997 | J10: =F10/D10 -> 18.745724 | K10: =I10-J10 -> -12.501924
B12: Nota:
B13: El saldo consolidado incluye los siguientes despachos
B14: Samantha, Samantha 2, Sofia, Edith, Fernando, Olguin y Federico
