Workbook

Sheet REPORTE DIARIO
B3: COBRANZA GENERAL SAMANTHA
B4: Segmento | C4: Cuentas | D4: Recuperación
B5: Extrajudicial - 0 a 28 semanas de atraso | C5: 5918 | D5: 113456.8
B6: Extrajudicial - 29 a 39 semanas de atraso | C6: 6677 | D6: 39808.86
B7: Extrajudicial - 40 a 55 semanas de atraso | C7: 9869 | D7: 41090
B8: JUDICIAL | C8: 21 | D8: 0
B9: Mas 55 semanas de atraso | C9: 28838 | D9: 70145.94
B10: Total general | C10: =SUM(C5:C9) -> 51323 | D10: =SUM(D5:D9) -> 264501.6
B12: COBRANZA GENERAL SAMANTHA 2
B13: Segmento | C13: Cuentas | D13: Recuperación
B14: Extrajudicial - 0 a 28 semanas de atraso | C14: 2426 | D14: 32372
B15: Extrajudicial - 29 a 39 semanas de atraso | C15: 1419 | D15: 11709
B16: Extrajudicial - 40 a 55 semanas de atraso | C16: 3399 | D16: 7540
B17: JUDICIAL | C17: 2 | D17: 0
B18: Mas 55 semanas de atraso | C18: 21142 | D18: 35690
B19: Total general | C19: =SUM(C14:C18) -> 28388 | D19: =SUM(D14:D18) -> 87311
B21: COBRANZA GENERAL EDITH
B22: Segmento | C22: Cuentas | D22: Recuperación
B23: Extrajudicial - 0 a 28 semanas de atraso | C23: 1664 | D23: 47931.23
B24: Extrajudicial - 29 a 39 semanas de atraso | C24: 1498 | D24: 9230.31
B25: Extrajudicial - 40 a 55 semanas de atraso | C25: 843 | D25: 3246
B26: Mas 55 semanas de atraso | C26: 8346 | D26: 2604
B27: Total general | C27: =SUM(C23:C26) -> 12351 | D27: =SUM(D23:D26) -> 63011.54
B29: COBRANZA GENERAL SOFIA
B30: Segmento | C30: Cuentas | D30: Recuperación
B31: Extrajudicial - 0 a 28 semanas de atraso | C31: 1394 | D31: 11637.57
B32: Extrajudicial - 29 a 39 semanas de atraso | C32: 1287 | D32: 9977
B33: Extrajudicial - 40 a 55 semanas de atraso | C33: 2932 | D33: 0
B34: Mas 55 semanas de atraso | C34: 1828 | D34: 2340
B35: Total general | C35: =SUM(C31:C34) -> 7441 | D35: =SUM(D31:D34) -> 23954.57
B37: COBRANZA GENERAL FERNANDO
B38: Segmento | C38: Cuentas | D38: Recuperación
B39: Extrajudicial - 0 a 28 semanas de atraso | C39: 2737 | D39: 11080
B40: Total general | C40: =SUM(C39:C39) -> 2737 | D40: =SUM(D39:D39) -> 11080
B42: COBRANZA GENERAL FEDERICO
B43: Segmento | C43: Cuentas | D43: Recuperación
B44: Extrajudicial - 0 a 28 semanas de atraso | C44: 31 | D44: 2019
B45: Extrajudicial - 29 a 39 semanas de atraso | C45: 124 | D45: 0
B46: Extrajudicial - 40 a 55 semanas de atraso | C46: 143 | D46: 0
B47: Mas 55 semanas de atraso | C47: 1578 | D47: 538
...

Sheet DATA

Sheet EPR 5 ABR
B2: REPORTE CONSOLIDADO POR SEGMENTOS
B3: COBRANZA 05 ABRIL
B5: COORDINADOR | C5: SEGMENTO | D5: CUENTAS | E5: COBRANZA REAL | F5: CUOTA IDEAL | G5: VARIACION | H5: % VAR | I5: EPR | J5: EPR IDEAL | K5: VAR EPR
B6: Samatha y Zareth | C6: Extrajudicial - 0 a 28 semanas de atraso | D6: =SUMIF('REPORTE DIARIO'!B:B,'EPR 5 ABR'!C6, 'REPORTE DIARIO'!C:C) -> 14238 | E6: =SUMIF('REPORTE DIARIO'!B:B,'EPR 5 ABR'!C6, 'REPORTE DIARIO'!D:D) -> 219466.6 | F6: =J6*D6 -> 406800 | G6: =+E6-F6 -> -187333.4 | H6: =ABS(G6/F6) -> 0.46050492 | I6: =E6/D6 -> 15.414145 | J6: =200/7 -> 28.571429 | K6: =+I6-J6 -> -13.157283
B7: Gabriel | C7: Extrajudicial - 29 a 39 semanas de atraso | D7: =SUMIF('REPORTE DIARIO'!B:B,'EPR 5 ABR'!C7, 'REPORTE DIARIO'!C:C) -> 11067 | E7: =SUMIF('REPORTE DIARIO'!B:B,'EPR 5 ABR'!C7, 'REPORTE DIARIO'!D:D) -> 70725.17 | F7: =J7*D7 -> 173910 | G7: =+E7-F7 -> -103184.83 | H7: =ABS(G7/F7) -> 0.59332316 | I7: =E7/D7 -> 6.3906361 | J7: =110/7 -> 15.714286 | K7: =+I7-J7 -> -9.3236496
B8: Gabriel | C8: Extrajudicial - 40 a 55 semanas de atraso | D8: =SUMIF('REPORTE DIARIO'!B:B,'EPR 5 ABR'!C8, 'REPORTE DIARIO'!C:C) -> 17199 | E8: =SUMIF('REPORTE DIARIO'!B:B,'EPR 5 ABR'!C8, 'REPORTE DIARIO'!D:D) -> 51876 | F8: =J8*D8 -> 110565 | G8: =+E8-F8 -> -58689 | H8: =ABS(G8/F8) -> 0.53080993 | I8: =E8/D8 -> 3.0162219 | J8: =45/7 -> 6.4285714 | K8: =+I8-J8 -> -3.4123496
B9: Fernando | C9: Mas 55 semanas de atraso | D9: =SUMIF('REPORTE DIARIO'!B:B,'EPR 5 ABR'!C9, 'REPORTE DIARIO'!C:C) -> 61741 | E9: =SUMIF('REPORTE DIARIO'!B:B,'EPR 5 ABR'!C9, 'REPORTE DIARIO'!D:D) -> 111317.94 | F9: =J9*D9 -> 132302.14 | G9: =+E9-F9 -> -20984.203 | H9: =ABS(G9/F9) -> 0.15860819 | I9: =E9/D9 -> 1.8029825 | J9: =15/7 -> 2.1428571 | K9: =+I9-J9 -> -0.33987468
C10: TOTAL | D10: =SUM(D6:D9) -> 104245 | E10: =SUM(E6:E9) -> 453385.71 | F10: =SUM(F6:F9) -> 823577.14 | G10: =+E10-F10 -> -370191.43 | H10: =ABS(G10/F10) -> 0.44949212 | I10: =E10/D10 -> 4.3492322 | J10: =F10/D10 -> 7.9003995 | K10: =I10-J10 -> -3.5511673
B12: Nota:
B13: El saldo consolidado incluye los siguientes despachos
B14: Samantha, Samantha 2, Sofia, Edith, Olguin, Fernando y Federico
