Workbook

Sheet REPORTE DIARIO
B3: COBRANZA GENERAL SAMANTHA
B4: Segmento | C4: Cuentas | D4: Recuperación
B5: Extrajudicial - 0 a 28 semanas de atraso | C5: 4326 | D5: 80789.93
B6: Extrajudicial - 29 a 39 semanas de atraso | C6: 4403 | D6: 50570
B7: Extrajudicial - 40 a 55 semanas de atraso | C7: 6171 | D7: 42048
B8: JUDICIAL | C8: 12 | D8: 0
B9: Mas 55 semanas de atraso | C9: 13215 | D9: 75990.54
B10: Total general | C10: =SUM(C5:C9) -> 28127 | D10: =SUM(D5:D9) -> 249398.47
B12: COBRANZA GENERAL EDITH
B13: Segmento | C13: Cuentas | D13: Recuperación
B14: Extrajudicial - 0 a 28 semanas de atraso | C14: 3454 | D14: 71195.85
B15: Extrajudicial - 29 a 39 semanas de atraso | C15: 1759 | D15: 23653.07
B16: Extrajudicial - 40 a 55 semanas de atraso | C16: 2265 | D16: 25081.65
B17: JUDICIAL | C17: 1 | D17: 0
B18: Mas 55 semanas de atraso | C18: 17377 | D18: 8762.13
B19: Total general | C19: =SUM(C14:C18) -> 24856 | D19: =SUM(D14:D18) -> 128692.7
B21: COBRANZA GENERAL SAMANTHA 2
B22: Segmento | C22: Cuentas | D22: Recuperación
B23: Extrajudicial - 0 a 28 semanas de atraso | C23: 2044 | D23: 23306
B24: Extrajudicial - 29 a 39 semanas de atraso | C24: 1994 | D24: -5303
B25: Extrajudicial - 40 a 55 semanas de atraso | C25: 3272 | D25: 8720
B26: JUDICIAL | C26: 2 | D26: 0
B27: Mas 55 semanas de atraso | C27: 20635 | D27: 30162.83
B28: Total general | C28: =SUM(C23:C27) -> 27947 | D28: =SUM(D23:D27) -> 56885.83
B30: COBRANZA GENERAL SOFIA
B31: Segmento | C31: Cuentas | D31: Recuperación
B32: Extrajudicial - 0 a 28 semanas de atraso | C32: 251 | D32: 30482
B33: Extrajudicial - 29 a 39 semanas de atraso | C33: 2860 | D33: 15779.2
B34: Extrajudicial - 40 a 55 semanas de atraso | C34: 1856 | D34: 2265
B35: Mas 55 semanas de atraso | C35: 4234 | D35: 971
B36: Total general | C36: =SUM(C32:C35) -> 9201 | D36: =SUM(D32:D35) -> 49497.2
B38: COBRANZA GENERAL FERNANDO
B39: Segmento | C39: Cuentas | D39: Recuperación
B40: Extrajudicial - 0 a 28 semanas de atraso | C40: 2003 | D40: 9559
B41: Total general | C41: =SUM(C40:C40) -> 2003 | D41: =SUM(D40:D40) -> 9559
B43: COBRANZA GENERAL FEDERICO
B44: Segmento | C44: Cuentas | D44: Recuperación
B45: Extrajudicial - 0 a 28 semanas de atraso | C45: 341 | D45: 0
B46: Extrajudicial - 29 a 39 semanas de atraso | C46: 753 | D46: 0
B47: Extrajudicial - 40 a 55 semanas de atraso | C47: 672 | D47: 0
...

Sheet DATA

Sheet EPR 16 MAYO
B2: REPORTE CONSOLIDADO POR SEGMENTOS
B3: COBRANZA 16 MAYO
B5: COORDINADOR | C5: SEGMENTO | D5: CUENTAS | E5: COBRANZA REAL | F5: CUOTA IDEAL | G5: VARIACION | H5: % VAR | I5: EPR | J5: EPR IDEAL | K5: VAR EPR
B6: Zareth | C6: Extrajudicial - 0 a 28 semanas de atraso | D6: =SUMIF('REPORTE DIARIO'!B:B,'EPR 16 MAYO'!C6, 'REPORTE DIARIO'!C:C) -> 12805 | E6: =SUMIF('REPORTE DIARIO'!B:B,'EPR 16 MAYO'!C6, 'REPORTE DIARIO'!D:D) -> 215332.78 | F6: =J6*D6 -> 402442.86 | G6: =+E6-F6 -> -187110.08 | H6: =ABS(G6/F6) -> 0.46493576 | I6: =E6/D6 -> 16.816305 | J6: =220/7 -> 31.428571 | K6: =+I6-J6 -> -14.612267
B7: Gabriel | C7: Extrajudicial - 29 a 39 semanas de atraso | D7: =SUMIF('REPORTE DIARIO'!B:B,'EPR 16 MAYO'!C7, 'REPORTE DIARIO'!C:C) -> 12356 | E7: =SUMIF('REPORTE DIARIO'!B:B,'EPR 16 MAYO'!C7, 'REPORTE DIARIO'!D:D) -> 84699.27 | F7: =J7*D7 -> 194165.71 | G7: =+E7-F7 -> -109466.44 | H7: =ABS(G7/F7) -> 0.56377844 | I7: =E7/D7 -> 6.8549102 | J7: =110/7 -> 15.714286 | K7: =+I7-J7 -> -8.8593755
B8: Gabriel | C8: Extrajudicial - 40 a 55 semanas de atraso | D8: =SUMIF('REPORTE DIARIO'!B:B,'EPR 16 MAYO'!C8, 'REPORTE DIARIO'!C:C) -> 15220 | E8: =SUMIF('REPORTE DIARIO'!B:B,'EPR 16 MAYO'!C8, 'REPORTE DIARIO'!D:D) -> 78114.65 | F8: =J8*D8 -> 97842.857 | G8: =+E8-F8 -> -19728.207 | H8: =ABS(G8/F8) -> 0.20163155 | I8: =E8/D8 -> 5.1323686 | J8: =45/7 -> 6.4285714 | K8: =+I8-J8 -> -1.2962028
B9: Fernando (Naucalpan) | C9: Mas 55 semanas de atraso | D9: =SUMIF('REPORTE DIARIO'!B:B,'EPR 16 MAYO'!C9, 'REPORTE DIARIO'!C:C) -> 58916 | E9: =SUMIF('REPORTE DIARIO'!B:B,'EPR 16 MAYO'!C9, 'REPORTE DIARIO'!D:D) -> 118911.5 | F9: =J9*D9 -> 126248.57 | G9: =+E9-F9 -> -7337.0714 | H9: =ABS(G9/F9) -> 0.058116075 | I9: =E9/D9 -> 2.0183227 | J9: =15/7 -> 2.1428571 | K9: =+I9-J9 -> -0.12453445
C10: TOTAL | D10: =SUM(D6:D9) -> 99297 | E10: =SUM(E6:E9) -> 497058.2 | F10: =SUM(F6:F9) -> 820700 | G10: =+E10-F10 -> -323641.8 | H10: =ABS(G10/F10) -> 0.39434848 | I10: =E10/D10 -> 5.0057726 | J10: =F10/D10 -> 8.2651037 | K10: =I10-J10 -> -3.2593311
B12: Nota:
B13: El saldo consolidado incluye los siguientes despachos
B14: Samantha, Samantha 2, Sofia, Edith, Fernando, Olguin y Federico
