Workbook

Sheet REPORTE DIARIO
B3: COBRANZA GENERAL SAMANTHA
B4: Segmento | C4: Cuentas | D4: Recuperación
B5: Extrajudicial - 0 a 28 semanas de atraso | C5: 3124 | D5: 144785.45
B6: Extrajudicial - 29 a 39 semanas de atraso | C6: 3536 | D6: 57509.97
B7: Extrajudicial - 40 a 55 semanas de atraso | C7: 6138 | D7: 64413
B8: JUDICIAL | C8: 11 | D8: 0
B9: Mas 55 semanas de atraso | C9: 12495 | D9: 65974.66
B10: Total general | C10: =SUM(C5:C9) -> 25304 | D10: =SUM(D5:D9) -> 332683.08
B12: COBRANZA GENERAL SAMANTHA 2
B13: Segmento | C13: Cuentas | D13: Recuperación
B14: Extrajudicial - 0 a 28 semanas de atraso | C14: 2838 | D14: 27101
B15: Extrajudicial - 29 a 39 semanas de atraso | C15: 1944 | D15: 29952
B16: Extrajudicial - 40 a 55 semanas de atraso | C16: 2535 | D16: 22701
B17: JUDICIAL | C17: 0 | D17: 0
B18: Mas 55 semanas de atraso | C18: 12610 | D18: 16142
B19: Total general | C19: =SUM(C14:C18) -> 19927 | D19: =SUM(D14:D18) -> 95896
B21: COBRANZA GENERAL EDITH
B22: Segmento | C22: Cuentas | D22: Recuperación
B23: Extrajudicial - 0 a 28 semanas de atraso | C23: 3355 | D23: 31583.46
B24: Extrajudicial - 29 a 39 semanas de atraso | C24: 1424 | D24: 7179
B25: Extrajudicial - 40 a 55 semanas de atraso | C25: 2070 | D25: 4548
B26: JUDICIAL | C26: 1 | D26: 0
B27: Mas 55 semanas de atraso | C27: 16857 | D27: 9023
B28: Total general | C28: =SUM(C23:C27) -> 23707 | D28: =SUM(D23:D27) -> 52333.46
B30: COBRANZA GENERAL SOFIA
B31: Segmento | C31: Cuentas | D31: Recuperación
B32: Extrajudicial - 0 a 28 semanas de atraso | C32: 456 | D32: 19421.14
B33: Extrajudicial - 29 a 39 semanas de atraso | C33: 2865 | D33: 14446.5
B34: Extrajudicial - 40 a 55 semanas de atraso | C34: 327 | D34: 966
B35: Mas 55 semanas de atraso | C35: 3983 | D35: 12758.4
B36: Total general | C36: =SUM(C32:C35) -> 7631 | D36: =SUM(D32:D35) -> 47592.04
B38: COBRANZA GENERAL OLGUIN
B39: Segmento | C39: Cuentas | D39: Recuperación
B40: Extrajudicial - 0 a 28 semanas de atraso | C40: 2278 | D40: 8032.38
B41: Extrajudicial - 29 a 39 semanas de atraso | C41: 1437 | D41: 5847
B42: Extrajudicial - 40 a 55 semanas de atraso | C42: 1974 | D42: 468
B43: Mas 55 semanas de atraso | C43: 1840 | D43: 3272
B44: Total general | C44: =SUM(C40:C43) -> 7529 | D44: =SUM(D40:D43) -> 17619.38
B46: COBRANZA GENERAL FERNANDO
B47: Segmento | C47: Cuentas | D47: Recuperación
...

Sheet DATA

Sheet EPR 14 JUN
B2: REPORTE CONSOLIDADO POR SEGMENTOS
B3: COBRANZA 14 JUNIO
B5: COORDINADOR | C5: SEGMENTO | D5: CUENTAS | E5: COBRANZA REAL | F5: CUOTA IDEAL | G5: VARIACION | H5: % VAR | I5: EPR | J5: EPR IDEAL | K5: VAR EPR
B6: Zareth | C6: Extrajudicial - 0 a 28 semanas de atraso | D6: =SUMIF('REPORTE DIARIO'!B:B,'EPR 14 JUN'!C6, 'REPORTE DIARIO'!C:C) -> 15271 | E6: =SUMIF('REPORTE DIARIO'!B:B,'EPR 14 JUN'!C6, 'REPORTE DIARIO'!D:D) -> 238614.43 | F6: =J6*D6 -> 479945.71 | G6: =+E6-F6 -> -241331.28 | H6: =ABS(G6/F6) -> 0.50283038 | I6: =E6/D6 -> 15.625331 | J6: =220/7 -> 31.428571 | K6: =+I6-J6 -> -15.80324
B7: Gabriel | C7: Extrajudicial - 29 a 39 semanas de atraso | D7: =SUMIF('REPORTE DIARIO'!B:B,'EPR 14 JUN'!C7, 'REPORTE DIARIO'!C:C) -> 11813 | E7: =SUMIF('REPORTE DIARIO'!B:B,'EPR 14 JUN'!C7, 'REPORTE DIARIO'!D:D) -> 115184.47 | F7: =J7*D7 -> 185632.86 | G7: =+E7-F7 -> -70448.387 | H7: =ABS(G7/F7) -> 0.37950387 | I7: =E7/D7 -> 9.7506535 | J7: =110/7 -> 15.714286 | K7: =+I7-J7 -> -5.9636322
B8: Gabriel | C8: Extrajudicial - 40 a 55 semanas de atraso | D8: =SUMIF('REPORTE DIARIO'!B:B,'EPR 14 JUN'!C8, 'REPORTE DIARIO'!C:C) -> 13819 | E8: =SUMIF('REPORTE DIARIO'!B:B,'EPR 14 JUN'!C8, 'REPORTE DIARIO'!D:D) -> 94406 | F8: =J8*D8 -> 88836.429 | G8: =+E8-F8 -> 5569.5714 | H8: =ABS(G8/F8) -> 0.06269468 | I8: =E8/D8 -> 6.8316087 | J8: =45/7 -> 6.4285714 | K8: =+I8-J8 -> 0.40303723
B9: Fernando (Naucalpan) | C9: Mas 55 semanas de atraso | D9: =SUMIF('REPORTE DIARIO'!B:B,'EPR 14 JUN'!C9, 'REPORTE DIARIO'!C:C) -> 50212 | E9: =SUMIF('REPORTE DIARIO'!B:B,'EPR 14 JUN'!C9, 'REPORTE DIARIO'!D:D) -> 109926.06 | F9: =J9*D9 -> 107597.14 | G9: =+E9-F9 -> 2328.9171 | H9: =ABS(G9/F9) -> 0.021644786 | I9: =E9/D9 -> 2.1892388 | J9: =15/7 -> 2.1428571 | K9: =+I9-J9 -> 0.046381685
C10: TOTAL | D10: =SUM(D6:D9) -> 91115 | E10: =SUM(E6:E9) -> 558130.96 | F10: =SUM(F6:F9) -> 862012.14 | G10: =+E10-F10 -> -303881.18 | H10: =ABS(G10/F10) -> 0.35252541 | I10: =E10/D10 -> 6.1255662 | J10: =F10/D10 -> 9.4607051 | K10: =I10-J10 -> -3.3351389
B12: Nota:
B13: El saldo consolidado incluye los siguientes despachos
B14: Samantha, Samantha 2, Sofia, Edith, Fernando, Olguin y Federico
