Workbook

Sheet REPORTE DIARIO
B3: COBRANZA GENERAL SAMANTHA
B4: Segmento | C4: Cuentas | D4: Recuperación
B5: Extrajudicial - 0 a 28 semanas de atraso | C5: 6607 | D5: 244460.75
B6: Extrajudicial - 29 a 39 semanas de atraso | C6: 5817 | D6: 260504
B7: Extrajudicial - 40 a 55 semanas de atraso | C7: 8797 | D7: 114127.54
B8: JUDICIAL | C8: 21 | D8: 0
B9: Mas 55 semanas de atraso | C9: 21216 | D9: 207313.38
B10: Total general | C10: =SUM(C5:C9) -> 42458 | D10: =SUM(D5:D9) -> 826405.67
B12: COBRANZA GENERAL EDITH
B13: Segmento | C13: Cuentas | D13: Recuperación
B14: Extrajudicial - 0 a 28 semanas de atraso | C14: 2025 | D14: 203043.79
B15: Extrajudicial - 29 a 39 semanas de atraso | C15: 2179 | D15: 119799.57
B16: Extrajudicial - 40 a 55 semanas de atraso | C16: 936 | D16: 22580.92
B17: Mas 55 semanas de atraso | C17: 9098 | D17: 20757.25
B18: Total general | C18: =SUM(C14:C17) -> 14238 | D18: =SUM(D14:D17) -> 366181.53
B20: COBRANZA GENERAL SAMANTHA 2
B21: Segmento | C21: Cuentas | D21: Recuperación
B22: Extrajudicial - 0 a 28 semanas de atraso | C22: 2399 | D22: 104823.61
B23: Extrajudicial - 29 a 39 semanas de atraso | C23: 1551 | D23: 45656.05
B24: Extrajudicial - 40 a 55 semanas de atraso | C24: 3315 | D24: 17903
B25: JUDICIAL | C25: 2 | D25: 0
B26: Mas 55 semanas de atraso | C26: 21325 | D26: 64259.56
B27: Total general | C27: =SUM(C22:C26) -> 28592 | D27: =SUM(D22:D26) -> 232642.22
B29: COBRANZA GENERAL SOFIA
B30: Segmento | C30: Cuentas | D30: Recuperación
B31: Extrajudicial - 0 a 28 semanas de atraso | C31: 1357 | D31: 87254.73
B32: Extrajudicial - 29 a 39 semanas de atraso | C32: 1957 | D32: 28870.38
B33: Extrajudicial - 40 a 55 semanas de atraso | C33: 2746 | D33: 2325
B34: Mas 55 semanas de atraso | C34: 4265 | D34: 4368.29
B35: Total general | C35: =SUM(C31:C34) -> 10325 | D35: =SUM(D31:D34) -> 122818.4
B37: COBRANZA GENERAL FERNANDO
B38: Segmento | C38: Cuentas | D38: Recuperación
B39: Extrajudicial - 0 a 28 semanas de atraso | C39: 2522 | D39: 49933.63
B40: Total general | C40: =SUM(C39:C39) -> 2522 | D40: =SUM(D39:D39) -> 49933.63
B42: COBRANZA GENERAL FEDERICO
B43: Segmento | C43: Cuentas | D43: Recuperación
B44: Extrajudicial - 0 a 28 semanas de atraso | C44: 39 | D44: 2113
B45: Extrajudicial - 29 a 39 semanas de atraso | C45: 323 | D45: 13300
B46: Extrajudicial - 40 a 55 semanas de atraso | C46: 255 | D46: 0
B47: Mas 55 semanas de atraso | C47: 1931 | D47: 7873
...

Sheet DATA

Sheet EPR 16 ABR
B2: REPORTE CONSOLIDADO POR SEGMENTOS
B3: SALDO ACUMULADO SEMANA 16
B5: COORDINADOR | C5: SEGMENTO | D5: CUENTAS | E5: COBRANZA REAL | F5: CUOTA IDEAL | G5: VARIACION | H5: % VAR | I5: EPR | J5: EPR IDEAL | K5: VAR EPR
B6: Samatha y Zareth | C6: Extrajudicial - 0 a 28 semanas de atraso | D6: =SUMIF('REPORTE DIARIO'!B:B,'EPR 16 ABR'!C6, 'REPORTE DIARIO'!C:C) -> 14949 | E6: =SUMIF('REPORTE DIARIO'!B:B,'EPR 16 ABR'!C6, 'REPORTE DIARIO'!D:D) -> 691629.51 | F6: =J6*D6 -> 1281342.9 | G6: =+E6-F6 -> -589713.35 | H6: =ABS(G6/F6) -> 0.46023072 | I6: =E6/D6 -> 46.265938 | J6: =(200/7)*3 -> 85.714286 | K6: =+I6-J6 -> -39.448348
B7: Gabriel | C7: Extrajudicial - 29 a 39 semanas de atraso | D7: =SUMIF('REPORTE DIARIO'!B:B,'EPR 16 ABR'!C7, 'REPORTE DIARIO'!C:C) -> 11827 | E7: =SUMIF('REPORTE DIARIO'!B:B,'EPR 16 ABR'!C7, 'REPORTE DIARIO'!D:D) -> 468130 | F7: =J7*D7 -> 557558.57 | G7: =+E7-F7 -> -89428.571 | H7: =ABS(G7/F7) -> 0.16039314 | I7: =E7/D7 -> 39.581466 | J7: =(110/7)*3 -> 47.142857 | K7: =+I7-J7 -> -7.561391
B8: Gabriel | C8: Extrajudicial - 40 a 55 semanas de atraso | D8: =SUMIF('REPORTE DIARIO'!B:B,'EPR 16 ABR'!C8, 'REPORTE DIARIO'!C:C) -> 16049 | E8: =SUMIF('REPORTE DIARIO'!B:B,'EPR 16 ABR'!C8, 'REPORTE DIARIO'!D:D) -> 156936.46 | F8: =J8*D8 -> 309516.43 | G8: =+E8-F8 -> -152579.97 | H8: =ABS(G8/F8) -> 0.49296242 | I8: =E8/D8 -> 9.7785818 | J8: =(45/7)*3 -> 19.285714 | K8: =+I8-J8 -> -9.5071324
B9: Fernando | C9: Mas 55 semanas de atraso | D9: =SUMIF('REPORTE DIARIO'!B:B,'EPR 16 ABR'!C9, 'REPORTE DIARIO'!C:C) -> 57835 | E9: =SUMIF('REPORTE DIARIO'!B:B,'EPR 16 ABR'!C9, 'REPORTE DIARIO'!D:D) -> 304571.48 | F9: =J9*D9 -> 371796.43 | G9: =+E9-F9 -> -67224.949 | H9: =ABS(G9/F9) -> 0.18081117 | I9: =E9/D9 -> 5.2662139 | J9: =(15/7)*3 -> 6.4285714 | K9: =+I9-J9 -> -1.1623575
C10: TOTAL | D10: =SUM(D6:D9) -> 100660 | E10: =SUM(E6:E9) -> 1621267.5 | F10: =SUM(F6:F9) -> 2520214.3 | G10: =+E10-F10 -> -898946.84 | H10: =ABS(G10/F10) -> 0.3566946 | I10: =E10/D10 -> 16.106372 | J10: =F10/D10 -> 25.036899 | K10: =I10-J10 -> -8.9305269
B12: Nota:
B13: El saldo consolidado incluye los siguientes despachos
B14: Samantha, Samantha 2, Sofia, Edith, Fernando y Federico
