Workbook

Sheet REPORTE DIARIO
B3: COBRANZA GENERAL SKIC COBRO SOLUTION
B4: Segmento | C4: Cuentas | D4: Recuperación
B5: Extrajudicial - 0 a 28 semanas de atraso | C5: 7412 | D5: 70079.75
B6: Extrajudicial - 29 a 39 semanas de atraso | C6: 8180 | D6: 39894.5
B7: Extrajudicial - 40 a 55 semanas de atraso | C7: 5834 | D7: 19420.74
B8: JUDICIAL | C8: 502 | D8: 0
B9: Mas 55 semanas de atraso | C9: 36007 | D9: 68325.49
B10: Total general | C10: =SUM(C5:C9) -> 57935 | D10: =SUM(D5:D9) -> 197720.48
B12: COBRANZA GENERAL ANDREA
B13: Segmento | C13: Cuentas | D13: Recuperación
B14: Extrajudicial - 0 a 28 semanas de atraso | C14: 85 | D14: 2788
B15: Extrajudicial - 29 a 39 semanas de atraso | C15: 110 | D15: 6470
B16: Extrajudicial - 40 a 55 semanas de atraso | C16: 2241 | D16: 5936
B17: Mas 55 semanas de atraso | C17: 14172 | D17: 25376
B18: Total general | C18: =SUM(C14:C17) -> 16608 | D18: =SUM(D14:D17) -> 40570
B20: COBRANZA GENERAL FERNANDO
B21: Segmento | C21: Cuentas | D21: Recuperación
B22: Extrajudicial - 0 a 28 semanas de atraso | C22: 4391 | D22: 9576
B23: Extrajudicial - 29 a 39 semanas de atraso | C23: 645 | D23: 11107
B24: Extrajudicial - 40 a 55 semanas de atraso | C24: 3572 | D24: 19348.86
B25: Mas 55 semanas de atraso | C25: 1008 | D25: 300
B26: Total general | C26: =SUM(C22:C25) -> 9616 | D26: =SUM(D22:D25) -> 40331.86
B28: COBRANZA GENERAL EDITH
B29: Segmento | C29: Cuentas | D29: Recuperación
B30: Extrajudicial - 0 a 28 semanas de atraso | C30: 538 | D30: 1712
B31: Extrajudicial - 29 a 39 semanas de atraso | C31: 1090 | D31: 6820
B32: Extrajudicial - 40 a 55 semanas de atraso | C32: 3860 | D32: 9101
B33: Mas 55 semanas de atraso | C33: 4903 | D33: 13950
B34: Total general | C34: =SUM(C30:C33) -> 10391 | D34: =SUM(D30:D33) -> 31583
B36: COBRANZA GENERAL FEDERICO
B37: Segmento | C37: Cuentas | D37: Recuperación
B38: Extrajudicial - 0 a 28 semanas de atraso | C38: 13 | D38: 625
B39: Extrajudicial - 29 a 39 semanas de atraso | C39: 8 | D39: 0
B40: Extrajudicial - 40 a 55 semanas de atraso | C40: 6 | D40: 0
B41: Mas 55 semanas de atraso | C41: 687 | D41: 819
B42: Total general | C42: =SUM(C38:C41) -> 714 | D42: =SUM(D38:D41) -> 1444
B50: Cobranza Total | C50: =SUMIF(B:B, "Total general", C:C) -> 95264 | D50: =SUMIF(B:B, "Total general", D:D) -> 311649.34

Sheet CDC
B1: ETIQUETA PROYECTO CDC
B3: COBRANZA GENERAL CDC 100
B4: Segmento | C4: Cuentas | D4: Recuperación
B5: Extrajudicial - 0 a 28 semanas de atraso | C5: 6807 | D5: 42188
B6: Extrajudicial - 29 a 39 semanas de atraso | C6: 8650 | D6: 54325.18
B7: Extrajudicial - 40 a 55 semanas de atraso | C7: 8102 | D7: 11649
B8: JUDICIAL | C8: 2737 | D8: 400
B9: Mas 55 semanas de atraso | C9: 11242 | D9: 20407.83
B10: Total general | C10: =SUM(C5:C9) -> 37538 | D10: =SUM(D5:D9) -> 128970.01
B12: COBRANZA GENERAL FERNANDO
B13: Segmento | C13: Cuentas | D13: Recuperación
B14: Extrajudicial - 0 a 28 semanas de atraso | C14: 4407 | D14: 9576
B15: Extrajudicial - 29 a 39 semanas de atraso | C15: 540 | D15: 7419
B16: Extrajudicial - 40 a 55 semanas de atraso | C16: 3483 | D16: 19348.86
B17: Mas 55 semanas de atraso | C17: 27 | D17: 300
B18: Total general | C18: =SUM(C14:C17) -> 8457 | D18: =SUM(D14:D17) -> 36643.86
B20: COBRANZA GENERAL SKIC COBRO SOLUTION
B21: Segmento | C21: Cuentas | D21: Recuperación
B22: Extrajudicial - 0 a 28 semanas de atraso | C22: 1254 | D22: 1766
B23: Extrajudicial - 29 a 39 semanas de atraso | C23: 1032 | D23: 210
B24: Extrajudicial - 40 a 55 semanas de atraso | C24: 1080 | D24: 10
B25: Mas 55 semanas de atraso | C25: 304 | D25: 4879
B26: Total general | C26: =SUM(C22:C25) -> 3670 | D26: =SUM(D22:D25) -> 6865
B28: COBRANZA GENERAL FEDERICO
B29: Segmento | C29: Cuentas | D29: Recuperación
B30: Extrajudicial - 0 a 28 semanas de atraso | C30: 2 | D30: 0
B31: Mas 55 semanas de atraso | C31: 64 | D31: 0
B32: Total general | C32: =SUM(C30:C31) -> 66 | D32: =SUM(D30:D31) -> 0
B34: COBRANZA GENERAL ANDREA
B35: Segmento | C35: Cuentas | D35: Recuperación
B36: Extrajudicial - 0 a 28 semanas de atraso | C36: 2 | D36: 0
B37: Extrajudicial - 29 a 39 semanas de atraso | C37: 0 | D37: 0
B38: Extrajudicial - 40 a 55 semanas de atraso | C38: 1 | D38: 0
B39: Mas 55 semanas de atraso | C39: 330 | D39: 0
B40: Total general | C40: =SUM(C36:C39) -> 333 | D40: =SUM(D36:D39) -> 0
B42: COBRANZA GENERAL EDITH
B43: Segmento | C43: Cuentas | D43: Recuperación
B44: Extrajudicial - 0 a 28 semanas de atraso | C44: 2 | D44: 0
B45: Extrajudicial - 29 a 39 semanas de atraso | C45: 0 | D45: 0
B46: Mas 55 semanas de atraso | C46: 176 | D46: 0
...

Sheet COBRANZA CDC
B1: ETIQUETA PROYECTO CDC
B2: Segmento | C2: Cuentas | D2: Recuperación
B3: Extrajudicial - 0 a 28 semanas de atraso | C3: =SUMIF(CDC!B:B, "Extrajudicial - 0 a 28 semanas de atraso", CDC!C:C) -> 12474 | D3: =SUMIF(CDC!B:B, "Extrajudicial - 0 a 28 semanas de atraso", CDC!D:D) -> 53530
B4: Extrajudicial - 29 a 39 semanas de atraso | C4: =SUMIF(CDC!B:B, "Extrajudicial - 29 a 39 semanas de atraso", CDC!C:C) -> 10222 | D4: =SUMIF(CDC!B:B, "Extrajudicial - 29 a 39 semanas de atraso", CDC!D:D) -> 61954.18
B5: Extrajudicial - 40 a 55 semanas de atraso | C5: =SUMIF(CDC!B:B, "Extrajudicial - 40 a 55 semanas de atraso", CDC!C:C) -> 12666 | D5: =SUMIF(CDC!B:B, "Extrajudicial - 40 a 55 semanas de atraso", CDC!D:D) -> 31007.86
B6: JUDICIAL | C6: =SUMIF(CDC!B:B, "JUDICIAL", CDC!C:C) -> 2737 | D6: =SUMIF(CDC!B:B, "JUDICIAL", CDC!D:D) -> 400
B7: Mas 55 semanas de atraso | C7: =SUMIF(CDC!B:B, "Mas 55 semanas de atraso", CDC!C:C) -> 12143 | D7: =SUMIF(CDC!B:B, "Mas 55 semanas de atraso", CDC!D:D) -> 25586.83
B8: Total general | C8: =SUM(C3:C7) -> 50242 | D8: =SUM(D3:D7) -> 172478.87
