Workbook

Sheet REPORTE DIARIO
B3: COBRANZA GENERAL SAMANTHA
B4: Segmento | C4: Cuentas | D4: Recuperación
B5: Extrajudicial - 0 a 28 semanas de atraso | C5: 2538 | D5: 495675.16
B6: Extrajudicial - 29 a 39 semanas de atraso | C6: 3126 | D6: 305722.92
B7: Extrajudicial - 40 a 55 semanas de atraso | C7: 4936 | D7: 267519.22
B8: JUDICIAL | C8: 1980 | D8: 900.06
B9: Mas 55 semanas de atraso | C9: 11341 | D9: 414100.67
B10: Total general | C10: =SUM(C5:C9) -> 23921 | D10: =SUM(D5:D9) -> 1483918
B12: COBRANZA GENERAL SAMANTHA 2
B13: Segmento | C13: Cuentas | D13: Recuperación
B14: Extrajudicial - 0 a 28 semanas de atraso | C14: 2700 | D14: 231874.23
B15: Extrajudicial - 29 a 39 semanas de atraso | C15: 2215 | D15: 124798.71
B16: Extrajudicial - 40 a 55 semanas de atraso | C16: 2622 | D16: 66240.31
B17: JUDICIAL | C17: 2 | D17: 0
B18: Mas 55 semanas de atraso | C18: 17759 | D18: 204087.76
B19: Total general | C19: =SUM(C14:C18) -> 25298 | D19: =SUM(D14:D18) -> 627001.01
B21: COBRANZA GENERAL EDITH
B22: Segmento | C22: Cuentas | D22: Recuperación
B23: Extrajudicial - 0 a 28 semanas de atraso | C23: 3224 | D23: 297491.11
B24: Extrajudicial - 29 a 39 semanas de atraso | C24: 1156 | D24: 73673.89
B25: Extrajudicial - 40 a 55 semanas de atraso | C25: 2152 | D25: 55484.82
B26: JUDICIAL | C26: 1 | D26: 39
B27: Mas 55 semanas de atraso | C27: 17177 | D27: 124704.95
B28: Total general | C28: =SUM(C23:C27) -> 23710 | D28: =SUM(D23:D27) -> 551393.77
B30: COBRANZA GENERAL SOFIA
B31: Segmento | C31: Cuentas | D31: Recuperación
B32: Extrajudicial - 0 a 28 semanas de atraso | C32: 55 | D32: 28421.06
B33: Extrajudicial - 29 a 39 semanas de atraso | C33: 3357 | D33: 261472.52
B34: Extrajudicial - 40 a 55 semanas de atraso | C34: 282 | D34: 9433.67
B35: Mas 55 semanas de atraso | C35: 3972 | D35: 8116
B36: Total general | C36: =SUM(C32:C35) -> 7666 | D36: =SUM(D32:D35) -> 307443.25
B38: COBRANZA GENERAL OLGUIN
B39: Segmento | C39: Cuentas | D39: Recuperación
B40: Extrajudicial - 0 a 28 semanas de atraso | C40: 1960 | D40: 76482.79
B41: Extrajudicial - 29 a 39 semanas de atraso | C41: 1197 | D41: 28019.3
B42: Extrajudicial - 40 a 55 semanas de atraso | C42: 1986 | D42: 9703
B43: Mas 55 semanas de atraso | C43: 2026 | D43: 12265
B44: Total general | C44: =SUM(C40:C43) -> 7169 | D44: =SUM(D40:D43) -> 126470.09
B46: COBRANZA GENERAL FERNANDO
B47: Segmento | C47: Cuentas | D47: Recuperación
...

Sheet DATA

Sheet EPR 31 MAYO
B2: REPORTE CONSOLIDADO POR SEGMENTOS
B3: SALDO ACUMULADO SEMANA 22
B5: COORDINADOR | C5: SEGMENTO | D5: CUENTAS | E5: COBRANZA REAL | F5: CUOTA IDEAL | G5: VARIACION | H5: % VAR | I5: EPR | J5: EPR IDEAL | K5: VAR EPR
B6: Zareth | C6: Extrajudicial - 0 a 28 semanas de atraso | D6: =SUMIF('REPORTE DIARIO'!B:B,'EPR 31 MAYO'!C6, 'REPORTE DIARIO'!C:C) -> 13905 | E6: =SUMIF('REPORTE DIARIO'!B:B,'EPR 31 MAYO'!C6, 'REPORTE DIARIO'!D:D) -> 1276346.1 | F6: =J6*D6 -> 2622085.7 | G6: =+E6-F6 -> -1345739.6 | H6: =ABS(G6/F6) -> 0.51323249 | I6: =E6/D6 -> 91.790445 | J6: =(220/7)*6 -> 188.57143 | K6: =+I6-J6 -> -96.780983
B7: Gabriel | C7: Extrajudicial - 29 a 39 semanas de atraso | D7: =SUMIF('REPORTE DIARIO'!B:B,'EPR 31 MAYO'!C7, 'REPORTE DIARIO'!C:C) -> 11756 | E7: =SUMIF('REPORTE DIARIO'!B:B,'EPR 31 MAYO'!C7, 'REPORTE DIARIO'!D:D) -> 811115.15 | F7: =J7*D7 -> 1108422.9 | G7: =+E7-F7 -> -297307.71 | H7: =ABS(G7/F7) -> 0.26822589 | I7: =E7/D7 -> 68.995845 | J7: =(110/7)*6 -> 94.285714 | K7: =+I7-J7 -> -25.28987
B8: Gabriel | C8: Extrajudicial - 40 a 55 semanas de atraso | D8: =SUMIF('REPORTE DIARIO'!B:B,'EPR 31 MAYO'!C8, 'REPORTE DIARIO'!C:C) -> 12789 | E8: =SUMIF('REPORTE DIARIO'!B:B,'EPR 31 MAYO'!C8, 'REPORTE DIARIO'!D:D) -> 413682.02 | F8: =J8*D8 -> 493290 | G8: =+E8-F8 -> -79607.98 | H8: =ABS(G8/F8) -> 0.1613817 | I8: =E8/D8 -> 32.346706 | J8: =(45/7)*6 -> 38.571429 | K8: =+I8-J8 -> -6.2247228
B9: Fernando (Naucalpan) | C9: Mas 55 semanas de atraso | D9: =SUMIF('REPORTE DIARIO'!B:B,'EPR 31 MAYO'!C9, 'REPORTE DIARIO'!C:C) -> 54747 | E9: =SUMIF('REPORTE DIARIO'!B:B,'EPR 31 MAYO'!C9, 'REPORTE DIARIO'!D:D) -> 768738.38 | F9: =J9*D9 -> 703890 | G9: =+E9-F9 -> 64848.38 | H9: =ABS(G9/F9) -> 0.092128571 | I9: =E9/D9 -> 14.041653 | J9: =(15/7)*6 -> 12.857143 | K9: =+I9-J9 -> 1.1845102
C10: TOTAL | D10: =SUM(D6:D9) -> 93197 | E10: =SUM(E6:E9) -> 3269881.7 | F10: =SUM(F6:F9) -> 4927688.6 | G10: =+E10-F10 -> -1657806.9 | H10: =ABS(G10/F10) -> 0.33642688 | I10: =E10/D10 -> 35.085697 | J10: =F10/D10 -> 52.873897 | K10: =I10-J10 -> -17.7882
B12: Nota:
B13: El saldo consolidado incluye los siguientes despachos
B14: Samantha, Samantha 2, Sofia, Edith, Fernando, Olguin y Federico
