Workbook

Sheet REPORTE DIARIO
B3: COBRANZA GENERAL SAMANTHA
B4: Segmento | C4: Cuentas | D4: Recuperación
B5: Extrajudicial - 0 a 28 semanas de atraso | C5: 4198 | D5: 476720.76
B6: Extrajudicial - 29 a 39 semanas de atraso | C6: 4264 | D6: 203941.39
B7: Extrajudicial - 40 a 55 semanas de atraso | C7: 6004 | D7: 207794.62
B8: JUDICIAL | C8: 10 | D8: 0
B9: Mas 55 semanas de atraso | C9: 13280 | D9: 276870.6
B10: Total general | C10: =SUM(C5:C9) -> 27756 | D10: =SUM(D5:D9) -> 1165327.4
B12: COBRANZA GENERAL EDITH
B13: Segmento | C13: Cuentas | D13: Recuperación
B14: Extrajudicial - 0 a 28 semanas de atraso | C14: 3657 | D14: 284286.78
B15: Extrajudicial - 29 a 39 semanas de atraso | C15: 1960 | D15: 89920
B16: Extrajudicial - 40 a 55 semanas de atraso | C16: 2221 | D16: 27044.48
B17: Mas 55 semanas de atraso | C17: 9811 | D17: 72756.8
B18: Total general | C18: =SUM(C14:C17) -> 17649 | D18: =SUM(D14:D17) -> 474008.06
B20: COBRANZA GENERAL SAMANTHA 2
B21: Segmento | C21: Cuentas | D21: Recuperación
B22: Extrajudicial - 0 a 28 semanas de atraso | C22: 1927 | D22: 159942.34
B23: Extrajudicial - 29 a 39 semanas de atraso | C23: 1802 | D23: 58207
B24: Extrajudicial - 40 a 55 semanas de atraso | C24: 3081 | D24: 92828
B25: JUDICIAL | C25: 2 | D25: 0
B26: Mas 55 semanas de atraso | C26: 20762 | D26: 127170.04
B27: Total general | C27: =SUM(C22:C26) -> 27574 | D27: =SUM(D22:D26) -> 438147.38
B29: COBRANZA GENERAL SOFIA
B30: Segmento | C30: Cuentas | D30: Recuperación
B31: Extrajudicial - 0 a 28 semanas de atraso | C31: 292 | D31: 48125.97
B32: Extrajudicial - 29 a 39 semanas de atraso | C32: 1538 | D32: 92761.99
B33: Extrajudicial - 40 a 55 semanas de atraso | C33: 2249 | D33: 34268.99
B34: Mas 55 semanas de atraso | C34: 4229 | D34: 3238
B35: Total general | C35: =SUM(C31:C34) -> 8308 | D35: =SUM(D31:D34) -> 178394.95
B37: COBRANZA GENERAL OLGUIN
B38: Segmento | C38: Cuentas | D38: Recuperación
B39: Extrajudicial - 0 a 28 semanas de atraso | C39: 150 | D39: 14872
B40: Extrajudicial - 29 a 39 semanas de atraso | C40: 445 | D40: 76054
B41: Extrajudicial - 40 a 55 semanas de atraso | C41: 781 | D41: 1589
B42: Mas 55 semanas de atraso | C42: 1034 | D42: 3261
B43: Total general | C43: =SUM(C39:C42) -> 2410 | D43: =SUM(D39:D42) -> 95776
B45: COBRANZA GENERAL FEDERICO
B46: Segmento | C46: Cuentas | D46: Recuperación
B47: Extrajudicial - 0 a 28 semanas de atraso | C47: 110 | D47: 2323
...

Sheet DATA

Sheet EPR 10 MAYO
B2: REPORTE CONSOLIDADO POR SEGMENTOS
B3: SALDO ACUMULADO SEMANA 19
B5: COORDINADOR | C5: SEGMENTO | D5: CUENTAS | E5: COBRANZA REAL | F5: CUOTA IDEAL | G5: VARIACION | H5: % VAR | I5: EPR | J5: EPR IDEAL | K5: VAR EPR
B6: Zareth | C6: Extrajudicial - 0 a 28 semanas de atraso | D6: =SUMIF('REPORTE DIARIO'!B:B,'EPR 10 MAYO'!C6, 'REPORTE DIARIO'!C:C) -> 12339 | E6: =SUMIF('REPORTE DIARIO'!B:B,'EPR 10 MAYO'!C6, 'REPORTE DIARIO'!D:D) -> 1013484.8 | F6: =J6*D6 -> 2326782.9 | G6: =+E6-F6 -> -1313298 | H6: =ABS(G6/F6) -> 0.56442654 | I6: =E6/D6 -> 82.136709 | J6: =(220/7)*6 -> 188.57143 | K6: =+I6-J6 -> -106.43472
B7: Gabriel | C7: Extrajudicial - 29 a 39 semanas de atraso | D7: =SUMIF('REPORTE DIARIO'!B:B,'EPR 10 MAYO'!C7, 'REPORTE DIARIO'!C:C) -> 10630 | E7: =SUMIF('REPORTE DIARIO'!B:B,'EPR 10 MAYO'!C7, 'REPORTE DIARIO'!D:D) -> 524307.38 | F7: =J7*D7 -> 1002257.1 | G7: =+E7-F7 -> -477949.76 | H7: =ABS(G7/F7) -> 0.47687339 | I7: =E7/D7 -> 49.323366 | J7: =(110/7)*6 -> 94.285714 | K7: =+I7-J7 -> -44.962348
B8: Gabriel | C8: Extrajudicial - 40 a 55 semanas de atraso | D8: =SUMIF('REPORTE DIARIO'!B:B,'EPR 10 MAYO'!C8, 'REPORTE DIARIO'!C:C) -> 14806 | E8: =SUMIF('REPORTE DIARIO'!B:B,'EPR 10 MAYO'!C8, 'REPORTE DIARIO'!D:D) -> 364845.09 | F8: =J8*D8 -> 571088.57 | G8: =+E8-F8 -> -206243.48 | H8: =ABS(G8/F8) -> 0.36114097 | I8: =E8/D8 -> 24.641705 | J8: =(45/7)*6 -> 38.571429 | K8: =+I8-J8 -> -13.929723
B9: Fernando (Naucalpan) | C9: Mas 55 semanas de atraso | D9: =SUMIF('REPORTE DIARIO'!B:B,'EPR 10 MAYO'!C9, 'REPORTE DIARIO'!C:C) -> 51243 | E9: =SUMIF('REPORTE DIARIO'!B:B,'EPR 10 MAYO'!C9, 'REPORTE DIARIO'!D:D) -> 512270.44 | F9: =J9*D9 -> 658838.57 | G9: =+E9-F9 -> -146568.13 | H9: =ABS(G9/F9) -> 0.22246441 | I9: =E9/D9 -> 9.9968862 | J9: =(15/7)*6 -> 12.857143 | K9: =+I9-J9 -> -2.8602566
C10: TOTAL | D10: =SUM(D6:D9) -> 89018 | E10: =SUM(E6:E9) -> 2414907.8 | F10: =SUM(F6:F9) -> 4558967.1 | G10: =+E10-F10 -> -2144059.4 | H10: =ABS(G10/F10) -> 0.47029498 | I10: =E10/D10 -> 27.128308 | J10: =F10/D10 -> 51.213992 | K10: =I10-J10 -> -24.085684
B12: Nota:
B13: El saldo consolidado incluye los siguientes despachos
B14: Samantha, Samantha 2, Sofia, Edith, Fernando, Olguin y Federico
