Workbook

Sheet REPORTE DIARIO
B3: COBRANZA GENERAL SAMANTHA
B4: Segmento | C4: Cuentas | D4: Recuperación
B5: Extrajudicial - 0 a 28 semanas de atraso | C5: 3101 | D5: 144758.87
B6: Extrajudicial - 29 a 39 semanas de atraso | C6: 3488 | D6: 38575
B7: Extrajudicial - 40 a 55 semanas de atraso | C7: 6073 | D7: 30672
B8: JUDICIAL | C8: 11 | D8: 0
B9: Mas 55 semanas de atraso | C9: 12452 | D9: 73058.89
B10: Total general | C10: =SUM(C5:C9) -> 25125 | D10: =SUM(D5:D9) -> 287064.76
B12: COBRANZA GENERAL SAMANTHA 2
B13: Segmento | C13: Cuentas | D13: Recuperación
B14: Extrajudicial - 0 a 28 semanas de atraso | C14: 2864 | D14: 31317.44
B15: Extrajudicial - 29 a 39 semanas de atraso | C15: 1942 | D15: 5516.53
B16: Extrajudicial - 40 a 55 semanas de atraso | C16: 2518 | D16: 6987
B17: JUDICIAL | C17: 0 | D17: 0
B18: Mas 55 semanas de atraso | C18: 12600 | D18: 56352
B19: Total general | C19: =SUM(C14:C18) -> 19924 | D19: =SUM(D14:D18) -> 100172.97
B21: COBRANZA GENERAL SOFIA
B22: Segmento | C22: Cuentas | D22: Recuperación
B23: Extrajudicial - 0 a 28 semanas de atraso | C23: 447 | D23: 8042
B24: Extrajudicial - 29 a 39 semanas de atraso | C24: 2866 | D24: 47995
B25: Extrajudicial - 40 a 55 semanas de atraso | C25: 323 | D25: 1912
B26: Mas 55 semanas de atraso | C26: 3976 | D26: 11022
B27: Total general | C27: =SUM(C23:C26) -> 7612 | D27: =SUM(D23:D26) -> 68971
B29: COBRANZA GENERAL EDITH
B30: Segmento | C30: Cuentas | D30: Recuperación
B31: Extrajudicial - 0 a 28 semanas de atraso | C31: 3397 | D31: 38612.23
B32: Extrajudicial - 29 a 39 semanas de atraso | C32: 1366 | D32: 9553
B33: Extrajudicial - 40 a 55 semanas de atraso | C33: 2069 | D33: 6101
B34: JUDICIAL | C34: 1 | D34: 0
B35: Mas 55 semanas de atraso | C35: 16858 | D35: 7199
B36: Total general | C36: =SUM(C31:C35) -> 23691 | D36: =SUM(D31:D35) -> 61465.23
B38: COBRANZA GENERAL OLGUIN
B39: Segmento | C39: Cuentas | D39: Recuperación
B40: Extrajudicial - 0 a 28 semanas de atraso | C40: 2276 | D40: 10825
B41: Extrajudicial - 29 a 39 semanas de atraso | C41: 1423 | D41: 19828
B42: Extrajudicial - 40 a 55 semanas de atraso | C42: 1969 | D42: 6842
B43: Mas 55 semanas de atraso | C43: 1830 | D43: 2171
B44: Total general | C44: =SUM(C40:C43) -> 7498 | D44: =SUM(D40:D43) -> 39666
B46: COBRANZA GENERAL FERNANDO
B47: Segmento | C47: Cuentas | D47: Recuperación
...

Sheet DATA

Sheet EPR 13 JUN
B2: REPORTE CONSOLIDADO POR SEGMENTOS
B3: COBRANZA 13 JUNIO
B5: COORDINADOR | C5: SEGMENTO | D5: CUENTAS | E5: COBRANZA REAL | F5: CUOTA IDEAL | G5: VARIACION | H5: % VAR | I5: EPR | J5: EPR IDEAL | K5: VAR EPR
B6: Zareth | C6: Extrajudicial - 0 a 28 semanas de atraso | D6: =SUMIF('REPORTE DIARIO'!B:B,'EPR 13 JUN'!C6, 'REPORTE DIARIO'!C:C) -> 15320 | E6: =SUMIF('REPORTE DIARIO'!B:B,'EPR 13 JUN'!C6, 'REPORTE DIARIO'!D:D) -> 239969.67 | F6: =J6*D6 -> 481485.71 | G6: =+E6-F6 -> -241516.04 | H6: =ABS(G6/F6) -> 0.50160584 | I6: =E6/D6 -> 15.663817 | J6: =220/7 -> 31.428571 | K6: =+I6-J6 -> -15.764755
B7: Gabriel | C7: Extrajudicial - 29 a 39 semanas de atraso | D7: =SUMIF('REPORTE DIARIO'!B:B,'EPR 13 JUN'!C7, 'REPORTE DIARIO'!C:C) -> 11691 | E7: =SUMIF('REPORTE DIARIO'!B:B,'EPR 13 JUN'!C7, 'REPORTE DIARIO'!D:D) -> 121467.53 | F7: =J7*D7 -> 183715.71 | G7: =+E7-F7 -> -62248.184 | H7: =ABS(G7/F7) -> 0.33882885 | I7: =E7/D7 -> 10.389832 | J7: =110/7 -> 15.714286 | K7: =+I7-J7 -> -5.3244534
B8: Gabriel | C8: Extrajudicial - 40 a 55 semanas de atraso | D8: =SUMIF('REPORTE DIARIO'!B:B,'EPR 13 JUN'!C8, 'REPORTE DIARIO'!C:C) -> 13727 | E8: =SUMIF('REPORTE DIARIO'!B:B,'EPR 13 JUN'!C8, 'REPORTE DIARIO'!D:D) -> 53834 | F8: =J8*D8 -> 88245 | G8: =+E8-F8 -> -34411 | H8: =ABS(G8/F8) -> 0.38994844 | I8: =E8/D8 -> 3.92176 | J8: =45/7 -> 6.4285714 | K8: =+I8-J8 -> -2.5068114
B9: Fernando (Naucalpan) | C9: Mas 55 semanas de atraso | D9: =SUMIF('REPORTE DIARIO'!B:B,'EPR 13 JUN'!C9, 'REPORTE DIARIO'!C:C) -> 50143 | E9: =SUMIF('REPORTE DIARIO'!B:B,'EPR 13 JUN'!C9, 'REPORTE DIARIO'!D:D) -> 151428.89 | F9: =J9*D9 -> 107449.29 | G9: =+E9-F9 -> 43979.604 | H9: =ABS(G9/F9) -> 0.40930569 | I9: =E9/D9 -> 3.0199408 | J9: =15/7 -> 2.1428571 | K9: =+I9-J9 -> 0.87708363
C10: TOTAL | D10: =SUM(D6:D9) -> 90881 | E10: =SUM(E6:E9) -> 566700.09 | F10: =SUM(F6:F9) -> 860895.71 | G10: =+E10-F10 -> -294195.62 | H10: =ABS(G10/F10) -> 0.34173201 | I10: =E10/D10 -> 6.2356278 | J10: =F10/D10 -> 9.4727799 | K10: =I10-J10 -> -3.2371521
B12: Nota:
B13: El saldo consolidado incluye los siguientes despachos
B14: Samantha, Samantha 2, Sofia, Edith, Fernando, Olguin y Federico
