Workbook

Sheet REPORTE DIARIO
B3: COBRANZA GENERAL SAMANTHA
B4: Segmento | C4: Cuentas | D4: Recuperación
B5: Extrajudicial - 0 a 28 semanas de atraso | C5: 2519 | D5: 421515.06
B6: Extrajudicial - 29 a 39 semanas de atraso | C6: 3102 | D6: 208595.29
B7: Extrajudicial - 40 a 55 semanas de atraso | C7: 4832 | D7: 210781.22
B8: JUDICIAL | C8: 1980 | D8: 0.06
B9: Mas 55 semanas de atraso | C9: 11315 | D9: 310518.06
B10: Total general | C10: =SUM(C5:C9) -> 23748 | D10: =SUM(D5:D9) -> 1151409.7
B12: COBRANZA GENERAL EDITH
B13: Segmento | C13: Cuentas | D13: Recuperación
B14: Extrajudicial - 0 a 28 semanas de atraso | C14: 3214 | D14: 269816.24
B15: Extrajudicial - 29 a 39 semanas de atraso | C15: 1156 | D15: 66068.77
B16: Extrajudicial - 40 a 55 semanas de atraso | C16: 2152 | D16: 43300.82
B17: JUDICIAL | C17: 1 | D17: 39
B18: Mas 55 semanas de atraso | C18: 17177 | D18: 120338.95
B19: Total general | C19: =SUM(C14:C18) -> 23700 | D19: =SUM(D14:D18) -> 499563.78
B21: COBRANZA GENERAL SAMANTHA 2
B22: Segmento | C22: Cuentas | D22: Recuperación
B23: Extrajudicial - 0 a 28 semanas de atraso | C23: 2666 | D23: 176057.64
B24: Extrajudicial - 29 a 39 semanas de atraso | C24: 2185 | D24: 106208.71
B25: Extrajudicial - 40 a 55 semanas de atraso | C25: 2599 | D25: 47874.31
B26: JUDICIAL | C26: 2 | D26: 0
B27: Mas 55 semanas de atraso | C27: 17752 | D27: 163382.76
B28: Total general | C28: =SUM(C23:C27) -> 25204 | D28: =SUM(D23:D27) -> 493523.42
B30: COBRANZA GENERAL SOFIA
B31: Segmento | C31: Cuentas | D31: Recuperación
B32: Extrajudicial - 0 a 28 semanas de atraso | C32: 55 | D32: 27879.06
B33: Extrajudicial - 29 a 39 semanas de atraso | C33: 3348 | D33: 205929.9
B34: Extrajudicial - 40 a 55 semanas de atraso | C34: 273 | D34: 8692.67
B35: Mas 55 semanas de atraso | C35: 3972 | D35: 7194
B36: Total general | C36: =SUM(C32:C35) -> 7648 | D36: =SUM(D32:D35) -> 249695.63
B38: COBRANZA GENERAL OLGUIN
B39: Segmento | C39: Cuentas | D39: Recuperación
B40: Extrajudicial - 0 a 28 semanas de atraso | C40: 1929 | D40: 72601.79
B41: Extrajudicial - 29 a 39 semanas de atraso | C41: 1165 | D41: 22709.3
B42: Extrajudicial - 40 a 55 semanas de atraso | C42: 1966 | D42: 9438
B43: Mas 55 semanas de atraso | C43: 2023 | D43: 9002
B44: Total general | C44: =SUM(C40:C43) -> 7083 | D44: =SUM(D40:D43) -> 113751.09
B46: COBRANZA GENERAL FERNANDO
B47: Segmento | C47: Cuentas | D47: Recuperación
...

Sheet DATA

Sheet EPR 30 MAYO
B2: REPORTE CONSOLIDADO POR SEGMENTOS
B3: SALDO ACUMULADO SEMANA 22
B5: COORDINADOR | C5: SEGMENTO | D5: CUENTAS | E5: COBRANZA REAL | F5: CUOTA IDEAL | G5: VARIACION | H5: % VAR | I5: EPR | J5: EPR IDEAL | K5: VAR EPR
B6: Zareth | C6: Extrajudicial - 0 a 28 semanas de atraso | D6: =SUMIF('REPORTE DIARIO'!B:B,'EPR 30 MAYO'!C6, 'REPORTE DIARIO'!C:C) -> 13811 | E6: =SUMIF('REPORTE DIARIO'!B:B,'EPR 30 MAYO'!C6, 'REPORTE DIARIO'!D:D) -> 1103597.6 | F6: =J6*D6 -> 2604360 | G6: =+E6-F6 -> -1500762.4 | H6: =ABS(G6/F6) -> 0.57624999 | I6: =E6/D6 -> 79.907145 | J6: =(220/7)*6 -> 188.57143 | K6: =+I6-J6 -> -108.66428
B7: Gabriel | C7: Extrajudicial - 29 a 39 semanas de atraso | D7: =SUMIF('REPORTE DIARIO'!B:B,'EPR 30 MAYO'!C7, 'REPORTE DIARIO'!C:C) -> 11661 | E7: =SUMIF('REPORTE DIARIO'!B:B,'EPR 30 MAYO'!C7, 'REPORTE DIARIO'!D:D) -> 625876.78 | F7: =J7*D7 -> 1099465.7 | G7: =+E7-F7 -> -473588.93 | H7: =ABS(G7/F7) -> 0.43074461 | I7: =E7/D7 -> 53.672651 | J7: =(110/7)*6 -> 94.285714 | K7: =+I7-J7 -> -40.613064
B8: Gabriel | C8: Extrajudicial - 40 a 55 semanas de atraso | D8: =SUMIF('REPORTE DIARIO'!B:B,'EPR 30 MAYO'!C8, 'REPORTE DIARIO'!C:C) -> 12633 | E8: =SUMIF('REPORTE DIARIO'!B:B,'EPR 30 MAYO'!C8, 'REPORTE DIARIO'!D:D) -> 324078.02 | F8: =J8*D8 -> 487272.86 | G8: =+E8-F8 -> -163194.84 | H8: =ABS(G8/F8) -> 0.33491469 | I8: =E8/D8 -> 25.653291 | J8: =(45/7)*6 -> 38.571429 | K8: =+I8-J8 -> -12.918138
B9: Fernando (Naucalpan) | C9: Mas 55 semanas de atraso | D9: =SUMIF('REPORTE DIARIO'!B:B,'EPR 30 MAYO'!C9, 'REPORTE DIARIO'!C:C) -> 54711 | E9: =SUMIF('REPORTE DIARIO'!B:B,'EPR 30 MAYO'!C9, 'REPORTE DIARIO'!D:D) -> 615455.77 | F9: =J9*D9 -> 703427.14 | G9: =+E9-F9 -> -87971.373 | H9: =ABS(G9/F9) -> 0.1250611 | I9: =E9/D9 -> 11.249214 | J9: =(15/7)*6 -> 12.857143 | K9: =+I9-J9 -> -1.6079284
C10: TOTAL | D10: =SUM(D6:D9) -> 92816 | E10: =SUM(E6:E9) -> 2669008.2 | F10: =SUM(F6:F9) -> 4894525.7 | G10: =+E10-F10 -> -2225517.6 | H10: =ABS(G10/F10) -> 0.45469524 | I10: =E10/D10 -> 28.755906 | J10: =F10/D10 -> 52.733642 | K10: =I10-J10 -> -23.977736
B12: Nota:
B13: El saldo consolidado incluye los siguientes despachos
B14: Samantha, Samantha 2, Sofia, Edith, Fernando, Olguin y Federico
