Workbook

Sheet REPORTE DIARIO
B3: COBRANZA GENERAL SAMANTHA
B4: Segmento | C4: Cuentas | D4: Recuperación
B5: Extrajudicial - 0 a 28 semanas de atraso | C5: 4045 | D5: 47451.24
B6: Extrajudicial - 29 a 39 semanas de atraso | C6: 3876 | D6: 36122.52
B7: Extrajudicial - 40 a 55 semanas de atraso | C7: 4333 | D7: 49177.1
B8: JUDICIAL | C8: 11 | D8: 0
B9: Mas 55 semanas de atraso | C9: 11409 | D9: 31260.78
B10: Total general | C10: =SUM(C5:C9) -> 23674 | D10: =SUM(D5:D9) -> 164011.64
B12: COBRANZA GENERAL EDITH
B13: Segmento | C13: Cuentas | D13: Recuperación
B14: Extrajudicial - 0 a 28 semanas de atraso | C14: 3311 | D14: 57101.36
B15: Extrajudicial - 29 a 39 semanas de atraso | C15: 1468 | D15: 2658
B16: Extrajudicial - 40 a 55 semanas de atraso | C16: 2145 | D16: 3318.64
B17: JUDICIAL | C17: 1 | D17: 0
B18: Mas 55 semanas de atraso | C18: 17180 | D18: 99976.85
B19: Total general | C19: =SUM(C14:C18) -> 24105 | D19: =SUM(D14:D18) -> 163054.85
B21: COBRANZA GENERAL SAMANTHA 2
B22: Segmento | C22: Cuentas | D22: Recuperación
B23: Extrajudicial - 0 a 28 semanas de atraso | C23: 2453 | D23: 18376.94
B24: Extrajudicial - 29 a 39 semanas de atraso | C24: 2100 | D24: 6485
B25: Extrajudicial - 40 a 55 semanas de atraso | C25: 2076 | D25: 1565
B26: JUDICIAL | C26: 2 | D26: 0
B27: Mas 55 semanas de atraso | C27: 20987 | D27: 14041.9
B28: Total general | C28: =SUM(C23:C27) -> 27618 | D28: =SUM(D23:D27) -> 40468.84
B30: COBRANZA GENERAL SOFIA
B31: Segmento | C31: Cuentas | D31: Recuperación
B32: Extrajudicial - 0 a 28 semanas de atraso | C32: 217 | D32: 5582.38
B33: Extrajudicial - 29 a 39 semanas de atraso | C33: 3348 | D33: 31012.48
B34: Extrajudicial - 40 a 55 semanas de atraso | C34: 267 | D34: 2000
B35: Mas 55 semanas de atraso | C35: 3972 | D35: 1000
B36: Total general | C36: =SUM(C32:C35) -> 7804 | D36: =SUM(D32:D35) -> 39594.86
B38: COBRANZA GENERAL FERNANDO
B39: Segmento | C39: Cuentas | D39: Recuperación
B40: Extrajudicial - 0 a 28 semanas de atraso | C40: 2888 | D40: 21259
B41: Total general | C41: =SUM(C40:C40) -> 2888 | D41: =SUM(D40:D40) -> 21259
B43: COBRANZA GENERAL OLGUIN
B44: Segmento | C44: Cuentas | D44: Recuperación
B45: Extrajudicial - 0 a 28 semanas de atraso | C45: 989 | D45: 11393
B46: Extrajudicial - 29 a 39 semanas de atraso | C46: 1035 | D46: 4151
B47: Extrajudicial - 40 a 55 semanas de atraso | C47: 1720 | D47: 1231
...

Sheet DATA

Sheet EPR 27 MAYO
B2: REPORTE CONSOLIDADO POR SEGMENTOS
B3: COBRANZA 27 MAYO
B5: COORDINADOR | C5: SEGMENTO | D5: CUENTAS | E5: COBRANZA REAL | F5: CUOTA IDEAL | G5: VARIACION | H5: % VAR | I5: EPR | J5: EPR IDEAL | K5: VAR EPR
B6: Zareth | C6: Extrajudicial - 0 a 28 semanas de atraso | D6: =SUMIF('REPORTE DIARIO'!B:B,'EPR 27 MAYO'!C6, 'REPORTE DIARIO'!C:C) -> 14514 | E6: =SUMIF('REPORTE DIARIO'!B:B,'EPR 27 MAYO'!C6, 'REPORTE DIARIO'!D:D) -> 167526.92 | F6: =J6*D6 -> 456154.29 | G6: =+E6-F6 -> -288627.37 | H6: =ABS(G6/F6) -> 0.63274066 | I6: =E6/D6 -> 11.542436 | J6: =220/7 -> 31.428571 | K6: =+I6-J6 -> -19.886135
B7: Gabriel | C7: Extrajudicial - 29 a 39 semanas de atraso | D7: =SUMIF('REPORTE DIARIO'!B:B,'EPR 27 MAYO'!C7, 'REPORTE DIARIO'!C:C) -> 12698 | E7: =SUMIF('REPORTE DIARIO'!B:B,'EPR 27 MAYO'!C7, 'REPORTE DIARIO'!D:D) -> 82563 | F7: =J7*D7 -> 199540 | G7: =+E7-F7 -> -116977 | H7: =ABS(G7/F7) -> 0.58623334 | I7: =E7/D7 -> 6.5020476 | J7: =110/7 -> 15.714286 | K7: =+I7-J7 -> -9.2122381
B8: Gabriel | C8: Extrajudicial - 40 a 55 semanas de atraso | D8: =SUMIF('REPORTE DIARIO'!B:B,'EPR 27 MAYO'!C8, 'REPORTE DIARIO'!C:C) -> 11363 | E8: =SUMIF('REPORTE DIARIO'!B:B,'EPR 27 MAYO'!C8, 'REPORTE DIARIO'!D:D) -> 59821.74 | F8: =J8*D8 -> 73047.857 | G8: =+E8-F8 -> -13226.117 | H8: =ABS(G8/F8) -> 0.18106099 | I8: =E8/D8 -> 5.2646079 | J8: =45/7 -> 6.4285714 | K8: =+I8-J8 -> -1.1639635
B9: Fernando (Naucalpan) | C9: Mas 55 semanas de atraso | D9: =SUMIF('REPORTE DIARIO'!B:B,'EPR 27 MAYO'!C9, 'REPORTE DIARIO'!C:C) -> 57964 | E9: =SUMIF('REPORTE DIARIO'!B:B,'EPR 27 MAYO'!C9, 'REPORTE DIARIO'!D:D) -> 151418.53 | F9: =J9*D9 -> 124208.57 | G9: =+E9-F9 -> 27209.959 | H9: =ABS(G9/F9) -> 0.21906667 | I9: =E9/D9 -> 2.6122857 | J9: =15/7 -> 2.1428571 | K9: =+I9-J9 -> 0.46942859
C10: TOTAL | D10: =SUM(D6:D9) -> 96539 | E10: =SUM(E6:E9) -> 461330.19 | F10: =SUM(F6:F9) -> 852950.71 | G10: =+E10-F10 -> -391620.52 | H10: =ABS(G10/F10) -> 0.45913617 | I10: =E10/D10 -> 4.7786924 | J10: =F10/D10 -> 8.8352968 | K10: =I10-J10 -> -4.0566043
B12: Nota:
B13: El saldo consolidado incluye los siguientes despachos
B14: Samantha, Samantha 2, Sofia, Edith, Fernando, Olguin y Federico
