Workbook

Sheet REPORTE DIARIO
B3: COBRANZA GENERAL SAMANTHA
B4: Segmento | C4: Cuentas | D4: Recuperación
B5: Extrajudicial - 0 a 28 semanas de atraso | C5: 4077 | D5: 74243.31
B6: Extrajudicial - 29 a 39 semanas de atraso | C6: 4152 | D6: 57885.46
B7: Extrajudicial - 40 a 55 semanas de atraso | C7: 4246 | D7: 50514.08
B8: JUDICIAL | C8: 11 | D8: 0
B9: Mas 55 semanas de atraso | C9: 11389 | D9: 64699.22
B10: Total general | C10: =SUM(C5:C9) -> 23875 | D10: =SUM(D5:D9) -> 247342.07
B12: COBRANZA GENERAL SAMANTHA 2
B13: Segmento | C13: Cuentas | D13: Recuperación
B14: Extrajudicial - 0 a 28 semanas de atraso | C14: 2407 | D14: 25417.96
B15: Extrajudicial - 29 a 39 semanas de atraso | C15: 2109 | D15: 19797.49
B16: Extrajudicial - 40 a 55 semanas de atraso | C16: 2109 | D16: 55207.24
B17: JUDICIAL | C17: 2 | D17: 0
B18: Mas 55 semanas de atraso | C18: 20952 | D18: 24924.03
B19: Total general | C19: =SUM(C14:C18) -> 27579 | D19: =SUM(D14:D18) -> 125346.72
B21: COBRANZA GENERAL EDITH
B22: Segmento | C22: Cuentas | D22: Recuperación
B23: Extrajudicial - 0 a 28 semanas de atraso | C23: 3325 | D23: 58387.65
B24: Extrajudicial - 29 a 39 semanas de atraso | C24: 1476 | D24: 31838.95
B25: Extrajudicial - 40 a 55 semanas de atraso | C25: 2145 | D25: 4232
B26: JUDICIAL | C26: 1 | D26: 0
B27: Mas 55 semanas de atraso | C27: 17181 | D27: 7316
B28: Total general | C28: =SUM(C23:C27) -> 24128 | D28: =SUM(D23:D27) -> 101774.6
B30: COBRANZA GENERAL SOFIA
B31: Segmento | C31: Cuentas | D31: Recuperación
B32: Extrajudicial - 0 a 28 semanas de atraso | C32: 220 | D32: 13141.38
B33: Extrajudicial - 29 a 39 semanas de atraso | C33: 3350 | D33: 24095.48
B34: Extrajudicial - 40 a 55 semanas de atraso | C34: 269 | D34: 1369
B35: Mas 55 semanas de atraso | C35: 3972 | D35: 4710
B36: Total general | C36: =SUM(C32:C35) -> 7811 | D36: =SUM(D32:D35) -> 43315.86
B38: COBRANZA GENERAL OLGUIN
B39: Segmento | C39: Cuentas | D39: Recuperación
B40: Extrajudicial - 0 a 28 semanas de atraso | C40: 922 | D40: 7396
B41: Extrajudicial - 29 a 39 semanas de atraso | C41: 982 | D41: 5057
B42: Extrajudicial - 40 a 55 semanas de atraso | C42: 1551 | D42: 1500
B43: Mas 55 semanas de atraso | C43: 1875 | D43: 11245
B44: Total general | C44: =SUM(C40:C43) -> 5330 | D44: =SUM(D40:D43) -> 25198
B46: COBRANZA GENERAL FERNANDO
B47: Segmento | C47: Cuentas | D47: Recuperación
...

Sheet DATA

Sheet EPR 25 MAYO
B2: REPORTE CONSOLIDADO POR SEGMENTOS
B3: COBRANZA 25 MAYO
B5: COORDINADOR | C5: SEGMENTO | D5: CUENTAS | E5: COBRANZA REAL | F5: CUOTA IDEAL | G5: VARIACION | H5: % VAR | I5: EPR | J5: EPR IDEAL | K5: VAR EPR
B6: Zareth | C6: Extrajudicial - 0 a 28 semanas de atraso | D6: =SUMIF('REPORTE DIARIO'!B:B,'EPR 25 MAYO'!C6, 'REPORTE DIARIO'!C:C) -> 14283 | E6: =SUMIF('REPORTE DIARIO'!B:B,'EPR 25 MAYO'!C6, 'REPORTE DIARIO'!D:D) -> 190541.3 | F6: =J6*D6 -> 448894.29 | G6: =+E6-F6 -> -258352.99 | H6: =ABS(G6/F6) -> 0.57553191 | I6: =E6/D6 -> 13.340426 | J6: =220/7 -> 31.428571 | K6: =+I6-J6 -> -18.088146
B7: Gabriel | C7: Extrajudicial - 29 a 39 semanas de atraso | D7: =SUMIF('REPORTE DIARIO'!B:B,'EPR 25 MAYO'!C7, 'REPORTE DIARIO'!C:C) -> 12934 | E7: =SUMIF('REPORTE DIARIO'!B:B,'EPR 25 MAYO'!C7, 'REPORTE DIARIO'!D:D) -> 138674.38 | F7: =J7*D7 -> 203248.57 | G7: =+E7-F7 -> -64574.191 | H7: =ABS(G7/F7) -> 0.31771043 | I7: =E7/D7 -> 10.721693 | J7: =110/7 -> 15.714286 | K7: =+I7-J7 -> -4.9925925
B8: Gabriel | C8: Extrajudicial - 40 a 55 semanas de atraso | D8: =SUMIF('REPORTE DIARIO'!B:B,'EPR 25 MAYO'!C8, 'REPORTE DIARIO'!C:C) -> 11129 | E8: =SUMIF('REPORTE DIARIO'!B:B,'EPR 25 MAYO'!C8, 'REPORTE DIARIO'!D:D) -> 112822.32 | F8: =J8*D8 -> 71543.571 | G8: =+E8-F8 -> 41278.749 | H8: =ABS(G8/F8) -> 0.57697355 | I8: =E8/D8 -> 10.137687 | J8: =45/7 -> 6.4285714 | K8: =+I8-J8 -> 3.7091157
B9: Fernando (Naucalpan) | C9: Mas 55 semanas de atraso | D9: =SUMIF('REPORTE DIARIO'!B:B,'EPR 25 MAYO'!C9, 'REPORTE DIARIO'!C:C) -> 57841 | E9: =SUMIF('REPORTE DIARIO'!B:B,'EPR 25 MAYO'!C9, 'REPORTE DIARIO'!D:D) -> 114779.25 | F9: =J9*D9 -> 123945 | G9: =+E9-F9 -> -9165.75 | H9: =ABS(G9/F9) -> 0.073950139 | I9: =E9/D9 -> 1.9843926 | J9: =15/7 -> 2.1428571 | K9: =+I9-J9 -> -0.15846458
C10: TOTAL | D10: =SUM(D6:D9) -> 96187 | E10: =SUM(E6:E9) -> 556817.25 | F10: =SUM(F6:F9) -> 847631.43 | G10: =+E10-F10 -> -290814.18 | H10: =ABS(G10/F10) -> 0.34309037 | I10: =E10/D10 -> 5.7889034 | J10: =F10/D10 -> 8.8123284 | K10: =I10-J10 -> -3.023425
B12: Nota:
B13: El saldo consolidado incluye los siguientes despachos
B14: Samantha, Samantha 2, Sofia, Edith, Fernando, Olguin y Federico
