Workbook

Sheet REPORTE DIARIO
B3: COBRANZA GENERAL SAMANTHA
B4: Segmento | C4: Cuentas | D4: Recuperación
B5: Extrajudicial - 0 a 28 semanas de atraso | C5: 7518 | D5: 25977.2
B6: Extrajudicial - 29 a 39 semanas de atraso | C6: 8307 | D6: 26680.15
B7: Extrajudicial - 40 a 55 semanas de atraso | C7: 10167 | D7: 26627
B8: JUDICIAL | C8: 21 | D8: 0
B9: Mas 55 semanas de atraso | C9: 50924 | D9: 46074
B10: Total general | C10: =SUM(C5:C9) -> 76937 | D10: =SUM(D5:D9) -> 125358.35
B12: COBRANZA GENERAL SAMANTHA 2
B13: Segmento | C13: Cuentas | D13: Recuperación
B14: Extrajudicial - 0 a 28 semanas de atraso | C14: 3407 | D14: 36978
B15: Extrajudicial - 29 a 39 semanas de atraso | C15: 1799 | D15: 6033
B16: Extrajudicial - 40 a 55 semanas de atraso | C16: 3291 | D16: 2170
B17: JUDICIAL | C17: 2 | D17: 0
B18: Mas 55 semanas de atraso | C18: 21223 | D18: 11364
B19: Total general | C19: =SUM(C14:C18) -> 29722 | D19: =SUM(D14:D18) -> 56545
B21: COBRANZA GENERAL EDITH
B22: Segmento | C22: Cuentas | D22: Recuperación
B23: Extrajudicial - 0 a 28 semanas de atraso | C23: 2068 | D23: 17276.15
B24: Extrajudicial - 29 a 39 semanas de atraso | C24: 1758 | D24: 5695.5
B25: Extrajudicial - 40 a 55 semanas de atraso | C25: 288 | D25: 0
B26: Mas 55 semanas de atraso | C26: 8257 | D26: 3414
B27: Total general | C27: =SUM(C23:C26) -> 12371 | D27: =SUM(D23:D26) -> 26385.65
B29: COBRANZA GENERAL SOFIA
B30: Segmento | C30: Cuentas | D30: Recuperación
B31: Extrajudicial - 0 a 28 semanas de atraso | C31: 1672 | D31: 37674.06
B32: Extrajudicial - 29 a 39 semanas de atraso | C32: 901 | D32: 1990
B33: Extrajudicial - 40 a 55 semanas de atraso | C33: 3188 | D33: 93
B34: Mas 55 semanas de atraso | C34: 1901 | D34: 0
B35: Total general | C35: =SUM(C31:C34) -> 7662 | D35: =SUM(D31:D34) -> 39757.06
B37: COBRANZA GENERAL FERNANDO
B38: Segmento | C38: Cuentas | D38: Recuperación
B39: Extrajudicial - 0 a 28 semanas de atraso | C39: 3082 | D39: 4577
B40: Total general | C40: =SUM(C39:C39) -> 3082 | D40: =SUM(D39:D39) -> 4577
B42: COBRANZA GENERAL OLGUIN
B43: Segmento | C43: Cuentas | D43: Recuperación
B44: Extrajudicial - 0 a 28 semanas de atraso | C44: 68 | D44: 435
B45: Extrajudicial - 29 a 39 semanas de atraso | C45: 94 | D45: 0
B46: Extrajudicial - 40 a 55 semanas de atraso | C46: 14 | D46: 0
B47: Mas 55 semanas de atraso | C47: 10 | D47: 0
...

Sheet DATA

Sheet EPR 25 MAR
B2: REPORTE CONSOLIDADO POR SEGMENTOS
B3: COBRANZA 25 MARZO
B5: COORDINADOR | C5: SEGMENTO | D5: CUENTAS | E5: COBRANZA REAL | F5: CUOTA IDEAL | G5: VARIACION | H5: % VAR | I5: EPR | J5: EPR IDEAL | K5: VAR EPR
B6: Samatha y Zareth | C6: Extrajudicial - 0 a 28 semanas de atraso | D6: =SUMIF('REPORTE DIARIO'!B:B,'EPR 25 MAR'!C6, 'REPORTE DIARIO'!C:C) -> 17815 | E6: =SUMIF('REPORTE DIARIO'!B:B,'EPR 25 MAR'!C6, 'REPORTE DIARIO'!D:D) -> 122917.41 | F6: =J6*D6 -> 509000 | G6: =+E6-F6 -> -386082.59 | H6: =ABS(G6/F6) -> 0.75851196 | I6: =E6/D6 -> 6.8996582 | J6: =200/7 -> 28.571429 | K6: =+I6-J6 -> -21.67177
B7: Gabriel | C7: Extrajudicial - 29 a 39 semanas de atraso | D7: =SUMIF('REPORTE DIARIO'!B:B,'EPR 25 MAR'!C7, 'REPORTE DIARIO'!C:C) -> 12982 | E7: =SUMIF('REPORTE DIARIO'!B:B,'EPR 25 MAR'!C7, 'REPORTE DIARIO'!D:D) -> 40398.65 | F7: =J7*D7 -> 204002.86 | G7: =+E7-F7 -> -163604.21 | H7: =ABS(G7/F7) -> 0.80197018 | I7: =E7/D7 -> 3.1118972 | J7: =110/7 -> 15.714286 | K7: =+I7-J7 -> -12.602388
B8: Gabriel | C8: Extrajudicial - 40 a 55 semanas de atraso | D8: =SUMIF('REPORTE DIARIO'!B:B,'EPR 25 MAR'!C8, 'REPORTE DIARIO'!C:C) -> 17112 | E8: =SUMIF('REPORTE DIARIO'!B:B,'EPR 25 MAR'!C8, 'REPORTE DIARIO'!D:D) -> 28890 | F8: =J8*D8 -> 110005.71 | G8: =+E8-F8 -> -81115.714 | H8: =ABS(G8/F8) -> 0.73737728 | I8: =E8/D8 -> 1.6882889 | J8: =45/7 -> 6.4285714 | K8: =+I8-J8 -> -4.7402825
B9: Fernando | C9: Mas 55 semanas de atraso | D9: =SUMIF('REPORTE DIARIO'!B:B,'EPR 25 MAR'!C9, 'REPORTE DIARIO'!C:C) -> 82666 | E9: =SUMIF('REPORTE DIARIO'!B:B,'EPR 25 MAR'!C9, 'REPORTE DIARIO'!D:D) -> 60852 | F9: =J9*D9 -> 177141.43 | G9: =+E9-F9 -> -116289.43 | H9: =ABS(G9/F9) -> 0.65647787 | I9: =E9/D9 -> 0.73611884 | J9: =15/7 -> 2.1428571 | K9: =+I9-J9 -> -1.4067383
C10: TOTAL | D10: =SUM(D6:D9) -> 130575 | E10: =SUM(E6:E9) -> 253058.06 | F10: =SUM(F6:F9) -> 1000150 | G10: =+E10-F10 -> -747091.94 | H10: =ABS(G10/F10) -> 0.74697989 | I10: =E10/D10 -> 1.9380284 | J10: =F10/D10 -> 7.6595826 | K10: =I10-J10 -> -5.7215542
B12: Nota:
B13: El saldo consolidado incluye los siguientes despachos
B14: Samantha, Samantha 2, Sofia, Edith, Olguin, Fernando y Federico
