Workbook

Sheet REPORTE DIARIO
B3: COBRANZA GENERAL SAMANTHA
B4: Segmento | C4: Cuentas | D4: Recuperación
B5: Extrajudicial - 0 a 28 semanas de atraso | C5: 2558 | D5: 284767.82
B6: Extrajudicial - 29 a 39 semanas de atraso | C6: 3261 | D6: 134382.29
B7: Extrajudicial - 40 a 55 semanas de atraso | C7: 4789 | D7: 151234.53
B8: JUDICIAL | C8: 1980 | D8: 0
B9: Mas 55 semanas de atraso | C9: 11303 | D9: 181311.42
B10: Total general | C10: =SUM(C5:C9) -> 23891 | D10: =SUM(D5:D9) -> 751696.06
B12: COBRANZA GENERAL EDITH
B13: Segmento | C13: Cuentas | D13: Recuperación
B14: Extrajudicial - 0 a 28 semanas de atraso | C14: 3225 | D14: 196094.4
B15: Extrajudicial - 29 a 39 semanas de atraso | C15: 1170 | D15: 46900.37
B16: Extrajudicial - 40 a 55 semanas de atraso | C16: 2153 | D16: 34321.82
B17: JUDICIAL | C17: 1 | D17: 0
B18: Mas 55 semanas de atraso | C18: 17178 | D18: 109395.46
B19: Total general | C19: =SUM(C14:C18) -> 23727 | D19: =SUM(D14:D18) -> 386712.05
B21: COBRANZA GENERAL SAMANTHA 2
B22: Segmento | C22: Cuentas | D22: Recuperación
B23: Extrajudicial - 0 a 28 semanas de atraso | C23: 2655 | D23: 127827.64
B24: Extrajudicial - 29 a 39 semanas de atraso | C24: 2194 | D24: 92163
B25: Extrajudicial - 40 a 55 semanas de atraso | C25: 2576 | D25: 36476.31
B26: JUDICIAL | C26: 2 | D26: 0
B27: Mas 55 semanas de atraso | C27: 17736 | D27: 105862.95
B28: Total general | C28: =SUM(C23:C27) -> 25163 | D28: =SUM(D23:D27) -> 362329.9
B30: COBRANZA GENERAL SOFIA
B31: Segmento | C31: Cuentas | D31: Recuperación
B32: Extrajudicial - 0 a 28 semanas de atraso | C32: 55 | D32: 23877.06
B33: Extrajudicial - 29 a 39 semanas de atraso | C33: 3341 | D33: 133504.24
B34: Extrajudicial - 40 a 55 semanas de atraso | C34: 265 | D34: 3578.68
B35: Mas 55 semanas de atraso | C35: 3972 | D35: 4723
B36: Total general | C36: =SUM(C32:C35) -> 7633 | D36: =SUM(D32:D35) -> 165682.98
B38: COBRANZA GENERAL OLGUIN
B39: Segmento | C39: Cuentas | D39: Recuperación
B40: Extrajudicial - 0 a 28 semanas de atraso | C40: 1910 | D40: 70242.79
B41: Extrajudicial - 29 a 39 semanas de atraso | C41: 1146 | D41: 18933.3
B42: Extrajudicial - 40 a 55 semanas de atraso | C42: 1923 | D42: 6887
B43: Mas 55 semanas de atraso | C43: 2014 | D43: 6200
B44: Total general | C44: =SUM(C40:C43) -> 6993 | D44: =SUM(D40:D43) -> 102263.09
B46: COBRANZA GENERAL FERNANDO
B47: Segmento | C47: Cuentas | D47: Recuperación
...

Sheet DATA

Sheet EPR 29 MAYO
B2: REPORTE CONSOLIDADO POR SEGMENTOS
B3: SALDO ACUMULADO SEMANA 22
B5: COORDINADOR | C5: SEGMENTO | D5: CUENTAS | E5: COBRANZA REAL | F5: CUOTA IDEAL | G5: VARIACION | H5: % VAR | I5: EPR | J5: EPR IDEAL | K5: VAR EPR
B6: Zareth | C6: Extrajudicial - 0 a 28 semanas de atraso | D6: =SUMIF('REPORTE DIARIO'!B:B,'EPR 29 MAYO'!C6, 'REPORTE DIARIO'!C:C) -> 13839 | E6: =SUMIF('REPORTE DIARIO'!B:B,'EPR 29 MAYO'!C6, 'REPORTE DIARIO'!D:D) -> 778466.71 | F6: =J6*D6 -> 1739760 | G6: =+E6-F6 -> -961293.29 | H6: =ABS(G6/F6) -> 0.55254362 | I6: =E6/D6 -> 56.251659 | J6: =(220/7)*4 -> 125.71429 | K6: =+I6-J6 -> -69.462627
B7: Gabriel | C7: Extrajudicial - 29 a 39 semanas de atraso | D7: =SUMIF('REPORTE DIARIO'!B:B,'EPR 29 MAYO'!C7, 'REPORTE DIARIO'!C:C) -> 11818 | E7: =SUMIF('REPORTE DIARIO'!B:B,'EPR 29 MAYO'!C7, 'REPORTE DIARIO'!D:D) -> 441948.01 | F7: =J7*D7 -> 742845.71 | G7: =+E7-F7 -> -300897.7 | H7: =ABS(G7/F7) -> 0.40506083 | I7: =E7/D7 -> 37.396176 | J7: =(110/7)*4 -> 62.857143 | K7: =+I7-J7 -> -25.460967
B8: Gabriel | C8: Extrajudicial - 40 a 55 semanas de atraso | D8: =SUMIF('REPORTE DIARIO'!B:B,'EPR 29 MAYO'!C8, 'REPORTE DIARIO'!C:C) -> 12517 | E8: =SUMIF('REPORTE DIARIO'!B:B,'EPR 29 MAYO'!C8, 'REPORTE DIARIO'!D:D) -> 235169.34 | F8: =J8*D8 -> 321865.71 | G8: =+E8-F8 -> -86696.374 | H8: =ABS(G8/F8) -> 0.26935573 | I8: =E8/D8 -> 18.787996 | J8: =(45/7)*4 -> 25.714286 | K8: =+I8-J8 -> -6.9262902
B9: Fernando (Naucalpan) | C9: Mas 55 semanas de atraso | D9: =SUMIF('REPORTE DIARIO'!B:B,'EPR 29 MAYO'!C9, 'REPORTE DIARIO'!C:C) -> 54675 | E9: =SUMIF('REPORTE DIARIO'!B:B,'EPR 29 MAYO'!C9, 'REPORTE DIARIO'!D:D) -> 411476.83 | F9: =J9*D9 -> 468642.86 | G9: =+E9-F9 -> -57166.027 | H9: =ABS(G9/F9) -> 0.12198207 | I9: =E9/D9 -> 7.5258679 | J9: =(15/7)*4 -> 8.5714286 | K9: =+I9-J9 -> -1.0455606
C10: TOTAL | D10: =SUM(D6:D9) -> 92849 | E10: =SUM(E6:E9) -> 1867060.9 | F10: =SUM(F6:F9) -> 3273114.3 | G10: =+E10-F10 -> -1406053.4 | H10: =ABS(G10/F10) -> 0.42957663 | I10: =E10/D10 -> 20.108573 | J10: =F10/D10 -> 35.252014 | K10: =I10-J10 -> -15.143441
B12: Nota:
B13: El saldo consolidado incluye los siguientes despachos
B14: Samantha, Samantha 2, Sofia, Edith, Fernando, Olguin y Federico
