Workbook

Sheet REPORTE DIARIO
B3: COBRANZA GENERAL SAMANTHA
B4: Segmento | C4: Cuentas | D4: Recuperación
B5: Extrajudicial - 0 a 28 semanas de atraso | C5: 4236 | D5: 28732
B6: Extrajudicial - 29 a 39 semanas de atraso | C6: 4290 | D6: 15399
B7: Extrajudicial - 40 a 55 semanas de atraso | C7: 6045 | D7: 82983
B8: JUDICIAL | C8: 10 | D8: 0
B9: Mas 55 semanas de atraso | C9: 13146 | D9: 23697.71
B10: Total general | C10: =SUM(C5:C9) -> 27727 | D10: =SUM(D5:D9) -> 150811.71
B12: COBRANZA GENERAL SAMANTHA 2
B13: Segmento | C13: Cuentas | D13: Recuperación
B14: Extrajudicial - 0 a 28 semanas de atraso | C14: 1965 | D14: 63804.1
B15: Extrajudicial - 29 a 39 semanas de atraso | C15: 1739 | D15: 1622
B16: Extrajudicial - 40 a 55 semanas de atraso | C16: 3033 | D16: 2212
B17: JUDICIAL | C17: 2 | D17: 0
B18: Mas 55 semanas de atraso | C18: 20753 | D18: 47149
B19: Total general | C19: =SUM(C14:C18) -> 27492 | D19: =SUM(D14:D18) -> 114787.1
B21: COBRANZA GENERAL OLGUIN
B22: Segmento | C22: Cuentas | D22: Recuperación
B23: Extrajudicial - 0 a 28 semanas de atraso | C23: 150 | D23: 14872
B24: Extrajudicial - 29 a 39 semanas de atraso | C24: 385 | D24: 73314
B25: Extrajudicial - 40 a 55 semanas de atraso | C25: 725 | D25: 0
B26: Mas 55 semanas de atraso | C26: 1008 | D26: 0
B27: Total general | C27: =SUM(C23:C26) -> 2268 | D27: =SUM(D23:D26) -> 88186
B29: COBRANZA GENERAL EDITH
B30: Segmento | C30: Cuentas | D30: Recuperación
B31: Extrajudicial - 0 a 28 semanas de atraso | C31: 3749 | D31: 13069.47
B32: Extrajudicial - 29 a 39 semanas de atraso | C32: 1968 | D32: 2152
B33: Extrajudicial - 40 a 55 semanas de atraso | C33: 2198 | D33: 1415
B34: Mas 55 semanas de atraso | C34: 9704 | D34: 9687
B35: Total general | C35: =SUM(C31:C34) -> 17619 | D35: =SUM(D31:D34) -> 26323.47
B37: COBRANZA GENERAL SOFIA
B38: Segmento | C38: Cuentas | D38: Recuperación
B39: Extrajudicial - 0 a 28 semanas de atraso | C39: 294 | D39: 3255.49
B40: Extrajudicial - 29 a 39 semanas de atraso | C40: 1402 | D40: 1294
B41: Extrajudicial - 40 a 55 semanas de atraso | C41: 2318 | D41: 280
B42: Mas 55 semanas de atraso | C42: 4229 | D42: 0
B43: Total general | C43: =SUM(C39:C42) -> 8243 | D43: =SUM(D39:D42) -> 4829.49
B45: COBRANZA GENERAL FERNANDO
B46: Segmento | C46: Cuentas | D46: Recuperación
B47: Extrajudicial - 0 a 28 semanas de atraso | C47: 2072 | D47: 400
...

Sheet DATA

Sheet EPR 07 MAYO
B2: REPORTE CONSOLIDADO POR SEGMENTOS
B3: COBRANZA 07 MAYO
B5: COORDINADOR | C5: SEGMENTO | D5: CUENTAS | E5: COBRANZA REAL | F5: CUOTA IDEAL | G5: VARIACION | H5: % VAR | I5: EPR | J5: EPR IDEAL | K5: VAR EPR
B6: Zareth | C6: Extrajudicial - 0 a 28 semanas de atraso | D6: =SUMIF('REPORTE DIARIO'!B:B,'EPR 07 MAYO'!C6, 'REPORTE DIARIO'!C:C) -> 12576 | E6: =SUMIF('REPORTE DIARIO'!B:B,'EPR 07 MAYO'!C6, 'REPORTE DIARIO'!D:D) -> 124133.06 | F6: =J6*D6 -> 395245.71 | G6: =+E6-F6 -> -271112.65 | H6: =ABS(G6/F6) -> 0.68593446 | I6: =E6/D6 -> 9.8706314 | J6: =220/7 -> 31.428571 | K6: =+I6-J6 -> -21.55794
B7: Gabriel | C7: Extrajudicial - 29 a 39 semanas de atraso | D7: =SUMIF('REPORTE DIARIO'!B:B,'EPR 07 MAYO'!C7, 'REPORTE DIARIO'!C:C) -> 10344 | E7: =SUMIF('REPORTE DIARIO'!B:B,'EPR 07 MAYO'!C7, 'REPORTE DIARIO'!D:D) -> 93781 | F7: =J7*D7 -> 162548.57 | G7: =+E7-F7 -> -68767.571 | H7: =ABS(G7/F7) -> 0.4230586 | I7: =E7/D7 -> 9.066222 | J7: =110/7 -> 15.714286 | K7: =+I7-J7 -> -6.6480637
B8: Gabriel | C8: Extrajudicial - 40 a 55 semanas de atraso | D8: =SUMIF('REPORTE DIARIO'!B:B,'EPR 07 MAYO'!C8, 'REPORTE DIARIO'!C:C) -> 14733 | E8: =SUMIF('REPORTE DIARIO'!B:B,'EPR 07 MAYO'!C8, 'REPORTE DIARIO'!D:D) -> 86890 | F8: =J8*D8 -> 94712.143 | G8: =+E8-F8 -> -7822.1429 | H8: =ABS(G8/F8) -> 0.082588596 | I8: =E8/D8 -> 5.8976447 | J8: =45/7 -> 6.4285714 | K8: =+I8-J8 -> -0.53092669
B9: Fernando (Naucalpan) | C9: Mas 55 semanas de atraso | D9: =SUMIF('REPORTE DIARIO'!B:B,'EPR 07 MAYO'!C9, 'REPORTE DIARIO'!C:C) -> 50939 | E9: =SUMIF('REPORTE DIARIO'!B:B,'EPR 07 MAYO'!C9, 'REPORTE DIARIO'!D:D) -> 80533.71 | F9: =J9*D9 -> 109155 | G9: =+E9-F9 -> -28621.29 | H9: =ABS(G9/F9) -> 0.26220778 | I9: =E9/D9 -> 1.5809833 | J9: =15/7 -> 2.1428571 | K9: =+I9-J9 -> -0.56187381
C10: TOTAL | D10: =SUM(D6:D9) -> 88592 | E10: =SUM(E6:E9) -> 385337.77 | F10: =SUM(F6:F9) -> 761661.43 | G10: =+E10-F10 -> -376323.66 | H10: =ABS(G10/F10) -> 0.4940826 | I10: =E10/D10 -> 4.3495775 | J10: =F10/D10 -> 8.5974064 | K10: =I10-J10 -> -4.2478289
B12: Nota:
B13: El saldo consolidado incluye los siguientes despachos
B14: Samantha, Samantha 2, Sofia, Edith, Fernando, Olguin y Federico
