Workbook

Sheet REPORTE DIARIO
B3: COBRANZA GENERAL SAMANTHA
B4: Segmento | C4: Cuentas | D4: Recuperación
B5: Extrajudicial - 0 a 28 semanas de atraso | C5: 4239 | D5: 314963.84
B6: Extrajudicial - 29 a 39 semanas de atraso | C6: 4539 | D6: 185596.69
B7: Extrajudicial - 40 a 55 semanas de atraso | C7: 6224 | D7: 161431.19
B8: JUDICIAL | C8: 10 | D8: 0
B9: Mas 55 semanas de atraso | C9: 13420 | D9: 254696.59
B10: Total general | C10: =SUM(C5:C9) -> 28432 | D10: =SUM(D5:D9) -> 916688.31
B12: COBRANZA GENERAL SAMANTHA 2
B13: Segmento | C13: Cuentas | D13: Recuperación
B14: Extrajudicial - 0 a 28 semanas de atraso | C14: 1981 | D14: 129618.66
B15: Extrajudicial - 29 a 39 semanas de atraso | C15: 1733 | D15: 162881.78
B16: Extrajudicial - 40 a 55 semanas de atraso | C16: 3081 | D16: 27349
B17: JUDICIAL | C17: 2 | D17: 0
B18: Mas 55 semanas de atraso | C18: 21622 | D18: 144577.57
B19: Total general | C19: =SUM(C14:C18) -> 28419 | D19: =SUM(D14:D18) -> 464427.01
B21: COBRANZA GENERAL EDITH
B22: Segmento | C22: Cuentas | D22: Recuperación
B23: Extrajudicial - 0 a 28 semanas de atraso | C23: 3867 | D23: 217157.72
B24: Extrajudicial - 29 a 39 semanas de atraso | C24: 2266 | D24: 96951.83
B25: Extrajudicial - 40 a 55 semanas de atraso | C25: 1841 | D25: 21771.69
B26: Mas 55 semanas de atraso | C26: 9600 | D26: 24167.04
B27: Total general | C27: =SUM(C23:C26) -> 17574 | D27: =SUM(D23:D26) -> 360048.28
B29: COBRANZA GENERAL SOFIA
B30: Segmento | C30: Cuentas | D30: Recuperación
B31: Extrajudicial - 0 a 28 semanas de atraso | C31: 322 | D31: 54014.27
B32: Extrajudicial - 29 a 39 semanas de atraso | C32: 1291 | D32: 43032.63
B33: Extrajudicial - 40 a 55 semanas de atraso | C33: 2374 | D33: 8616.15
B34: Mas 55 semanas de atraso | C34: 4259 | D34: 11675
B35: Total general | C35: =SUM(C31:C34) -> 8246 | D35: =SUM(D31:D34) -> 117338.05
B37: COBRANZA GENERAL FERNANDO
B38: Segmento | C38: Cuentas | D38: Recuperación
B39: Extrajudicial - 0 a 28 semanas de atraso | C39: 2048 | D39: 42808
B40: Total general | C40: =SUM(C39:C39) -> 2048 | D40: =SUM(D39:D39) -> 42808
B42: COBRANZA GENERAL FEDERICO
B43: Segmento | C43: Cuentas | D43: Recuperación
B44: Extrajudicial - 0 a 28 semanas de atraso | C44: 37 | D44: 2323
B45: Extrajudicial - 29 a 39 semanas de atraso | C45: 478 | D45: 2523
B46: Extrajudicial - 40 a 55 semanas de atraso | C46: 339 | D46: 600
B47: Mas 55 semanas de atraso | C47: 1987 | D47: 9320
...

Sheet DATA

Sheet EPR 02 MAYO
B2: REPORTE CONSOLIDADO POR SEGMENTOS
B3: SALDO ACUMULADO SEMANA 18
B5: COORDINADOR | C5: SEGMENTO | D5: CUENTAS | E5: COBRANZA REAL | F5: CUOTA IDEAL | G5: VARIACION | H5: % VAR | I5: EPR | J5: EPR IDEAL | K5: VAR EPR
B6: Samatha y Zareth | C6: Extrajudicial - 0 a 28 semanas de atraso | D6: =SUMIF('REPORTE DIARIO'!B:B,'EPR 02 MAYO'!C6, 'REPORTE DIARIO'!C:C) -> 12569 | E6: =SUMIF('REPORTE DIARIO'!B:B,'EPR 02 MAYO'!C6, 'REPORTE DIARIO'!D:D) -> 761695.49 | F6: =J6*D6 -> 1975128.6 | G6: =+E6-F6 -> -1213433.1 | H6: =ABS(G6/F6) -> 0.6143565 | I6: =E6/D6 -> 60.601121 | J6: =(220/7)*5 -> 157.14286 | K6: =+I6-J6 -> -96.541736
B7: Gabriel | C7: Extrajudicial - 29 a 39 semanas de atraso | D7: =SUMIF('REPORTE DIARIO'!B:B,'EPR 02 MAYO'!C7, 'REPORTE DIARIO'!C:C) -> 10609 | E7: =SUMIF('REPORTE DIARIO'!B:B,'EPR 02 MAYO'!C7, 'REPORTE DIARIO'!D:D) -> 492614.93 | F7: =J7*D7 -> 833564.29 | G7: =+E7-F7 -> -340949.36 | H7: =ABS(G7/F7) -> 0.40902587 | I7: =E7/D7 -> 46.433682 | J7: =(110/7)*5 -> 78.571429 | K7: =+I7-J7 -> -32.137747
B8: Gabriel | C8: Extrajudicial - 40 a 55 semanas de atraso | D8: =SUMIF('REPORTE DIARIO'!B:B,'EPR 02 MAYO'!C8, 'REPORTE DIARIO'!C:C) -> 14508 | E8: =SUMIF('REPORTE DIARIO'!B:B,'EPR 02 MAYO'!C8, 'REPORTE DIARIO'!D:D) -> 219768.03 | F8: =J8*D8 -> 466328.57 | G8: =+E8-F8 -> -246560.54 | H8: =ABS(G8/F8) -> 0.52872707 | I8: =E8/D8 -> 15.148058 | J8: =(45/7)*5 -> 32.142857 | K8: =+I8-J8 -> -16.994799
B9: Fernando | C9: Mas 55 semanas de atraso | D9: =SUMIF('REPORTE DIARIO'!B:B,'EPR 02 MAYO'!C9, 'REPORTE DIARIO'!C:C) -> 51768 | E9: =SUMIF('REPORTE DIARIO'!B:B,'EPR 02 MAYO'!C9, 'REPORTE DIARIO'!D:D) -> 446721.2 | F9: =J9*D9 -> 554657.14 | G9: =+E9-F9 -> -107935.94 | H9: =ABS(G9/F9) -> 0.19459939 | I9: =E9/D9 -> 8.6292922 | J9: =(15/7)*5 -> 10.714286 | K9: =+I9-J9 -> -2.0849935
C10: TOTAL | D10: =SUM(D6:D9) -> 89454 | E10: =SUM(E6:E9) -> 1920799.6 | F10: =SUM(F6:F9) -> 3829678.6 | G10: =+E10-F10 -> -1908878.9 | H10: =ABS(G10/F10) -> 0.49844364 | I10: =E10/D10 -> 21.472485 | J10: =F10/D10 -> 42.811708 | K10: =I10-J10 -> -21.339224
B12: Nota:
B13: El saldo consolidado incluye los siguientes despachos
B14: Samantha, Samantha 2, Sofia, Edith, Fernando, Olguin y Federico
