Workbook

Sheet REPORTE DIARIO
B3: COBRANZA GENERAL SAMANTHA
B4: Segmento | C4: Cuentas | D4: Recuperación
B5: Extrajudicial - 0 a 28 semanas de atraso | C5: 7291 | D5: 547137.55
B6: Extrajudicial - 29 a 39 semanas de atraso | C6: 8523 | D6: 291391.5
B7: Extrajudicial - 40 a 55 semanas de atraso | C7: 9755 | D7: 290808.31
B8: JUDICIAL | C8: 21 | D8: 0
B9: Mas 55 semanas de atraso | C9: 50531 | D9: 502077.86
B10: Total general | C10: =SUM(C5:C9) -> 76121 | D10: =SUM(D5:D9) -> 1631415.2
B12: COBRANZA GENERAL EDITH
B13: Segmento | C13: Cuentas | D13: Recuperación
B14: Extrajudicial - 0 a 28 semanas de atraso | C14: 2045 | D14: 193017.39
B15: Extrajudicial - 29 a 39 semanas de atraso | C15: 1739 | D15: 122318.39
B16: Extrajudicial - 40 a 55 semanas de atraso | C16: 266 | D16: 46539.05
B17: Mas 55 semanas de atraso | C17: 8252 | D17: 94933.01
B18: Total general | C18: =SUM(C14:C17) -> 12302 | D18: =SUM(D14:D17) -> 456807.84
B20: COBRANZA GENERAL OLGUIN
B21: Segmento | C21: Cuentas | D21: Recuperación
B22: Extrajudicial - 0 a 28 semanas de atraso | C22: 3606 | D22: 235698.12
B23: Extrajudicial - 29 a 39 semanas de atraso | C23: 1622 | D23: 25257.53
B24: Extrajudicial - 40 a 55 semanas de atraso | C24: 3188 | D24: 32047.99
B25: Mas 55 semanas de atraso | C25: 20984 | D25: 134870.76
B26: Total general | C26: =SUM(C22:C25) -> 29400 | D26: =SUM(D22:D25) -> 427874.4
B28: COBRANZA GENERAL SOFIA
B29: Segmento | C29: Cuentas | D29: Recuperación
B30: Extrajudicial - 0 a 28 semanas de atraso | C30: 1667 | D30: 144401.89
B31: Extrajudicial - 29 a 39 semanas de atraso | C31: 883 | D31: 90060.9
B32: Extrajudicial - 40 a 55 semanas de atraso | C32: 3198 | D32: 19198
B33: Mas 55 semanas de atraso | C33: 1892 | D33: 2595.38
B34: Total general | C34: =SUM(C30:C33) -> 7640 | D34: =SUM(D30:D33) -> 256256.17
B36: COBRANZA GENERAL FERNANDO
B37: Segmento | C37: Cuentas | D37: Recuperación
B38: Extrajudicial - 0 a 28 semanas de atraso | C38: 3054 | D38: 81955
B39: Total general | C39: =SUM(C38:C38) -> 3054 | D39: =SUM(D38:D38) -> 81955
B41: COBRANZA GENERAL SAMANTHA 2
B42: Segmento | C42: Cuentas | D42: Recuperación
B43: Extrajudicial - 0 a 28 semanas de atraso | C43: 1 | D43: 0
B44: Extrajudicial - 29 a 39 semanas de atraso | C44: 195 | D44: 0
B45: Extrajudicial - 40 a 55 semanas de atraso | C45: 127 | D45: 0
B46: JUDICIAL | C46: 2 | D46: 0
B47: Mas 55 semanas de atraso | C47: 151 | D47: 3973
...

Sheet DATA

Sheet EPR 22 MAR
B2: REPORTE CONSOLIDADO POR SEGMENTOS
B3: SALDO ACUMULADO SEMANA 12
B5: COORDINADOR | C5: SEGMENTO | D5: CUENTAS | E5: COBRANZA REAL | F5: CUOTA IDEAL | G5: VARIACION | H5: % VAR | I5: EPR | J5: EPR IDEAL | K5: VAR EPR
B6: Samatha y Zareth | C6: Extrajudicial - 0 a 28 semanas de atraso | D6: =SUMIF('REPORTE DIARIO'!B:B,'EPR 22 MAR'!C6, 'REPORTE DIARIO'!C:C) -> 17664 | E6: =SUMIF('REPORTE DIARIO'!B:B,'EPR 22 MAR'!C6, 'REPORTE DIARIO'!D:D) -> 1202209.9 | F6: =J6*D6 -> 3028114.3 | G6: =+E6-F6 -> -1825904.3 | H6: =ABS(G6/F6) -> 0.60298396 | I6: =E6/D6 -> 68.059893 | J6: =(200/7) *6 -> 171.42857 | K6: =+I6-J6 -> -103.36868
B7: Gabriel | C7: Extrajudicial - 29 a 39 semanas de atraso | D7: =SUMIF('REPORTE DIARIO'!B:B,'EPR 22 MAR'!C7, 'REPORTE DIARIO'!C:C) -> 13071 | E7: =SUMIF('REPORTE DIARIO'!B:B,'EPR 22 MAR'!C7, 'REPORTE DIARIO'!D:D) -> 531844.5 | F7: =J7*D7 -> 1232408.6 | G7: =+E7-F7 -> -700564.07 | H7: =ABS(G7/F7) -> 0.56845115 | I7: =E7/D7 -> 40.688891 | J7: =(110/7)*6 -> 94.285714 | K7: =+I7-J7 -> -53.596823
B8: Gabriel | C8: Extrajudicial - 40 a 55 semanas de atraso | D8: =SUMIF('REPORTE DIARIO'!B:B,'EPR 22 MAR'!C8, 'REPORTE DIARIO'!C:C) -> 16660 | E8: =SUMIF('REPORTE DIARIO'!B:B,'EPR 22 MAR'!C8, 'REPORTE DIARIO'!D:D) -> 388593.35 | F8: =J8*D8 -> 642600 | G8: =+E8-F8 -> -254006.65 | H8: =ABS(G8/F8) -> 0.39527957 | I8: =E8/D8 -> 23.324931 | J8: =(45/7)*6 -> 38.571429 | K8: =+I8-J8 -> -15.246498
B9: Fernando | C9: Mas 55 semanas de atraso | D9: =SUMIF('REPORTE DIARIO'!B:B,'EPR 22 MAR'!C9, 'REPORTE DIARIO'!C:C) -> 81959 | E9: =SUMIF('REPORTE DIARIO'!B:B,'EPR 22 MAR'!C9, 'REPORTE DIARIO'!D:D) -> 738450.01 | F9: =J9*D9 -> 1053758.6 | G9: =+E9-F9 -> -315308.56 | H9: =ABS(G9/F9) -> 0.29922277 | I9: =E9/D9 -> 9.0099929 | J9: =(15/7)*6 -> 12.857143 | K9: =+I9-J9 -> -3.8471499
C10: TOTAL | D10: =SUM(D6:D9) -> 129354 | E10: =SUM(E6:E9) -> 2861097.8 | F10: =SUM(F6:F9) -> 5956881.4 | G10: =+E10-F10 -> -3095783.6 | H10: =ABS(G10/F10) -> 0.51969871 | I10: =E10/D10 -> 22.118356 | J10: =F10/D10 -> 46.051003 | K10: =I10-J10 -> -23.932647
B12: Nota:
B13: El saldo consolidado incluye los siguientes despachos
B14: Samantha, Samantha 2, Sofia, Edith, Olguin, Fernando y Federico
