Workbook

Sheet REPORTE DIARIO
B3: COBRANZA GENERAL SAMANTHA
B4: Segmento | C4: Cuentas | D4: Recuperación
B5: Extrajudicial - 0 a 28 semanas de atraso | C5: 3083 | D5: 308029.4
B6: Extrajudicial - 29 a 39 semanas de atraso | C6: 3488 | D6: 139060.96
B7: Extrajudicial - 40 a 55 semanas de atraso | C7: 6304 | D7: 154586.46
B8: JUDICIAL | C8: 11 | D8: 0
B9: Mas 55 semanas de atraso | C9: 12593 | D9: 203088
B10: Total general | C10: =SUM(C5:C9) -> 25479 | D10: =SUM(D5:D9) -> 804764.82
B12: COBRANZA GENERAL EDITH
B13: Segmento | C13: Cuentas | D13: Recuperación
B14: Extrajudicial - 0 a 28 semanas de atraso | C14: 3402 | D14: 183593.48
B15: Extrajudicial - 29 a 39 semanas de atraso | C15: 1370 | D15: 18477.5
B16: Extrajudicial - 40 a 55 semanas de atraso | C16: 2069 | D16: 104733.8
B17: JUDICIAL | C17: 1 | D17: 39
B18: Mas 55 semanas de atraso | C18: 16858 | D18: 41023
B19: Total general | C19: =SUM(C14:C18) -> 23700 | D19: =SUM(D14:D18) -> 347866.78
B21: COBRANZA GENERAL SAMANTHA 2
B22: Segmento | C22: Cuentas | D22: Recuperación
B23: Extrajudicial - 0 a 28 semanas de atraso | C23: 2877 | D23: 77196
B24: Extrajudicial - 29 a 39 semanas de atraso | C24: 1957 | D24: 40592.32
B25: Extrajudicial - 40 a 55 semanas de atraso | C25: 2564 | D25: 43515
B26: JUDICIAL | C26: 0 | D26: 0
B27: Mas 55 semanas de atraso | C27: 12596 | D27: 71759.89
B28: Total general | C28: =SUM(C23:C27) -> 19994 | D28: =SUM(D23:D27) -> 233063.21
B30: COBRANZA GENERAL SOFIA
B31: Segmento | C31: Cuentas | D31: Recuperación
B32: Extrajudicial - 0 a 28 semanas de atraso | C32: 437 | D32: 76078.32
B33: Extrajudicial - 29 a 39 semanas de atraso | C33: 2867 | D33: 39740.5
B34: Extrajudicial - 40 a 55 semanas de atraso | C34: 317 | D34: 1805
B35: Mas 55 semanas de atraso | C35: 3972 | D35: 7800
B36: Total general | C36: =SUM(C32:C35) -> 7593 | D36: =SUM(D32:D35) -> 125423.82
B38: COBRANZA GENERAL OLGUIN
B39: Segmento | C39: Cuentas | D39: Recuperación
B40: Extrajudicial - 0 a 28 semanas de atraso | C40: 2276 | D40: 61149
B41: Extrajudicial - 29 a 39 semanas de atraso | C41: 1423 | D41: 15148
B42: Extrajudicial - 40 a 55 semanas de atraso | C42: 2039 | D42: 9820
B43: Mas 55 semanas de atraso | C43: 1825 | D43: 8650
B44: Total general | C44: =SUM(C40:C43) -> 7563 | D44: =SUM(D40:D43) -> 94767
B46: COBRANZA GENERAL FERNANDO
B47: Segmento | C47: Cuentas | D47: Recuperación
...

Sheet DATA

Sheet EPR 12 JUN
B2: REPORTE CONSOLIDADO POR SEGMENTOS
B3: SALDO ACUMULADO SEMANA 24
B5: COORDINADOR | C5: SEGMENTO | D5: CUENTAS | E5: COBRANZA REAL | F5: CUOTA IDEAL | G5: VARIACION | H5: % VAR | I5: EPR | J5: EPR IDEAL | K5: VAR EPR
B6: Zareth | C6: Extrajudicial - 0 a 28 semanas de atraso | D6: =SUMIF('REPORTE DIARIO'!B:B,'EPR 12 JUN'!C6, 'REPORTE DIARIO'!C:C) -> 15385 | E6: =SUMIF('REPORTE DIARIO'!B:B,'EPR 12 JUN'!C6, 'REPORTE DIARIO'!D:D) -> 769191.64 | F6: =J6*D6 -> 1934114.3 | G6: =+E6-F6 -> -1164922.6 | H6: =ABS(G6/F6) -> 0.6023029 | I6: =E6/D6 -> 49.996207 | J6: =(220/7)*4 -> 125.71429 | K6: =+I6-J6 -> -75.718079
B7: Gabriel | C7: Extrajudicial - 29 a 39 semanas de atraso | D7: =SUMIF('REPORTE DIARIO'!B:B,'EPR 12 JUN'!C7, 'REPORTE DIARIO'!C:C) -> 11712 | E7: =SUMIF('REPORTE DIARIO'!B:B,'EPR 12 JUN'!C7, 'REPORTE DIARIO'!D:D) -> 258972.28 | F7: =J7*D7 -> 736182.86 | G7: =+E7-F7 -> -477210.58 | H7: =ABS(G7/F7) -> 0.64822289 | I7: =E7/D7 -> 22.111704 | J7: =(110/7)*4 -> 62.857143 | K7: =+I7-J7 -> -40.745439
B8: Gabriel | C8: Extrajudicial - 40 a 55 semanas de atraso | D8: =SUMIF('REPORTE DIARIO'!B:B,'EPR 12 JUN'!C8, 'REPORTE DIARIO'!C:C) -> 14097 | E8: =SUMIF('REPORTE DIARIO'!B:B,'EPR 12 JUN'!C8, 'REPORTE DIARIO'!D:D) -> 314601.26 | F8: =J8*D8 -> 362494.29 | G8: =+E8-F8 -> -47893.026 | H8: =ABS(G8/F8) -> 0.13212077 | I8: =E8/D8 -> 22.316894 | J8: =(45/7)*4 -> 25.714286 | K8: =+I8-J8 -> -3.3973913
B9: Fernando (Naucalpan) | C9: Mas 55 semanas de atraso | D9: =SUMIF('REPORTE DIARIO'!B:B,'EPR 12 JUN'!C9, 'REPORTE DIARIO'!C:C) -> 50271 | E9: =SUMIF('REPORTE DIARIO'!B:B,'EPR 12 JUN'!C9, 'REPORTE DIARIO'!D:D) -> 335857.89 | F9: =J9*D9 -> 430894.29 | G9: =+E9-F9 -> -95036.396 | H9: =ABS(G9/F9) -> 0.22055618 | I9: =E9/D9 -> 6.6809471 | J9: =(15/7)*4 -> 8.5714286 | K9: =+I9-J9 -> -1.8904815
C10: TOTAL | D10: =SUM(D6:D9) -> 91465 | E10: =SUM(E6:E9) -> 1678623.1 | F10: =SUM(F6:F9) -> 3463685.7 | G10: =+E10-F10 -> -1785062.6 | H10: =ABS(G10/F10) -> 0.51536507 | I10: =E10/D10 -> 18.352627 | J10: =F10/D10 -> 37.868974 | K10: =I10-J10 -> -19.516347
B12: Nota:
B13: El saldo consolidado incluye los siguientes despachos
B14: Samantha, Samantha 2, Sofia, Edith, Fernando, Olguin y Federico
