Workbook

Sheet REPORTE DIARIO
B3: COBRANZA GENERAL SAMANTHA
B4: Segmento | C4: Cuentas | D4: Recuperación
B5: Extrajudicial - 0 a 28 semanas de atraso | C5: 4211 | D5: 244778.23
B6: Extrajudicial - 29 a 39 semanas de atraso | C6: 4322 | D6: 116354.03
B7: Extrajudicial - 40 a 55 semanas de atraso | C7: 6109 | D7: 165362.6
B8: JUDICIAL | C8: 12 | D8: 803.56
B9: Mas 55 semanas de atraso | C9: 13177 | D9: 152094.39
B10: Total general | C10: =SUM(C5:C9) -> 27831 | D10: =SUM(D5:D9) -> 679392.81
B12: COBRANZA GENERAL SOFIA
B13: Segmento | C13: Cuentas | D13: Recuperación
B14: Extrajudicial - 0 a 28 semanas de atraso | C14: 247 | D14: 31986.83
B15: Extrajudicial - 29 a 39 semanas de atraso | C15: 2813 | D15: 156319.59
B16: Extrajudicial - 40 a 55 semanas de atraso | C16: 1864 | D16: 18956
B17: Mas 55 semanas de atraso | C17: 4230 | D17: 530
B18: Total general | C18: =SUM(C14:C17) -> 9154 | D18: =SUM(D14:D17) -> 207792.42
B20: COBRANZA GENERAL EDITH
B21: Segmento | C21: Cuentas | D21: Recuperación
B22: Extrajudicial - 0 a 28 semanas de atraso | C22: 3343 | D22: 106146.47
B23: Extrajudicial - 29 a 39 semanas de atraso | C23: 1733 | D23: 45431.43
B24: Extrajudicial - 40 a 55 semanas de atraso | C24: 2267 | D24: 24901.45
B25: JUDICIAL | C25: 1 | D25: 0
B26: Mas 55 semanas de atraso | C26: 17376 | D26: 26455
B27: Total general | C27: =SUM(C22:C26) -> 24720 | D27: =SUM(D22:D26) -> 202934.35
B29: COBRANZA GENERAL SAMANTHA 2
B30: Segmento | C30: Cuentas | D30: Recuperación
B31: Extrajudicial - 0 a 28 semanas de atraso | C31: 1998 | D31: 64326.92
B32: Extrajudicial - 29 a 39 semanas de atraso | C32: 1926 | D32: 37442
B33: Extrajudicial - 40 a 55 semanas de atraso | C33: 3214 | D33: 26328
B34: JUDICIAL | C34: 2 | D34: 0
B35: Mas 55 semanas de atraso | C35: 20623 | D35: 74357.81
B36: Total general | C36: =SUM(C31:C35) -> 27763 | D36: =SUM(D31:D35) -> 202454.73
B38: COBRANZA GENERAL OLGUIN
B39: Segmento | C39: Cuentas | D39: Recuperación
B40: Extrajudicial - 0 a 28 semanas de atraso | C40: 342 | D40: 648
B41: Extrajudicial - 29 a 39 semanas de atraso | C41: 546 | D41: 2700
B42: Extrajudicial - 40 a 55 semanas de atraso | C42: 935 | D42: 49629
B43: Mas 55 semanas de atraso | C43: 1153 | D43: 2077
B44: Total general | C44: =SUM(C40:C43) -> 2976 | D44: =SUM(D40:D43) -> 55054
B46: COBRANZA GENERAL FERNANDO
B47: Segmento | C47: Cuentas | D47: Recuperación
...

Sheet DATA

Sheet EPR 15 MAYO
B2: REPORTE CONSOLIDADO POR SEGMENTOS
B3: SALDO ACUMULADO SEMANA 20
B5: COORDINADOR | C5: SEGMENTO | D5: CUENTAS | E5: COBRANZA REAL | F5: CUOTA IDEAL | G5: VARIACION | H5: % VAR | I5: EPR | J5: EPR IDEAL | K5: VAR EPR
B6: Zareth | C6: Extrajudicial - 0 a 28 semanas de atraso | D6: =SUMIF('REPORTE DIARIO'!B:B,'EPR 15 MAYO'!C6, 'REPORTE DIARIO'!C:C) -> 12447 | E6: =SUMIF('REPORTE DIARIO'!B:B,'EPR 15 MAYO'!C6, 'REPORTE DIARIO'!D:D) -> 470357.45 | F6: =J6*D6 -> 1564765.7 | G6: =+E6-F6 -> -1094408.3 | H6: =ABS(G6/F6) -> 0.69940711 | I6: =E6/D6 -> 37.788821 | J6: =(220/7)*4 -> 125.71429 | K6: =+I6-J6 -> -87.925465
B7: Gabriel | C7: Extrajudicial - 29 a 39 semanas de atraso | D7: =SUMIF('REPORTE DIARIO'!B:B,'EPR 15 MAYO'!C7, 'REPORTE DIARIO'!C:C) -> 12056 | E7: =SUMIF('REPORTE DIARIO'!B:B,'EPR 15 MAYO'!C7, 'REPORTE DIARIO'!D:D) -> 362270.05 | F7: =J7*D7 -> 757805.71 | G7: =+E7-F7 -> -395535.66 | H7: =ABS(G7/F7) -> 0.52194864 | I7: =E7/D7 -> 30.048942 | J7: =(110/7)*4 -> 62.857143 | K7: =+I7-J7 -> -32.8082
B8: Gabriel | C8: Extrajudicial - 40 a 55 semanas de atraso | D8: =SUMIF('REPORTE DIARIO'!B:B,'EPR 15 MAYO'!C8, 'REPORTE DIARIO'!C:C) -> 15008 | E8: =SUMIF('REPORTE DIARIO'!B:B,'EPR 15 MAYO'!C8, 'REPORTE DIARIO'!D:D) -> 285677.05 | F8: =J8*D8 -> 385920 | G8: =+E8-F8 -> -100242.95 | H8: =ABS(G8/F8) -> 0.2597506 | I8: =E8/D8 -> 19.034985 | J8: =(45/7)*4 -> 25.714286 | K8: =+I8-J8 -> -6.679301
B9: Fernando (Naucalpan) | C9: Mas 55 semanas de atraso | D9: =SUMIF('REPORTE DIARIO'!B:B,'EPR 15 MAYO'!C9, 'REPORTE DIARIO'!C:C) -> 58829 | E9: =SUMIF('REPORTE DIARIO'!B:B,'EPR 15 MAYO'!C9, 'REPORTE DIARIO'!D:D) -> 258069.2 | F9: =J9*D9 -> 504248.57 | G9: =+E9-F9 -> -246179.37 | H9: =ABS(G9/F9) -> 0.48821035 | I9: =E9/D9 -> 4.3867684 | J9: =(15/7)*4 -> 8.5714286 | K9: =+I9-J9 -> -4.1846601
C10: TOTAL | D10: =SUM(D6:D9) -> 98340 | E10: =SUM(E6:E9) -> 1376373.8 | F10: =SUM(F6:F9) -> 3212740 | G10: =+E10-F10 -> -1836366.2 | H10: =ABS(G10/F10) -> 0.57158882 | I10: =E10/D10 -> 13.996072 | J10: =F10/D10 -> 32.669717 | K10: =I10-J10 -> -18.673645
B12: Nota:
B13: El saldo consolidado incluye los siguientes despachos
B14: Samantha, Samantha 2, Sofia, Edith, Fernando, Olguin y Federico
